Workbook

Sheet AlexVargas
A1: EventType | B1: SegmentID | C1: ElementID | D1: TimeOnPlatform | E1: RelativePositionStd | F1: RelativePositionMean | G1: RelativePositionMax | H1: RelativePositionMin | I1: SampleCount | J1: EdgeRiskTime | K1: CorrectionPeaks | L1: RawCorrectionsCount
A2: Platform | B2: 0 | C2: 0 | D2: 0.48 | E2: 0.4833 | F2: 1.3131 | G2: 2.6215 | H2: 0.9004 | I2: 19 | J2: 0.14 | K2: 0 | L2: 2
A3: Platform | B3: 0 | C3: 0 | D3: 0.3 | E3: 0.3674 | F3: 5.0387 | G3: 5.5911 | H3: 4.4498 | I3: 13 | J3: 0 | K3: 0 | L3: 1
A4: Platform | B4: 0 | C4: 0 | D4: 2.16 | E4: 0.2272 | F4: 4.3477 | G4: 4.6545 | H4: 4.0937 | I4: 91 | J4: 0.84 | K4: 0 | L4: 5
A5: Platform | B5: 1 | C5: 0 | D5: 0.25 | E5: 0.5778 | F5: 6.2408 | G5: 7.2342 | H5: 5.4052 | I5: 10 | J5: 0.13 | K5: 0 | L5: 0
A6: Platform | B6: 1 | C6: 0 | D6: 0.09 | E6: 0.2191 | F6: 8.8108 | G6: 9.0548 | H6: 8.4905 | I6: 4 | J6: 0 | K6: 0 | L6: 1
A7: Platform | B7: 1 | C7: 0 | D7: 1.44 | E7: 1.3715 | F7: 5.6702 | G7: 7.9216 | H7: 2.855 | I7: 61 | J7: 1 | K7: 0 | L7: 4
A8: DEATH
A9: Platform | B9: 2 | C9: 0 | D9: 0.04 | E9: 0 | F9: 5.5717 | G9: 5.5717 | H9: 5.5717 | I9: 1 | J9: 0 | K9: 0 | L9: 0
A10: Platform | B10: 2 | C10: 0 | D10: 2.18 | E10: 0.4496 | F10: 7.7784 | G10: 9.0118 | H10: 6.5942 | I10: 48 | J10: 0.33 | K10: 1 | L10: 15
A11: DEATH
A12: Platform | B12: 2 | C12: 0 | D12: 0.05 | E12: 0 | F12: 4.6627 | G12: 4.6627 | H12: 4.6627 | I12: 1 | J12: 0 | K12: 0 | L12: 0
A13: Platform | B13: 2 | C13: 0 | D13: 1.09 | E13: 0.5471 | F13: 5.73 | G13: 6.4341 | H13: 4.9928 | I13: 25 | J13: 0.11 | K13: 0 | L13: 3
A14: Platform | B14: 2 | C14: 0 | D14: 0.12 | E14: 0.0843 | F14: 5.4134 | G14: 5.5172 | H14: 5.3107 | I14: 3 | J14: 0 | K14: 0 | L14: 0
A15: Platform | B15: 2 | C15: 0 | D15: 0.13 | E15: 0.0644 | F15: 3.8754 | G15: 3.9542 | H15: 3.7966 | I15: 3 | J15: 0 | K15: 0 | L15: 1
A16: Platform | B16: 2 | C16: 0 | D16: 0.04 | E16: 0 | F16: 1.8892 | G16: 1.8892 | H16: 1.8892 | I16: 1 | J16: 0 | K16: 0 | L16: 0
A17: Platform | B17: 2 | C17: 0 | D17: 0.04 | E17: 0 | F17: 6.7948 | G17: 6.7948 | H17: 6.7948 | I17: 1 | J17: 0 | K17: 0 | L17: 0
A18: Platform | B18: 2 | C18: 0 | D18: 0.04 | E18: 0 | F18: 6.9962 | G18: 6.9962 | H18: 6.9962 | I18: 1 | J18: 0 | K18: 0 | L18: 0
A19: Platform | B19: 2 | C19: 0 | D19: 0.6 | E19: 0.6086 | F19: 3.7459 | G19: 4.4968 | H19: 2.8205 | I19: 15 | J19: 0 | K19: 0 | L19: 1
A20: DEATH
A21: Platform | B21: 2 | C21: 0 | D21: 0.03 | E21: 0 | F21: 9.0429 | G21: 9.0429 | H21: 9.0429 | I21: 1 | J21: 0 | K21: 0 | L21: 0
A22: DEATH
A23: Platform | B23: 2 | C23: 0 | D23: 0.05 | E23: 0 | F23: 7.9787 | G23: 7.9787 | H23: 7.9787 | I23: 1 | J23: 0 | K23: 0 | L23: 0
A24: Platform | B24: 2 | C24: 0 | D24: 1.9 | E24: 0.3217 | F24: 8.7158 | G24: 9.3291 | H24: 8.3394 | I24: 41 | J24: 0.83 | K24: 0 | L24: 3
A25: Platform | B25: 2 | C25: 0 | D25: 0.19 | E25: 0.1584 | F25: 7.4136 | G25: 7.6408 | H25: 7.2088 | I25: 4 | J25: 0 | K25: 0 | L25: 1
A26: Platform | B26: 2 | C26: 0 | D26: 0.04 | E26: 0 | F26: 7.6499 | G26: 7.6499 | H26: 7.6499 | I26: 1 | J26: 0 | K26: 0 | L26: 0
A27: DEATH
A28: Platform | B28: 2 | C28: 0 | D28: 0.04 | E28: 0 | F28: 4.6744 | G28: 4.6744 | H28: 4.6744 | I28: 1 | J28: 0 | K28: 0 | L28: 0
A29: Platform | B29: 2 | C29: 0 | D29: 1.78 | E29: 0.4187 | F29: 5.7569 | G29: 6.6164 | H29: 5.1611 | I29: 40 | J29: 0.25 | K29: 1 | L29: 4
A30: Platform | B30: 2 | C30: 0 | D30: 0.14 | E30: 0.0878 | F30: 6.3702 | G30: 6.4934 | H30: 6.2952 | I30: 3 | J30: 0 | K30: 0 | L30: 0
A31: Platform | B31: 2 | C31: 0 | D31: 0.04 | E31: 0 | F31: 7.8444 | G31: 7.8444 | H31: 7.8444 | I31: 1 | J31: 0 | K31: 0 | L31: 0
A32: DEATH
A33: Platform | B33: 2 | C33: 0 | D33: 1.88 | E33: 0.7345 | F33: 6.441 | G33: 7.3637 | H33: 5.2701 | I33: 39 | J33: 0.57 | K33: 2 | L33: 7
A34: Platform | B34: 2 | C34: 0 | D34: 0.14 | E34: 0.0476 | F34: 6.9386 | G34: 7.0052 | H34: 6.8964 | I34: 3 | J34: 0 | K34: 0 | L34: 0
A35: DEATH
A36: Platform | B36: 2 | C36: 0 | D36: 1.92 | E36: 1.0863 | F36: 7.3523 | G36: 8.5937 | H36: 4.1396 | I36: 48 | J36: 0.49 | K36: 2 | L36: 1
A37: DEATH
A38: Platform | B38: 2 | C38: 0 | D38: 0.05 | E38: 0 | F38: 5.2089 | G38: 5.2089 | H38: 5.2089 | I38: 1 | J38: 0 | K38: 0 | L38: 0
A39: Platform | B39: 2 | C39: 0 | D39: 2.04 | E39: 0.6773 | F39: 6.6367 | G39: 7.4107 | H39: 4.7779 | I39: 45 | J39: 0.44 | K39: 2 | L39: 5
A40: Platform | B40: 2 | C40: 0 | D40: 0.14 | E40: 0.0539 | F40: 6.2101 | G40: 6.2771 | H40: 6.145 | I40: 3 | J40: 0 | K40: 0 | L40: 0
...

Sheet AntoFlores
A1: EventType | B1: SegmentID | C1: ElementID | D1: TimeOnPlatform | E1: RelativePositionStd | F1: RelativePositionMean | G1: RelativePositionMax | H1: RelativePositionMin | I1: SampleCount | J1: EdgeRiskTime | K1: CorrectionPeaks | L1: RawCorrectionsCount
A2: Platform | B2: 0 | C2: 0 | D2: 1.27 | E2: 0.0548 | F2: 2.7317 | G2: 3.0521 | H2: 2.7141 | I2: 73 | J2: 0 | K2: 0 | L2: 1
A3: Platform | B3: 0 | C3: 0 | D3: 4.77 | E3: 0.0941 | F3: 2.8207 | G3: 3.0465 | H3: 2.714 | I3: 278 | J3: 2.42 | K3: 0 | L3: 0
A4: Platform | B4: 1 | C4: 0 | D4: 0.07 | E4: 0.1208 | F4: 5.2305 | G4: 5.3943 | H4: 5.0793 | I4: 4 | J4: 0 | K4: 0 | L4: 0
A5: Platform | B5: 1 | C5: 0 | D5: 0.02 | E5: 0 | F5: 8.3845 | G5: 8.3845 | H5: 8.3845 | I5: 1 | J5: 0 | K5: 0 | L5: 0
A6: DEATH
A7: Platform | B7: 0 | C7: 0 | D7: 2.04 | E7: 0.4936 | F7: 2.315 | G7: 4.6237 | H7: 2.1326 | I7: 118 | J7: 0 | K7: 0 | L7: 1
A8: Platform | B8: 0 | C8: 0 | D8: 3.67 | E8: 0.1656 | F8: 2.2167 | G8: 2.3466 | H8: 1.2337 | I8: 214 | J8: 1.54 | K8: 0 | L8: 1
A9: Platform | B9: 1 | C9: 0 | D9: 0.86 | E9: 0.8015 | F9: 5.6032 | G9: 6.67 | H9: 4.8475 | I9: 51 | J9: 0.48 | K9: 0 | L9: 2
A10: Platform | B10: 1 | C10: 0 | D10: 5.77 | E10: 0.4406 | F10: 6.1534 | G10: 6.6768 | H10: 5.0156 | I10: 338 | J10: 0.21 | K10: 0 | L10: 2
A11: Platform | B11: 2 | C11: 0 | D11: 2.24 | E11: 1.291 | F11: 7.4492 | G11: 8.2652 | H11: 4.2503 | I11: 80 | J11: 0.62 | K11: 0 | L11: 2
A12: Platform | B12: 2 | C12: 0 | D12: 1.46 | E12: 0.3723 | F12: 7.77 | G12: 8.2436 | H12: 7.4023 | I12: 50 | J12: 0.06 | K12: 0 | L12: 1
A13: DEATH
A14: Platform | B14: 2 | C14: 0 | D14: 0.04 | E14: 0 | F14: 6.5562 | G14: 6.5562 | H14: 6.5562 | I14: 1 | J14: 0 | K14: 0 | L14: 0
A15: Platform | B15: 2 | C15: 0 | D15: 2.06 | E15: 0.7053 | F15: 7.2692 | G15: 8.4552 | H15: 5.974 | I15: 64 | J15: 0.9 | K15: 0 | L15: 3
A16: Platform | B16: 2 | C16: 0 | D16: 1.31 | E16: 0.5142 | F16: 6.7781 | G16: 7.4371 | H16: 5.9629 | I16: 42 | J16: 0.56 | K16: 0 | L16: 1
A17: Platform | B17: 2 | C17: 0 | D17: 0.46 | E17: 0.2387 | F17: 6.2689 | G17: 6.616 | H17: 5.9638 | I17: 15 | J17: 0.03 | K17: 0 | L17: 2
A18: Platform | B18: 2 | C18: 0 | D18: 0.21 | E18: 0.6056 | F18: 7.7397 | G18: 8.6693 | H18: 6.8437 | I18: 7 | J18: 0.06 | K18: 0 | L18: 0
A19: DEATH
A20: Platform | B20: 2 | C20: 0 | D20: 0.06 | E20: 0.2783 | F20: 3.2473 | G20: 3.5255 | H20: 2.969 | I20: 2 | J20: 0 | K20: 1 | L20: 0
A21: Platform | B21: 2 | C21: 0 | D21: 1.79 | E21: 2.5967 | F21: 4.502 | G21: 8.0813 | H21: 0.8396 | I21: 60 | J21: 0.77 | K21: 0 | L21: 3
A22: Platform | B22: 2 | C22: 0 | D22: 0.62 | E22: 0.219 | F22: 6.8592 | G22: 6.9655 | H22: 6.2534 | I22: 21 | J22: 0.03 | K22: 0 | L22: 0
A23: Platform | B23: 2 | C23: 0 | D23: 0.04 | E23: 0.0181 | F23: 0.9245 | G23: 0.9426 | H23: 0.9063 | I23: 2 | J23: 0 | K23: 0 | L23: 0
A24: Platform | B24: 2 | C24: 0 | D24: 4.16 | E24: 0.0079 | F24: 1.2461 | G24: 1.2853 | H24: 1.2353 | I24: 196 | J24: 0.39 | K24: 0 | L24: 0

Sheet BenjaCarrasco
A1: EventType | B1: SegmentID | C1: ElementID | D1: TimeOnPlatform | E1: RelativePositionStd | F1: RelativePositionMean | G1: RelativePositionMax | H1: RelativePositionMin | I1: SampleCount | J1: EdgeRiskTime | K1: CorrectionPeaks | L1: RawCorrectionsCount
A2: Platform | B2: 0 | C2: 0 | D2: 2.46 | E2: 0.4971 | F2: 0.997 | G2: 2.1802 | H2: 0.1117 | I2: 145 | J2: 0.32 | K2: 0 | L2: 3
A3: Platform | B3: 0 | C3: 0 | D3: 2.06 | E3: 0.9381 | F3: 2.1072 | G3: 4.5219 | H3: 1.3291 | I3: 117 | J3: 0 | K3: 0 | L3: 2
A4: Platform | B4: 1 | C4: 0 | D4: 0.77 | E4: 0.2684 | F4: 6.5829 | G4: 7.3126 | H4: 6.2809 | I4: 46 | J4: 0.3 | K4: 0 | L4: 0
A5: Platform | B5: 1 | C5: 0 | D5: 5.68 | E5: 0.5808 | F5: 6.9807 | G5: 10.6006 | H5: 6.598 | I5: 339 | J5: 0.46 | K5: 0 | L5: 2
A6: Platform | B6: 2 | C6: 0 | D6: 0.04 | E6: 0 | F6: 7.3174 | G6: 7.3174 | H6: 7.3174 | I6: 1 | J6: 0 | K6: 0 | L6: 0
A7: Platform | B7: 2 | C7: 0 | D7: 0.98 | E7: 0.6302 | F7: 7.622 | G7: 8.377 | H7: 6.8296 | I7: 30 | J7: 0.55 | K7: 0 | L7: 2
A8: Platform | B8: 2 | C8: 0 | D8: 2.3 | E8: 0.2542 | F8: 8.6827 | G8: 9.0193 | H8: 8.2275 | I8: 70 | J8: 0.53 | K8: 0 | L8: 1
A9: DEATH
A10: Platform | B10: 2 | C10: 0 | D10: 0.03 | E10: 0 | F10: 8.5389 | G10: 8.5389 | H10: 8.5389 | I10: 1 | J10: 0 | K10: 0 | L10: 0
A11: Platform | B11: 2 | C11: 0 | D11: 0.68 | E11: 0.3718 | F11: 6.8617 | G11: 7.8408 | H11: 6.3581 | I11: 21 | J11: 0 | K11: 0 | L11: 2
A12: Platform | B12: 2 | C12: 0 | D12: 2.45 | E12: 0.4694 | F12: 8.266 | G12: 8.768 | H12: 6.9206 | I12: 75 | J12: 0.71 | K12: 0 | L12: 3
A13: Platform | B13: 2 | C13: 0 | D13: 0.04 | E13: 0 | F13: 8.1028 | G13: 8.1028 | H13: 8.1028 | I13: 1 | J13: 0 | K13: 0 | L13: 0
A14: Platform | B14: 2 | C14: 0 | D14: 0.22 | E14: 0.0295 | F14: 7.0494 | G14: 7.0785 | H14: 6.9884 | I14: 7 | J14: 0 | K14: 0 | L14: 0
A15: Platform | B15: 2 | C15: 0 | D15: 1.9 | E15: 0.3685 | F15: 6.2652 | G15: 7.0944 | H15: 5.9051 | I15: 60 | J15: 0 | K15: 0 | L15: 1
A16: Platform | B16: 2 | C16: 0 | D16: 2.36 | E16: 0.3674 | F16: 5.0317 | G16: 5.9264 | H16: 4.6339 | I16: 79 | J16: 0.03 | K16: 0 | L16: 1

Sheet CamilaCarrascoBaier
A1: EventType | B1: SegmentID | C1: ElementID | D1: TimeOnPlatform | E1: RelativePositionStd | F1: RelativePositionMean | G1: RelativePositionMax | H1: RelativePositionMin | I1: SampleCount | J1: EdgeRiskTime | K1: CorrectionPeaks | L1: RawCorrectionsCount
A2: Platform | B2: 0 | C2: 0 | D2: 4.67 | E2: 0.1539 | F2: 2.1015 | G2: 2.549 | H2: 1.745 | I2: 189 | J2: 0.45 | K2: 0 | L2: 26
A3: Platform | B3: 0 | C3: 0 | D3: 0.22 | E3: 0.1349 | F3: 1.4888 | G3: 1.7274 | H3: 1.3213 | I3: 9 | J3: 0 | K3: 0 | L3: 2
A4: Platform | B4: 1 | C4: 0 | D4: 1.07 | E4: 0.0262 | F4: 5.5297 | G4: 5.5691 | H4: 5.4263 | I4: 43 | J4: 0.18 | K4: 0 | L4: 2
A5: Platform | B5: 1 | C5: 0 | D5: 1.59 | E5: 0.0245 | F5: 8.4963 | G5: 8.538 | H5: 8.3651 | I5: 64 | J5: 0.15 | K5: 0 | L5: 4
A6: Platform | B6: 2 | C6: 0 | D6: 3.93 | E6: 0.6545 | F6: 9.7955 | G6: 10.5395 | H6: 8.5876 | I6: 95 | J6: 1.89 | K6: 1 | L6: 19
A7: DEATH | B7: 0 | C7: 0 | D7: 0 | E7: 0 | F7: 0 | G7: 0 | H7: 0 | I7: 0 | J7: 0 | K7: 0 | L7: 0
A8: Platform | B8: 2 | C8: 0 | D8: 3.79 | E8: 0.4109 | F8: 8.4703 | G8: 9.9613 | H8: 7.3193 | I8: 90 | J8: 0 | K8: 1 | L8: 21
A9: DEATH | B9: 0 | C9: 0 | D9: 0 | E9: 0 | F9: 0 | G9: 0 | H9: 0 | I9: 0 | J9: 0 | K9: 0 | L9: 0
A10: Platform | B10: 2 | C10: 0 | D10: 3.65 | E10: 0.753 | F10: 7.0626 | G10: 7.5381 | H10: 3.836 | I10: 86 | J10: 0.68 | K10: 1 | L10: 15
A11: DEATH | B11: 0 | C11: 0 | D11: 0 | E11: 0 | F11: 0 | G11: 0 | H11: 0 | I11: 0 | J11: 0 | K11: 0 | L11: 0
A12: Platform | B12: 2 | C12: 0 | D12: 3.34 | E12: 0.7336 | F12: 6.7466 | G12: 7.9979 | H12: 5.8889 | I12: 78 | J12: 1.48 | K12: 2 | L12: 16
A13: Platform | B13: 2 | C13: 0 | D13: 2.08 | E13: 0.0955 | F13: 7.5558 | G13: 7.736 | H13: 7.4109 | I13: 49 | J13: 0.52 | K13: 0 | L13: 13
... A18: Platform | B18: 2 | C18: 0 | D18: 4.7 | E18: 0.0268 | F18: 3.8385 | G18: 3.9142 | H18: 3.7889 | I18: 115 | J18: 0.75 | K18: 0 | L18: 15

Sheet CataAguilar
A1: EventType | B1: SegmentID | C1: ElementID | D1: TimeOnPlatform | E1: RelativePositionStd | F1: RelativePositionMean | G1: RelativePositionMax | H1: RelativePositionMin | I1: SampleCount | J1: EdgeRiskTime | K1: CorrectionPeaks | L1: RawCorrectionsCount
A2: Platform | B2: 0 | C2: 0 | D2: 0.52 | E2: 0.0068 | F2: 5.3302 | G2: 5.3531 | H2: 5.3197 | I2: 20 | J2: 0 | K2: 0 | L2: 0
A3: Platform | B3: 0 | C3: 0 | D3: 3.02 | E3: 0.8781 | F3: 1.9673 | G3: 3.897 | H3: 0.6051 | I3: 117 | J3: 0.62 | K3: 0 | L3: 5
A4: Platform | B4: 0 | C4: 0 | D4: 0.03 | E4: 0 | F4: 4.8679 | G4: 4.8679 | H4: 4.8679 | I4: 1 | J4: 0 | K4: 0 | L4: 0
A5: Platform | B5: 0 | C5: 0 | D5: 0.02 | E5: 0 | F5: 4.7896 | G5: 4.7896 | H5: 4.7896 | I5: 1 | J5: 0 | K5: 0 | L5: 0
A6: Platform | B6: 0 | C6: 0 | D6: 0.03 | E6: 0 | F6: 4.7793 | G6: 4.7793 | H6: 4.7793 | I6: 1 | J6: 0 | K6: 0 | L6: 0
A7: DEATH
A8: Platform | B8: 0 | C8: 0 | D8: 2.3 | E8: 0.2525 | F8: 2.3815 | G8: 2.4684 | H8: 1.198 | I8: 96 | J8: 0.21 | K8: 0 | L8: 0
A9: Platform | B9: 0 | C9: 0 | D9: 1.8 | E9: 0.1927 | F9: 2.2091 | G9: 2.2763 | H9: 1.1014 | I9: 75 | J9: 0.1 | K9: 0 | L9: 0
A10: Platform | B10: 1 | C10: 0 | D10: 1.28 | E10: 0.032 | F10: 4.3666 | G10: 4.415 | H10: 4.1972 | I10: 53 | J10: 0.09 | K10: 0 | L10: 0
A11: DEATH
A12: Platform | B12: 0 | C12: 0 | D12: 2.58 | E12: 0.1401 | F12: 1.0328 | G12: 1.0842 | H12: 0.2481 | I12: 108 | J12: 0.14 | K12: 0 | L12: 0
A13: DEATH
A14: Platform | B14: 0 | C14: 0 | D14: 2.7 | E14: 0.1359 | F14: 1.3643 | G14: 2.0713 | H14: 0.9075 | I14: 112 | J14: 0 | K14: 0 | L14: 2
A15: DEATH
A16: Platform | B16: 0 | C16: 0 | D16: 2.25 | E16: 0.1659 | F16: 2.0016 | G16: 2.0761 | H16: 1.3597 | I16: 94 | J16: 0.31 | K16: 0 | L16: 2
A17: Platform | B17: 0 | C17: 0 | D17: 0.17 | E17: 0.1678 | F17: 2.1799 | G17: 2.3146 | H17: 1.8416 | I17: 7 | J17: 0 | K17: 0 | L17: 1
A18: Platform | B18: 0 | C18: 0 | D18: 1.88 | E18: 0.6319 | F18: 1.5886 | G18: 2.2473 | H18: 0.2339 | I18: 79 | J18: 0.17 | K18: 0 | L18: 3
A19: Platform | B19: 1 | C19: 0 | D19: 0.45 | E19: 1.4207 | F19: 5.5613 | G19: 8.0096 | H19: 3.4221 | I19: 19 | J19: 0.33 | K19: 0 | L19: 0
A20: DEATH
A21: Platform | B21: 0 | C21: 0 | D21: 2.58 | E21: 0.4866 | F21: 1.4401 | G21: 2.3314 | H21: 0.204 | I21: 107 | J21: 0.21 | K21: 0 | L21: 1
A22: Platform | B22: 0 | C22: 0 | D22: 0.81 | E22: 0.381 | F22: 0.3859 | G22: 1.7727 | H22: 0.0644 | I22: 34 | J22: 0.12 | K22: 0 | L22: 2
A23: Platform | B23: 1 | C23: 0 | D23: 0.98 | E23: 0.4166 | F23: 7.4594 | G23: 8.9595 | H23: 7.2237 | I23: 41 | J23: 0.19 | K23: 0 | L23: 2
A24: DEATH
A25: Platform | B25: 0 | C25: 0 | D25: 0.03 | E25: 0 | F25: 4.8371 | G25: 4.8371 | H25: 4.8371 | I25: 1 | J25: 0 | K25: 0 | L25: 0
A26: Platform | B26: 0 | C26: 0 | D26: 2.78 | E26: 0.3316 | F26: 1.16 | G26: 2.9126 | H26: 1.0458 | I26: 116 | J26: 0 | K26: 0 | L26: 1
A27: Platform | B27: 0 | C27: 0 | D27: 1.09 | E27: 0.2141 | F27: 2.4163 | G27: 3.196 | H27: 1.7771 | I27: 46 | J27: 0.19 | K27: 0 | L27: 0
A28: Platform | B28: 1 | C28: 0 | D28: 1.4 | E28: 0.084 | F28: 6.58 | G28: 6.9203 | H28: 6.5281 | I28: 59 | J28: 0 | K28: 0 | L28: 1
A29: Platform | B29: 1 | C29: 0 | D29: 0.05 | E29: 0.0298 | F29: 10.6021 | G29: 10.6319 | H29: 10.5722 | I29: 2 | J29: 0 | K29: 0 | L29: 1
A30: DEATH
A31: Platform | B31: 0 | C31: 0 | D31: 0.05 | E31: 0.0214 | F31: 5.0345 | G31: 5.0559 | H31: 5.0132 | I31: 2 | J31: 0 | K31: 0 | L31: 0
A32: Platform | B32: 0 | C32: 0 | D32: 2.1 | E32: 0.0136 | F32: 2.0358 | G32: 2.0919 | H32: 1.9894 | I32: 87 | J32: 0.02 | K32: 0 | L32: 1
A33: Platform | B33: 0 | C33: 0 | D33: 1.46 | E33: 0.447 | F33: 1.4469 | G33: 3.3025 | H33: 0.6516 | I33: 59 | J33: 0.15 | K33: 0 | L33: 2
A34: Platform | B34: 1 | C34: 0 | D34: 0.02 | E34: 0 | F34: 2.2646 | G34: 2.2646 | H34: 2.2646 | I34: 1 | J34: 0 | K34: 0 | L34: 0
A35: DEATH
A36: Platform | B36: 0 | C36: 0 | D36: 2.41 | E36: 0.3252 | F36: 2.0609 | G36: 3.2455 | H36: 1.3315 | I36: 99 | J36: 0.49 | K36: 0 | L36: 2
A37: Platform | B37: 0 | C37: 0 | D37: 1.84 | E37: 0.5128 | F37: 3.3018 | G37: 5.229 | H37: 2.3969 | I37: 81 | J37: 0.2 | K37: 0 | L37: 2
A38: DEATH
A39: Platform | B39: 0 | C39: 0 | D39: 2.44 | E39: 0.0457 | F39: 2.1034 | G39: 2.1318 | H39: 1.8934 | I39: 101 | J39: 0.22 | K39: 0 | L39: 2
A40: DEATH
...

Sheet DiegoContreras
A1: EventType | B1: SegmentID | C1: ElementID | D1: TimeOnPlatform | E1: RelativePositionStd | F1: RelativePositionMean | G1: RelativePositionMax | H1: RelativePositionMin | I1: SampleCount | J1: EdgeRiskTime | K1: CorrectionPeaks | L1: RawCorrectionsCount
A2: Platform | B2: 0 | C2: 0 | D2: 0.04 | E2: 0.0942 | F2: 4.8993 | G2: 4.9935 | H2: 4.8052 | I2: 2 | J2: 0 | K2: 0 | L2: 1
A3: Platform | B3: 0 | C3: 0 | D3: 2.24 | E3: 0.3664 | F3: 1.5864 | G3: 2.7476 | H3: 1.0807 | I3: 126 | J3: 0 | K3: 0 | L3: 2
A4: Platform | B4: 0 | C4: 0 | D4: 2.2 | E4: 0.8819 | F4: 2.8779 | G4: 4.5409 | H4: 1.7451 | I4: 128 | J4: 0.04 | K4: 0 | L4: 4
A5: Platform | B5: 1 | C5: 0 | D5: 1.29 | E5: 0.3685 | F5: 7.7835 | G5: 8.2477 | H5: 7.017 | I5: 77 | J5: 0.32 | K5: 0 | L5: 2
A6: Platform | B6: 1 | C6: 0 | D6: 2.8 | E6: 0.1459 | F6: 6.1311 | G6: 7.0672 | H6: 5.9877 | I6: 165 | J6: 0 | K6: 0 | L6: 2
A7: Platform | B7: 2 | C7: 0 | D7: 0.06 | E7: 0.1123 | F7: 5.4268 | G7: 5.5391 | H7: 5.3145 | I7: 2 | J7: 0 | K7: 0 | L7: 0
A8: Platform | B8: 2 | C8: 0 | D8: 2.37 | E8: 1.1432 | F8: 6.7204 | G8: 8.0745 | H8: 5.1382 | I8: 75 | J8: 1.57 | K8: 0 | L8: 2
A9: Platform | B9: 2 | C9: 0 | D9: 0.03 | E9: 0 | F9: 6.2336 | G9: 6.2336 | H9: 6.2336 | I9: 1 | J9: 0 | K9: 0 | L9: 0
A10: DEATH
A11: Platform | B11: 2 | C11: 0 | D11: 0.05 | E11: 0.1204 | F11: 5.7303 | G11: 5.8507 | H11: 5.6098 | I11: 2 | J11: 0 | K11: 0 | L11: 0
A12: Platform | B12: 2 | C12: 0 | D12: 2.38 | E12: 0.5312 | F12: 7.5192 | G12: 7.9078 | H12: 5.8425 | I12: 74 | J12: 0.46 | K12: 0 | L12: 3
A13: Platform | B13: 2 | C13: 0 | D13: 0.03 | E13: 0 | F13: 5.6374 | G13: 5.6374 | H13: 5.6374 | I13: 1 | J13: 0 | K13: 0 | L13: 0
A14: DEATH
A15: Platform | B15: 2 | C15: 0 | D15: 0.06 | E15: 0.1981 | F15: 9.3476 | G15: 9.5457 | H15: 9.1495 | I15: 2 | J15: 0 | K15: 0 | L15: 0
A16: DEATH
A17: Platform | B17: 2 | C17: 0 | D17: 0.03 | E17: 0 | F17: 6.6391 | G17: 6.6391 | H17: 6.6391 | I17: 1 | J17: 0 | K17: 0 | L17: 0
A18: Platform | B18: 2 | C18: 0 | D18: 8.12 | E18: 0.1359 | F18: 5.4838 | G18: 6.1896 | H18: 5.1975 | I18: 274 | J18: 0 | K18: 0 | L18: 9
A19: Platform | B19: 2 | C19: 0 | D19: 0.08 | E19: 0.0868 | F19: 6.7359 | G19: 6.8314 | H19: 6.6214 | I19: 3 | J19: 0 | K19: 0 | L19: 1
A20: DEATH
A21: Platform | B21: 2 | C21: 0 | D21: 0.03 | E21: 0 | F21: 6.5434 | G21: 6.5434 | H21: 6.5434 | I21: 1 | J21: 0 | K21: 0 | L21: 0
A22: Platform | B22: 2 | C22: 0 | D22: 7.86 | E22: 0.0417 | F22: 6.0473 | G22: 6.2904 | H22: 5.9984 | I22: 255 | J22: 0.47 | K22: 0 | L22: 12
A23: Platform | B23: 2 | C23: 0 | D23: 0.83 | E23: 0.5372 | F23: 6.8588 | G23: 7.3931 | H23: 5.826 | I23: 29 | J23: 0.55 | K23: 0 | L23: 1
A24: Platform | B24: 2 | C24: 0 | D24: 0.4 | E24: 0.2248 | F24: 3.9684 | G24: 4.4129 | H24: 3.7596 | I24: 14 | J24: 0 | K24: 0 | L24: 1
A25: DEATH
A26: Platform | B26: 2 | C26: 0 | D26: 0.06 | E26: 0.1094 | F26: 6.8472 | G26: 6.9566 | H26: 6.7378 | I26: 2 | J26: 0 | K26: 0 | L26: 0
A27: Platform | B27: 2 | C27: 0 | D27: 8.56 | E27: 0.4465 | F27: 6.0235 | G27: 9.5004 | H27: 5.7701 | I27: 273 | J27: 0.27 | K27: 0 | L27: 12
A28: Platform | B28: 2 | C28: 0 | D28: 0.14 | E28: 0.0806 | F28: 8.9363 | G28: 8.9897 | H28: 8.777 | I28: 5 | J28: 0 | K28: 0 | L28: 1
A29: DEATH
A30: Platform | B30: 2 | C30: 0 | D30: 0.06 | E30: 0.2001 | F30: 5.4262 | G30: 5.6263 | H30: 5.2261 | I30: 2 | J30: 0 | K30: 0 | L30: 0
A31: Platform | B31: 2 | C31: 0 | D31: 2.45 | E31: 0.3756 | F31: 7.0909 | G31: 7.2729 | H31: 5.7623 | I31: 74 | J31: 0.46 | K31: 0 | L31: 0
A32: Platform | B32: 2 | C32: 0 | D32: 0.37 | E32: 0.164 | F32: 3.697 | G32: 4.1448 | H32: 3.5942 | I32: 12 | J32: 0.1 | K32: 0 | L32: 0
A33: Platform | B33: 2 | C33: 0 | D33: 0.43 | E33: 1.3801 | F33: 4.7894 | G33: 6.8327 | H33: 2.6619 | I33: 14 | J33: 0 | K33: 0 | L33: 1
A34: Platform | B34: 2 | C34: 0 | D34: 2.18 | E34: 0.1728 | F34: 6.6311 | G34: 6.7358 | H34: 6.1849 | I34: 71 | J34: 0.63 | K34: 0 | L34: 0
A35: DEATH
A36: Platform | B36: 2 | C36: 0 | D36: 2.42 | E36: 1.0248 | F36: 6.2269 | G36: 7.8288 | H36: 4.918 | I36: 75 | J36: 0.48 | K36: 0 | L36: 1
A37: Platform | B37: 2 | C37: 0 | D37: 0.77 | E37: 0.5265 | F37: 4.571 | G37: 6.1823 | H37: 4.1719 | I37: 25 | J37: 0.49 | K37: 0 | L37: 2
A38: DEATH
A39: Platform | B39: 2 | C39: 0 | D39: 0.06 | E39: 0.2224 | F39: 7.125 | G39: 7.3475 | H39: 6.9026 | I39: 2 | J39: 0 | K39: 0 | L39: 0
A40: Platform | B40: 2 | C40: 0 | D40: 5.05 | E40: 0.0486 | F40: 8.0347 | G40: 8.3383 | H40: 7.8546 | I40: 156 | J40: 0.33 | K40: 0 | L40: 5
...

Sheet FranPerez
A1: EventType | B1: SegmentID | C1: ElementID | D1: TimeOnPlatform | E1: RelativePositionStd | F1: RelativePositionMean | G1: RelativePositionMax | H1: RelativePositionMin | I1: SampleCount | J1: EdgeRiskTime | K1: CorrectionPeaks | L1: RawCorrectionsCount
A2: Platform | B2: 0 | C2: 0 | D2: 3.23 | E2: 0.245 | F2: 0.3862 | G2: 0.6506 | H2: 0.0239 | I2: 128 | J2: 0.37 | K2: 0 | L2: 21
A3: Platform | B3: 0 | C3: 0 | D3: 2.06 | E3: 0.6023 | F3: 1.7971 | G3: 2.9388 | H3: 1.3577 | I3: 81 | J3: 0.07 | K3: 0 | L3: 20
A4: Platform | B4: 1 | C4: 0 | D4: 1.67 | E4: 0.0286 | F4: 5.2244 | G4: 5.2588 | H4: 5.0751 | I4: 66 | J4: 0.14 | K4: 0 | L4: 2
A5: Platform | B5: 1 | C5: 0 | D5: 2.5 | E5: 0.7339 | F5: 8.0563 | G5: 9.3527 | H5: 7.3812 | I5: 103 | J5: 0.02 | K5: 0 | L5: 12
A6: Platform | B6: 1 | C6: 0 | D6: 0.61 | E6: 0.9267 | F6: 9.1299 | G6: 10.4222 | H6: 7.8654 | I6: 25 | J6: 0 | K6: 0 | L6: 2
A7: Platform | B7: 2 | C7: 0 | D7: 0.05 | E7: 0 | F7: 11.0917 | G7: 11.0917 | H7: 11.0917 | I7: 1 | J7: 0 | K7: 0 | L7: 0
A8: Platform | B8: 2 | C8: 0 | D8: 0.05 | E8: 0 | F8: 11.0822 | G8: 11.0822 | H8: 11.0822 | I8: 1 | J8: 0 | K8: 0 | L8: 0
A9: Platform | B9: 2 | C9: 0 | D9: 0.05 | E9: 0 | F9: 11.142 | G9: 11.142 | H9: 11.142 | I9: 1 | J9: 0 | K9: 0 | L9: 0
A10: Platform | B10: 2 | C10: 0 | D10: 0.05 | E10: 0 | F10: 11.1707 | G10: 11.1707 | H10: 11.1707 | I10: 1 | J10: 0 | K10: 0 | L10: 0
A11: Platform | B11: 2 | C11: 0 | D11: 0.05 | E11: 0 | F11: 11.1941 | G11: 11.1941 | H11: 11.1941 | I11: 1 | J11: 0 | K11: 0 | L11: 0
A12: Platform | B12: 2 | C12: 0 | D12: 0.05 | E12: 0 | F12: 11.1395 | G12: 11.1395 | H12: 11.1395 | I12: 1 | J12: 0 | K12: 0 | L12: 0
A13: Platform | B13: 2 | C13: 0 | D13: 0.05 | E13: 0 | F13: 11.1478 | G13: 11.1478 | H13: 11.1478 | I13: 1 | J13: 0 | K13: 0 | L13: 0
... A20: Platform | B20: 2 | C20: 0 | D20: 0.08 | E20: 0.3155 | F20: 9.912 | G20: 10.2274 | H20: 9.5965 | I20: 2 | J20: 0 | K20: 1 | L20: 0
A21: DEATH
A22: Platform | B22: 2 | C22: 0 | D22: 4.72 | E22: 1.0307 | F22: 6.8432 | G22: 8.5801 | H22: 5.0822 | I22: 108 | J22: 1 | K22: 7 | L22: 42
A23: Platform | B23: 2 | C23: 0 | D23: 0.04 | E23: 0 | F23: 9.1831 | G23: 9.1831 | H23: 9.1831 | I23: 1 | J23: 0 | K23: 0 | L23: 0
A24: Platform | B24: 2 | C24: 0 | D24: 0.08 | E24: 0.059 | F24: 9.2221 | G24: 9.2811 | H24: 9.1631 | I24: 2 | J24: 0 | K24: 0 | L24: 0
A25: Platform | B25: 2 | C25: 0 | D25: 0.12 | E25: 0.0396 | F25: 9.208 | G25: 9.2636 | H25: 9.1746 | I25: 3 | J25: 0 | K25: 0 | L25: 1
A26: Platform | B26: 2 | C26: 0 | D26: 2.01 | E26: 0.2607 | F26: 4.7056 | G26: 5.1357 | H26: 4.3677 | I26: 49 | J26: 0.56 | K26: 0 | L26: 20
A27: Platform | B27: 2 | C27: 0 | D27: 0.9 | E27: 1.2679 | F27: 5.5857 | G27: 8.3 | H27: 3.8195 | I27: 23 | J27: 0 | K27: 0 | L27: 3
A28: DEATH
A29: Platform | B29: 2 | C29: 0 | D29: 0.05 | E29: 0 | F29: 4.5863 | G29: 4.5863 | H29: 4.5863 | I29: 1 | J29: 0 | K29: 0 | L29: 0
A30: Platform | B30: 2 | C30: 0 | D30: 7.75 | E30: 0.278 | F30: 5.4239 | G30: 6.0692 | H30: 5.0003 | I30: 175 | J30: 0.28 | K30: 0 | L30: 82
A31: DEATH
A32: Platform | B32: 2 | C32: 0 | D32: 0.05 | E32: 0 | F32: 9.8753 | G32: 9.8753 | H32: 9.8753 | I32: 1 | J32: 0 | K32: 0 | L32: 0
A33: DEATH
A34: Platform | B34: 2 | C34: 0 | D34: 7.8 | E34: 0.9838 | F34: 3.9854 | G34: 7.2368 | H34: 3.204 | I34: 181 | J34: 0 | K34: 1 | L34: 61
A35: Platform | B35: 2 | C35: 0 | D35: 0.08 | E35: 0.1828 | F35: 7.1847 | G35: 7.3676 | H35: 7.0019 | I35: 2 | J35: 0 | K35: 0 | L35: 0

Sheet JoaquinAguilar
A1: EventType | B1: SegmentID | C1: ElementID | D1: TimeOnPlatform | E1: RelativePositionStd | F1: RelativePositionMean | G1: RelativePositionMax | H1: RelativePositionMin | I1: SampleCount | J1: EdgeRiskTime | K1: CorrectionPeaks | L1: RawCorrectionsCount
A2: Platform | B2: 0 | C2: 0 | D2: 2.52 | E2: 0.0321 | F2: 0.8904 | G2: 0.9636 | H2: 0.749 | I2: 94 | J2: 0 | K2: 0 | L2: 0
A3: Platform | B3: 0 | C3: 0 | D3: 0.76 | E3: 0.0794 | F3: 1.7249 | G3: 1.8876 | H3: 1.5259 | I3: 29 | J3: 0.32 | K3: 0 | L3: 0
A4: Platform | B4: 1 | C4: 0 | D4: 1.73 | E4: 0.8731 | F4: 6.9075 | G4: 8.0293 | H4: 3.9661 | I4: 66 | J4: 0.44 | K4: 0 | L4: 0
A5: Platform | B5: 2 | C5: 0 | D5: 0.05 | E5: 0 | F5: 5.3167 | G5: 5.3167 | H5: 5.3167 | I5: 1 | J5: 0 | K5: 0 | L5: 0
A6: Platform | B6: 2 | C6: 0 | D6: 2.26 | E6: 0.697 | F6: 6.1744 | G6: 7.3595 | H6: 5.3962 | I6: 41 | J6: 1.6 | K6: 0 | L6: 4
A7: DEATH
A8: Platform | B8: 2 | C8: 0 | D8: 0.05 | E8: 0 | F8: 9.2155 | G8: 9.2155 | H8: 9.2155 | I8: 1 | J8: 0 | K8: 0 | L8: 0
A9: Platform | B9: 2 | C9: 0 | D9: 0.6 | E9: 0.1842 | F9: 8.9736 | G9: 9.1344 | H9: 8.3844 | I9: 12 | J9: 0.06 | K9: 1 | L9: 5
A10: DEATH
A11: Platform | B11: 2 | C11: 0 | D11: 0.04 | E11: 0 | F11: 4.6885 | G11: 4.6885 | H11: 4.6885 | I11: 1 | J11: 0 | K11: 0 | L11: 0
A12: Platform | B12: 2 | C12: 0 | D12: 7.54 | E12: 0.1247 | F12: 5.3758 | G12: 5.5824 | H12: 5.0503 | I12: 156 | J12: 0.79 | K12: 0 | L12: 25
A13: DEATH
A14: Platform | B14: 2 | C14: 0 | D14: 7.87 | E14: 0.0769 | F14: 5.5806 | G14: 5.7888 | H14: 5.4341 | I14: 152 | J14: 1.08 | K14: 0 | L14: 27
A15: Platform | B15: 2 | C15: 0 | D15: 0.51 | E15: 0.3654 | F15: 4.2428 | G15: 5.0551 | H15: 3.9295 | I15: 12 | J15: 0 | K15: 0 | L15: 2
A16: Platform | B16: 2 | C16: 0 | D16: 0.08 | E16: 0.0718 | F16: 11.2128 | G16: 11.2846 | H16: 11.141 | I16: 2 | J16: 0 | K16: 0 | L16: 1

Sheet LourdesArtigas
A1: EventType | B1: SegmentID | C1: ElementID | D1: TimeOnPlatform | E1: RelativePositionStd | F1: RelativePositionMean | G1: RelativePositionMax | H1: RelativePositionMin | I1: SampleCount | J1: EdgeRiskTime | K1: CorrectionPeaks | L1: RawCorrectionsCount
A2: Platform | B2: 0 | C2: 0 | D2: 3.11 | E2: 0.1069 | F2: 0.947 | G2: 0.9951 | H2: 0.4081 | I2: 199 | J2: 0.35 | K2: 0 | L2: 2
A3: Platform | B3: 0 | C3: 0 | D3: 2.01 | E3: 0.0356 | F3: 4.4273 | G3: 4.5631 | H3: 4.367 | I3: 131 | J3: 0 | K3: 0 | L3: 3
A4: Platform | B4: 1 | C4: 0 | D4: 2.11 | E4: 0.0145 | F4: 6.9699 | G4: 6.9781 | H4: 6.8616 | I4: 137 | J4: 0.09 | K4: 0 | L4: 0
A5: Platform | B5: 1 | C5: 0 | D5: 1.95 | E5: 0.4619 | F5: 9.0005 | G5: 9.4779 | H5: 8.4881 | I5: 126 | J5: 0.09 | K5: 0 | L5: 1
A6: Platform | B6: 1 | C6: 0 | D6: 0.01 | E6: 0 | F6: 11.2765 | G6: 11.2765 | H6: 11.2765 | I6: 1 | J6: 0 | K6: 0 | L6: 0
A7: DEATH
A8: Platform | B8: 0 | C8: 0 | D8: 3.35 | E8: 0.42 | F8: 1.1208 | G8: 1.391 | H8: 0.3447 | I8: 219 | J8: 0.97 | K8: 0 | L8: 3
A9: Platform | B9: 0 | C9: 0 | D9: 2.08 | E9: 0.0505 | F9: 2.567 | G9: 2.7627 | H9: 2.213 | I9: 136 | J9: 0.12 | K9: 0 | L9: 0
A10: DEATH
A11: Platform | B11: 0 | C11: 0 | D11: 3.46 | E11: 0.6905 | F11: 1.9003 | G11: 2.2832 | H11: 0.453 | I11: 226 | J11: 1.09 | K11: 0 | L11: 0
A12: Platform | B12: 0 | C12: 0 | D12: 2.08 | E12: 0.3574 | F12: 1.2936 | G12: 1.6622 | H12: 0.4088 | I12: 136 | J12: 0.68 | K12: 0 | L12: 3
A13: DEATH
A14: Platform | B14: 0 | C14: 0 | D14: 3.34 | E14: 0.6974 | F14: 2.5324 | G14: 3.0674 | H14: 0.9908 | I14: 216 | J14: 1.39 | K14: 0 | L14: 2
A15: Platform | B15: 0 | C15: 0 | D15: 1.92 | E15: 0.0543 | F15: 2.6138 | G15: 2.7137 | H15: 2.2477 | I15: 109 | J15: 0.13 | K15: 0 | L15: 2
A16: Platform | B16: 1 | C16: 0 | D16: 1.55 | E16: 0.0407 | F16: 6.1686 | G16: 6.1952 | H16: 5.9134 | I16: 98 | J16: 0.07 | K16: 0 | L16: 2
A17: Platform | B17: 1 | C17: 0 | D17: 2.66 | E17: 0.605 | F17: 9.1198 | G17: 9.6726 | H17: 8.3621 | I17: 172 | J17: 0.1 | K17: 0 | L17: 1
A18: Platform | B18: 2 | C18: 0 | D18: 0.02 | E18: 0 | F18: 6.6359 | G18: 6.6359 | H18: 6.6359 | I18: 1 | J18: 0 | K18: 0 | L18: 0
A19: Platform | B19: 2 | C19: 0 | D19: 0.82 | E19: 0.5983 | F19: 8.1117 | G19: 9.8251 | H19: 7.0922 | I19: 40 | J19: 0.45 | K19: 0 | L19: 0
A20: DEATH
A21: Platform | B21: 2 | C21: 0 | D21: 0.02 | E21: 0 | F21: 2.9707 | G21: 2.9707 | H21: 2.9707 | I21: 1 | J21: 0 | K21: 0 | L21: 0
A22: Platform | B22: 2 | C22: 0 | D22: 2.53 | E22: 0.3945 | F22: 4.3762 | G22: 4.6659 | H22: 3.1446 | I22: 110 | J22: 0.52 | K22: 0 | L22: 0
A23: DEATH
A24: Platform | B24: 2 | C24: 0 | D24: 3.07 | E24: 0.7111 | F24: 7.0788 | G24: 9.604 | H24: 5.8476 | I24: 130 | J24: 0.89 | K24: 0 | L24: 2
A25: DEATH
A26: Platform | B26: 2 | C26: 0 | D26: 0.02 | E26: 0 | F26: 6.3259 | G26: 6.3259 | H26: 6.3259 | I26: 1 | J26: 0 | K26: 0 | L26: 0
A27: Platform | B27: 2 | C27: 0 | D27: 2.44 | E27: 0.6803 | F27: 7.1867 | G27: 9.1551 | H27: 6.3755 | I27: 87 | J27: 1.59 | K27: 0 | L27: 0
A28: Platform | B28: 2 | C28: 0 | D28: 0.44 | E28: 1.1879 | F28: 7.3573 | G28: 9.2751 | H28: 5.6424 | I28: 15 | J28: 0.29 | K28: 0 | L28: 0
A29: Platform | B29: 2 | C29: 0 | D29: 0.58 | E29: 0.1673 | F29: 6.0988 | G29: 6.5737 | H29: 5.9898 | I29: 20 | J29: 0 | K29: 0 | L29: 1
A30: Platform | B30: 2 | C30: 0 | D30: 2.04 | E30: 0.5239 | F30: 5.7469 | G30: 6.3229 | H30: 4.4796 | I30: 71 | J30: 1.15 | K30: 0 | L30: 0
A31: Platform | B31: 2 | C31: 0 | D31: 0.03 | E31: 0 | F31: 5.5963 | G31: 5.5963 | H31: 5.5963 | I31: 1 | J31: 0 | K31: 0 | L31: 0
A32: Platform | B32: 2 | C32: 0 | D32: 1.06 | E32: 0.6357 | F32: 6.5205 | G32: 7.066 | H32: 5.5204 | I32: 39 | J32: 0.65 | K32: 0 | L32: 1
A33: Platform | B33: 2 | C33: 0 | D33: 0.13 | E33: 0.3811 | F33: 9.184 | G33: 9.7515 | H33: 8.6669 | I33: 5 | J33: 0 | K33: 0 | L33: 0
A34: Platform | B34: 2 | C34: 0 | D34: 0.1 | E34: 0.071 | F34: 9.0616 | G34: 9.1835 | H34: 9.0058 | I34: 4 | J34: 0 | K34: 0 | L34: 1
A35: DEATH
A36: Platform | B36: 2 | C36: 0 | D36: 0.02 | E36: 0 | F36: 7.9156 | G36: 7.9156 | H36: 7.9156 | I36: 1 | J36: 0 | K36: 0 | L36: 0
A37: Platform | B37: 2 | C37: 0 | D37: 2.86 | E37: 0.6207 | F37: 8.9578 | G37: 10.2023 | H37: 7.9716 | I37: 105 | J37: 1.07 | K37: 0 | L37: 0
A38: DEATH
A39: Platform | B39: 2 | C39: 0 | D39: 0.02 | E39: 0 | F39: 5.9417 | G39: 5.9417 | H39: 5.9417 | I39: 1 | J39: 0 | K39: 0 | L39: 0
A40: Platform | B40: 2 | C40: 0 | D40: 2.45 | E40: 0.3562 | F40: 7.2551 | G40: 8.7213 | H40: 6.271 | I40: 90 | J40: 0.54 | K40: 0 | L40: 2
...

Sheet Pantrucas
A1: EventType | B1: SegmentID | C1: ElementID | D1: TimeOnPlatform | E1: RelativePositionStd | F1: RelativePositionMean | G1: RelativePositionMax | H1: RelativePositionMin | I1: SampleCount | J1: EdgeRiskTime | K1: CorrectionPeaks | L1: RawCorrectionsCount
A2: Platform | B2: 0 | C2: 0 | D2: 0.02 | E2: 0 | F2: 5.0361 | G2: 5.0361 | H2: 5.0361 | I2: 1 | J2: 0 | K2: 0 | L2: 0
A3: Platform | B3: 0 | C3: 0 | D3: 3.02 | E3: 1.0304 | F3: 1.3007 | G3: 3.0378 | H3: 0.2412 | I3: 181 | J3: 1.09 | K3: 0 | L3: 3
A4: Platform | B4: 0 | C4: 0 | D4: 1.03 | E4: 1.1843 | F4: 1.9291 | G4: 4.3557 | H4: 0.2486 | I4: 62 | J4: 0.08 | K4: 0 | L4: 4
A5: Platform | B5: 1 | C5: 0 | D5: 1.12 | E5: 0.0384 | F5: 7.3478 | G5: 7.3765 | H5: 7.1473 | I5: 67 | J5: 0.08 | K5: 0 | L5: 0
A6: Platform | B6: 1 | C6: 0 | D6: 2.29 | E6: 0.8809 | F6: 7.2926 | G6: 10.442 | H6: 6.7657 | I6: 135 | J6: 0 | K6: 0 | L6: 2
A7: Platform | B7: 2 | C7: 0 | D7: 0.04 | E7: 0 | F7: 8.0995 | G7: 8.0995 | H7: 8.0995 | I7: 1 | J7: 0 | K7: 0 | L7: 0
A8: Platform | B8: 2 | C8: 0 | D8: 2.7 | E8: 0.8486 | F8: 9.5412 | G8: 11.1991 | H8: 8.1446 | I8: 86 | J8: 1.01 | K8: 0 | L8: 3
A9: Platform | B9: 2 | C9: 0 | D9: 4.34 | E9: 0.3498 | F9: 6.3768 | G9: 8.2809 | H9: 6.1519 | I9: 151 | J9: 0.2 | K9: 0 | L9: 4
A10: Platform | B10: 2 | C10: 0 | D10: 0.22 | E10: 0.0108 | F10: 7.551 | G10: 7.5647 | H10: 7.5366 | I10: 8 | J10: 0.03 | K10: 0 | L10: 0

Sheet Sepumae
A1: EventType | B1: SegmentID | C1: ElementID | D1: TimeOnPlatform | E1: RelativePositionStd | F1: RelativePositionMean | G1: RelativePositionMax | H1: RelativePositionMin | I1: SampleCount | J1: EdgeRiskTime | K1: CorrectionPeaks | L1: RawCorrectionsCount
A2: Platform | B2: 0 | C2: 0 | D2: 2.72 | E2: 0.4826 | F2: 0.9167 | G2: 1.6662 | H2: 0.0344 | I2: 163 | J2: 0.44 | K2: 0 | L2: 5
A3: Platform | B3: 0 | C3: 0 | D3: 0.12 | E3: 0.0153 | F3: 4.8012 | G3: 4.8279 | H3: 4.7716 | I3: 8 | J3: 0.03 | K3: 0 | L3: 0
A4: Platform | B4: 0 | C4: 0 | D4: 0.03 | E4: 0.0315 | F4: 4.6915 | G4: 4.723 | H4: 4.6599 | I4: 2 | J4: 0 | K4: 0 | L4: 1
A5: Platform | B5: 1 | C5: 0 | D5: 1.29 | E5: 0.637 | F5: 6.4692 | G5: 7.2554 | H5: 4.3868 | I5: 76 | J5: 0.4 | K5: 0 | L5: 1
A6: Platform | B6: 1 | C6: 0 | D6: 2.49 | E6: 0.4599 | F6: 8.5636 | G6: 9.2738 | H6: 7.547 | I6: 147 | J6: 0.27 | K6: 0 | L6: 4
A7: DEATH
A8: Platform | B8: 0 | C8: 0 | D8: 2.97 | E8: 0.263 | F8: 1.1829 | G8: 2.5198 | H8: 0.94 | I8: 177 | J8: 0 | K8: 0 | L8: 1
A9: Platform | B9: 0 | C9: 0 | D9: 1.75 | E9: 0.4088 | F9: 1.7054 | G9: 2.6932 | H9: 1.2929 | I9: 104 | J9: 0.2 | K9: 0 | L9: 2
A10: Platform | B10: 1 | C10: 0 | D10: 1.4 | E10: 0.2715 | F10: 7.2167 | G10: 7.3601 | H10: 5.9772 | I10: 84 | J10: 0.15 | K10: 0 | L10: 0
A11: Platform | B11: 1 | C11: 0 | D11: 2.4 | E11: 0.2818 | F11: 8.4588 | G11: 9.6094 | H11: 7.9989 | I11: 143 | J11: 0 | K11: 0 | L11: 2
A12: Platform | B12: 1 | C12: 0 | D12: 0.01 | E12: 0 | F12: 11.0028 | G12: 11.0028 | H12: 11.0028 | I12: 1 | J12: 0 | K12: 0 | L12: 0
A13: Platform | B13: 1 | C13: 0 | D13: 0.04 | E13: 0.0011 | F13: 11.0711 | G13: 11.0722 | H13: 11.07 | I13: 2 | J13: 0 | K13: 0 | L13: 0
A14: Platform | B14: 2 | C14: 0 | D14: 0.06 | E14: 0.0205 | F14: 7.0987 | G14: 7.1192 | H14: 7.0782 | I14: 2 | J14: 0 | K14: 0 | L14: 0
A15: Platform | B15: 2 | C15: 0 | D15: 2.62 | E15: 0.6634 | F15: 9.0038 | G15: 9.6094 | H15: 7.0898 | I15: 86 | J15: 1.59 | K15: 0 | L15: 0
A16: Platform | B16: 2 | C16: 0 | D16: 0.11 | E16: 0.0096 | F16: 9.1265 | G16: 9.141 | H16: 9.1171 | I16: 4 | J16: 0 | K16: 0 | L16: 0
A17: Platform | B17: 2 | C17: 0 | D17: 0.2 | E17: 0.0574 | F17: 8.4994 | G17: 8.6294 | H17: 8.4543 | I17: 7 | J17: 0 | K17: 0 | L17: 1
A18: Platform | B18: 2 | C18: 0 | D18: 2.01 | E18: 0.6257 | F18: 5.4266 | G18: 5.8697 | H18: 4.1455 | I18: 72 | J18: 1.08 | K18: 0 | L18: 0
A19: Platform | B19: 2 | C19: 0 | D19: 0.04 | E19: 0.0251 | F19: 4.7192 | G19: 4.7444 | H19: 4.6941 | I19: 2 | J19: 0 | K19: 0 | L19: 1
A20: Platform | B20: 2 | C20: 0 | D20: 0.37 | E20: 0.1106 | F20: 5.237 | G20: 5.4176 | H20: 5.0574 | I20: 16 | J20: 0.02 | K20: 0 | L20: 2

Sheet VicenteFigueroa
A1: EventType | B1: SegmentID | C1: ElementID | D1: TimeOnPlatform | E1: RelativePositionStd | F1: RelativePositionMean | G1: RelativePositionMax | H1: RelativePositionMin | I1: SampleCount | J1: EdgeRiskTime | K1: CorrectionPeaks | L1: RawCorrectionsCount
A2: Platform | B2: 0 | C2: 0 | D2: 0.05 | E2: 0.0423 | F2: 5.0781 | G2: 5.1283 | H2: 5.0248 | I2: 3 | J2: 0 | K2: 0 | L2: 1
A3: Platform | B3: 0 | C3: 0 | D3: 2.56 | E3: 0.4953 | F3: 1.6336 | G3: 2.2947 | H3: 0.8014 | I3: 153 | J3: 0.77 | K3: 0 | L3: 3
A4: Platform | B4: 0 | C4: 0 | D4: 1.26 | E4: 0.6065 | F4: 1.9365 | G4: 3.2498 | H4: 0.3203 | I4: 76 | J4: 0.58 | K4: 0 | L4: 2
A5: Platform | B5: 1 | C5: 0 | D5: 1.19 | E5: 0.4011 | F5: 7.0313 | G5: 7.4811 | H5: 6.1095 | I5: 72 | J5: 0.72 | K5: 0 | L5: 0
A6: Platform | B6: 1 | C6: 0 | D6: 1.39 | E6: 0.8867 | F6: 8.0541 | G6: 9.7751 | H6: 7.4457 | I6: 83 | J6: 0.02 | K6: 0 | L6: 2
A7: Platform | B7: 2 | C7: 0 | D7: 2.3 | E7: 0.5535 | F7: 8.1807 | G7: 8.8066 | H7: 6.3625 | I7: 93 | J7: 0.45 | K7: 0 | L7: 1
A8: DEATH
A9: Platform | B9: 2 | C9: 0 | D9: 0.02 | E9: 0 | F9: 4.5876 | G9: 4.5876 | H9: 4.5876 | I9: 1 | J9: 0 | K9: 0 | L9: 0
A10: Platform | B10: 2 | C10: 0 | D10: 2.04 | E10: 1.0112 | F10: 8.0023 | G10: 8.9968 | H10: 5.1357 | I10: 67 | J10: 1.07 | K10: 0 | L10: 3
A11: DEATH
A12: Platform | B12: 2 | C12: 0 | D12: 0.02 | E12: 0 | F12: 7.3377 | G12: 7.3377 | H12: 7.3377 | I12: 1 | J12: 0 | K12: 0 | L12: 0
A13: Platform | B13: 2 | C13: 0 | D13: 2.13 | E13: 0.6941 | F13: 8.4028 | G13: 8.9367 | H13: 6.7915 | I13: 72 | J13: 0.66 | K13: 0 | L13: 3
A14: DEATH
A15: Platform | B15: 2 | C15: 0 | D15: 0.05 | E15: 0.1854 | F15: 6.4267 | G15: 6.6121 | H15: 6.2413 | I15: 2 | J15: 0 | K15: 0 | L15: 0
A16: Platform | B16: 2 | C16: 0 | D16: 3.56 | E16: 0.6989 | F16: 6.3819 | G16: 7.5156 | H16: 5.7077 | I16: 118 | J16: 0.52 | K16: 0 | L16: 2
A17: DEATH
A18: Platform | B18: 2 | C18: 0 | D18: 0.06 | E18: 0.075 | F18: 8.7562 | G18: 8.8312 | H18: 8.6812 | I18: 2 | J18: 0 | K18: 0 | L18: 0
A19: Platform | B19: 2 | C19: 0 | D19: 2.58 | E19: 1.0225 | F19: 10.1786 | G19: 10.6994 | H19: 7.2944 | I19: 86 | J19: 0.66 | K19: 0 | L19: 3
A20: Platform | B20: 2 | C20: 0 | D20: 1.93 | E20: 0.3999 | F20: 7.8058 | G20: 8.1842 | H20: 7.1126 | I20: 66 | J20: 0.53 | K20: 0 | L20: 3
A21: Platform | B21: 2 | C21: 0 | D21: 0.08 | E21: 0.0482 | F21: 2.4127 | G21: 2.4494 | H21: 2.3446 | I21: 3 | J21: 0 | K21: 0 | L21: 0
A22: Platform | B22: 2 | C22: 0 | D22: 0.09 | E22: 0.0584 | F22: 1.087 | G22: 1.1866 | H22: 1.0389 | I22: 4 | J22: 0 | K22: 0 | L22: 0

Sheet VicenteHernandez
A1: EventType | B1: SegmentID | C1: ElementID | D1: TimeOnPlatform | E1: RelativePositionStd | F1: RelativePositionMean | G1: RelativePositionMax | H1: RelativePositionMin | I1: SampleCount | J1: EdgeRiskTime | K1: CorrectionPeaks | L1: RawCorrectionsCount
A2: Platform | B2: 0 | C2: 0 | D2: 0.04 | E2: 0.0069 | F2: 4.854 | G2: 4.8609 | H2: 4.8472 | I2: 2 | J2: 0 | K2: 0 | L2: 0
A3: Platform | B3: 0 | C3: 0 | D3: 2.99 | E3: 1.0536 | F3: 1.785 | G3: 4.569 | H3: 0.8622 | I3: 173 | J3: 0 | K3: 0 | L3: 4
A4: Platform | B4: 0 | C4: 0 | D4: 1.79 | E4: 0.4101 | F4: 0.8892 | G4: 1.6032 | H4: 0.0425 | I4: 105 | J4: 0.4 | K4: 0 | L4: 3
A5: Platform | B5: 1 | C5: 0 | D5: 0.03 | E5: 0.0022 | F5: 4.754 | G5: 4.7562 | H5: 4.7517 | I5: 2 | J5: 0 | K5: 0 | L5: 0
A6: DEATH
A7: Platform | B7: 0 | C7: 0 | D7: 0.02 | E7: 0 | F7: 4.8438 | G7: 4.8438 | H7: 4.8438 | I7: 1 | J7: 0 | K7: 0 | L7: 0
A8: Platform | B8: 0 | C8: 0 | D8: 2.59 | E8: 0.658 | F8: 1.3113 | G8: 2.1333 | H8: 0.5896 | I8: 151 | J8: 0.14 | K8: 0 | L8: 3
A9: Platform | B9: 0 | C9: 0 | D9: 1.66 | E9: 0.8989 | F9: 1.6819 | G9: 3.1079 | H9: 0.9755 | I9: 97 | J9: 0.16 | K9: 0 | L9: 1
A10: Platform | B10: 1 | C10: 0 | D10: 1.7 | E10: 0.2076 | F10: 6.2443 | G10: 6.3235 | H10: 5.0748 | I10: 100 | J10: 0.14 | K10: 0 | L10: 0
A11: Platform | B11: 2 | C11: 0 | D11: 0.03 | E11: 0 | F11: 9.1711 | G11: 9.1711 | H11: 9.1711 | I11: 1 | J11: 0 | K11: 0 | L11: 0
A12: Platform | B12: 2 | C12: 0 | D12: 0.03 | E12: 0 | F12: 9.2307 | G12: 9.2307 | H12: 9.2307 | I12: 1 | J12: 0 | K12: 0 | L12: 0
A13: Platform | B13: 2 | C13: 0 | D13: 0.03 | E13: 0 | F13: 9.2541 | G13: 9.2541 | H13: 9.2541 | I13: 1 | J13: 0 | K13: 0 | L13: 0
A14: Platform | B14: 2 | C14: 0 | D14: 0.03 | E14: 0 | F14: 9.2675 | G14: 9.2675 | H14: 9.2675 | I14: 1 | J14: 0 | K14: 0 | L14: 0
A15: Platform | B15: 2 | C15: 0 | D15: 0.03 | E15: 0 | F15: 9.2682 | G15: 9.2682 | H15: 9.2682 | I15: 1 | J15: 0 | K15: 0 | L15: 0
A16: Platform | B16: 2 | C16: 0 | D16: 0.04 | E16: 0 | F16: 9.3237 | G16: 9.3237 | H16: 9.3237 | I16: 1 | J16: 0 | K16: 0 | L16: 0
A17: Platform | B17: 2 | C17: 0 | D17: 0.04 | E17: 0 | F17: 9.3228 | G17: 9.3228 | H17: 9.3228 | I17: 1 | J17: 0 | K17: 0 | L17: 0
A18: Platform | B18: 2 | C18: 0 | D18: 0.04 | E18: 0 | F18: 9.3222 | G18: 9.3222 | H18: 9.3222 | I18: 1 | J18: 0 | K18: 0 | L18: 0
... A21: Platform | B21: 2 | C21: 0 | D21: 1.91 | E21: 1.0078 | F21: 8.7533 | G21: 10.0681 | H21: 6.9911 | I21: 60 | J21: 1.13 | K21: 0 | L21: 4
A22: DEATH
A23: Platform | B23: 2 | C23: 0 | D23: 0.03 | E23: 0 | F23: 6.5772 | G23: 6.5772 | H23: 6.5772 | I23: 1 | J23: 0 | K23: 0 | L23: 0
A24: Platform | B24: 2 | C24: 0 | D24: 2.23 | E24: 0.3189 | F24: 8.4992 | G24: 8.7169 | H24: 7.2929 | I24: 68 | J24: 0.39 | K24: 0 | L24: 1
A25: Platform | B25: 2 | C25: 0 | D25: 0.64 | E25: 0.3169 | F25: 6.829 | G25: 7.5448 | H25: 6.4449 | I25: 20 | J25: 0.46 | K25: 0 | L25: 0
A26: Platform | B26: 2 | C26: 0 | D26: 0.03 | E26: 0 | F26: 13.2533 | G26: 13.2533 | H26: 13.2533 | I26: 1 | J26: 0 | K26: 0 | L26: 0
A27: DEATH
A28: Platform | B28: 2 | C28: 0 | D28: 2.04 | E28: 0.4676 | F28: 7.4296 | G28: 8.139 | H28: 5.8898 | I28: 64 | J28: 0.36 | K28: 0 | L28: 1
A29: DEATH
A30: Platform | B30: 2 | C30: 0 | D30: 0.02 | E30: 0 | F30: 7.9656 | G30: 7.9656 | H30: 7.9656 | I30: 1 | J30: 0 | K30: 0 | L30: 0
A31: Platform | B31: 2 | C31: 0 | D31: 2.43 | E31: 0.7387 | F31: 6.773 | G31: 7.9222 | H31: 5.9034 | I31: 77 | J31: 0.97 | K31: 0 | L31: 2
A32: DEATH
A33: Platform | B33: 2 | C33: 0 | D33: 0.02 | E33: 0 | F33: 4.7782 | G33: 4.7782 | H33: 4.7782 | I33: 1 | J33: 0 | K33: 0 | L33: 0
A34: Platform | B34: 2 | C34: 0 | D34: 2.45 | E34: 0.9589 | F34: 6.7988 | G34: 7.8891 | H34: 4.4461 | I34: 83 | J34: 1.31 | K34: 0 | L34: 2
A35: Platform | B35: 2 | C35: 0 | D35: 0.77 | E35: 1.7225 | F35: 6.2164 | G35: 8.3975 | H35: 3.3904 | I35: 25 | J35: 0.6 | K35: 0 | L35: 0
A36: DEATH
A37: Platform | B37: 2 | C37: 0 | D37: 2.38 | E37: 0.7233 | F37: 9.0185 | G37: 9.9213 | H37: 6.8215 | I37: 76 | J37: 0.39 | K37: 0 | L37: 1
A38: Platform | B38: 2 | C38: 0 | D38: 0.04 | E38: 0 | F38: 4.8829 | G38: 4.8829 | H38: 4.8829 | I38: 1 | J38: 0 | K38: 0 | L38: 0
A39: Platform | B39: 2 | C39: 0 | D39: 0.03 | E39: 0 | F39: 4.3882 | G39: 4.3882 | H39: 4.3882 | I39: 1 | J39: 0 | K39: 0 | L39: 0
A40: Platform | B40: 2 | C40: 0 | D40: 0.07 | E40: 0.108 | F40: 4.9318 | G40: 5.0398 | H40: 4.8238 | I40: 2 | J40: 0 | K40: 0 | L40: 0
A41: Platform | B41: 2 | C41: 0 | D41: 0.03 | E41: 0 | F41: 5.9358 | G41: 5.9358 | H41: 5.9358 | I41: 1 | J41: 0 | K41: 0 | L41: 0
A42: Platform | B42: 2 | C42: 0 | D42: 0.28 | E42: 0.0077 | F42: 3.4324 | G42: 3.4459 | H42: 3.4244 | I42: 10 | J42: 0 | K42: 0 | L42: 0

Sheet VicenteLineros
A1: EventType | B1: SegmentID | C1: ElementID | D1: TimeOnPlatform | E1: RelativePositionStd | F1: RelativePositionMean | G1: RelativePositionMax | H1: RelativePositionMin | I1: SampleCount | J1: EdgeRiskTime | K1: CorrectionPeaks | L1: RawCorrectionsCount
A2: Platform | B2: 0 | C2: 0 | D2: 2.72 | E2: 0.021 | F2: 2.7379 | G2: 2.8916 | H2: 2.7105 | I2: 163 | J2: 0.05 | K2: 0 | L2: 0
A3: DEATH
A4: Platform | B4: 0 | C4: 0 | D4: 2.85 | E4: 0.0246 | F4: 1.6628 | G4: 1.8824 | H4: 1.6424 | I4: 171 | J4: 0 | K4: 0 | L4: 1
A5: Platform | B5: 0 | C5: 0 | D5: 2.25 | E5: 0.4626 | F5: 2.9847 | G5: 4.408 | H5: 2.6273 | I5: 135 | J5: 0.03 | K5: 0 | L5: 1
A6: DEATH
A7: Platform | B7: 0 | C7: 0 | D7: 2.95 | E7: 0.3134 | F7: 2.0533 | G7: 3.9552 | H7: 1.9582 | I7: 177 | J7: 0 | K7: 0 | L7: 1
A8: Platform | B8: 0 | C8: 0 | D8: 1.92 | E8: 0.0486 | F8: 3.862 | G8: 3.9031 | H8: 3.5274 | I8: 115 | J8: 0.12 | K8: 0 | L8: 0
A9: Platform | B9: 1 | C9: 0 | D9: 1.4 | E9: 0.3748 | F9: 3.9608 | G9: 4.7343 | H9: 3.5195 | I9: 84 | J9: 0.8 | K9: 0 | L9: 2
A10: Platform | B10: 1 | C10: 0 | D10: 0.97 | E10: 1.1186 | F10: 8.3758 | G10: 9.0764 | H10: 5.5064 | I10: 58 | J10: 0.43 | K10: 0 | L10: 0
A11: Platform | B11: 1 | C11: 0 | D11: 0.4 | E11: 1.2831 | F11: 8.1323 | G11: 10.446 | H11: 6.1014 | I11: 24 | J11: 0.32 | K11: 0 | L11: 0
A12: Platform | B12: 2 | C12: 0 | D12: 0.07 | E12: 0.0389 | F12: 7.7175 | G12: 7.7564 | H12: 7.6786 | I12: 2 | J12: 0 | K12: 0 | L12: 1
A13: Platform | B13: 2 | C13: 0 | D13: 4.78 | E13: 0.3358 | F13: 7.1998 | G13: 7.7064 | H13: 6.3504 | I13: 151 | J13: 0.78 | K13: 0 | L13: 1
A14: DEATH
A15: Platform | B15: 2 | C15: 0 | D15: 0.03 | E15: 0 | F15: 7.6064 | G15: 7.6064 | H15: 7.6064 | I15: 1 | J15: 0 | K15: 0 | L15: 0
A16: Platform | B16: 2 | C16: 0 | D16: 2.05 | E16: 0.6376 | F16: 9.3291 | G16: 9.6608 | H16: 7.7038 | I16: 66 | J16: 0.64 | K16: 0 | L16: 0
A17: DEATH
A18: Platform | B18: 2 | C18: 0 | D18: 2.16 | E18: 0.4652 | F18: 7.5509 | G18: 7.7493 | H18: 6.1324 | I18: 71 | J18: 0.42 | K18: 0 | L18: 0
A19: Platform | B19: 2 | C19: 0 | D19: 0.17 | E19: 0.453 | F19: 8.9056 | G19: 9.5744 | H19: 8.2488 | I19: 6 | J19: 0.03 | K19: 0 | L19: 0
A20: DEATH
A21: Platform | B21: 2 | C21: 0 | D21: 1.86 | E21: 0.1501 | F21: 8.4961 | G21: 8.5933 | H21: 8.0919 | I21: 64 | J21: 0.5 | K21: 0 | L21: 2
A22: Platform | B22: 2 | C22: 0 | D22: 0.59 | E22: 1.198 | F22: 9.9453 | G22: 12.2138 | H22: 8.5639 | I22: 21 | J22: 0.45 | K22: 0 | L22: 0
A23: DEATH
A24: Platform | B24: 2 | C24: 0 | D24: 2.41 | E24: 0.8035 | F24: 6.9827 | G24: 8.0042 | H24: 5.8655 | I24: 85 | J24: 2.12 | K24: 0 | L24: 0
A25: Platform | B25: 2 | C25: 0 | D25: 0.05 | E25: 0.1503 | F25: 10.7831 | G25: 10.9334 | H25: 10.6328 | I25: 2 | J25: 0 | K25: 0 | L25: 0
A26: DEATH
A27: Platform | B27: 2 | C27: 0 | D27: 0.03 | E27: 0 | F27: 7.88 | G27: 7.88 | H27: 7.88 | I27: 1 | J27: 0 | K27: 0 | L27: 0
A28: Platform | B28: 2 | C28: 0 | D28: 2.06 | E28: 0.3161 | F28: 8.3496 | G28: 8.6819 | H28: 7.5133 | I28: 69 | J28: 0.23 | K28: 0 | L28: 2
A29: DEATH
A30: Platform | B30: 2 | C30: 0 | D30: 0.02 | E30: 0 | F30: 6.0346 | G30: 6.0346 | H30: 6.0346 | I30: 1 | J30: 0 | K30: 0 | L30: 0
A31: Platform | B31: 2 | C31: 0 | D31: 1.92 | E31: 1.1696 | F31: 8.088 | G31: 9.3706 | H31: 5.5631 | I31: 60 | J31: 0.79 | K31: 0 | L31: 4
A32: DEATH
A33: Platform | B33: 2 | C33: 0 | D33: 2.04 | E33: 0.7168 | F33: 9.2719 | G33: 10.3952 | H33: 8.4103 | I33: 66 | J33: 0.68 | K33: 0 | L33: 3
A34: DEATH
A35: Platform | B35: 2 | C35: 0 | D35: 0.06 | E35: 0.2188 | F35: 7.06 | G35: 7.2789 | H35: 6.8412 | I35: 2 | J35: 0 | K35: 0 | L35: 0
A36: Platform | B36: 2 | C36: 0 | D36: 2.21 | E36: 0.349 | F36: 7.8621 | G36: 8.5764 | H36: 7.1199 | I36: 70 | J36: 0.26 | K36: 0 | L36: 1
A37: Platform | B37: 2 | C37: 0 | D37: 0.28 | E37: 0.1034 | F37: 5.8545 | G37: 6.1046 | H37: 5.7753 | I37: 9 | J37: 0 | K37: 0 | L37: 1
A38: DEATH
A39: Platform | B39: 2 | C39: 0 | D39: 0.03 | E39: 0 | F39: 6.5405 | G39: 6.5405 | H39: 6.5405 | I39: 1 | J39: 0 | K39: 0 | L39: 0
A40: Platform | B40: 2 | C40: 0 | D40: 2.14 | E40: 0.1849 | F40: 6.2218 | G40: 6.4389 | H40: 5.6811 | I40: 70 | J40: 0.23 | K40: 0 | L40: 2
...

Sheet yoelchupa
A1: EventType | B1: SegmentID | C1: ElementID | D1: TimeOnPlatform | E1: RelativePositionStd | F1: RelativePositionMean | G1: RelativePositionMax | H1: RelativePositionMin | I1: SampleCount | J1: EdgeRiskTime | K1: CorrectionPeaks | L1: RawCorrectionsCount
A2: Platform | B2: 0 | C2: 0 | D2: 2.69 | E2: 0.0883 | F2: 1.1575 | G2: 1.3386 | H2: 1.0421 | I2: 141 | J2: 0.2 | K2: 0 | L2: 5
A3: Platform | B3: 0 | C3: 0 | D3: 2.5 | E3: 0.2404 | F3: 1.0721 | G3: 2.6893 | H3: 0.9329 | I3: 131 | J3: 0.22 | K3: 0 | L3: 2
A4: Platform | B4: 1 | C4: 0 | D4: 1.5 | E4: 0.3717 | F4: 7.3136 | G4: 7.8162 | H4: 6.9043 | I4: 81 | J4: 0.83 | K4: 0 | L4: 4
A5: Platform | B5: 1 | C5: 0 | D5: 3.59 | E5: 0.4822 | F5: 7.0109 | G5: 7.7168 | H5: 5.8154 | I5: 186 | J5: 0.02 | K5: 0 | L5: 10
A6: Platform | B6: 1 | C6: 0 | D6: 1.4 | E6: 0.6759 | F6: 7.6518 | G6: 10.0352 | H6: 7.258 | I6: 72 | J6: 0.45 | K6: 0 | L6: 2
A7: Platform | B7: 2 | C7: 0 | D7: 1.96 | E7: 0.8361 | F7: 6.2154 | G7: 7.3879 | H7: 4.9043 | I7: 48 | J7: 1.02 | K7: 0 | L7: 5
A8: Platform | B8: 2 | C8: 0 | D8: 1.8 | E8: 0.2 | F8: 7.4506 | G8: 7.6586 | H8: 6.8867 | I8: 49 | J8: 0.44 | K8: 0 | L8: 12
A9: Platform | B9: 2 | C9: 0 | D9: 0.39 | E9: 0.3977 | F9: 5.9545 | G9: 6.7722 | H9: 5.5954 | I9: 11 | J9: 0.13 | K9: 0 | L9: 4
A10: Platform | B10: 2 | C10: 0 | D10: 2.84 | E10: 0.7639 | F10: 6.1129 | G10: 6.9933 | H10: 4.086 | I10: 79 | J10: 0.35 | K10: 0 | L10: 12
A11: Platform | B11: 2 | C11: 0 | D11: 1.96 | E11: 0.8122 | F11: 6.2833 | G11: 6.9626 | H11: 4.5348 | I11: 57 | J11: 0.67 | K11: 0 | L11: 16
A12: Platform | B12: 2 | C12: 0 | D12: 0.12 | E12: 0.3014 | F12: 6.3403 | G12: 6.7603 | H12: 5.9198 | I12: 4 | J12: 0 | K12: 0 | L12: 1

Sheet Thresholds
A1: Jugador | B1: TimeOnPlatform | C1: RelativePositionStd | D1: RelativePositionMean | E1: RelativePositionMax | F1: RelativePositionMin | G1: SampleCount | H1: EdgeRiskTime | I1: CorrectionPeaks | J1: RawCorrectionsCount | K1: AbandonoPilar
A2: Jug1 | B2: =AVERAGE(AlexVargas!D:D) -> 0.61160714 | C2: =AVERAGE(AlexVargas!E:E) -> 0.3088625 | D2: =AVERAGE(AlexVargas!F:F) -> 6.0130518 | E2: =AVERAGE(AlexVargas!G:G) -> 6.4395482 | F2: =AVERAGE(AlexVargas!H:H) -> 5.408375 | G2: =AVERAGE(AlexVargas!I:I) -> 15.392857 | H2: =AVERAGE(AlexVargas!J:J) -> 0.175 | I2: =AVERAGE(AlexVargas!K:K) -> 0.28571429 | J2: =AVERAGE(AlexVargas!L:L) -> 1.7678571 | K2: 0
A3: Jug2 | B3: =AVERAGE(AntoFlores!D:D) -> 1.646 | C3: =AVERAGE(AntoFlores!E:E) -> 0.450905 | D3: =AVERAGE(AntoFlores!F:F) -> 5.103305 | E3: =AVERAGE(AntoFlores!G:G) -> 5.761865 | F3: =AVERAGE(AntoFlores!H:H) -> 4.363905 | G3: =AVERAGE(AntoFlores!I:I) -> 80.85 | H3: =AVERAGE(AntoFlores!J:J) -> 0.4035 | I3: =AVERAGE(AntoFlores!K:K) -> 0.05 | J3: =AVERAGE(AntoFlores!L:L) -> 0.95 | K3: 0
A4: Jug3 | B4: =AVERAGE(BenjaCarrasco!D:D) -> 1.5692857 | C4: =AVERAGE(BenjaCarrasco!E:E) -> 0.3411 | D4: =AVERAGE(BenjaCarrasco!F:F) -> 6.4575429 | E4: =AVERAGE(BenjaCarrasco!G:G) -> 7.3342 | F4: =AVERAGE(BenjaCarrasco!H:H) -> 6.0101429 | G4: =AVERAGE(BenjaCarrasco!I:I) -> 70.857143 | H4: =AVERAGE(BenjaCarrasco!J:J) -> 0.20714286 | I4: =AVERAGE(BenjaCarrasco!K:K) -> 0 | J4: =AVERAGE(BenjaCarrasco!L:L) -> 1.2142857 | K4: 0
A5: Jug4 | B5: =AVERAGE(CamilaCarrascoBaier!D:D) -> 2.0370588 | C5: =AVERAGE(CamilaCarrascoBaier!E:E) -> 0.21547059 | D5: =AVERAGE(CamilaCarrascoBaier!F:F) -> 4.7141118 | E5: =AVERAGE(CamilaCarrascoBaier!G:G) -> 5.0899941 | F5: =AVERAGE(CamilaCarrascoBaier!H:H) -> 4.2435824 | G5: =AVERAGE(CamilaCarrascoBaier!I:I) -> 55.588235 | H5: =AVERAGE(CamilaCarrascoBaier!J:J) -> 0.50470588 | I5: =AVERAGE(CamilaCarrascoBaier!K:K) -> 0.35294118 | J5: =AVERAGE(CamilaCarrascoBaier!L:L) -> 9.8235294 | K5: 0
A6: Jug5 | B6: =AVERAGE(CataAguilar!D:D) -> 0.93894366 | C6: =AVERAGE(CataAguilar!E:E) -> 0.29522958 | D6: =AVERAGE(CataAguilar!F:F) -> 6.0211775 | E6: =AVERAGE(CataAguilar!G:G) -> 6.5499873 | F6: =AVERAGE(CataAguilar!H:H) -> 5.5527331 | G6: =AVERAGE(CataAguilar!I:I) -> 28.584507 | H6: =AVERAGE(CataAguilar!J:J) -> 0.23323944 | I6: =AVERAGE(CataAguilar!K:K) -> 0.32394366 | J6: =AVERAGE(CataAguilar!L:L) -> 1.2816901 | K6: 0
A7: Jug6 | B7: =AVERAGE(DiegoContreras!D:D) -> 1.502093 | C7: =AVERAGE(DiegoContreras!E:E) -> 0.33312093 | D7: =AVERAGE(DiegoContreras!F:F) -> 5.9618488 | E7: =AVERAGE(DiegoContreras!G:G) -> 6.606607 | F7: =AVERAGE(DiegoContreras!H:H) -> 5.4395581 | G7: =AVERAGE(DiegoContreras!I:I) -> 53.55814 | H7: =AVERAGE(DiegoContreras!J:J) -> 0.18767442 | I7: =AVERAGE(DiegoContreras!K:K) -> 0 | J7: =AVERAGE(DiegoContreras!L:L) -> 1.7906977 | K7: 0
A8: Jug7 | B8: =AVERAGE(FranPerez!D:D) -> 1.229 | C8: =AVERAGE(FranPerez!E:E) -> 0.25147 | D8: =AVERAGE(FranPerez!F:F) -> 7.8196733 | E8: =AVERAGE(FranPerez!G:G) -> 8.32916 | F8: =AVERAGE(FranPerez!H:H) -> 7.5190867 | G8: =AVERAGE(FranPerez!I:I) -> 33.966667 | H8: =AVERAGE(FranPerez!J:J) -> 0.081333333 | I8: =AVERAGE(FranPerez!K:K) -> 0.33333333 | J8: =AVERAGE(FranPerez!L:L) -> 9.5 | K8: 0
A9: Jug8 | B9: =AVERAGE(JoaquinAguilar!D:D) -> 2.0008333 | C9: =AVERAGE(JoaquinAguilar!E:E) -> 0.20871667 | D9: =AVERAGE(JoaquinAguilar!F:F) -> 5.858625 | E9: =AVERAGE(JoaquinAguilar!G:G) -> 6.1921667 | F9: =AVERAGE(JoaquinAguilar!H:H) -> 5.3997667 | G9: =AVERAGE(JoaquinAguilar!I:I) -> 47.25 | H9: =AVERAGE(JoaquinAguilar!J:J) -> 0.3575 | I9: =AVERAGE(JoaquinAguilar!K:K) -> 0.083333333 | J9: =AVERAGE(JoaquinAguilar!L:L) -> 5.3333333 | K9: 0
A10: Jug9 | B10: =AVERAGE(LourdesArtigas!D:D) -> 1.4457895 | C10: =AVERAGE(LourdesArtigas!E:E) -> 0.32909211 | D10: =AVERAGE(LourdesArtigas!F:F) -> 5.9284947 | E10: =AVERAGE(LourdesArtigas!G:G) -> 6.4562368 | F10: =AVERAGE(LourdesArtigas!H:H) -> 5.2918 | G10: =AVERAGE(LourdesArtigas!I:I) -> 75.210526 | H10: =AVERAGE(LourdesArtigas!J:J) -> 0.38236842 | I10: =AVERAGE(LourdesArtigas!K:K) -> 0 | J10: =AVERAGE(LourdesArtigas!L:L) -> 0.81578947 | K10: 0
A11: Jug10 | B11: =AVERAGE(Pantrucas!D:D) -> 1.6422222 | C11: =AVERAGE(Pantrucas!E:E) -> 0.48257778 | D11: =AVERAGE(Pantrucas!F:F) -> 6.0527556 | E11: =AVERAGE(Pantrucas!G:G) -> 7.2658111 | F11: =AVERAGE(Pantrucas!H:H) -> 5.4857222 | G11: =AVERAGE(Pantrucas!I:I) -> 76.888889 | H11: =AVERAGE(Pantrucas!J:J) -> 0.27666667 | I11: =AVERAGE(Pantrucas!K:K) -> 0 | J11: =AVERAGE(Pantrucas!L:L) -> 1.7777778 | K11: 0
A12: Jug11 | B12: =AVERAGE(Sepumae!D:D) -> 1.1461111 | C12: =AVERAGE(Sepumae!E:E) -> 0.24248889 | D12: =AVERAGE(Sepumae!F:F) -> 6.3995056 | E12: =AVERAGE(Sepumae!G:G) -> 6.8074722 | F12: =AVERAGE(Sepumae!H:H) -> 5.8509944 | G12: =AVERAGE(Sepumae!I:I) -> 60.888889 | H12: =AVERAGE(Sepumae!J:J) -> 0.23222222 | I12: =AVERAGE(Sepumae!K:K) -> 0 | J12: =AVERAGE(Sepumae!L:L) -> 1.1111111 | K12: 0
A13: Jug12 | B13: =AVERAGE(VicenteFigueroa!D:D) -> 1.2535294 | C13: =AVERAGE(VicenteFigueroa!E:E) -> 0.42229412 | D13: =AVERAGE(VicenteFigueroa!F:F) -> 6.0760941 | E13: =AVERAGE(VicenteFigueroa!G:G) -> 6.5925235 | F13: =AVERAGE(VicenteFigueroa!H:H) -> 5.1963176 | G13: =AVERAGE(VicenteFigueroa!I:I) -> 53.058824 | H13: =AVERAGE(VicenteFigueroa!J:J) -> 0.35176471 | I13: =AVERAGE(VicenteFigueroa!K:K) -> 0 | J13: =AVERAGE(VicenteFigueroa!L:L) -> 1.3529412 | K13: 0
A14: Jug13 | B14: =AVERAGE(VicenteHernandez!D:D) -> 0.75914286 | C14: =AVERAGE(VicenteHernandez!E:E) -> 0.27450286 | D14: =AVERAGE(VicenteHernandez!F:F) -> 6.7300343 | E14: =AVERAGE(VicenteHernandez!G:G) -> 7.1368029 | F14: =AVERAGE(VicenteHernandez!H:H) -> 6.2263229 | G14: =AVERAGE(VicenteHernandez!I:I) -> 32.371429 | H14: =AVERAGE(VicenteHernandez!J:J) -> 0.18428571 | I14: =AVERAGE(VicenteHernandez!K:K) -> 0 | J14: =AVERAGE(VicenteHernandez!L:L) -> 0.62857143 | K14: 0
A15: Jug14 | B15: =AVERAGE(VicenteLineros!D:D) -> 1.1165574 | C15: =AVERAGE(VicenteLineros!E:E) -> 0.42234426 | D15: =AVERAGE(VicenteLineros!F:F) -> 6.6162852 | E15: =AVERAGE(VicenteLineros!G:G) -> 7.2252459 | F15: =AVERAGE(VicenteLineros!H:H) -> 5.8485344 | G15: =AVERAGE(VicenteLineros!I:I) -> 45.737705 | H15: =AVERAGE(VicenteLineros!J:J) -> 0.26622951 | I15: =AVERAGE(VicenteLineros!K:K) -> 0.016393443 | J15: =AVERAGE(VicenteLineros!L:L) -> 0.80327869 | K15: 0
A16: Jug15 | B16: =AVERAGE(yoelchupa!D:D) -> 1.8863636 | C16: =AVERAGE(yoelchupa!E:E) -> 0.46998182 | D16: =AVERAGE(yoelchupa!F:F) -> 5.6875364 | E16: =AVERAGE(yoelchupa!G:G) -> 6.5573636 | F16: =AVERAGE(yoelchupa!H:H) -> 4.8981545 | G16: =AVERAGE(yoelchupa!I:I) -> 78.090909 | H16: =AVERAGE(yoelchupa!J:J) -> 0.39363636 | I16: =AVERAGE(yoelchupa!K:K) -> 0 | J16: =AVERAGE(yoelchupa!L:L) -> 6.6363636 | K16: 0
A18: Percentil50 (comun) | B18: =_xlfn.PERCENTILE.EXC(B2:B16,0.5) -> 1.4457895 | C18: =_xlfn.PERCENTILE.EXC(C2:C16,0.5) -> 0.32909211 | D18: =_xlfn.PERCENTILE.EXC(D2:D16,0.5) -> 6.0211775 | E18: =_xlfn.PERCENTILE.EXC(E2:E16,0.5) -> 6.5925235 | F18: =_xlfn.PERCENTILE.EXC(F2:F16,0.5) -> 5.4395581 | G18: =_xlfn.PERCENTILE.EXC(G2:G16,0.5) -> 53.55814 | H18: =_xlfn.PERCENTILE.EXC(H2:H16,0.5) -> 0.26622951 | I18: =_xlfn.PERCENTILE.EXC(I2:I16,0.5) -> 0 | J18: =_xlfn.PERCENTILE.EXC(J2:J16,0.5) -> 1.3529412
A19: Percentil75 (activacion) | B19: =_xlfn.PERCENTILE.EXC(B2:B16,0.75) -> 1.646 | C19: =_xlfn.PERCENTILE.EXC(C2:C16,0.75) -> 0.42234426 | D19: =_xlfn.PERCENTILE.EXC(D2:D16,0.75) -> 6.4575429 | E19: =_xlfn.PERCENTILE.EXC(E2:E16,0.75) -> 7.2252459 | F19: =_xlfn.PERCENTILE.EXC(F2:F16,0.75) -> 5.8509944 | G19: =_xlfn.PERCENTILE.EXC(G2:G16,0.75) -> 75.210526 | H19: =_xlfn.PERCENTILE.EXC(H2:H16,0.75) -> 0.38236842 | I19: =_xlfn.PERCENTILE.EXC(I2:I16,0.75) -> 0.28571429 | J19: =_xlfn.PERCENTILE.EXC(J2:J16,0.75) -> 5.3333333
A20: Percentil90 (critico) | B20: =_xlfn.PERCENTILE.EXC(B2:B16,0.9) -> 2.0153235 | C20: =_xlfn.PERCENTILE.EXC(C2:C16,0.9) -> 0.4750202 | D20: =_xlfn.PERCENTILE.EXC(D2:D16,0.9) -> 7.1658899 | E20: =_xlfn.PERCENTILE.EXC(E2:E16,0.9) -> 7.732184 | F20: =_xlfn.PERCENTILE.EXC(F2:F16,0.9) -> 6.7434284 | G20: =_xlfn.PERCENTILE.EXC(G2:G16,0.9) -> 79.194545 | H20: =_xlfn.PERCENTILE.EXC(H2:H16,0.9) -> 0.44398235 | I20: =_xlfn.PERCENTILE.EXC(I2:I16,0.9) -> 0.34117647 | J20: =_xlfn.PERCENTILE.EXC(J2:J16,0.9) -> 9.6294118
