Workbook

Sheet AlexVargas
A1: EventType | B1: AttemptID | C1: SegmentID | D1: GateID | E1: EntryTime | F1: ExitTime | G1: TimeToClear_s | H1: Cleared | I1: ObstacleTouched | J1: ContactDuration_s | K1: ContactCount | L1: FirstContactTime_s | M1: JetpackActiveTime_s | N1: CrouchTime_s | O1: AirborneTime_s | P1: ContactX | Q1: ContactY | R1: ContactZ
A2: GATE | B2: 1 | C2: 1 | D2: 1 | E2: 1541.12 | F2: 1543.34 | G2: 2.22 | H2: 1 | I2: 1 | J2: 0.4199 | K2: 4 | L2: 1.02 | M2: 0.0849 | N2: 0 | O2: 1.477 | P2: 109.6867 | Q2: 2.2446 | R2: 6.4942
A3: GATE | B3: 2 | C3: 2 | D3: 2 | E3: 1546.54 | F3: 1549 | G3: 2.4601 | H3: 1 | I3: 0 | J3: 0 | K3: 0 | L3: -1 | M3: 0.7939 | N3: 0 | O3: 2.3406 | P3: 157.5121 | Q3: 4.9898 | R3: 7.3635
A4: GATE | B4: 3 | C4: 3 | D4: 3 | E4: 1550.58 | F4: 1551.76 | G4: 1.1801 | H4: 1 | I4: 0 | J4: 0 | K4: 0 | L4: -1 | M4: 0.514 | N4: 0 | O4: 1.0975 | P4: 187.6421 | Q4: 2.6938 | R4: 9.8791
A5: GATE | B5: 4 | C5: 4 | D5: 4 | E5: 1560.82 | F5: 1562.02 | G5: 1.2001 | H5: 1 | I5: 0 | J5: 0 | K5: 0 | L5: -1 | M5: 0.5448 | N5: 0 | O5: 1.1982 | P5: 0 | Q5: 0 | R5: 0
A6: DEATH
A7: GATE | B7: 4 | C7: 4 | D7: 4 | E7: 1571.02 | F7: 1572.72 | G7: 1.7 | H7: 1 | I7: 1 | J7: 0.38 | K7: 3 | L7: 0.5 | M7: 0.7891 | N7: 0 | O7: 1.5596 | P7: 178.5665 | Q7: 2.2662 | R7: 57.9375
A8: GATE | B8: 5 | C8: 5 | D8: 5 | E8: 1572.78 | F8: 1574.16 | G8: 1.38 | H8: 1 | I8: 0 | J8: 0 | K8: 0 | L8: -1 | M8: 0.6477 | N8: 0 | O8: 1.3845 | P8: 164.4668 | Q8: 6.676 | R8: 57.4339
A9: GATE | B9: 6 | C9: 6 | D9: 6 | E9: 1574.5 | F9: 1575.14 | G9: 0.64 | H9: 1 | I9: 1 | J9: 0.02 | K9: 1 | L9: 0.62 | M9: 0 | N9: 0 | O9: 0.6333 | P9: 0 | Q9: 0 | R9: 0
A10: DEATH
A11: GATE | B11: 4 | C11: 4 | D11: 4 | E11: 1583.32 | F11: 1584.46 | G11: 1.14 | H11: 1 | I11: 0 | J11: 0 | K11: 0 | L11: -1 | M11: 0.4327 | N11: 0 | O11: 1.1192 | P11: 178.8392 | Q11: 2.367 | R11: 57.9843
A12: GATE | B12: 5 | C12: 5 | D12: 5 | E12: 1584.48 | F12: 1585.7 | G12: 1.22 | H12: 1 | I12: 0 | J12: 0 | K12: 0 | L12: -1 | M12: 0.5223 | N12: 0 | O12: 1.2169 | P12: 164.6145 | Q12: 4.6003 | R12: 58.3468
A13: GATE | B13: 6 | C13: 6 | D13: 6 | E13: 1585.84 | F13: 1586.66 | G13: 0.8199 | H13: 1 | I13: 1 | J13: 0.2 | K13: 3 | L13: 0.3 | M13: 0.4538 | N13: 0 | O13: 0.8157 | P13: 146.9869 | Q13: 2.2684 | R13: 58.2955
A14: GATE | B14: 7 | C14: 7 | D14: 7 | E14: 1588.82 | F14: 1589.78 | G14: 0.96 | H14: 1 | I14: 1 | J14: 0.2001 | K14: 3 | L14: 0.46 | M14: 0 | N14: 0 | O14: 0.5187 | P14: 108.014 | Q14: 2.2577 | R14: 56.9142
A15: GATE | B15: 8 | C15: 8 | D15: 8 | E15: 1590.28 | F15: 1594.4 | G15: 4.1201 | H15: 1 | I15: 1 | J15: 1.1201 | K15: 3 | L15: 0.52 | M15: 0.5512 | N15: 0 | O15: 2.8183 | P15: 87.4517 | Q15: 2.0043 | R15: 58.6728
A16: DEATH
A17: DEATH
A18: GATE | B18: 4 | C18: 4 | D18: 4 | E18: 1611.98 | F18: 1613.22 | G18: 1.24 | H18: 1 | I18: 0 | J18: 0 | K18: 0 | L18: -1 | M18: 0.4022 | N18: 0 | O18: 1.2319 | P18: 178.7918 | Q18: 2.552 | R18: 59.8935
A19: GATE | B19: 5 | C19: 5 | D19: 5 | E19: 1613.22 | F19: 1614.04 | G19: 0.8199 | H19: 1 | I19: 0 | J19: 0 | K19: 0 | L19: -1 | M19: 0.3308 | N19: 0 | O19: 0.8181 | P19: 0 | Q19: 0 | R19: 0
A20: GATE | B20: 6 | C20: 6 | D20: 6 | E20: 1614.36 | F20: 1615.64 | G20: 1.28 | H20: 1 | I20: 1 | J20: 0.34 | K20: 3 | L20: 0.48 | M20: 0.3953 | N20: 0 | O20: 1.098 | P20: 147.2363 | Q20: 2.2502 | R20: 59.2383
A21: GATE | B21: 7 | C21: 7 | D21: 7 | E21: 1617.42 | F21: 1619.08 | G21: 1.66 | H21: 1 | I21: 0 | J21: 0 | K21: 0 | L21: -1 | M21: 0.2364 | N21: 0 | O21: 1.0503 | P21: 108.0231 | Q21: 2.2622 | R21: 60.6047
A22: GATE | B22: 8 | C22: 8 | D22: 8 | E22: 1619.8 | F22: 1620.58 | G22: 0.78 | H22: 1 | I22: 1 | J22: 0.04 | K22: 1 | L22: 0.66 | M22: 0 | N22: 0 | O22: 0.7907 | P22: 0 | Q22: 0 | R22: 0
A23: DEATH
A24: GATE | B24: 4 | C24: 4 | D24: 4 | E24: 1629.46 | F24: 1630.46 | G24: 1 | H24: 1 | I24: 0 | J24: 0 | K24: 0 | L24: -1 | M24: 0.1916 | N24: 0 | O24: 1.0064 | P24: 0 | Q24: 0 | R24: 0
A25: GATE | B25: 5 | C25: 5 | D25: 5 | E25: 1630.56 | F25: 1633.3 | G25: 2.74 | H25: 1 | I25: 0 | J25: 0 | K25: 0 | L25: -1 | M25: 1.3696 | N25: 0 | O25: 2.6952 | P25: 164.5792 | Q25: 1.7914 | R25: 62.5393
A26: DEATH
A27: GATE | B27: 4 | C27: 4 | D27: 4 | E27: 1641.32 | F27: 1642.26 | G27: 0.9401 | H27: 1 | I27: 0 | J27: 0 | K27: 0 | L27: -1 | M27: 0.2998 | N27: 0 | O27: 0.9466 | P27: 178.5522 | Q27: 3.1435 | R27: 58.3913
A28: GATE | B28: 5 | C28: 5 | D28: 5 | E28: 1642.3 | F28: 1642.6 | G28: 0.3 | H28: 1 | I28: 0 | J28: 0 | K28: 0 | L28: -1 | M28: 0 | N28: 0 | O28: 0.2687 | P28: 0 | Q28: 0 | R28: 0
A29: DEATH
A30: GATE | B30: 4 | C30: 4 | D30: 4 | E30: 1651.36 | F30: 1653.34 | G30: 1.98 | H30: 1 | I30: 0 | J30: 0 | K30: 0 | L30: -1 | M30: 1.2499 | N30: 0 | O30: 1.975 | P30: 178.6483 | Q30: 4.1097 | R30: 58.854
A31: GATE | B31: 5 | C31: 5 | D31: 5 | E31: 1653.34 | F31: 1654.72 | G31: 1.38 | H31: 1 | I31: 0 | J31: 0 | K31: 0 | L31: -1 | M31: 0.2894 | N31: 0 | O31: 1.3957 | P31: 164.4808 | Q31: 6.3476 | R31: 58.9457
A32: DEATH
A33: GATE | B33: 4 | C33: 4 | D33: 4 | E33: 1663.46 | F33: 1664.72 | G33: 1.26 | H33: 1 | I33: 0 | J33: 0 | K33: 0 | L33: -1 | M33: 0.3757 | N33: 0 | O33: 0.7843 | P33: 0 | Q33: 0 | R33: 0
A34: GATE | B34: 5 | C34: 5 | D34: 5 | E34: 1664.76 | F34: 1665.54 | G34: 0.7799 | H34: 1 | I34: 1 | J34: 0.04 | K34: 1 | L34: 0.34 | M34: 0.0908 | N34: 0 | O34: 0.6959 | P34: 0 | Q34: 0 | R34: 0
A35: GATE | B35: 6 | C35: 6 | D35: 6 | E35: 1665.76 | F35: 1666.96 | G35: 1.2 | H35: 1 | I35: 1 | J35: 0.24 | K35: 3 | L35: 0.6 | M35: 0.1129 | N35: 0 | O35: 0.6923 | P35: 147.0782 | Q35: 2.2416 | R35: 57.5254
A36: GATE | B36: 7 | C36: 7 | D36: 7 | E36: 1668.9 | F36: 1670.82 | G36: 1.92 | H36: 1 | I36: 0 | J36: 0 | K36: 0 | L36: -1 | M36: 1.3167 | N36: 0 | O36: 1.9206 | P36: 108.5383 | Q36: 3.2884 | R36: 58.7818
A37: GATE | B37: 8 | C37: 8 | D37: 8 | E37: 1671.56 | F37: 1674.2 | G37: 2.64 | H37: 1 | I37: 0 | J37: 0 | K37: 0 | L37: -1 | M37: 0.1496 | N37: 0 | O37: 2.2432 | P37: 87.2217 | Q37: 3.8501 | R37: 59.1094
A38: DEATH
A39: GATE | B39: 4 | C39: 4 | D39: 4 | E39: 1683.18 | F39: 1684.38 | G39: 1.2001 | H39: 1 | I39: 0 | J39: 0 | K39: 0 | L39: -1 | M39: 0.3243 | N39: 0 | O39: 1.1973 | P39: 178.836 | Q39: 3.9096 | R39: 59.3684
A40: GATE | B40: 5 | C40: 5 | D40: 5 | E40: 1684.38 | F40: 1686.16 | G40: 1.7799 | H40: 1 | I40: 1 | J40: 0.2 | K40: 1 | L40: 0.76 | M40: 0.5793 | N40: 0 | O40: 0.997 | P40: 164.5608 | Q40: 1.8953 | R40: 60.4597
...

Sheet AntoFlores
A1: EventType | B1: AttemptID | C1: SegmentID | D1: GateID | E1: EntryTime | F1: ExitTime | G1: TimeToClear_s | H1: Cleared | I1: ObstacleTouched | J1: ContactDuration_s | K1: ContactCount | L1: FirstContactTime_s | M1: JetpackActiveTime_s | N1: CrouchTime_s | O1: AirborneTime_s | P1: ContactX | Q1: ContactY | R1: ContactZ
A2: GATE | B2: 1 | C2: 1 | D2: 1 | E2: 24.16 | F2: 25.9 | G2: 1.74 | H2: 1 | I2: 1 | J2: 0.24 | K2: 3 | L2: 0.76 | M2: 0 | N2: 1.4088 | O2: 0 | P2: 0 | Q2: 0 | R2: 0
A3: GATE | B3: 2 | C3: 2 | D3: 2 | E3: 29.74 | F3: 30.68 | G3: 0.94 | H3: 1 | I3: 1 | J3: 0.1 | K3: 2 | L3: 0.42 | M3: 0.6585 | N3: 0 | O3: 0.9429 | P3: 0 | Q3: 0 | R3: 0
A4: DEATH
A5: GATE | B5: 1 | C5: 1 | D5: 1 | E5: 38.44 | F5: 40.14 | G5: 1.7 | H5: 1 | I5: 1 | J5: 0.22 | K5: 3 | L5: 0.74 | M5: 0 | N5: 1.2149 | O5: 0 | P5: 0 | Q5: 0 | R5: 0
A6: GATE | B6: 2 | C6: 2 | D6: 2 | E6: 43.62 | F6: 45.34 | G6: 1.72 | H6: 1 | I6: 1 | J6: 0.22 | K6: 3 | L6: 0.76 | M6: 0 | N6: 1.7068 | O6: 0 | P6: 0 | Q6: 0 | R6: 0
A7: GATE | B7: 3 | C7: 3 | D7: 3 | E7: 47.3 | F7: 49.54 | G7: 2.24 | H7: 1 | I7: 1 | J7: 0.62 | K7: 2 | L7: 0.76 | M7: 0.5269 | N7: 1.4168 | O7: 0.7859 | P7: 0 | Q7: 0 | R7: 0
A8: GATE | B8: 4 | C8: 4 | D8: 4 | E8: 63.1 | F8: 64.14 | G8: 1.04 | H8: 1 | I8: 1 | J8: 0.1 | K8: 3 | L8: 0.46 | M8: 0 | N8: 1.0514 | O8: 0 | P8: 0 | Q8: 0 | R8: 0
A9: GATE | B9: 5 | C9: 5 | D9: 5 | E9: 64.14 | F9: 65.54 | G9: 1.4 | H9: 1 | I9: 0 | J9: 0 | K9: 0 | L9: -1 | M9: 0.4744 | N9: 0.0275 | O9: 1.1388 | P9: 164.7419 | Q9: 1.9224 | R9: 56.3486
A10: GATE | B10: 6 | C10: 6 | D10: 6 | E10: 65.92 | F10: 67.16 | G10: 1.24 | H10: 1 | I10: 0 | J10: 0 | K10: 0 | L10: -1 | M10: 0.6657 | N10: 0 | O10: 1.2341 | P10: 0 | Q10: 0 | R10: 0
A11: DEATH
A12: GATE | B12: 4 | C12: 4 | D12: 4 | E12: 80.02 | F12: 81 | G12: 0.98 | H12: 1 | I12: 1 | J12: 0.12 | K12: 3 | L12: 0.46 | M12: 0 | N12: 0.9963 | O12: 0 | P12: 0 | Q12: 0 | R12: 0
A13: GATE | B13: 5 | C13: 5 | D13: 5 | E13: 81.04 | F13: 83.16 | G13: 2.12 | H13: 1 | I13: 1 | J13: 0.68 | K13: 1 | L13: 0.44 | M13: 0.2789 | N13: 0.4312 | O13: 1.1565 | P13: 164.2066 | Q13: 1.7683 | R13: 54.7047
A14: GATE | B14: 6 | C14: 6 | D14: 6 | E14: 83.58 | F14: 85.86 | G14: 2.28 | H14: 1 | I14: 0 | J14: 0 | K14: 0 | L14: -1 | M14: 0.7888 | N14: 0 | O14: 2.2742 | P14: 0 | Q14: 0 | R14: 0
A15: DEATH
A16: GATE | B16: 4 | C16: 4 | D16: 4 | E16: 95.16 | F16: 96.3 | G16: 1.14 | H16: 1 | I16: 1 | J16: 0.2 | K16: 3 | L16: 0.48 | M16: 0 | N16: 0.885 | O16: 0.5038 | P16: 0 | Q16: 0 | R16: 0
A17: GATE | B17: 5 | C17: 5 | D17: 5 | E17: 96.32 | F17: 119.52 | G17: 23.2 | H17: 1 | I17: 0 | J17: 0 | K17: 0 | L17: -1 | M17: 0.0593 | N17: 0 | O17: 1.515 | P17: 164.4769 | Q17: 1.8168 | R17: 58.4843
A18: GATE | B18: 6 | C18: 6 | D18: 6 | E18: 119.72 | F18: 120.8 | G18: 1.08 | H18: 1 | I18: 1 | J18: 0.12 | K18: 3 | L18: 0.52 | M18: 0 | N18: 0.6933 | O18: 0.1319 | P18: 0 | Q18: 0 | R18: 0
A19: GATE | B19: 7 | C19: 7 | D19: 7 | E19: 122.76 | F19: 123.82 | G19: 1.06 | H19: 1 | I19: 1 | J19: 0.1 | K19: 2 | L19: 0.5 | M19: 0 | N19: 1.055 | O19: 0 | P19: 0 | Q19: 0 | R19: 0
A20: GATE | B20: 8 | C20: 8 | D20: 8 | E20: 124.38 | F20: 125.54 | G20: 1.16 | H20: 1 | I20: 0 | J20: 0 | K20: 0 | L20: -1 | M20: 1.0801 | N20: 0 | O20: 1.1621 | P20: 87.457 | Q20: 5.5738 | R20: 54.7951

Sheet BenjaCarrasco
A1: EventType | B1: AttemptID | C1: SegmentID | D1: GateID | E1: EntryTime | F1: ExitTime | G1: TimeToClear_s | H1: Cleared | I1: ObstacleTouched | J1: ContactDuration_s | K1: ContactCount | L1: FirstContactTime_s | M1: JetpackActiveTime_s | N1: CrouchTime_s | O1: AirborneTime_s | P1: ContactX | Q1: ContactY | R1: ContactZ
A2: GATE | B2: 1 | C2: 1 | D2: 1 | E2: 637.94 | F2: 639.36 | G2: 1.42 | H2: 1 | I2: 0 | J2: 0 | K2: 0 | L2: -1 | M2: 0.338 | N2: 0 | O2: 1.2193 | P2: 109.4823 | Q2: 4.3888 | R2: 6.3321
A3: GATE | B3: 2 | C3: 2 | D3: 2 | E3: 643.2 | F3: 644.9 | G3: 1.7 | H3: 1 | I3: 1 | J3: 0.22 | K3: 3 | L3: 0.7599 | M3: 0 | N3: 1.7066 | O3: 0 | P3: 0 | Q3: 0 | R3: 0
A4: GATE | B4: 3 | C4: 3 | D4: 3 | E4: 646.84 | F4: 648.44 | G4: 1.6 | H4: 1 | I4: 1 | J4: 0.22 | K4: 3 | L4: 0.74 | M4: 0 | N4: 1.2188 | O4: 0.017 | P4: 0 | Q4: 0 | R4: 0
A5: GATE | B5: 4 | C5: 4 | D5: 4 | E5: 655.48 | F5: 656.48 | G5: 1 | H5: 1 | I5: 1 | J5: 0.12 | K5: 2 | L5: 0.46 | M5: 0 | N5: 0.65 | O5: 0 | P5: 0 | Q5: 0 | R5: 0
A6: GATE | B6: 5 | C6: 5 | D6: 5 | E6: 656.5 | F6: 658.18 | G6: 1.68 | H6: 1 | I6: 0 | J6: 0 | K6: 0 | L6: -1 | M6: 0.6426 | N6: 0.515 | O6: 1.686 | P6: 164.7325 | Q6: 2.9357 | R6: 58.8915
A7: GATE | B7: 6 | C7: 6 | D7: 6 | E7: 658.54 | F7: 658.62 | G7: 0.08 | H7: 1 | I7: 0 | J7: 0 | K7: 0 | L7: -1 | M7: 0 | N7: 0.063 | O7: 0.063 | P7: 0 | Q7: 0 | R7: 0
A8: GATE | B8: 6 | C8: 6 | D8: 6 | E8: 658.8 | F8: 658.96 | G8: 0.16 | H8: 1 | I8: 0 | J8: 0 | K8: 0 | L8: -1 | M8: 0 | N8: 0.1584 | O8: 0.1584 | P8: 0 | Q8: 0 | R8: 0
A9: DEATH
A10: GATE | B10: 4 | C10: 4 | D10: 4 | E10: 668.28 | F10: 669.36 | G10: 1.08 | H10: 1 | I10: 1 | J10: 0.14 | K10: 3 | L10: 0.48 | M10: 0 | N10: 0.9457 | O10: 0.1357 | P10: 0 | Q10: 0 | R10: 0
A11: GATE | B11: 5 | C11: 5 | D11: 5 | E11: 669.36 | F11: 670.48 | G11: 1.12 | H11: 1 | I11: 0 | J11: 0 | K11: 0 | L11: -1 | M11: 0.3915 | N11: 0 | O11: 1.1257 | P11: 164.5284 | Q11: 3.43 | R11: 58.7156
A12: GATE | B12: 6 | C12: 6 | D12: 6 | E12: 670.64 | F12: 671.6 | G12: 0.96 | H12: 1 | I12: 1 | J12: 0.1 | K12: 3 | L12: 0.46 | M12: 0 | N12: 0.6072 | O12: 0 | P12: 0 | Q12: 0 | R12: 0
A13: GATE | B13: 7 | C13: 7 | D13: 7 | E13: 673.56 | F13: 674.6 | G13: 1.04 | H13: 1 | I13: 1 | J13: 0.14 | K13: 3 | L13: 0.46 | M13: 0 | N13: 0.7741 | O13: 0 | P13: 0 | Q13: 0 | R13: 0
A14: GATE | B14: 8 | C14: 8 | D14: 8 | E14: 675.12 | F14: 676.22 | G14: 1.1 | H14: 1 | I14: 0 | J14: 0 | K14: 0 | L14: -1 | M14: 0.8941 | N14: 0 | O14: 1.0931 | P14: 87.4506 | Q14: 2.4905 | R14: 58.8178

Sheet CamilaCarrascoBaier
A1: EventType | B1: AttemptID | C1: SegmentID | D1: GateID | E1: EntryTime | F1: ExitTime | G1: TimeToClear_s | H1: Cleared | I1: ObstacleTouched | J1: ContactDuration_s | K1: ContactCount | L1: FirstContactTime_s | M1: JetpackActiveTime_s | N1: CrouchTime_s | O1: AirborneTime_s | P1: ContactX | Q1: ContactY | R1: ContactZ
A2: GATE | B2: 1 | C2: 1 | D2: 1 | E2: 28.92 | F2: 30.9 | G2: 1.98 | H2: 1 | I2: 1 | J2: 0.04 | K2: 1 | L2: 0.76 | M2: 0.0542 | N2: 0 | O2: 1.1959 | P2: 0 | Q2: 0 | R2: 0
A3: GATE | B3: 2 | C3: 2 | D3: 2 | E3: 34.06 | F3: 35.7 | G3: 1.64 | H3: 1 | I3: 0 | J3: 0 | K3: 0 | L3: -1 | M3: 0 | N3: 0 | O3: 1.0222 | P3: 157.4541 | Q3: 2.2317 | R3: 11.0899
A4: GATE | B4: 3 | C4: 3 | D4: 3 | E4: 37.4 | F4: 38.56 | G4: 1.16 | H4: 1 | I4: 0 | J4: 0 | K4: 0 | L4: -1 | M4: 0.4179 | N4: 0 | O4: 0.9821 | P4: 187.8026 | Q4: 2.2433 | R4: 12.5525
A5: GATE | B5: 4 | C5: 4 | D5: 4 | E5: 69.6 | F5: 71.12 | G5: 1.52 | H5: 1 | I5: 1 | J5: 0.06 | K5: 3 | L5: 0.4 | M5: 0 | N5: 0 | O5: 0.9588 | P5: 178.5443 | Q5: 2.2453 | R5: 61.3611
A6: GATE | B6: 5 | C6: 5 | D6: 5 | E6: 71.14 | F6: 72.52 | G6: 1.38 | H6: 1 | I6: 0 | J6: 0 | K6: 0 | L6: -1 | M6: 1.3154 | N6: 0 | O6: 1.3642 | P6: 164.7464 | Q6: 3.5061 | R6: 59.3541
A7: GATE | B7: 6 | C7: 6 | D7: 6 | E7: 72.92 | F7: 74.32 | G7: 1.4 | H7: 1 | I7: 0 | J7: 0 | K7: 0 | L7: -1 | M7: 0.0851 | N7: 0 | O7: 1.4046 | P7: 147.6033 | Q7: 12.1432 | R7: 62.7825
A8: DEATH | B8: 0 | C8: 0 | D8: 0 | E8: 0 | F8: 0 | G8: 0 | H8: 0 | I8: 0 | J8: 0 | K8: 0 | L8: 0 | M8: 0 | N8: 0 | O8: 0 | P8: 0 | Q8: 0 | R8: 0
A9: GATE | B9: 4 | C9: 4 | D9: 4 | E9: 91.88 | F9: 93.36 | G9: 1.48 | H9: 1 | I9: 1 | J9: 0.02 | K9: 1 | L9: 0.46 | M9: 0 | N9: 0 | O9: 1.0235 | P9: 0 | Q9: 0 | R9: 0
A10: GATE | B10: 5 | C10: 5 | D10: 5 | E10: 93.4 | F10: 94.76 | G10: 1.36 | H10: 1 | I10: 0 | J10: 0 | K10: 0 | L10: -1 | M10: 1.2364 | N10: 0 | O10: 1.3575 | P10: 164.5155 | Q10: 3.0442 | R10: 61.2939
A11: GATE | B11: 6 | C11: 6 | D11: 6 | E11: 95.12 | F11: 96.1 | G11: 0.98 | H11: 1 | I11: 0 | J11: 0 | K11: 0 | L11: -1 | M11: 0 | N11: 0 | O11: 0.9819 | P11: 147.5701 | Q11: 3.6847 | R11: 62.0627
A12: DEATH | B12: 0 | C12: 0 | D12: 0 | E12: 0 | F12: 0 | G12: 0 | H12: 0 | I12: 0 | J12: 0 | K12: 0 | L12: 0 | M12: 0 | N12: 0 | O12: 0 | P12: 0 | Q12: 0 | R12: 0
A13: GATE | B13: 4 | C13: 4 | D13: 4 | E13: 114.12 | F13: 115.68 | G13: 1.56 | H13: 1 | I13: 0 | J13: 0 | K13: 0 | L13: -1 | M13: 0.1304 | N13: 0 | O13: 1.1406 | P13: 178.1993 | Q13: 2.5786 | R13: 59.1091
... A25: GATE | B25: 8 | C25: 8 | D25: 8 | E25: 165.5 | F25: 166.4 | G25: 0.9 | H25: 1 | I25: 0 | J25: 0 | K25: 0 | L25: -1 | M25: 0 | N25: 0 | O25: 0.5845 | P25: 86.9275 | Q25: 1.9951 | R25: 57.9409

Sheet CataAguilar
A1: EventType | B1: AttemptID | C1: SegmentID | D1: GateID | E1: EntryTime | F1: ExitTime | G1: TimeToClear_s | H1: Cleared | I1: ObstacleTouched | J1: ContactDuration_s | K1: ContactCount | L1: FirstContactTime_s | M1: JetpackActiveTime_s | N1: CrouchTime_s | O1: AirborneTime_s | P1: ContactX | Q1: ContactY | R1: ContactZ
A2: GATE | B2: 1 | C2: 1 | D2: 1 | E2: 4397.26 | F2: 4398.2 | G2: 0.9399 | H2: 1 | I2: 1 | J2: 0.04 | K2: 2 | L2: 0.46 | M2: 0 | N2: 0 | O2: 0.5879 | P2: 109.6299 | Q2: 2.2665 | R2: 11.1297
A3: DEATH
A4: GATE | B4: 1 | C4: 1 | D4: 1 | E4: 4431.52 | F4: 4433.38 | G4: 1.8599 | H4: 1 | I4: 1 | J4: 0.3799 | K4: 3 | L4: 0.7598 | M4: 0.4849 | N4: 0 | O4: 1.4702 | P4: 109.585 | Q4: 2.2482 | R4: 10.0963
A5: GATE | B5: 2 | C5: 2 | D5: 2 | E5: 4437.16 | F5: 4438.24 | G5: 1.0801 | H5: 1 | I5: 0 | J5: 0 | K5: 0 | L5: -1 | M5: 0.743 | N5: 0 | O5: 1.0771 | P5: 157.5687 | Q5: 2.577 | R5: 9.2687
A6: DEATH
A7: GATE | B7: 1 | C7: 1 | D7: 1 | E7: 4445.98 | F7: 4448.82 | G7: 2.8398 | H7: 1 | I7: 0 | J7: 0 | K7: 0 | L7: -1 | M7: 0.9792 | N7: 0 | O7: 2.7107 | P7: 109.5427 | Q7: 7.0117 | R7: 11.3224
A8: DEATH
A9: GATE | B9: 1 | C9: 1 | D9: 1 | E9: 4455.18 | F9: 4457.62 | G9: 2.4404 | H9: 1 | I9: 1 | J9: 0.1602 | K9: 2 | L9: 2.2803 | M9: 0.6468 | N9: 0 | O9: 2.1666 | P9: 0 | Q9: 0 | R9: 0
A10: DEATH
A11: GATE | B11: 1 | C11: 1 | D11: 1 | E11: 4463.88 | F11: 4465.8 | G11: 1.9199 | H11: 1 | I11: 1 | J11: 0.2798 | K11: 3 | L11: 0.7402 | M11: 0 | N11: 0 | O11: 1.1329 | P11: 109.5792 | Q11: 2.2628 | R11: 9.7797
A12: GATE | B12: 2 | C12: 2 | D12: 2 | E12: 4470.04 | F12: 4471.2 | G12: 1.1597 | H12: 1 | I12: 0 | J12: 0 | K12: 0 | L12: -1 | M12: 0.2147 | N12: 0 | O12: 1.1179 | P12: 157.5773 | Q12: 4.6972 | R12: 9.2416
A13: GATE | B13: 3 | C13: 3 | D13: 3 | E13: 4472.3 | F13: 4473.22 | G13: 0.9199 | H13: 1 | I13: 1 | J13: 0.3198 | K13: 2 | L13: 0.6001 | M13: 0.0756 | N13: 0 | O13: 0.9313 | P13: 0 | Q13: 0 | R13: 0
A14: DEATH
A15: GATE | B15: 1 | C15: 1 | D15: 1 | E15: 4481.1 | F15: 4483.2 | G15: 2.0996 | H15: 1 | I15: 0 | J15: 0 | K15: 0 | L15: -1 | M15: 0.9998 | N15: 0 | O15: 1.9511 | P15: 109.4868 | Q15: 11.073 | R15: 10.1646
A16: GATE | B16: 2 | C16: 2 | D16: 2 | E16: 4486.26 | F16: 4487.36 | G16: 1.1001 | H16: 1 | I16: 0 | J16: 0 | K16: 0 | L16: -1 | M16: 0.0228 | N16: 0 | O16: 0.901 | P16: 157.5478 | Q16: 2.298 | R16: 11.3895
A17: GATE | B17: 3 | C17: 3 | D17: 3 | E17: 4489.02 | F17: 4490.5 | G17: 1.48 | H17: 1 | I17: 0 | J17: 0 | K17: 0 | L17: -1 | M17: 0.2132 | N17: 0 | O17: 1.464 | P17: 187.4743 | Q17: 2.8176 | R17: 14.3021
A18: DEATH
A19: GATE | B19: 1 | C19: 1 | D19: 1 | E19: 4499.16 | F19: 4500.98 | G19: 1.8203 | H19: 1 | I19: 0 | J19: 0 | K19: 0 | L19: -1 | M19: 0.7361 | N19: 0 | O19: 1.5351 | P19: 109.5588 | Q19: 2.4164 | R19: 11.4123
A20: GATE | B20: 2 | C20: 2 | D20: 2 | E20: 4504.44 | F20: 4505.48 | G20: 1.04 | H20: 1 | I20: 0 | J20: 0 | K20: 0 | L20: -1 | M20: 0.5496 | N20: 0 | O20: 0.8668 | P20: 157.5222 | Q20: 2.3201 | R20: 10.346
A21: DEATH
A22: GATE | B22: 1 | C22: 1 | D22: 1 | E22: 4514.62 | F22: 4516.9 | G22: 2.2798 | H22: 1 | I22: 0 | J22: 0 | K22: 0 | L22: -1 | M22: 1.1478 | N22: 0 | O22: 2.2723 | P22: 109.5256 | Q22: 18.1268 | R22: 11.1869
A23: GATE | B23: 2 | C23: 2 | D23: 2 | E23: 4520.9 | F23: 4522.28 | G23: 1.3799 | H23: 1 | I23: 0 | J23: 0 | K23: 0 | L23: -1 | M23: 0.0974 | N23: 0 | O23: 1.3747 | P23: 157.4576 | Q23: 12.7282 | R23: 10.0247
A24: DEATH
A25: GATE | B25: 1 | C25: 1 | D25: 1 | E25: 4530.84 | F25: 4533.66 | G25: 2.8198 | H25: 1 | I25: 0 | J25: 0 | K25: 0 | L25: -1 | M25: 1.4202 | N25: 0 | O25: 2.6748 | P25: 109.4578 | Q25: 4.525 | R25: 9.0703
A26: DEATH
A27: GATE | B27: 1 | C27: 1 | D27: 1 | E27: 4547.76 | F27: 4550.18 | G27: 2.4199 | H27: 1 | I27: 0 | J27: 0 | K27: 0 | L27: -1 | M27: 0.5675 | N27: 0 | O27: 2.2761 | P27: 109.4652 | Q27: 2.2791 | R27: 10.3712
A28: DEATH
A29: GATE | B29: 1 | C29: 1 | D29: 1 | E29: 4558 | F29: 4559.08 | G29: 1.0801 | H29: 1 | I29: 0 | J29: 0 | K29: 0 | L29: -1 | M29: 0.6617 | N29: 0 | O29: 1.0868 | P29: 109.8642 | Q29: 2.5005 | R29: 10.5243
A30: DEATH
A31: GATE | B31: 1 | C31: 1 | D31: 1 | E31: 4567.7 | F31: 4569.08 | G31: 1.3804 | H31: 1 | I31: 0 | J31: 0 | K31: 0 | L31: -1 | M31: 0 | N31: 0 | O31: 0.8683 | P31: 109.5891 | Q31: 2.2757 | R31: 8.5842
A32: DEATH
A33: GATE | B33: 1 | C33: 1 | D33: 1 | E33: 4577.68 | F33: 4579.84 | G33: 2.1602 | H33: 1 | I33: 0 | J33: 0 | K33: 0 | L33: -1 | M33: 1.0831 | N33: 0 | O33: 2.1658 | P33: 109.4602 | Q33: 10.4954 | R33: 12.1774
A34: GATE | B34: 2 | C34: 2 | D34: 2 | E34: 4582.74 | F34: 4583.84 | G34: 1.1001 | H34: 1 | I34: 0 | J34: 0 | K34: 0 | L34: -1 | M34: 0 | N34: 0 | O34: 0.8665 | P34: 157.8559 | Q34: 2.2372 | R34: 11.7537
A35: DEATH
A36: GATE | B36: 1 | C36: 1 | D36: 1 | E36: 4591.2 | F36: 4593.08 | G36: 1.8804 | H36: 1 | I36: 1 | J36: 0.02 | K36: 1 | L36: 0.7402 | M36: 0.0234 | N36: 0 | O36: 1.1476 | P36: 0 | Q36: 0 | R36: 0
A37: GATE | B37: 1 | C37: 1 | D37: 1 | E37: 4596.26 | F37: 4597.42 | G37: 1.1602 | H37: 1 | I37: 0 | J37: 0 | K37: 0 | L37: -1 | M37: 0 | N37: 0 | O37: 0.4726 | P37: 0 | Q37: 0 | R37: 0
A38: DEATH
A39: GATE | B39: 1 | C39: 1 | D39: 1 | E39: 4606.68 | F39: 4607.62 | G39: 0.9404 | H39: 1 | I39: 0 | J39: 0 | K39: 0 | L39: -1 | M39: 0.0969 | N39: 0 | O39: 0.6085 | P39: 109.6598 | Q39: 2.267 | R39: 12.3892
A40: DEATH
...

Sheet DiegoContreras
A1: EventType | B1: AttemptID | C1: SegmentID | D1: GateID | E1: EntryTime | F1: ExitTime | G1: TimeToClear_s | H1: Cleared | I1: ObstacleTouched | J1: ContactDuration_s | K1: ContactCount | L1: FirstContactTime_s | M1: JetpackActiveTime_s | N1: CrouchTime_s | O1: AirborneTime_s | P1: ContactX | Q1: ContactY | R1: ContactZ
A2: GATE | B2: 1 | C2: 1 | D2: 1 | E2: 2353.32 | F2: 2354.5 | G2: 1.1799 | H2: 1 | I2: 0 | J2: 0 | K2: 0 | L2: -1 | M2: 0 | N2: 0 | O2: 0.8013 | P2: 0 | Q2: 0 | R2: 0
A3: GATE | B3: 2 | C3: 2 | D3: 2 | E3: 2358.34 | F3: 2360.1 | G3: 1.76 | H3: 1 | I3: 1 | J3: 0.02 | K3: 1 | L3: 0.54 | M3: 0 | N3: 0 | O3: 0.6667 | P3: 157.5288 | Q3: 2.2912 | R3: 10.0462
A4: GATE | B4: 3 | C4: 3 | D4: 3 | E4: 2362.1 | F4: 2363.34 | G4: 1.24 | H4: 1 | I4: 0 | J4: 0 | K4: 0 | L4: -1 | M4: 0.8164 | N4: 0 | O4: 1.0645 | P4: 187.6158 | Q4: 2.532 | R4: 9.4382
A5: GATE | B5: 4 | C5: 4 | D5: 4 | E5: 2370.98 | F5: 2371.76 | G5: 0.78 | H5: 1 | I5: 1 | J5: 0.04 | K5: 1 | L5: 0.4399 | M5: 0 | N5: 0 | O5: 0.6237 | P5: 178.3818 | Q5: 2.2437 | R5: 58.4177
A6: GATE | B6: 5 | C6: 5 | D6: 5 | E6: 2371.8 | F6: 2374.84 | G6: 3.0398 | H6: 1 | I6: 0 | J6: 0 | K6: 0 | L6: -1 | M6: 1.5164 | N6: 0 | O6: 2.7573 | P6: 0 | Q6: 0 | R6: 0
A7: GATE | B7: 6 | C7: 6 | D7: 6 | E7: 2375.26 | F7: 2376.24 | G7: 0.98 | H7: 1 | I7: 1 | J7: 0.0601 | K7: 1 | L7: 0.6599 | M7: 0.0325 | N7: 0 | O7: 0.9818 | P7: 0 | Q7: 0 | R7: 0
A8: GATE | B8: 6 | C8: 6 | D8: 6 | E8: 2376.4 | F8: 2376.5 | G8: 0.1001 | H8: 1 | I8: 0 | J8: 0 | K8: 0 | L8: -1 | M8: 0 | N8: 0 | O8: 0.0917 | P8: 0 | Q8: 0 | R8: 0
A9: DEATH
A10: GATE | B10: 4 | C10: 4 | D10: 4 | E10: 2385.96 | F10: 2386.68 | G10: 0.72 | H10: 1 | I10: 1 | J10: 0.0999 | K10: 3 | L10: 0.3 | M10: 0 | N10: 0 | O10: 0.6011 | P10: 178.486 | Q10: 2.2396 | R10: 57.4886
A11: GATE | B11: 5 | C11: 5 | D11: 5 | E11: 2386.68 | F11: 2388.78 | G11: 2.1001 | H11: 1 | I11: 1 | J11: 0.5 | K11: 1 | L11: 0.72 | M11: 0.1542 | N11: 0 | O11: 1.2059 | P11: 164.7516 | Q11: 1.9059 | R11: 56.7204
A12: GATE | B12: 6 | C12: 6 | D12: 6 | E12: 2389.16 | F12: 2390.54 | G12: 1.3801 | H12: 1 | I12: 0 | J12: 0 | K12: 0 | L12: -1 | M12: 0.9318 | N12: 0 | O12: 1.3949 | P12: 147.5761 | Q12: 3.5115 | R12: 57.606
A13: DEATH
A14: DEATH
A15: GATE | B15: 4 | C15: 4 | D15: 4 | E15: 2408.88 | F15: 2409.94 | G15: 1.0601 | H15: 1 | I15: 0 | J15: 0 | K15: 0 | L15: -1 | M15: 0 | N15: 0 | O15: 0 | P15: 0 | Q15: 0 | R15: 0
A16: GATE | B16: 5 | C16: 5 | D16: 5 | E16: 2409.94 | F16: 2411 | G16: 1.0601 | H16: 1 | I16: 0 | J16: 0 | K16: 0 | L16: -1 | M16: 0 | N16: 0 | O16: 0 | P16: 0 | Q16: 0 | R16: 0
A17: GATE | B17: 6 | C17: 6 | D17: 6 | E17: 2411.3 | F17: 2412.36 | G17: 1.0598 | H17: 1 | I17: 0 | J17: 0 | K17: 0 | L17: -1 | M17: 0 | N17: 0 | O17: 0 | P17: 0 | Q17: 0 | R17: 0
A18: GATE | B18: 7 | C18: 7 | D18: 7 | E18: 2414.3 | F18: 2415.72 | G18: 1.4199 | H18: 1 | I18: 0 | J18: 0 | K18: 0 | L18: -1 | M18: 0.1936 | N18: 0 | O18: 1.0014 | P18: 0 | Q18: 0 | R18: 0
A19: GATE | B19: 8 | C19: 8 | D19: 8 | E19: 2416.7 | F19: 2418.4 | G19: 1.7 | H19: 1 | I19: 0 | J19: 0 | K19: 0 | L19: -1 | M19: 0.5438 | N19: 0 | O19: 1.6312 | P19: 87.3154 | Q19: 5.2217 | R19: 60.8736
A20: DEATH
A21: GATE | B21: 4 | C21: 4 | D21: 4 | E21: 2428.84 | F21: 2429.9 | G21: 1.0601 | H21: 1 | I21: 0 | J21: 0 | K21: 0 | L21: -1 | M21: 0 | N21: 0 | O21: 0 | P21: 0 | Q21: 0 | R21: 0
A22: GATE | B22: 5 | C22: 5 | D22: 5 | E22: 2429.92 | F22: 2430.96 | G22: 1.04 | H22: 1 | I22: 0 | J22: 0 | K22: 0 | L22: -1 | M22: 0 | N22: 0 | O22: 0 | P22: 0 | Q22: 0 | R22: 0
A23: GATE | B23: 6 | C23: 6 | D23: 6 | E23: 2431.24 | F23: 2432.3 | G23: 1.0601 | H23: 1 | I23: 0 | J23: 0 | K23: 0 | L23: -1 | M23: 0 | N23: 0 | O23: 0 | P23: 0 | Q23: 0 | R23: 0
A24: GATE | B24: 7 | C24: 7 | D24: 7 | E24: 2434.2 | F24: 2434.96 | G24: 0.76 | H24: 1 | I24: 1 | J24: 0.02 | K24: 1 | L24: 0.3999 | M24: 0 | N24: 0 | O24: 0.6005 | P24: 108.2375 | Q24: 2.246 | R24: 58.1321
A25: GATE | B25: 8 | C25: 8 | D25: 8 | E25: 2435.76 | F25: 2436.68 | G25: 0.9199 | H25: 1 | I25: 1 | J25: 0.0398 | K25: 1 | L25: 0.3 | M25: 0 | N25: 0 | O25: 0.6759 | P25: 87.333 | Q25: 1.8309 | R25: 59.8161
A26: DEATH
A27: GATE | B27: 4 | C27: 4 | D27: 4 | E27: 2454.54 | F27: 2455.56 | G27: 1.02 | H27: 1 | I27: 0 | J27: 0 | K27: 0 | L27: -1 | M27: 0 | N27: 0 | O27: 0 | P27: 0 | Q27: 0 | R27: 0
A28: GATE | B28: 5 | C28: 5 | D28: 5 | E28: 2455.6 | F28: 2456.64 | G28: 1.04 | H28: 1 | I28: 0 | J28: 0 | K28: 0 | L28: -1 | M28: 0 | N28: 0 | O28: 0 | P28: 0 | Q28: 0 | R28: 0
A29: GATE | B29: 6 | C29: 6 | D29: 6 | E29: 2456.92 | F29: 2457.96 | G29: 1.04 | H29: 1 | I29: 0 | J29: 0 | K29: 0 | L29: -1 | M29: 0 | N29: 0 | O29: 0 | P29: 0 | Q29: 0 | R29: 0
A30: GATE | B30: 7 | C30: 7 | D30: 7 | E30: 2459.92 | F30: 2462.18 | G30: 2.26 | H30: 1 | I30: 1 | J30: 1.1799 | K30: 5 | L30: 0.48 | M30: 1.1907 | N30: 0 | O30: 1.676 | P30: 0 | Q30: 0 | R30: 0
A31: GATE | B31: 8 | C31: 8 | D31: 8 | E31: 2462.92 | F31: 2463.96 | G31: 1.04 | H31: 1 | I31: 0 | J31: 0 | K31: 0 | L31: -1 | M31: 0.0257 | N31: 0 | O31: 1.0495 | P31: 0 | Q31: 0 | R31: 0
A32: DEATH
A33: GATE | B33: 4 | C33: 4 | D33: 4 | E33: 2475 | F33: 2475.8 | G33: 0.8 | H33: 1 | I33: 0 | J33: 0 | K33: 0 | L33: -1 | M33: 0 | N33: 0 | O33: 0.6484 | P33: 178.3375 | Q33: 2.2418 | R33: 56.5448
A34: GATE | B34: 5 | C34: 5 | D34: 5 | E34: 2475.84 | F34: 2477.12 | G34: 1.28 | H34: 1 | I34: 1 | J34: 0.28 | K34: 1 | L34: 0.3801 | M34: 0 | N34: 0 | O34: 0.7582 | P34: 164.6786 | Q34: 1.8533 | R34: 55.7368
A35: GATE | B35: 6 | C35: 6 | D35: 6 | E35: 2477.28 | F35: 2478.22 | G35: 0.9399 | H35: 1 | I35: 1 | J35: 0.2998 | K35: 3 | L35: 0.24 | M35: 0 | N35: 0 | O35: 0.6539 | P35: 0 | Q35: 0 | R35: 0
A36: GATE | B36: 7 | C36: 7 | D36: 7 | E36: 2480.28 | F36: 2482.32 | G36: 2.0398 | H36: 1 | I36: 0 | J36: 0 | K36: 0 | L36: -1 | M36: 0.4489 | N36: 0 | O36: 1.0848 | P36: 108.3296 | Q36: 2.2427 | R36: 59.7128
A37: GATE | B37: 8 | C37: 8 | D37: 8 | E37: 2483.08 | F37: 2484.48 | G37: 1.4001 | H37: 1 | I37: 0 | J37: 0 | K37: 0 | L37: -1 | M37: 0.3275 | N37: 0 | O37: 1.3999 | P37: 87.2512 | Q37: 11.7969 | R37: 58.9423
A38: DEATH
A39: GATE | B39: 4 | C39: 4 | D39: 4 | E39: 2496.98 | F39: 2497.94 | G39: 0.96 | H39: 1 | I39: 0 | J39: 0 | K39: 0 | L39: -1 | M39: 0 | N39: 0 | O39: 0.6808 | P39: 0 | Q39: 0 | R39: 0
A40: GATE | B40: 5 | C40: 5 | D40: 5 | E40: 2497.98 | F40: 2499.76 | G40: 1.78 | H40: 1 | I40: 1 | J40: 0.3 | K40: 1 | L40: 0.46 | M40: 0.2458 | N40: 0 | O40: 1.1138 | P40: 164.6896 | Q40: 1.8295 | R40: 55.2913
...

Sheet FranPerez
A1: EventType | B1: AttemptID | C1: SegmentID | D1: GateID | E1: EntryTime | F1: ExitTime | G1: TimeToClear_s | H1: Cleared | I1: ObstacleTouched | J1: ContactDuration_s | K1: ContactCount | L1: FirstContactTime_s | M1: JetpackActiveTime_s | N1: CrouchTime_s | O1: AirborneTime_s | P1: ContactX | Q1: ContactY | R1: ContactZ
A2: GATE | B2: 1 | C2: 1 | D2: 1 | E2: 1152.96 | F2: 1154.38 | G2: 1.42 | H2: 1 | I2: 1 | J2: 0.0801 | K2: 3 | L2: 0.74 | M2: 0 | N2: 0 | O2: 0.7196 | P2: 109.6224 | Q2: 2.4084 | R2: 11.1423
A3: GATE | B3: 2 | C3: 2 | D3: 2 | E3: 1158.36 | F3: 1159.54 | G3: 1.1799 | H3: 1 | I3: 0 | J3: 0 | K3: 0 | L3: -1 | M3: 0 | N3: 0 | O3: 0.6011 | P3: 157.6779 | Q3: 2.3199 | R3: 10.9076
A4: GATE | B4: 3 | C4: 3 | D4: 3 | E4: 1161.64 | F4: 1163.36 | G4: 1.72 | H4: 1 | I4: 0 | J4: 0 | K4: 0 | L4: -1 | M4: 0.0748 | N4: 0 | O4: 0.8207 | P4: 187.8502 | Q4: 2.2975 | R4: 10.8371
A5: GATE | B5: 4 | C5: 4 | D5: 4 | E5: 1173.86 | F5: 1174.84 | G5: 0.98 | H5: 1 | I5: 1 | J5: 0.14 | K5: 3 | L5: 0.48 | M5: 0 | N5: 0 | O5: 0.5768 | P5: 178.3295 | Q5: 2.2474 | R5: 57.3808
A6: GATE | B6: 5 | C6: 5 | D6: 5 | E6: 1174.84 | F6: 1175.64 | G6: 0.8 | H6: 1 | I6: 1 | J6: 0.1 | K6: 1 | L6: 0.4 | M6: 0 | N6: 0 | O6: 0.5456 | P6: 0 | Q6: 0 | R6: 0
A7: GATE | B7: 6 | C7: 6 | D7: 6 | E7: 1175.84 | F7: 1176.9 | G7: 1.0601 | H7: 1 | I7: 1 | J7: 0.12 | K7: 3 | L7: 0.62 | M7: 0 | N7: 0 | O7: 0.6663 | P7: 0 | Q7: 0 | R7: 0
A8: DEATH
A9: GATE | B9: 4 | C9: 4 | D9: 4 | E9: 1189.44 | F9: 1190.44 | G9: 1 | H9: 1 | I9: 0 | J9: 0 | K9: 0 | L9: -1 | M9: 0 | N9: 0 | O9: 0 | P9: 0 | Q9: 0 | R9: 0
A10: GATE | B10: 5 | C10: 5 | D10: 5 | E10: 1190.48 | F10: 1191.82 | G10: 1.34 | H10: 1 | I10: 0 | J10: 0 | K10: 0 | L10: -1 | M10: 0 | N10: 0 | O10: 0.3028 | P10: 0 | Q10: 0 | R10: 0
A11: GATE | B11: 6 | C11: 6 | D11: 6 | E11: 1192.08 | F11: 1192.8 | G11: 0.72 | H11: 1 | I11: 0 | J11: 0 | K11: 0 | L11: -1 | M11: 0 | N11: 0 | O11: 0.5977 | P11: 0 | Q11: 0 | R11: 0
A12: GATE | B12: 7 | C12: 7 | D12: 7 | E12: 1194.78 | F12: 1196.4 | G12: 1.62 | H12: 1 | I12: 1 | J12: 0.02 | K12: 1 | L12: 0.36 | M12: 0.1212 | N12: 0 | O12: 1.0663 | P12: 0 | Q12: 0 | R12: 0
A13: GATE | B13: 8 | C13: 8 | D13: 8 | E13: 1197.18 | F13: 1200.38 | G13: 3.2001 | H13: 1 | I13: 1 | J13: 0.7001 | K13: 1 | L13: 1.62 | M13: 0.5089 | N13: 0 | O13: 2.2527 | P13: 87.4616 | Q13: 5.2626 | R13: 58.9422
A14: DEATH
A15: GATE | B15: 4 | C15: 4 | D15: 4 | E15: 1209.78 | F15: 1210.84 | G15: 1.0599 | H15: 1 | I15: 0 | J15: 0 | K15: 0 | L15: -1 | M15: 0 | N15: 0 | O15: 0 | P15: 0 | Q15: 0 | R15: 0
A16: GATE | B16: 5 | C16: 5 | D16: 5 | E16: 1210.84 | F16: 1211.9 | G16: 1.0601 | H16: 1 | I16: 0 | J16: 0 | K16: 0 | L16: -1 | M16: 0 | N16: 0 | O16: 0 | P16: 0 | Q16: 0 | R16: 0
A17: GATE | B17: 6 | C17: 6 | D17: 6 | E17: 1212.18 | F17: 1213.24 | G17: 1.0601 | H17: 1 | I17: 0 | J17: 0 | K17: 0 | L17: -1 | M17: 0 | N17: 0 | O17: 0 | P17: 0 | Q17: 0 | R17: 0
A18: GATE | B18: 7 | C18: 7 | D18: 7 | E18: 1215.16 | F18: 1217.1 | G18: 1.9401 | H18: 1 | I18: 1 | J18: 0.0399 | K18: 1 | L18: 0.4801 | M18: 0.3691 | N18: 0 | O18: 1.406 | P18: 108.284 | Q18: 2.5529 | R18: 55.0235
A19: GATE | B19: 8 | C19: 8 | D19: 8 | E19: 1217.82 | F19: 1218.06 | G19: 0.24 | H19: 1 | I19: 0 | J19: 0 | K19: 0 | L19: -1 | M19: 0 | N19: 0 | O19: 0.2386 | P19: 0 | Q19: 0 | R19: 0
A20: DEATH
A21: DEATH
A22: GATE | B22: 4 | C22: 4 | D22: 4 | E22: 1259.04 | F22: 1260.08 | G22: 1.04 | H22: 1 | I22: 0 | J22: 0 | K22: 0 | L22: -1 | M22: 0 | N22: 0 | O22: 0 | P22: 0 | Q22: 0 | R22: 0
A23: GATE | B23: 5 | C23: 5 | D23: 5 | E23: 1260.12 | F23: 1261.14 | G23: 1.02 | H23: 1 | I23: 0 | J23: 0 | K23: 0 | L23: -1 | M23: 0 | N23: 0 | O23: 0 | P23: 0 | Q23: 0 | R23: 0
A24: GATE | B24: 6 | C24: 6 | D24: 6 | E24: 1261.46 | F24: 1262.48 | G24: 1.02 | H24: 1 | I24: 0 | J24: 0 | K24: 0 | L24: -1 | M24: 0 | N24: 0 | O24: 0 | P24: 0 | Q24: 0 | R24: 0
A25: GATE | B25: 7 | C25: 7 | D25: 7 | E25: 1264.44 | F25: 1265.36 | G25: 0.92 | H25: 1 | I25: 0 | J25: 0 | K25: 0 | L25: -1 | M25: 0.119 | N25: 0 | O25: 0.7028 | P25: 108.4478 | Q25: 2.3077 | R25: 55.3766
A26: GATE | B26: 8 | C26: 8 | D26: 8 | E26: 1265.92 | F26: 1267.62 | G26: 1.7001 | H26: 1 | I26: 1 | J26: 0.0399 | K26: 1 | L26: 0.4601 | M26: 0 | N26: 0 | O26: 1.0617 | P26: 87.2977 | Q26: 1.8607 | R26: 62.3503
A27: GATE | B27: 8 | C27: 8 | D27: 8 | E27: 1268.04 | F27: 1268.24 | G27: 0.2001 | H27: 1 | I27: 0 | J27: 0 | K27: 0 | L27: -1 | M27: 0.1155 | N27: 0 | O27: 0.194 | P27: 0 | Q27: 0 | R27: 0

Sheet JoaquinAguilar
A1: EventType | B1: AttemptID | C1: SegmentID | D1: GateID | E1: EntryTime | F1: ExitTime | G1: TimeToClear_s | H1: Cleared | I1: ObstacleTouched | J1: ContactDuration_s | K1: ContactCount | L1: FirstContactTime_s | M1: JetpackActiveTime_s | N1: CrouchTime_s | O1: AirborneTime_s | P1: ContactX | Q1: ContactY | R1: ContactZ
A2: GATE | B2: 1 | C2: 1 | D2: 1 | E2: 1466.98 | F2: 1468.98 | G2: 2 | H2: 1 | I2: 0 | J2: 0 | K2: 0 | L2: -1 | M2: 1.3063 | N2: 0 | O2: 2.0005 | P2: 109.4854 | Q2: 2.5369 | R2: 10.9766
A3: GATE | B3: 2 | C3: 2 | D3: 2 | E3: 1472.86 | F3: 1474.04 | G3: 1.1799 | H3: 1 | I3: 0 | J3: 0 | K3: 0 | L3: -1 | M3: 0.1363 | N3: 0 | O3: 1.0594 | P3: 157.6338 | Q3: 5.1698 | R3: 10.4113
A4: GATE | B4: 3 | C4: 3 | D4: 3 | E4: 1475.66 | F4: 1476.84 | G4: 1.1801 | H4: 1 | I4: 0 | J4: 0 | K4: 0 | L4: -1 | M4: 0.6932 | N4: 0 | O4: 1.0951 | P4: 187.6945 | Q4: 2.271 | R4: 9.4139
A5: GATE | B5: 4 | C5: 4 | D5: 4 | E5: 1494.64 | F5: 1496.26 | G5: 1.62 | H5: 1 | I5: 0 | J5: 0 | K5: 0 | L5: -1 | M5: 1.1059 | N5: 0 | O5: 1.6315 | P5: 0 | Q5: 0 | R5: 0
A6: GATE | B6: 5 | C6: 5 | D6: 5 | E6: 1496.3 | F6: 1497.7 | G6: 1.4 | H6: 1 | I6: 0 | J6: 0 | K6: 0 | L6: -1 | M6: 0.3739 | N6: 0 | O6: 1.4082 | P6: 164.6581 | Q6: 14.9401 | R6: 56.5432
A7: GATE | B7: 6 | C7: 6 | D7: 6 | E7: 1498.12 | F7: 1499.1 | G7: 0.98 | H7: 1 | I7: 1 | J7: 0.16 | K7: 3 | L7: 0.6599 | M7: 0.0233 | N7: 0 | O7: 0.9789 | P7: 0 | Q7: 0 | R7: 0
A8: DEATH
A9: GATE | B9: 4 | C9: 4 | D9: 4 | E9: 1508.14 | F9: 1509.58 | G9: 1.4399 | H9: 1 | I9: 0 | J9: 0 | K9: 0 | L9: -1 | M9: 1.005 | N9: 0 | O9: 1.4552 | P9: 0 | Q9: 0 | R9: 0
A10: GATE | B10: 5 | C10: 5 | D10: 5 | E10: 1509.58 | F10: 1510.96 | G10: 1.38 | H10: 1 | I10: 0 | J10: 0 | K10: 0 | L10: -1 | M10: 0.2898 | N10: 0 | O10: 1.3696 | P10: 164.3648 | Q10: 4.7751 | R10: 57.8643
A11: DEATH
A12: GATE | B12: 4 | C12: 4 | D12: 4 | E12: 1519.7 | F12: 1520.74 | G12: 1.04 | H12: 1 | I12: 0 | J12: 0 | K12: 0 | L12: -1 | M12: 0 | N12: 0 | O12: 0 | P12: 0 | Q12: 0 | R12: 0
A13: GATE | B13: 5 | C13: 5 | D13: 5 | E13: 1520.74 | F13: 1521.82 | G13: 1.08 | H13: 1 | I13: 0 | J13: 0 | K13: 0 | L13: -1 | M13: 0 | N13: 0 | O13: 0 | P13: 0 | Q13: 0 | R13: 0
A14: GATE | B14: 6 | C14: 6 | D14: 6 | E14: 1522.1 | F14: 1523.16 | G14: 1.0599 | H14: 1 | I14: 0 | J14: 0 | K14: 0 | L14: -1 | M14: 0 | N14: 0 | O14: 0 | P14: 0 | Q14: 0 | R14: 0
A15: GATE | B15: 7 | C15: 7 | D15: 7 | E15: 1524.98 | F15: 1526.74 | G15: 1.76 | H15: 1 | I15: 0 | J15: 0 | K15: 0 | L15: -1 | M15: 0.5544 | N15: 0 | O15: 1.7404 | P15: 107.9163 | Q15: 2.6592 | R15: 58.2691
A16: GATE | B16: 8 | C16: 8 | D16: 8 | E16: 1527.46 | F16: 1528.9 | G16: 1.4401 | H16: 1 | I16: 0 | J16: 0 | K16: 0 | L16: -1 | M16: 0.5604 | N16: 0 | O16: 1.4383 | P16: 87.4726 | Q16: 5.8904 | R16: 59.8889
A17: DEATH
A18: GATE | B18: 4 | C18: 4 | D18: 4 | E18: 1539.68 | F18: 1540.72 | G18: 1.04 | H18: 1 | I18: 0 | J18: 0 | K18: 0 | L18: -1 | M18: 0 | N18: 0 | O18: 0 | P18: 0 | Q18: 0 | R18: 0
A19: GATE | B19: 5 | C19: 5 | D19: 5 | E19: 1540.72 | F19: 1541.78 | G19: 1.0599 | H19: 1 | I19: 0 | J19: 0 | K19: 0 | L19: -1 | M19: 0 | N19: 0 | O19: 0 | P19: 0 | Q19: 0 | R19: 0
A20: GATE | B20: 6 | C20: 6 | D20: 6 | E20: 1542.04 | F20: 1543.1 | G20: 1.0601 | H20: 1 | I20: 0 | J20: 0 | K20: 0 | L20: -1 | M20: 0 | N20: 0 | O20: 0 | P20: 0 | Q20: 0 | R20: 0
A21: GATE | B21: 7 | C21: 7 | D21: 7 | E21: 1545.06 | F21: 1545.94 | G21: 0.88 | H21: 1 | I21: 0 | J21: 0 | K21: 0 | L21: -1 | M21: 0 | N21: 0 | O21: 0.6946 | P21: 0 | Q21: 0 | R21: 0
A22: GATE | B22: 8 | C22: 8 | D22: 8 | E22: 1546.34 | F22: 1547.86 | G22: 1.52 | H22: 1 | I22: 0 | J22: 0 | K22: 0 | L22: -1 | M22: 0.3292 | N22: 0 | O22: 1.2769 | P22: 86.9668 | Q22: 2.3 | R22: 60.0019

Sheet LourdesArtigas
A1: EventType | B1: AttemptID | C1: SegmentID | D1: GateID | E1: EntryTime | F1: ExitTime | G1: TimeToClear_s | H1: Cleared | I1: ObstacleTouched | J1: ContactDuration_s | K1: ContactCount | L1: FirstContactTime_s | M1: JetpackActiveTime_s | N1: CrouchTime_s | O1: AirborneTime_s | P1: ContactX | Q1: ContactY | R1: ContactZ | S1: Unnamed: 18 | T1: Unnamed: 19
A2: GATE | B2: 1 | C2: 1 | D2: 1 | E2: 67.14 | F2: 68.3 | G2: 1.16 | H2: 1 | I2: 1 | J2: 0.04 | K2: 2 | L2: 0.68 | M2: 0 | N2: 0 | O2: 0.5764 | P2: 109.5334 | Q2: 2.2497 | R2: 11.6704
A3: GATE | B3: 2 | C3: 2 | D3: 2 | E3: 72.64 | F3: 73.8 | G3: 1.16 | H3: 1 | I3: 1 | J3: 0.02 | K3: 1 | L3: 0.72 | M3: 0 | N3: 0 | O3: 0.6102 | P3: 157.7393 | Q3: 2.248 | R3: 13.0537
A4: GATE | B4: 3 | C4: 3 | D4: 3 | E4: 75.88 | F4: 76.98 | G4: 1.1 | H4: 1 | I4: 0 | J4: 0 | K4: 0 | L4: -1 | M4: 0 | N4: 0 | O4: 1.0351 | P4: 0 | Q4: 0 | R4: 0
A5: DEATH
A6: GATE | B6: 1 | C6: 1 | D6: 1 | E6: 84.9 | F6: 86.14 | G6: 1.24 | H6: 1 | I6: 1 | J6: 0.1 | K6: 3 | L6: 0.68 | M6: 0 | N6: 0 | O6: 0.5345 | P6: 109.5201 | Q6: 2.2472 | R6: 10.9372
A7: DEATH | T7: 1
A8: GATE | B8: 1 | C8: 1 | D8: 1 | E8: 97.16 | F8: 98.46 | G8: 1.3 | H8: 1 | I8: 1 | J8: 0.12 | K8: 3 | L8: 0.72 | M8: 0 | N8: 0 | O8: 0.5217 | P8: 109.5029 | Q8: 2.2511 | R8: 11.7883
A9: GATE | B9: 2 | C9: 2 | D9: 2 | E9: 103.06 | F9: 104.06 | G9: 1 | H9: 1 | I9: 1 | J9: 0.32 | K9: 4 | L9: 0.68 | M9: 0 | N9: 0 | O9: 1.0032 | P9: 0 | Q9: 0 | R9: 0
A10: DEATH
A11: GATE | B11: 1 | C11: 1 | D11: 1 | E11: 111.84 | F11: 112.94 | G11: 1.1 | H11: 1 | I11: 0 | J11: 0 | K11: 0 | L11: -1 | M11: 0 | N11: 0 | O11: 0.6029 | P11: 109.5591 | Q11: 2.2321 | R11: 10.8582
A12: GATE | B12: 2 | C12: 2 | D12: 2 | E12: 116.66 | F12: 117.82 | G12: 1.16 | H12: 1 | I12: 0 | J12: 0 | K12: 0 | L12: -1 | M12: 0 | N12: 0 | O12: 0.532 | P12: 157.6609 | Q12: 2.2542 | R12: 10.5436
A13: GATE | B13: 3 | C13: 3 | D13: 3 | E13: 120.02 | F13: 121.32 | G13: 1.3 | H13: 1 | I13: 0 | J13: 0 | K13: 0 | L13: -1 | M13: 0.4146 | N13: 0 | O13: 0.8495 | P13: 0 | Q13: 0 | R13: 0
A14: DEATH
A15: GATE | B15: 4 | C15: 4 | D15: 4 | E15: 147.18 | F15: 148.58 | G15: 1.4 | H15: 1 | I15: 1 | J15: 0.3 | K15: 3 | L15: 0.42 | M15: 0 | N15: 0 | O15: 0.9096 | P15: 178.6158 | Q15: 2.2302 | R15: 58.8902
A16: GATE | B16: 5 | C16: 5 | D16: 5 | E16: 148.6 | F16: 148.66 | G16: 0.06 | H16: 1 | I16: 0 | J16: 0 | K16: 0 | L16: -1 | M16: 0 | N16: 0 | O16: 0.0619 | P16: 0 | Q16: 0 | R16: 0
A17: DEATH
A18: GATE | B18: 4 | C18: 4 | D18: 4 | E18: 158.48 | F18: 160.34 | G18: 1.86 | H18: 1 | I18: 1 | J18: 0.6 | K18: 3 | L18: 0.5 | M18: 0 | N18: 0 | O18: 1.2044 | P18: 178.6357 | Q18: 2.298 | R18: 55.5682
A19: GATE | B19: 5 | C19: 5 | D19: 5 | E19: 160.36 | F19: 160.4 | G19: 0.04 | H19: 1 | I19: 0 | J19: 0 | K19: 0 | L19: -1 | M19: 0 | N19: 0 | O19: 0.0312 | P19: 0 | Q19: 0 | R19: 0
A20: DEATH
A21: GATE | B21: 4 | C21: 4 | D21: 4 | E21: 170.38 | F21: 171.22 | G21: 0.84 | H21: 1 | I21: 1 | J21: 0.16 | K21: 3 | L21: 0.34 | M21: 0 | N21: 0 | O21: 0.6234 | P21: 0 | Q21: 0 | R21: 0
A22: GATE | B22: 5 | C22: 5 | D22: 5 | E22: 171.22 | F22: 172.38 | G22: 1.16 | H22: 1 | I22: 0 | J22: 0 | K22: 0 | L22: -1 | M22: 0 | N22: 0 | O22: 0.6163 | P22: 164.4816 | Q22: 1.7617 | R22: 60.0409
A23: GATE | B23: 6 | C23: 6 | D23: 6 | E23: 172.66 | F23: 173.7 | G23: 1.04 | H23: 1 | I23: 1 | J23: 0.24 | K23: 3 | L23: 0.48 | M23: 0 | N23: 0 | O23: 0.6022 | P23: 0 | Q23: 0 | R23: 0
A24: GATE | B24: 7 | C24: 7 | D24: 7 | E24: 175.74 | F24: 176.52 | G24: 0.78 | H24: 1 | I24: 1 | J24: 0.12 | K24: 2 | L24: 0.32 | M24: 0 | N24: 0 | O24: 0.6009 | P24: 0 | Q24: 0 | R24: 0
A25: GATE | B25: 8 | C25: 8 | D25: 8 | E25: 177.46 | F25: 179.32 | G25: 1.86 | H25: 1 | I25: 0 | J25: 0 | K25: 0 | L25: -1 | M25: 0 | N25: 0 | O25: 1.4201 | P25: 87.1129 | Q25: 1.8929 | R25: 58.5543
A26: DEATH
A27: GATE | B27: 4 | C27: 4 | D27: 4 | E27: 188.44 | F27: 190.24 | G27: 1.8 | H27: 1 | I27: 1 | J27: 0.44 | K27: 3 | L27: 0.44 | M27: 0.5928 | N27: 0 | O27: 1.3943 | P27: 178.7066 | Q27: 2.2789 | R27: 58.7113
A28: GATE | B28: 5 | C28: 5 | D28: 5 | E28: 190.28 | F28: 192.14 | G28: 1.86 | H28: 1 | I28: 0 | J28: 0 | K28: 0 | L28: -1 | M28: 0.8883 | N28: 0 | O28: 1.8584 | P28: 164.7701 | Q28: 12.215 | R28: 58.4021
A29: GATE | B29: 6 | C29: 6 | D29: 6 | E29: 192.52 | F29: 192.8 | G29: 0.28 | H29: 1 | I29: 0 | J29: 0 | K29: 0 | L29: -1 | M29: 0 | N29: 0 | O29: 0.2901 | P29: 0 | Q29: 0 | R29: 0
A30: DEATH
A31: GATE | B31: 4 | C31: 4 | D31: 4 | E31: 201.88 | F31: 202.98 | G31: 1.1 | H31: 1 | I31: 0 | J31: 0 | K31: 0 | L31: -1 | M31: 0 | N31: 0 | O31: 0.9633 | P31: 178.6709 | Q31: 2.2911 | R31: 61.0699
A32: DEATH
A33: GATE | B33: 4 | C33: 4 | D33: 4 | E33: 212.44 | F33: 213.4 | G33: 0.96 | H33: 1 | I33: 1 | J33: 0.2 | K33: 3 | L33: 0.44 | M33: 0 | N33: 0 | O33: 0.6188 | P33: 178.4818 | Q33: 2.2326 | R33: 56.6697
A34: GATE | B34: 5 | C34: 5 | D34: 5 | E34: 213.4 | F34: 214.66 | G34: 1.26 | H34: 1 | I34: 1 | J34: 0.42 | K34: 3 | L34: 0.38 | M34: 0 | N34: 0 | O34: 0.7044 | P34: 164.6239 | Q34: 1.8264 | R34: 58.2834
A35: GATE | B35: 6 | C35: 6 | D35: 6 | E35: 214.8 | F35: 215.72 | G35: 0.92 | H35: 1 | I35: 1 | J35: 0.2 | K35: 3 | L35: 0.38 | M35: 0 | N35: 0 | O35: 0.6079 | P35: 147.357 | Q35: 2.2306 | R35: 58.5953
A36: GATE | B36: 7 | C36: 7 | D36: 7 | E36: 218 | F36: 219 | G36: 1 | H36: 1 | I36: 1 | J36: 0.2 | K36: 3 | L36: 0.46 | M36: 0 | N36: 0 | O36: 0.6061 | P36: 108.2303 | Q36: 2.2311 | R36: 59.4063
A37: GATE | B37: 8 | C37: 8 | D37: 8 | E37: 219.46 | F37: 220.24 | G37: 0.78 | H37: 1 | I37: 0 | J37: 0 | K37: 0 | L37: -1 | M37: 0 | N37: 0 | O37: 0.5222 | P37: 87.0939 | Q37: 1.7747 | R37: 58.0505

Sheet Pantrucas
A1: EventType | B1: AttemptID | C1: SegmentID | D1: GateID | E1: EntryTime | F1: ExitTime | G1: TimeToClear_s | H1: Cleared | I1: ObstacleTouched | J1: ContactDuration_s | K1: ContactCount | L1: FirstContactTime_s | M1: JetpackActiveTime_s | N1: CrouchTime_s | O1: AirborneTime_s | P1: ContactX | Q1: ContactY | R1: ContactZ
A2: GATE | B2: 1 | C2: 1 | D2: 1 | E2: 970.48 | F2: 972.4 | G2: 1.92 | H2: 1 | I2: 0 | J2: 0 | K2: 0 | L2: -1 | M2: 0.0164 | N2: 0 | O2: 1.1707 | P2: 109.477 | Q2: 2.279 | R2: 10.8726
A3: GATE | B3: 2 | C3: 2 | D3: 2 | E3: 975.6 | F3: 977.2 | G3: 1.6 | H3: 1 | I3: 0 | J3: 0 | K3: 0 | L3: -1 | M3: 0.4406 | N3: 0 | O3: 1.2809 | P3: 157.4646 | Q3: 2.2963 | R3: 11.4922
A4: GATE | B4: 3 | C4: 3 | D4: 3 | E4: 979.28 | F4: 980.64 | G4: 1.36 | H4: 1 | I4: 0 | J4: 0 | K4: 0 | L4: -1 | M4: 0.3348 | N4: 0 | O4: 0.807 | P4: 187.46 | Q4: 2.3003 | R4: 10.8266
A5: GATE | B5: 4 | C5: 4 | D5: 4 | E5: 987.46 | F5: 988.44 | G5: 0.98 | H5: 1 | I5: 0 | J5: 0 | K5: 0 | L5: -1 | M5: 0 | N5: 0 | O5: 0.6869 | P5: 0 | Q5: 0 | R5: 0
A6: GATE | B6: 5 | C6: 5 | D6: 5 | E6: 988.48 | F6: 989.44 | G6: 0.96 | H6: 1 | I6: 0 | J6: 0 | K6: 0 | L6: -1 | M6: 0 | N6: 0 | O6: 0 | P6: 0 | Q6: 0 | R6: 0
A7: GATE | B7: 6 | C7: 6 | D7: 6 | E7: 989.7 | F7: 990.78 | G7: 1.08 | H7: 1 | I7: 0 | J7: 0 | K7: 0 | L7: -1 | M7: 0 | N7: 0 | O7: 0 | P7: 0 | Q7: 0 | R7: 0
A8: GATE | B8: 7 | C8: 7 | D8: 7 | E8: 992.72 | F8: 993.7 | G8: 0.98 | H8: 1 | I8: 0 | J8: 0 | K8: 0 | L8: -1 | M8: 0.1964 | N8: 0 | O8: 0.865 | P8: 108.4933 | Q8: 2.2354 | R8: 56.8299
A9: GATE | B9: 8 | C9: 8 | D9: 8 | E9: 994.2 | F9: 995.82 | G9: 1.6201 | H9: 1 | I9: 0 | J9: 0 | K9: 0 | L9: -1 | M9: 0.9334 | N9: 0 | O9: 1.6247 | P9: 87.2075 | Q9: 2.3322 | R9: 60.7429

Sheet Sepumae
A1: EventType | B1: AttemptID | C1: SegmentID | D1: GateID | E1: EntryTime | F1: ExitTime | G1: TimeToClear_s | H1: Cleared | I1: ObstacleTouched | J1: ContactDuration_s | K1: ContactCount | L1: FirstContactTime_s | M1: JetpackActiveTime_s | N1: CrouchTime_s | O1: AirborneTime_s | P1: ContactX | Q1: ContactY | R1: ContactZ
A2: GATE | B2: 1 | C2: 1 | D2: 1 | E2: 974.38 | F2: 975.54 | G2: 1.16 | H2: 1 | I2: 0 | J2: 0 | K2: 0 | L2: -1 | M2: 0.0691 | N2: 0 | O2: 0.8924 | P2: 109.5139 | Q2: 2.2602 | R2: 11.6952
A3: GATE | B3: 2 | C3: 2 | D3: 2 | E3: 979.58 | F3: 981 | G3: 1.42 | H3: 1 | I3: 0 | J3: 0 | K3: 0 | L3: -1 | M3: 0.1315 | N3: 0 | O3: 0.8495 | P3: 157.722 | Q3: 2.2331 | R3: 11.4524
A4: GATE | B4: 3 | C4: 3 | D4: 3 | E4: 982.98 | F4: 984.24 | G4: 1.26 | H4: 1 | I4: 0 | J4: 0 | K4: 0 | L4: -1 | M4: 0.0847 | N4: 0 | O4: 1.1157 | P4: 187.73 | Q4: 2.254 | R4: 11.9784
A5: GATE | B5: 3 | C5: 3 | D5: 3 | E5: 985.48 | F5: 986.18 | G5: 0.7 | H5: 1 | I5: 0 | J5: 0 | K5: 0 | L5: -1 | M5: 0.1838 | N5: 0 | O5: 0.6961 | P5: 0 | Q5: 0 | R5: 0
A6: DEATH
A7: GATE | B7: 1 | C7: 1 | D7: 1 | E7: 993.9 | F7: 995.3 | G7: 1.4 | H7: 1 | I7: 0 | J7: 0 | K7: 0 | L7: -1 | M7: 0 | N7: 0 | O7: 0.7002 | P7: 0 | Q7: 0 | R7: 0
A8: GATE | B8: 2 | C8: 2 | D8: 2 | E8: 998.92 | F8: 1000.34 | G8: 1.42 | H8: 1 | I8: 0 | J8: 0 | K8: 0 | L8: -1 | M8: 0 | N8: 0 | O8: 0.7361 | P8: 0 | Q8: 0 | R8: 0
A9: GATE | B9: 3 | C9: 3 | D9: 3 | E9: 1002.38 | F9: 1003.76 | G9: 1.3799 | H9: 1 | I9: 1 | J9: 0.02 | K9: 1 | L9: 0.7599 | M9: 0 | N9: 0 | O9: 1.0305 | P9: 0 | Q9: 0 | R9: 0
A10: GATE | B10: 3 | C10: 3 | D10: 3 | E10: 1003.82 | F10: 1004.88 | G10: 1.06 | H10: 1 | I10: 0 | J10: 0 | K10: 0 | L10: -1 | M10: 0.6685 | N10: 0 | O10: 1.0286 | P10: 0 | Q10: 0 | R10: 0
A11: GATE | B11: 4 | C11: 4 | D11: 4 | E11: 1012.38 | F11: 1013.34 | G11: 0.96 | H11: 1 | I11: 0 | J11: 0 | K11: 0 | L11: -1 | M11: 0 | N11: 0 | O11: 0.5838 | P11: 0 | Q11: 0 | R11: 0
A12: GATE | B12: 5 | C12: 5 | D12: 5 | E12: 1013.38 | F12: 1014.3 | G12: 0.92 | H12: 1 | I12: 0 | J12: 0 | K12: 0 | L12: -1 | M12: 0 | N12: 0 | O12: 0.774 | P12: 164.7483 | Q12: 1.8092 | R12: 60.4162
A13: GATE | B13: 6 | C13: 6 | D13: 6 | E13: 1014.54 | F13: 1015.46 | G13: 0.92 | H13: 1 | I13: 0 | J13: 0 | K13: 0 | L13: -1 | M13: 0 | N13: 0 | O13: 0.7187 | P13: 0 | Q13: 0 | R13: 0
A14: GATE | B14: 7 | C14: 7 | D14: 7 | E14: 1017.42 | F14: 1018.34 | G14: 0.92 | H14: 1 | I14: 0 | J14: 0 | K14: 0 | L14: -1 | M14: 0 | N14: 0 | O14: 0.752 | P14: 108.0488 | Q14: 2.2502 | R14: 59.1661
A15: GATE | B15: 8 | C15: 8 | D15: 8 | E15: 1019.08 | F15: 1020.14 | G15: 1.06 | H15: 1 | I15: 1 | J15: 0.1 | K15: 1 | L15: 0.46 | M15: 0 | N15: 0 | O15: 0.6254 | P15: 87.3453 | Q15: 1.8362 | R15: 59.3871

Sheet VicenteFigueroa
A1: EventType | B1: AttemptID | C1: SegmentID | D1: GateID | E1: EntryTime | F1: ExitTime | G1: TimeToClear_s | H1: Cleared | I1: ObstacleTouched | J1: ContactDuration_s | K1: ContactCount | L1: FirstContactTime_s | M1: JetpackActiveTime_s | N1: CrouchTime_s | O1: AirborneTime_s | P1: ContactX | Q1: ContactY | R1: ContactZ
A2: GATE | B2: 1 | C2: 1 | D2: 1 | E2: 745.56 | F2: 747.74 | G2: 2.18 | H2: 1 | I2: 0 | J2: 0 | K2: 0 | L2: -1 | M2: 0.8222 | N2: 0 | O2: 2.0237 | P2: 109.4744 | Q2: 8.4873 | R2: 11.0196
A3: GATE | B3: 2 | C3: 2 | D3: 2 | E3: 750.72 | F3: 751.98 | G3: 1.26 | H3: 1 | I3: 0 | J3: 0 | K3: 0 | L3: -1 | M3: 0.4874 | N3: 0 | O3: 0.8545 | P3: 157.4648 | Q3: 2.2409 | R3: 10.329
A4: GATE | B4: 3 | C4: 3 | D4: 3 | E4: 754.3 | F4: 755.52 | G4: 1.22 | H4: 1 | I4: 0 | J4: 0 | K4: 0 | L4: -1 | M4: 0.4979 | N4: 0 | O4: 0.9462 | P4: 187.6995 | Q4: 2.2798 | R4: 9.2942
A5: GATE | B5: 4 | C5: 4 | D5: 4 | E5: 762.54 | F5: 764.24 | G5: 1.7 | H5: 1 | I5: 1 | J5: 0.1201 | K5: 4 | L5: 0.3 | M5: 0.03 | N5: 0 | O5: 1.5899 | P5: 178.7309 | Q5: 2.4551 | R5: 58.8364
A6: GATE | B6: 6 | C6: 6 | D6: 6 | E6: 766.12 | F6: 767.08 | G6: 0.96 | H6: 1 | I6: 1 | J6: 0.3199 | K6: 2 | L6: 0.64 | M6: 0 | N6: 0 | O6: 0.9561 | P6: 0 | Q6: 0 | R6: 0
A7: DEATH
A8: GATE | B8: 4 | C8: 4 | D8: 4 | E8: 780.62 | F8: 782.28 | G8: 1.66 | H8: 1 | I8: 0 | J8: 0 | K8: 0 | L8: -1 | M8: 1.1311 | N8: 0 | O8: 1.657 | P8: 178.6166 | Q8: 4.6767 | R8: 56.3985
A9: GATE | B9: 5 | C9: 5 | D9: 5 | E9: 782.3 | F9: 783.72 | G9: 1.42 | H9: 1 | I9: 0 | J9: 0 | K9: 0 | L9: -1 | M9: 0.3184 | N9: 0 | O9: 1.4237 | P9: 164.7906 | Q9: 8.9369 | R9: 56.6563
A10: DEATH
A11: GATE | B11: 4 | C11: 4 | D11: 4 | E11: 793.62 | F11: 795.96 | G11: 2.34 | H11: 1 | I11: 1 | J11: 0.4401 | K11: 5 | L11: 0.22 | M11: 0.8785 | N11: 0 | O11: 2.1578 | P11: 178.601 | Q11: 2.2455 | R11: 55.5762
A12: GATE | B12: 5 | C12: 5 | D12: 5 | E12: 795.98 | F12: 807.36 | G12: 11.38 | H12: 1 | I12: 0 | J12: 0 | K12: 0 | L12: -1 | M12: 0.702 | N12: 0 | O12: 9.9892 | P12: 164.7883 | Q12: 6.7891 | R12: 57.7303
A13: GATE | B13: 6 | C13: 6 | D13: 6 | E13: 807.7 | F13: 808.84 | G13: 1.14 | H13: 1 | I13: 0 | J13: 0 | K13: 0 | L13: -1 | M13: 0.189 | N13: 0 | O13: 1.1331 | P13: 147.6232 | Q13: 3.4845 | R13: 60.371
A14: GATE | B14: 6 | C14: 6 | D14: 6 | E14: 809.32 | F14: 810.3 | G14: 0.98 | H14: 1 | I14: 1 | J14: 0.08 | K14: 2 | L14: 0.22 | M14: 0.3352 | N14: 0 | O14: 0.9823 | P14: 0 | Q14: 0 | R14: 0
A15: DEATH
A16: GATE | B16: 4 | C16: 4 | D16: 4 | E16: 818.78 | F16: 819.82 | G16: 1.04 | H16: 1 | I16: 0 | J16: 0 | K16: 0 | L16: -1 | M16: 0 | N16: 0 | O16: 0 | P16: 0 | Q16: 0 | R16: 0
A17: GATE | B17: 5 | C17: 5 | D17: 5 | E17: 819.82 | F17: 821.3 | G17: 1.48 | H17: 1 | I17: 0 | J17: 0 | K17: 0 | L17: -1 | M17: 0.3783 | N17: 0 | O17: 1.117 | P17: 164.7922 | Q17: 1.9327 | R17: 57.0566
A18: GATE | B18: 6 | C18: 6 | D18: 6 | E18: 821.54 | F18: 822.82 | G18: 1.28 | H18: 1 | I18: 0 | J18: 0 | K18: 0 | L18: -1 | M18: 0.7961 | N18: 0 | O18: 1.2792 | P18: 147.5379 | Q18: 3.7511 | R18: 58.3365
A19: DEATH
A20: GATE | B20: 4 | C20: 4 | D20: 4 | E20: 834.1 | F20: 834.82 | G20: 0.72 | H20: 1 | I20: 1 | J20: 0.14 | K20: 3 | L20: 0.32 | M20: 0 | N20: 0 | O20: 0.5703 | P20: 0 | Q20: 0 | R20: 0
A21: GATE | B21: 5 | C21: 5 | D21: 5 | E21: 834.82 | F21: 836.06 | G21: 1.24 | H21: 1 | I21: 1 | J21: 0.02 | K21: 1 | L21: 0.24 | M21: 0.71 | N21: 0 | O21: 1.2501 | P21: 164.4209 | Q21: 2.0011 | R21: 56.9848
A22: GATE | B22: 6 | C22: 6 | D22: 6 | E22: 836.36 | F22: 837.44 | G22: 1.08 | H22: 1 | I22: 0 | J22: 0 | K22: 0 | L22: -1 | M22: 0.2418 | N22: 0 | O22: 1.0856 | P22: 147.5116 | Q22: 7.0305 | R22: 55.7696
A23: GATE | B23: 7 | C23: 7 | D23: 7 | E23: 839.26 | F23: 840.08 | G23: 0.8199 | H23: 1 | I23: 1 | J23: 0.26 | K23: 3 | L23: 0.3 | M23: 0 | N23: 0 | O23: 0.5815 | P23: 0 | Q23: 0 | R23: 0
A24: GATE | B24: 8 | C24: 8 | D24: 8 | E24: 840.72 | F24: 841.64 | G24: 0.92 | H24: 1 | I24: 0 | J24: 0 | K24: 0 | L24: -1 | M24: 0 | N24: 0 | O24: 0.6609 | P24: 87.3674 | Q24: 1.8454 | R24: 57.4023

Sheet VicenteHernandez
A1: EventType | B1: AttemptID | C1: SegmentID | D1: GateID | E1: EntryTime | F1: ExitTime | G1: TimeToClear_s | H1: Cleared | I1: ObstacleTouched | J1: ContactDuration_s | K1: ContactCount | L1: FirstContactTime_s | M1: JetpackActiveTime_s | N1: CrouchTime_s | O1: AirborneTime_s | P1: ContactX | Q1: ContactY | R1: ContactZ
A2: GATE | B2: 1 | C2: 1 | D2: 1 | E2: 56.98 | F2: 58.72 | G2: 1.74 | H2: 1 | I2: 1 | J2: 0.14 | K2: 2 | L2: 0.52 | M2: 0 | N2: 0 | O2: 0.7739 | P2: 109.4676 | Q2: 2.2435 | R2: 11.8053
A3: GATE | B3: 2 | C3: 2 | D3: 2 | E3: 62.76 | F3: 63.86 | G3: 1.1 | H3: 1 | I3: 0 | J3: 0 | K3: 0 | L3: -1 | M3: 0.4704 | N3: 0 | O3: 1.0925 | P3: 0 | Q3: 0 | R3: 0
A4: DEATH
A5: GATE | B5: 1 | C5: 1 | D5: 1 | E5: 71.9 | F5: 73.4 | G5: 1.5 | H5: 1 | I5: 1 | J5: 0.26 | K5: 4 | L5: 0.64 | M5: 0.2573 | N5: 0 | O5: 1.2176 | P5: 0 | Q5: 0 | R5: 0
A6: GATE | B6: 2 | C6: 2 | D6: 2 | E6: 77.8 | F6: 78.84 | G6: 1.04 | H6: 1 | I6: 0 | J6: 0 | K6: 0 | L6: -1 | M6: 0 | N6: 0 | O6: 0.8718 | P6: 157.5905 | Q6: 2.2703 | R6: 9.5876
A7: GATE | B7: 3 | C7: 3 | D7: 3 | E7: 80.76 | F7: 82.28 | G7: 1.52 | H7: 1 | I7: 0 | J7: 0 | K7: 0 | L7: -1 | M7: 1.163 | N7: 0 | O7: 1.5258 | P7: 187.4735 | Q7: 7.1136 | R7: 11.4577
A8: GATE | B8: 4 | C8: 4 | D8: 4 | E8: 96.3 | F8: 97.52 | G8: 1.22 | H8: 1 | I8: 0 | J8: 0 | K8: 0 | L8: -1 | M8: 0.8245 | N8: 0 | O8: 1.2299 | P8: 178.3843 | Q8: 2.5166 | R8: 58.2458
A9: GATE | B9: 5 | C9: 5 | D9: 5 | E9: 97.56 | F9: 99.64 | G9: 2.08 | H9: 1 | I9: 0 | J9: 0 | K9: 0 | L9: -1 | M9: 0.6635 | N9: 0 | O9: 2.0965 | P9: 164.786 | Q9: 8.1858 | R9: 60.1492
A10: GATE | B10: 6 | C10: 6 | D10: 6 | E10: 100.04 | F10: 100.4 | G10: 0.36 | H10: 1 | I10: 0 | J10: 0 | K10: 0 | L10: -1 | M10: 0 | N10: 0 | O10: 0.3594 | P10: 0 | Q10: 0 | R10: 0
A11: DEATH
A12: GATE | B12: 4 | C12: 4 | D12: 4 | E12: 109.36 | F12: 110.1 | G12: 0.74 | H12: 1 | I12: 0 | J12: 0 | K12: 0 | L12: -1 | M12: 0 | N12: 0 | O12: 0.6543 | P12: 178.6543 | Q12: 2.2628 | R12: 58.624
A13: GATE | B13: 5 | C13: 5 | D13: 5 | E13: 110.12 | F13: 111.88 | G13: 1.76 | H13: 1 | I13: 1 | J13: 0.18 | K13: 3 | L13: 0.68 | M13: 0.2347 | N13: 0 | O13: 1.1296 | P13: 164.6887 | Q13: 1.8471 | R13: 60.7474
A14: GATE | B14: 6 | C14: 6 | D14: 6 | E14: 112.58 | F14: 114.1 | G14: 1.52 | H14: 1 | I14: 0 | J14: 0 | K14: 0 | L14: -1 | M14: 0.7846 | N14: 0 | O14: 1.5232 | P14: 147.4188 | Q14: 3.8594 | R14: 56.7872
A15: DEATH
A16: GATE | B16: 4 | C16: 4 | D16: 4 | E16: 130.58 | F16: 132.24 | G16: 1.66 | H16: 1 | I16: 0 | J16: 0 | K16: 0 | L16: -1 | M16: 1.0109 | N16: 0 | O16: 1.6739 | P16: 178.7569 | Q16: 4.1622 | R16: 59.9394
A17: GATE | B17: 5 | C17: 5 | D17: 5 | E17: 132.28 | F17: 133.72 | G17: 1.44 | H17: 1 | I17: 0 | J17: 0 | K17: 0 | L17: -1 | M17: 0.4341 | N17: 0 | O17: 1.4505 | P17: 164.5416 | Q17: 8.6242 | R17: 57.0206
A18: GATE | B18: 6 | C18: 6 | D18: 6 | E18: 134.1 | F18: 134.44 | G18: 0.34 | H18: 1 | I18: 0 | J18: 0 | K18: 0 | L18: -1 | M18: 0 | N18: 0 | O18: 0.3138 | P18: 0 | Q18: 0 | R18: 0
A19: DEATH
A20: GATE | B20: 4 | C20: 4 | D20: 4 | E20: 144.54 | F20: 145.72 | G20: 1.18 | H20: 1 | I20: 1 | J20: 0.14 | K20: 3 | L20: 0.34 | M20: 0 | N20: 0 | O20: 0.9634 | P20: 178.5639 | Q20: 2.2357 | R20: 60.0832
A21: DEATH
A22: GATE | B22: 4 | C22: 4 | D22: 4 | E22: 154.14 | F22: 155.22 | G22: 1.08 | H22: 1 | I22: 1 | J22: 0.28 | K22: 3 | L22: 0.42 | M22: 0 | N22: 0 | O22: 0.6417 | P22: 0 | Q22: 0 | R22: 0
A23: GATE | B23: 5 | C23: 5 | D23: 5 | E23: 155.24 | F23: 157.24 | G23: 2 | H23: 1 | I23: 1 | J23: 0.72 | K23: 3 | L23: 0.32 | M23: 0.153 | N23: 0 | O23: 1.2332 | P23: 0 | Q23: 0 | R23: 0
A24: DEATH
A25: GATE | B25: 4 | C25: 4 | D25: 4 | E25: 171.62 | F25: 172.4 | G25: 0.78 | H25: 1 | I25: 1 | J25: 0.12 | K25: 3 | L25: 0.3 | M25: 0 | N25: 0 | O25: 0.6002 | P25: 178.5612 | Q25: 2.2402 | R25: 59.3716
A26: GATE | B26: 5 | C26: 5 | D26: 5 | E26: 172.4 | F26: 173.9 | G26: 1.5 | H26: 1 | I26: 1 | J26: 0.5 | K26: 3 | L26: 0.46 | M26: 0.0937 | N26: 0 | O26: 0.9386 | P26: 164.6473 | Q26: 1.854 | R26: 57.3142
A27: GATE | B27: 6 | C27: 6 | D27: 6 | E27: 174.06 | F27: 174.8 | G27: 0.74 | H27: 1 | I27: 0 | J27: 0 | K27: 0 | L27: -1 | M27: 0.4581 | N27: 0 | O27: 0.7368 | P27: 0 | Q27: 0 | R27: 0
A28: GATE | B28: 7 | C28: 7 | D28: 7 | E28: 176.84 | F28: 177.92 | G28: 1.08 | H28: 1 | I28: 0 | J28: 0 | K28: 0 | L28: -1 | M28: 0.3556 | N28: 0 | O28: 1.0743 | P28: 108.4753 | Q28: 3.4871 | R28: 57.3806
A29: GATE | B29: 8 | C29: 8 | D29: 8 | E29: 178.34 | F29: 179.36 | G29: 1.02 | H29: 1 | I29: 0 | J29: 0 | K29: 0 | L29: -1 | M29: 0.2744 | N29: 0 | O29: 0.9898 | P29: 87.451 | Q29: 1.8174 | R29: 58.1333

Sheet VicenteLineros
A1: EventType | B1: AttemptID | C1: SegmentID | D1: GateID | E1: EntryTime | F1: ExitTime | G1: TimeToClear_s | H1: Cleared | I1: ObstacleTouched | J1: ContactDuration_s | K1: ContactCount | L1: FirstContactTime_s | M1: JetpackActiveTime_s | N1: CrouchTime_s | O1: AirborneTime_s | P1: ContactX | Q1: ContactY | R1: ContactZ
A2: GATE | B2: 1 | C2: 1 | D2: 1 | E2: 1529.68 | F2: 1531.9 | G2: 2.2201 | H2: 1 | I2: 0 | J2: 0 | K2: 0 | L2: -1 | M2: 0.8753 | N2: 0 | O2: 1.8249 | P2: 109.5753 | Q2: 2.9253 | R2: 11.4899
A3: DEATH
A4: GATE | B4: 1 | C4: 1 | D4: 1 | E4: 1542.4 | F4: 1543.44 | G4: 1.0399 | H4: 1 | I4: 0 | J4: 0 | K4: 0 | L4: -1 | M4: 0.0159 | N4: 0 | O4: 0.7647 | P4: 109.667 | Q4: 2.2412 | R4: 9.428
A5: GATE | B5: 2 | C5: 2 | D5: 2 | E5: 1548.56 | F5: 1549.78 | G5: 1.22 | H5: 1 | I5: 0 | J5: 0 | K5: 0 | L5: -1 | M5: 0.0163 | N5: 0 | O5: 1.224 | P5: 157.5442 | Q5: 6.6775 | R5: 8.0015
A6: DEATH
A7: GATE | B7: 1 | C7: 1 | D7: 1 | E7: 1557.36 | F7: 1558.44 | G7: 1.08 | H7: 1 | I7: 0 | J7: 0 | K7: 0 | L7: -1 | M7: 0 | N7: 0 | O7: 0.6639 | P7: 109.4672 | Q7: 2.2404 | R7: 9.1696
A8: GATE | B8: 2 | C8: 2 | D8: 2 | E8: 1562.38 | F8: 1563.66 | G8: 1.2799 | H8: 1 | I8: 0 | J8: 0 | K8: 0 | L8: -1 | M8: 0.4632 | N8: 0 | O8: 1.1299 | P8: 0 | Q8: 0 | R8: 0
A9: GATE | B9: 3 | C9: 3 | D9: 3 | E9: 1565.62 | F9: 1568.28 | G9: 2.6599 | H9: 1 | I9: 0 | J9: 0 | K9: 0 | L9: -1 | M9: 0.1158 | N9: 0 | O9: 1.5439 | P9: 187.6809 | Q9: 2.3563 | R9: 10.5081
A10: GATE | B10: 4 | C10: 4 | D10: 4 | E10: 1578.84 | F10: 1579.9 | G10: 1.0601 | H10: 1 | I10: 0 | J10: 0 | K10: 0 | L10: -1 | M10: 0 | N10: 0 | O10: 0 | P10: 0 | Q10: 0 | R10: 0
A11: GATE | B11: 5 | C11: 5 | D11: 5 | E11: 1579.9 | F11: 1580.96 | G11: 1.0599 | H11: 1 | I11: 0 | J11: 0 | K11: 0 | L11: -1 | M11: 0 | N11: 0 | O11: 0 | P11: 0 | Q11: 0 | R11: 0
A12: GATE | B12: 6 | C12: 6 | D12: 6 | E12: 1581.38 | F12: 1583.4 | G12: 2.02 | H12: 1 | I12: 0 | J12: 0 | K12: 0 | L12: -1 | M12: 1.5033 | N12: 0 | O12: 2.014 | P12: 0 | Q12: 0 | R12: 0
A13: DEATH
A14: GATE | B14: 4 | C14: 4 | D14: 4 | E14: 1594.3 | F14: 1596.12 | G14: 1.8201 | H14: 1 | I14: 0 | J14: 0 | K14: 0 | L14: -1 | M14: 1.5081 | N14: 0 | O14: 1.8307 | P14: 178.8082 | Q14: 4.2579 | R14: 58.315
A15: GATE | B15: 5 | C15: 5 | D15: 5 | E15: 1596.16 | F15: 1597.52 | G15: 1.3601 | H15: 1 | I15: 0 | J15: 0 | K15: 0 | L15: -1 | M15: 0.0145 | N15: 0 | O15: 1.3699 | P15: 164.6768 | Q15: 4.6991 | R15: 58.3962
A16: DEATH
A17: GATE | B17: 4 | C17: 4 | D17: 4 | E17: 1608 | F17: 1609.7 | G17: 1.7 | H17: 1 | I17: 1 | J17: 1.24 | K17: 4 | L17: 0.46 | M17: 0 | N17: 0 | O17: 1.4952 | P17: 0 | Q17: 0 | R17: 0
A18: DEATH
A19: GATE | B19: 4 | C19: 4 | D19: 4 | E19: 1619.02 | F19: 1620.52 | G19: 1.5 | H19: 1 | I19: 1 | J19: 1.02 | K19: 3 | L19: 0.48 | M19: 0 | N19: 0 | O19: 0.8479 | P19: 0 | Q19: 0 | R19: 0
A20: DEATH
A21: GATE | B21: 4 | C21: 4 | D21: 4 | E21: 1629.72 | F21: 1631.06 | G21: 1.34 | H21: 1 | I21: 1 | J21: 0.86 | K21: 2 | L21: 0.48 | M21: 0 | N21: 0 | O21: 1.237 | P21: 0 | Q21: 0 | R21: 0
A22: DEATH
A23: GATE | B23: 4 | C23: 4 | D23: 4 | E23: 1639.76 | F23: 1641.3 | G23: 1.5399 | H23: 1 | I23: 0 | J23: 0 | K23: 0 | L23: -1 | M23: 0.497 | N23: 0 | O23: 1.5235 | P23: 0 | Q23: 0 | R23: 0
A24: DEATH
A25: GATE | B25: 4 | C25: 4 | D25: 4 | E25: 1650.64 | F25: 1652.04 | G25: 1.3999 | H25: 1 | I25: 0 | J25: 0 | K25: 0 | L25: -1 | M25: 0.8264 | N25: 0 | O25: 1.4131 | P25: 178.5943 | Q25: 7.3407 | R25: 59.097
A26: GATE | B26: 5 | C26: 5 | D26: 5 | E26: 1652.08 | F26: 1653.12 | G26: 1.04 | H26: 1 | I26: 0 | J26: 0 | K26: 0 | L26: -1 | M26: 0.0334 | N26: 0 | O26: 1.0431 | P26: 164.4476 | Q26: 5.8571 | R26: 57.3157
A27: DEATH
A28: GATE | B28: 4 | C28: 4 | D28: 4 | E28: 1662.28 | F28: 1664.22 | G28: 1.9401 | H28: 1 | I28: 0 | J28: 0 | K28: 0 | L28: -1 | M28: 1.2921 | N28: 0 | O28: 1.9353 | P28: 178.6259 | Q28: 10.6381 | R28: 58.5688
A29: GATE | B29: 5 | C29: 5 | D29: 5 | E29: 1664.26 | F29: 1665.62 | G29: 1.36 | H29: 1 | I29: 0 | J29: 0 | K29: 0 | L29: -1 | M29: 0.1837 | N29: 0 | O29: 1.37 | P29: 164.7883 | Q29: 12.3954 | R29: 59.5
A30: GATE | B30: 6 | C30: 6 | D30: 6 | E30: 1665.98 | F30: 1666.28 | G30: 0.2999 | H30: 1 | I30: 0 | J30: 0 | K30: 0 | L30: -1 | M30: 0 | N30: 0 | O30: 0.3143 | P30: 0 | Q30: 0 | R30: 0
A31: DEATH
A32: GATE | B32: 4 | C32: 4 | D32: 4 | E32: 1674.9 | F32: 1675.9 | G32: 1 | H32: 1 | I32: 0 | J32: 0 | K32: 0 | L32: -1 | M32: 0.4011 | N32: 0 | O32: 0.9907 | P32: 178.2307 | Q32: 2.6304 | R32: 57.6705
A33: GATE | B33: 5 | C33: 5 | D33: 5 | E33: 1675.92 | F33: 1677.04 | G33: 1.12 | H33: 1 | I33: 0 | J33: 0 | K33: 0 | L33: -1 | M33: 0.3423 | N33: 0 | O33: 1.0492 | P33: 164.6163 | Q33: 4.0073 | R33: 55.3858
A34: GATE | B34: 6 | C34: 6 | D34: 6 | E34: 1677.28 | F34: 1678.8 | G34: 1.52 | H34: 1 | I34: 1 | J34: 0.0399 | K34: 1 | L34: 0.4601 | M34: 0.1243 | N34: 0 | O34: 1.4521 | P34: 146.9823 | Q34: 2.4966 | R34: 56.7284
A35: GATE | B35: 7 | C35: 7 | D35: 7 | E35: 1681.34 | F35: 1681.5 | G35: 0.16 | H35: 1 | I35: 0 | J35: 0 | K35: 0 | L35: -1 | M35: 0 | N35: 0 | O35: 0.1497 | P35: 0 | Q35: 0 | R35: 0
A36: DEATH
A37: GATE | B37: 4 | C37: 4 | D37: 4 | E37: 1691.62 | F37: 1693.1 | G37: 1.48 | H37: 1 | I37: 0 | J37: 0 | K37: 0 | L37: -1 | M37: 0.4366 | N37: 0 | O37: 1.4869 | P37: 178.5669 | Q37: 5.8265 | R37: 57.2169
A38: GATE | B38: 5 | C38: 5 | D38: 5 | E38: 1693.1 | F38: 1695.18 | G38: 2.08 | H38: 1 | I38: 1 | J38: 0.96 | K38: 3 | L38: 0.26 | M38: 1.0723 | N38: 0 | O38: 1.8797 | P38: 164.7443 | Q38: 2.1088 | R38: 58.136
A39: GATE | B39: 6 | C39: 6 | D39: 6 | E39: 1695.54 | F39: 1695.8 | G39: 0.26 | H39: 1 | I39: 0 | J39: 0 | K39: 0 | L39: -1 | M39: 0 | N39: 0 | O39: 0.2594 | P39: 0 | Q39: 0 | R39: 0
A40: DEATH
...

Sheet yoelchupa
A1: EventType | B1: AttemptID | C1: SegmentID | D1: GateID | E1: EntryTime | F1: ExitTime | G1: TimeToClear_s | H1: Cleared | I1: ObstacleTouched | J1: ContactDuration_s | K1: ContactCount | L1: FirstContactTime_s | M1: JetpackActiveTime_s | N1: CrouchTime_s | O1: AirborneTime_s | P1: ContactX | Q1: ContactY | R1: ContactZ
