Workbook

Sheet Orientation
A1: AttemptID | B1: SegmentId | C1: TotalDuration_s | D1: AverageAngle_deg | E1: TimeLookingAway_s | F1: PercentTimeLookingAway | G1: ReorientationCount | H1: EndedInDeath | I1: TargetPlatform
A2: 10 | B2: JetpackSegment_56 | C2: 1.321775 | D2: 39.82246 | E2: 0.6198165 | F2: 0.4689275 | G2: 0 | H2: 0 | I2: TargetAnchor1
A3: 10 | B3: JetpackSegment_57 | C3: 1.456395 | D3: 43.22823 | E3: 0.9967216 | F3: 0.6843761 | G3: 0 | H3: 0 | I3: TargetAnchor2
A4: 10 | B4: JetpackSegment_58 | C4: 1.210815 | D4: 13.61625 | E4: 0 | F4: 0 | G4: 0 | H4: 0 | I4: TargetAnchor3
A5: 10 | B5: JetpackSegment_59 | C5: 1.565221 | D5: 11.0845 | E5: 0 | F5: 0 | G5: 0 | H5: 0 | I5: TargetAnchor4
A6: 10 | B6: JetpackSegment_60 | C6: 1.728793 | D6: 27.44887 | E6: 0.5486585 | F6: 0.3173651 | G6: 0 | H6: 0 | I6: TargetAnchor5
A7: 10 | B7: JetpackSegment_61 | C7: 1.68739 | D7: 16.95908 | E7: 0.5271837 | F7: 0.3124255 | G7: 0 | H7: 0 | I7: TargetAnchor6
A8: 10 | B8: JetpackSegment_62 | C8: 1.579671 | D8: 15.85514 | E8: 0.2311801 | F8: 0.146347 | G8: 0 | H8: 0 | I8: TargetAnchor7
A9: 10 | B9: JetpackSegment_63 | C9: 1.916775 | D9: 63.73117 | E9: 1.916775 | F9: 1 | G9: 0 | H9: 0 | I9: TargetAnchor8

Sheet Trajectory
A1: AttemptID | B1: StartTime | C1: Duration | D1: Efficiency | E1: ZigZag_Average | F1: Curvature_Normalized | G1: MaxLateralOffset | H1: LandingError | I1: TotalDistance | J1: VerticalOscillation | K1: EndedInDeath | L1: TargetAnchorName
A2: 10 | B2: 495.9814 | C2: 1.318451 | D2: 1 | E2: 2.792159 | F2: 9.330626 | G2: 0.3609496 | H2: 1.85484 | I2: 14.36384 | J2: 6.488256 | K2: 0 | L2: TargetAnchor1
A3: 10 | B3: 500.0139 | C3: 1.455566 | D3: 1 | E3: 3.100274 | F3: 9.261591 | G3: 0.4050211 | H3: 2.266116 | I3: 16.06777 | J3: 9.130721 | K3: 0 | L3: TargetAnchor2
A4: 10 | B4: 504.7527 | C4: 1.2211 | D4: 1 | E4: 5.74819 | F4: 18.58801 | G4: 0.2413473 | H4: 1.987222 | I4: 12.67892 | J4: 3.894834 | K4: 0 | L4: TargetAnchor3
A5: 10 | B5: 510.5932 | C5: 1.547699 | D5: 1 | E5: 4.686971 | F5: 12.90726 | G5: 0.2056476 | H5: 2.312533 | I5: 15.61445 | J5: 2.988975 | K5: 0 | L5: TargetAnchor4
A6: 10 | B6: 516.2225 | C6: 1.72168 | D6: 1 | E6: 5.325408 | F6: 15.36746 | G6: 0.3260894 | H6: 1.259888 | I6: 17.67343 | J6: 4.168658 | K6: 0 | L6: TargetAnchor5
A7: 10 | B7: 520.5729 | C7: 1.680115 | D7: 1 | E7: 2.639277 | F7: 8.533431 | G7: 0.3197722 | H7: 1.324984 | I7: 18.24791 | J7: 6.545077 | K7: 0 | L7: TargetAnchor6
A8: 10 | B8: 526.2291 | C8: 1.584534 | D8: 1 | E8: 3.85905 | F8: 12.8882 | G8: 0.2715858 | H8: 1.757002 | I8: 16.46837 | J8: 4.081098 | K8: 0 | L8: TargetAnchor7
A9: 10 | B9: 533.9175 | C9: 1.906555 | D9: 1 | E9: 5.620111 | F9: 13.43414 | G9: 0.518519 | H9: 6.911128 | I9: 17.57051 | J9: 8.095402 | K9: 0 | L9: TargetAnchor8

Sheet Landing
A1: AttemptID | B1: SegmentId | C1: TargetPlatform | D1: LandingOffset_m | E1: LandingOffset_Forward_m | F1: LandingOffset_Side_m | G1: SafetyMargin_m | H1: VerticalSpeed_mps | I1: ApproachAngle_deg | J1: MicroCorrections_0_5s | K1: PreLandingHorizontalJitter | L1: PostStabilizationTime_s | M1: PostLandingDrift_m | N1: LandingFailed | O1: PostLandingFall | P1: LandingType
A2: 10 | B2: LandingSegment_1 | C2: TargetAnchor1 | D2: 1.854807 | E2: -1.811783 | F2: -0.3971825 | G2: 0.9746621 | H2: -11.0241 | I2: 0 | J2: 0 | K2: 0.5451718 | L2: 1.12088 | M2: 2.102713 | N2: 0 | O2: 0 | P2: CleanLanding
A3: 10 | B3: LandingSegment_2 | C3: TargetAnchor2 | D3: 2.265903 | E3: 0.9606781 | F3: -2.052174 | G3: 1.148193 | H3: -15.21336 | I3: 0 | J3: 0 | K3: 0 | L3: 0.5012817 | M3: 0.1713594 | N3: 0 | O3: 0 | P3: CleanLanding
A4: 10 | B4: LandingSegment_3 | C4: TargetAnchor3 | D4: 1.981501 | E4: 1.836823 | F4: 0.7432556 | G4: 1.166736 | H4: 3.999634 | I4: 0 | J4: 1 | K4: 3.22331 | L4: 1.176178 | M4: 1.929852 | N4: 0 | O4: 0 | P4: CleanLanding
A5: 10 | B5: LandingSegment_4 | C5: TargetAnchor4 | D5: 2.30635 | E5: 2.301643 | F5: -0.1472626 | G5: 0.5938475 | H5: -6.55875 | I5: 0 | J5: 0 | K5: 0.1600296 | L5: 0.5167847 | M5: 0.1436845 | N5: 0 | O5: 0 | P5: CleanLanding
A6: 10 | B6: LandingSegment_5 | C6: TargetAnchor5 | D6: 1.248502 | E6: -1.168243 | F6: 0.4404144 | G6: 1.922566 | H6: -9.586665 | I6: 0 | J6: 0 | K6: 0 | L6: 0.5071411 | M6: 0.1340654 | N6: 0 | O6: 0 | P6: CleanLanding
A7: 10 | B7: LandingSegment_6 | C7: TargetAnchor6 | D7: 1.314162 | E7: 1.299736 | F7: 0.1941833 | G7: 1.705077 | H7: -12.37454 | I7: 0 | J7: 0 | K7: 0 | L7: 0.5328369 | M7: 0.2702033 | N7: 0 | O7: 0 | P7: CleanLanding
A8: 10 | B8: LandingSegment_7 | C8: TargetAnchor7 | D8: 1.748855 | E8: 1.102331 | F8: -1.357704 | G8: 1.260049 | H8: -10.6836 | I8: 0 | J8: 0 | K8: 1.189432 | L8: 0.5286255 | M8: 0.2289537 | N8: 0 | O8: 0 | P8: CleanLanding

Sheet Multitasking
A1: AttemptID | B1: LapID | C1: LapDuration_s | D1: AttemptDuration_s | E1: LapProgress_0_1 | F1: DeathOccurred | G1: MeanDeviation_m | H1: SpeedSD_mps | I1: MicroCorrectionsRate_per_s | J1: ObstacleHitRate

Sheet Jitter
A1: AttemptID | B1: RetryNumber | C1: WaveNumber | D1: Death | E1: CurrentJitter | F1: SmoothedJitter | G1: IsHard | H1: JitterPeak | I1: JitterVariance | J1: JitterStdDev | K1: JitterEvents | L1: OvershootCount | M1: JitterArea | N1: JitterDirectionBias | O1: JitterClusters | P1: ExtraCol_15
A2: 10 | B2: 9 | C2: 0 | D2: 1 | E2: --- | F2: --- | G2: --- | H2: --- | I2: --- | J2: --- | K2: --- | L2: --- | M2: --- | N2: --- | O2: --- | P2: NoMovement
A3: 10 | B3: 9 | C3: 0 | D3: 1 | E3: --- | F3: --- | G3: --- | H3: --- | I3: --- | J3: --- | K3: --- | L3: --- | M3: --- | N3: --- | O3: --- | P3: NoMovement
A4: 10 | B4: 9 | C4: 0 | D4: 1 | E4: --- | F4: --- | G4: --- | H4: --- | I4: --- | J4: --- | K4: --- | L4: --- | M4: --- | N4: --- | O4: --- | P4: NoMovement
A5: 10 | B5: 9 | C5: 0 | D5: 1 | E5: --- | F5: --- | G5: --- | H5: --- | I5: --- | J5: --- | K5: --- | L5: --- | M5: --- | N5: --- | O5: --- | P5: NoMovement
A6: 10 | B6: 9 | C6: 0 | D6: 1 | E6: --- | F6: --- | G6: --- | H6: --- | I6: --- | J6: --- | K6: --- | L6: --- | M6: --- | N6: --- | O6: --- | P6: NoMovement
A7: 10 | B7: 9 | C7: 0 | D7: 1 | E7: --- | F7: --- | G7: --- | H7: --- | I7: --- | J7: --- | K7: --- | L7: --- | M7: --- | N7: --- | O7: --- | P7: NoMovement
A8: 10 | B8: 9 | C8: 0 | D8: 1 | E8: --- | F8: --- | G8: --- | H8: --- | I8: --- | J8: --- | K8: --- | L8: --- | M8: --- | N8: --- | O8: --- | P8: NoMovement
A9: 10 | B9: 9 | C9: 0 | D9: 1 | E9: --- | F9: --- | G9: --- | H9: --- | I9: --- | J9: --- | K9: --- | L9: --- | M9: --- | N9: --- | O9: --- | P9: NoMovement
A10: 10 | B10: 9 | C10: 0 | D10: 1 | E10: --- | F10: --- | G10: --- | H10: --- | I10: --- | J10: --- | K10: --- | L10: --- | M10: --- | N10: --- | O10: --- | P10: NoMovement
A11: 10 | B11: 9 | C11: 0 | D11: 1 | E11: --- | F11: --- | G11: --- | H11: --- | I11: --- | J11: --- | K11: --- | L11: --- | M11: --- | N11: --- | O11: --- | P11: NoMovement
A12: 10 | B12: 9 | C12: 0 | D12: 1 | E12: --- | F12: --- | G12: --- | H12: --- | I12: --- | J12: --- | K12: --- | L12: --- | M12: --- | N12: --- | O12: --- | P12: NoMovement
A13: 10 | B13: 9 | C13: 0 | D13: 1 | E13: 0.6246 | F13: 0.4612 | G13: 0 | H13: 0.6246 | I13: 0.029 | J13: 0.1704 | K13: 0 | L13: 2 | M13: 3.8139 | N13: 0.6246 | O13: 0 | P13: 0
A14: TimeToTargetHit | B14: 0 | C14: Enemy1_Wave0_BOT_rotador | D14: 1.6966 | E14: 0 | F14: 0 | G14: 0 | H14: 0 | I14: 0 | J14: 0 | K14: 0 | L14: 0 | M14: 0 | N14: 0 | O14: 0 | P14: 0
A15: 10 | B15: 9 | C15: 0 | D15: 1 | E15: 0.1342 | F15: 0.5314 | G15: 0 | H15: 0.8504 | I15: 0.0388 | J15: 0.197 | K15: 0 | L15: 5 | M15: 4.8807 | N15: -0.4905 | O15: 0 | P15: 0
A16: 10 | B16: 9 | C16: 0 | D16: 1 | E16: --- | F16: --- | G16: --- | H16: --- | I16: --- | J16: --- | K16: --- | L16: --- | M16: --- | N16: --- | O16: --- | P16: NoMovement
A17: 10 | B17: 9 | C17: 0 | D17: 1 | E17: --- | F17: --- | G17: --- | H17: --- | I17: --- | J17: --- | K17: --- | L17: --- | M17: --- | N17: --- | O17: --- | P17: NoMovement
A18: 10 | B18: 9 | C18: 0 | D18: 1 | E18: --- | F18: --- | G18: --- | H18: --- | I18: --- | J18: --- | K18: --- | L18: --- | M18: --- | N18: --- | O18: --- | P18: NoMovement
A19: 10 | B19: 9 | C19: 0 | D19: 1 | E19: --- | F19: --- | G19: --- | H19: --- | I19: --- | J19: --- | K19: --- | L19: --- | M19: --- | N19: --- | O19: --- | P19: NoMovement
A20: 10 | B20: 9 | C20: 0 | D20: 1 | E20: --- | F20: --- | G20: --- | H20: --- | I20: --- | J20: --- | K20: --- | L20: --- | M20: --- | N20: --- | O20: --- | P20: NoMovement
A21: 10 | B21: 9 | C21: 0 | D21: 1 | E21: --- | F21: --- | G21: --- | H21: --- | I21: --- | J21: --- | K21: --- | L21: --- | M21: --- | N21: --- | O21: --- | P21: NoMovement
A22: 10 | B22: 9 | C22: 0 | D22: 1 | E22: 0.5063 | F22: 0.3111 | G22: 0 | H22: 0.5063 | I22: 0.0303 | J22: 0.1741 | K22: 0 | L22: 3 | M22: 2.2695 | N22: 0.3721 | O22: 0 | P22: 0
A23: 10 | B23: 9 | C23: 0 | D23: 1 | E23: 0.633 | F23: 0.6928 | G23: 0 | H23: 1.1259 | I23: 0.0302 | J23: 0.1739 | K23: 0 | L23: 4 | M23: 6.3138 | N23: 0.1267 | O23: 0 | P23: 0
A24: 10 | B24: 9 | C24: 0 | D24: 1 | E24: --- | F24: --- | G24: --- | H24: --- | I24: --- | J24: --- | K24: --- | L24: --- | M24: --- | N24: --- | O24: --- | P24: OutOfAngle
A25: 10 | B25: 9 | C25: 0 | D25: 1 | E25: --- | F25: --- | G25: --- | H25: --- | I25: --- | J25: --- | K25: --- | L25: --- | M25: --- | N25: --- | O25: --- | P25: OutOfAngle
A26: 10 | B26: 9 | C26: 0 | D26: 1 | E26: --- | F26: --- | G26: --- | H26: --- | I26: --- | J26: --- | K26: --- | L26: --- | M26: --- | N26: --- | O26: --- | P26: OutOfAngle
A27: 10 | B27: 9 | C27: 0 | D27: 1 | E27: --- | F27: --- | G27: --- | H27: --- | I27: --- | J27: --- | K27: --- | L27: --- | M27: --- | N27: --- | O27: --- | P27: NoMovement
A28: 10 | B28: 9 | C28: 0 | D28: 1 | E28: --- | F28: --- | G28: --- | H28: --- | I28: --- | J28: --- | K28: --- | L28: --- | M28: --- | N28: --- | O28: --- | P28: NoMovement
A29: 10 | B29: 9 | C29: 0 | D29: 1 | E29: --- | F29: --- | G29: --- | H29: --- | I29: --- | J29: --- | K29: --- | L29: --- | M29: --- | N29: --- | O29: --- | P29: NoMovement
A30: 10 | B30: 9 | C30: 0 | D30: 1 | E30: --- | F30: --- | G30: --- | H30: --- | I30: --- | J30: --- | K30: --- | L30: --- | M30: --- | N30: --- | O30: --- | P30: NoMovement
A31: 10 | B31: 9 | C31: 0 | D31: 1 | E31: --- | F31: --- | G31: --- | H31: --- | I31: --- | J31: --- | K31: --- | L31: --- | M31: --- | N31: --- | O31: --- | P31: NoMovement
A32: 10 | B32: 9 | C32: 0 | D32: 1 | E32: --- | F32: --- | G32: --- | H32: --- | I32: --- | J32: --- | K32: --- | L32: --- | M32: --- | N32: --- | O32: --- | P32: NoMovement
A33: 10 | B33: 9 | C33: 0 | D33: 1 | E33: --- | F33: --- | G33: --- | H33: --- | I33: --- | J33: --- | K33: --- | L33: --- | M33: --- | N33: --- | O33: --- | P33: NoMovement
A34: 10 | B34: 9 | C34: 0 | D34: 1 | E34: --- | F34: --- | G34: --- | H34: --- | I34: --- | J34: --- | K34: --- | L34: --- | M34: --- | N34: --- | O34: --- | P34: NoMovement
A35: 10 | B35: 9 | C35: 0 | D35: 1 | E35: --- | F35: --- | G35: --- | H35: --- | I35: --- | J35: --- | K35: --- | L35: --- | M35: --- | N35: --- | O35: --- | P35: NoMovement
... A42: 10 | B42: 9 | C42: 0 | D42: 1 | E42: --- | F42: --- | G42: --- | H42: --- | I42: --- | J42: --- | K42: --- | L42: --- | M42: --- | N42: --- | O42: --- | P42: NoMovement
A43: 10 | B43: 9 | C43: 0 | D43: 1 | E43: 0.0816 | F43: 0.0191 | G43: 0 | H43: 0.7017 | I43: 0.0793 | J43: 0.2815 | K43: 0 | L43: 4 | M43: 1.5123 | N43: -0.5515 | O43: 0 | P43: 0
A44: 10 | B44: 9 | C44: 0 | D44: 1 | E44: 0.403 | F44: 0.4108 | G44: 0 | H44: 0.6991 | I44: 0.0102 | J44: 0.1012 | K44: 0 | L44: 4 | M44: 4.4011 | N44: 0.3214 | O44: 0 | P44: 0
A45: 10 | B45: 9 | C45: 0 | D45: 1 | E45: --- | F45: --- | G45: --- | H45: --- | I45: --- | J45: --- | K45: --- | L45: --- | M45: --- | N45: --- | O45: --- | P45: NoMovement
A46: 10 | B46: 9 | C46: 0 | D46: 1 | E46: --- | F46: --- | G46: --- | H46: --- | I46: --- | J46: --- | K46: --- | L46: --- | M46: --- | N46: --- | O46: --- | P46: NoMovement
...

Sheet Obstacle
A1: EventType | B1: AttemptID | C1: SegmentID | D1: GateID | E1: EntryTime | F1: ExitTime | G1: TimeToClear_s | H1: Cleared | I1: ObstacleTouched | J1: ContactDuration_s | K1: ContactCount | L1: FirstContactTime_s | M1: JetpackActiveTime_s | N1: CrouchTime_s | O1: AirborneTime_s | P1: ContactX | Q1: ContactY | R1: ContactZ
A2: GATE | B2: 1 | C2: 1 | D2: 1 | E2: 1152.96 | F2: 1154.38 | G2: 1.42 | H2: 1 | I2: 1 | J2: 0.0801 | K2: 3 | L2: 0.74 | M2: 0 | N2: 0 | O2: 0.7196 | P2: 109.6224 | Q2: 2.4084 | R2: 11.1423
A3: GATE | B3: 2 | C3: 2 | D3: 2 | E3: 1158.36 | F3: 1159.54 | G3: 1.1799 | H3: 1 | I3: 0 | J3: 0 | K3: 0 | L3: -1 | M3: 0 | N3: 0 | O3: 0.6011 | P3: 157.6779 | Q3: 2.3199 | R3: 10.9076
A4: GATE | B4: 3 | C4: 3 | D4: 3 | E4: 1161.64 | F4: 1163.36 | G4: 1.72 | H4: 1 | I4: 0 | J4: 0 | K4: 0 | L4: -1 | M4: 0.0748 | N4: 0 | O4: 0.8207 | P4: 187.8502 | Q4: 2.2975 | R4: 10.8371
A5: GATE | B5: 4 | C5: 4 | D5: 4 | E5: 1173.86 | F5: 1174.84 | G5: 0.98 | H5: 1 | I5: 1 | J5: 0.14 | K5: 3 | L5: 0.48 | M5: 0 | N5: 0 | O5: 0.5768 | P5: 178.3295 | Q5: 2.2474 | R5: 57.3808
A6: GATE | B6: 5 | C6: 5 | D6: 5 | E6: 1174.84 | F6: 1175.64 | G6: 0.8 | H6: 1 | I6: 1 | J6: 0.1 | K6: 1 | L6: 0.4 | M6: 0 | N6: 0 | O6: 0.5456 | P6: 0 | Q6: 0 | R6: 0
A7: GATE | B7: 6 | C7: 6 | D7: 6 | E7: 1175.84 | F7: 1176.9 | G7: 1.0601 | H7: 1 | I7: 1 | J7: 0.12 | K7: 3 | L7: 0.62 | M7: 0 | N7: 0 | O7: 0.6663 | P7: 0 | Q7: 0 | R7: 0
A8: DEATH
A9: GATE | B9: 4 | C9: 4 | D9: 4 | E9: 1189.44 | F9: 1190.44 | G9: 1 | H9: 1 | I9: 0 | J9: 0 | K9: 0 | L9: -1 | M9: 0 | N9: 0 | O9: 0 | P9: 0 | Q9: 0 | R9: 0
A10: GATE | B10: 5 | C10: 5 | D10: 5 | E10: 1190.48 | F10: 1191.82 | G10: 1.34 | H10: 1 | I10: 0 | J10: 0 | K10: 0 | L10: -1 | M10: 0 | N10: 0 | O10: 0.3028 | P10: 0 | Q10: 0 | R10: 0
A11: GATE | B11: 6 | C11: 6 | D11: 6 | E11: 1192.08 | F11: 1192.8 | G11: 0.72 | H11: 1 | I11: 0 | J11: 0 | K11: 0 | L11: -1 | M11: 0 | N11: 0 | O11: 0.5977 | P11: 0 | Q11: 0 | R11: 0
A12: GATE | B12: 7 | C12: 7 | D12: 7 | E12: 1194.78 | F12: 1196.4 | G12: 1.62 | H12: 1 | I12: 1 | J12: 0.02 | K12: 1 | L12: 0.36 | M12: 0.1212 | N12: 0 | O12: 1.0663 | P12: 0 | Q12: 0 | R12: 0
A13: GATE | B13: 8 | C13: 8 | D13: 8 | E13: 1197.18 | F13: 1200.38 | G13: 3.2001 | H13: 1 | I13: 1 | J13: 0.7001 | K13: 1 | L13: 1.62 | M13: 0.5089 | N13: 0 | O13: 2.2527 | P13: 87.4616 | Q13: 5.2626 | R13: 58.9422
A14: DEATH
A15: GATE | B15: 4 | C15: 4 | D15: 4 | E15: 1209.78 | F15: 1210.84 | G15: 1.0599 | H15: 1 | I15: 0 | J15: 0 | K15: 0 | L15: -1 | M15: 0 | N15: 0 | O15: 0 | P15: 0 | Q15: 0 | R15: 0
A16: GATE | B16: 5 | C16: 5 | D16: 5 | E16: 1210.84 | F16: 1211.9 | G16: 1.0601 | H16: 1 | I16: 0 | J16: 0 | K16: 0 | L16: -1 | M16: 0 | N16: 0 | O16: 0 | P16: 0 | Q16: 0 | R16: 0
A17: GATE | B17: 6 | C17: 6 | D17: 6 | E17: 1212.18 | F17: 1213.24 | G17: 1.0601 | H17: 1 | I17: 0 | J17: 0 | K17: 0 | L17: -1 | M17: 0 | N17: 0 | O17: 0 | P17: 0 | Q17: 0 | R17: 0
A18: GATE | B18: 7 | C18: 7 | D18: 7 | E18: 1215.16 | F18: 1217.1 | G18: 1.9401 | H18: 1 | I18: 1 | J18: 0.0399 | K18: 1 | L18: 0.4801 | M18: 0.3691 | N18: 0 | O18: 1.406 | P18: 108.284 | Q18: 2.5529 | R18: 55.0235
A19: GATE | B19: 8 | C19: 8 | D19: 8 | E19: 1217.82 | F19: 1218.06 | G19: 0.24 | H19: 1 | I19: 0 | J19: 0 | K19: 0 | L19: -1 | M19: 0 | N19: 0 | O19: 0.2386 | P19: 0 | Q19: 0 | R19: 0
A20: DEATH
A21: DEATH
A22: GATE | B22: 4 | C22: 4 | D22: 4 | E22: 1259.04 | F22: 1260.08 | G22: 1.04 | H22: 1 | I22: 0 | J22: 0 | K22: 0 | L22: -1 | M22: 0 | N22: 0 | O22: 0 | P22: 0 | Q22: 0 | R22: 0
A23: GATE | B23: 5 | C23: 5 | D23: 5 | E23: 1260.12 | F23: 1261.14 | G23: 1.02 | H23: 1 | I23: 0 | J23: 0 | K23: 0 | L23: -1 | M23: 0 | N23: 0 | O23: 0 | P23: 0 | Q23: 0 | R23: 0
A24: GATE | B24: 6 | C24: 6 | D24: 6 | E24: 1261.46 | F24: 1262.48 | G24: 1.02 | H24: 1 | I24: 0 | J24: 0 | K24: 0 | L24: -1 | M24: 0 | N24: 0 | O24: 0 | P24: 0 | Q24: 0 | R24: 0
A25: GATE | B25: 7 | C25: 7 | D25: 7 | E25: 1264.44 | F25: 1265.36 | G25: 0.92 | H25: 1 | I25: 0 | J25: 0 | K25: 0 | L25: -1 | M25: 0.119 | N25: 0 | O25: 0.7028 | P25: 108.4478 | Q25: 2.3077 | R25: 55.3766
A26: GATE | B26: 8 | C26: 8 | D26: 8 | E26: 1265.92 | F26: 1267.62 | G26: 1.7001 | H26: 1 | I26: 1 | J26: 0.0399 | K26: 1 | L26: 0.4601 | M26: 0 | N26: 0 | O26: 1.0617 | P26: 87.2977 | Q26: 1.8607 | R26: 62.3503
A27: GATE | B27: 8 | C27: 8 | D27: 8 | E27: 1268.04 | F27: 1268.24 | G27: 0.2001 | H27: 1 | I27: 0 | J27: 0 | K27: 0 | L27: -1 | M27: 0.1155 | N27: 0 | O27: 0.194 | P27: 0 | Q27: 0 | R27: 0

Sheet Movement
A1: EventType | B1: SegmentID | C1: ElementID | D1: TimeOnPlatform | E1: RelativePositionStd | F1: RelativePositionMean | G1: RelativePositionMax | H1: RelativePositionMin | I1: SampleCount | J1: EdgeRiskTime | K1: CorrectionPeaks | L1: ObstacleType | M1: ClearType | N1: MinClearance | O1: MicroCorrections | P1: ObstacleDuration
A2: Platform | B2: 0 | C2: 0 | D2: 3.23 | E2: 0.245 | F2: 0.3862 | G2: 0.6506 | H2: 0.0239 | I2: 128 | J2: 0.37 | K2: 0 | L2: 21
A3: Platform | B3: 0 | C3: 0 | D3: 2.06 | E3: 0.6023 | F3: 1.7971 | G3: 2.9388 | H3: 1.3577 | I3: 81 | J3: 0.07 | K3: 0 | L3: 20
A4: Platform | B4: 1 | C4: 0 | D4: 1.67 | E4: 0.0286 | F4: 5.2244 | G4: 5.2588 | H4: 5.0751 | I4: 66 | J4: 0.14 | K4: 0 | L4: 2
A5: Platform | B5: 1 | C5: 0 | D5: 2.5 | E5: 0.7339 | F5: 8.0563 | G5: 9.3527 | H5: 7.3812 | I5: 103 | J5: 0.02 | K5: 0 | L5: 12
A6: Platform | B6: 1 | C6: 0 | D6: 0.61 | E6: 0.9267 | F6: 9.1299 | G6: 10.4222 | H6: 7.8654 | I6: 25 | J6: 0 | K6: 0 | L6: 2
A7: Platform | B7: 2 | C7: 0 | D7: 0.05 | E7: 0 | F7: 11.0917 | G7: 11.0917 | H7: 11.0917 | I7: 1 | J7: 0 | K7: 0 | L7: 0
A8: Platform | B8: 2 | C8: 0 | D8: 0.05 | E8: 0 | F8: 11.0822 | G8: 11.0822 | H8: 11.0822 | I8: 1 | J8: 0 | K8: 0 | L8: 0
A9: Platform | B9: 2 | C9: 0 | D9: 0.05 | E9: 0 | F9: 11.142 | G9: 11.142 | H9: 11.142 | I9: 1 | J9: 0 | K9: 0 | L9: 0
A10: Platform | B10: 2 | C10: 0 | D10: 0.05 | E10: 0 | F10: 11.1707 | G10: 11.1707 | H10: 11.1707 | I10: 1 | J10: 0 | K10: 0 | L10: 0
A11: Platform | B11: 2 | C11: 0 | D11: 0.05 | E11: 0 | F11: 11.1941 | G11: 11.1941 | H11: 11.1941 | I11: 1 | J11: 0 | K11: 0 | L11: 0
A12: Platform | B12: 2 | C12: 0 | D12: 0.05 | E12: 0 | F12: 11.1395 | G12: 11.1395 | H12: 11.1395 | I12: 1 | J12: 0 | K12: 0 | L12: 0
A13: Platform | B13: 2 | C13: 0 | D13: 0.05 | E13: 0 | F13: 11.1478 | G13: 11.1478 | H13: 11.1478 | I13: 1 | J13: 0 | K13: 0 | L13: 0
... A20: Platform | B20: 2 | C20: 0 | D20: 0.08 | E20: 0.3155 | F20: 9.912 | G20: 10.2274 | H20: 9.5965 | I20: 2 | J20: 0 | K20: 1 | L20: 0
A21: DEATH
A22: Platform | B22: 2 | C22: 0 | D22: 4.72 | E22: 1.0307 | F22: 6.8432 | G22: 8.5801 | H22: 5.0822 | I22: 108 | J22: 1 | K22: 7 | L22: 42
A23: Platform | B23: 2 | C23: 0 | D23: 0.04 | E23: 0 | F23: 9.1831 | G23: 9.1831 | H23: 9.1831 | I23: 1 | J23: 0 | K23: 0 | L23: 0
A24: Platform | B24: 2 | C24: 0 | D24: 0.08 | E24: 0.059 | F24: 9.2221 | G24: 9.2811 | H24: 9.1631 | I24: 2 | J24: 0 | K24: 0 | L24: 0
A25: Platform | B25: 2 | C25: 0 | D25: 0.12 | E25: 0.0396 | F25: 9.208 | G25: 9.2636 | H25: 9.1746 | I25: 3 | J25: 0 | K25: 0 | L25: 1
A26: Platform | B26: 2 | C26: 0 | D26: 2.01 | E26: 0.2607 | F26: 4.7056 | G26: 5.1357 | H26: 4.3677 | I26: 49 | J26: 0.56 | K26: 0 | L26: 20
A27: Platform | B27: 2 | C27: 0 | D27: 0.9 | E27: 1.2679 | F27: 5.5857 | G27: 8.3 | H27: 3.8195 | I27: 23 | J27: 0 | K27: 0 | L27: 3
A28: DEATH
A29: Platform | B29: 2 | C29: 0 | D29: 0.05 | E29: 0 | F29: 4.5863 | G29: 4.5863 | H29: 4.5863 | I29: 1 | J29: 0 | K29: 0 | L29: 0
A30: Platform | B30: 2 | C30: 0 | D30: 7.75 | E30: 0.278 | F30: 5.4239 | G30: 6.0692 | H30: 5.0003 | I30: 175 | J30: 0.28 | K30: 0 | L30: 82
A31: DEATH
A32: Platform | B32: 2 | C32: 0 | D32: 0.05 | E32: 0 | F32: 9.8753 | G32: 9.8753 | H32: 9.8753 | I32: 1 | J32: 0 | K32: 0 | L32: 0
A33: DEATH
A34: Platform | B34: 2 | C34: 0 | D34: 7.8 | E34: 0.9838 | F34: 3.9854 | G34: 7.2368 | H34: 3.204 | I34: 181 | J34: 0 | K34: 1 | L34: 61
A35: Platform | B35: 2 | C35: 0 | D35: 0.08 | E35: 0.1828 | F35: 7.1847 | G35: 7.3676 | H35: 7.0019 | I35: 2 | J35: 0 | K35: 0 | L35: 0

Sheet GeneralStats
A1: Checkpoint | B1: Tiempo Absoluto (seg) | C1: Tiempo Desde Anterior (seg) | D1: Muertes entre checkpoints | E1: Muertes totales | F1: Muertes por enemigos | G1: Muertes por vacío | H1: Enemigos eliminados | I1: Disparos Blaster | J1: Acertados Blaster | K1: Fallados Blaster | L1: Precisión Blaster (%) | M1: Disparos Escopeta | N1: Acertados Escopeta | O1: Fallados Escopeta | P1: Precisión Escopeta (%) | Q1: Disparos Totales | R1: Acertados Totales | S1: Fallados Totales | T1: Precisión Total (%)
A2: Checkpoint_1 | B2: 0 | C2: 0 | D2: 0 | E2: 0 | F2: 0 | G2: 0 | H2: 0 | I2: 0 | J2: 0 | K2: 0 | L2: 0 | M2: 0 | N2: 0 | O2: 0 | P2: 0 | Q2: 0 | R2: 0 | S2: 0 | T2: 0
A3: Checkpoint_2 | B3: 88.6 | C3: 88.6 | D3: 0 | E3: 0 | F3: 0 | G3: 0 | H3: 6 | I3: 96 | J3: 42 | K3: 54 | L3: 43.8 | M3: 0 | N3: 0 | O3: 0 | P3: 0 | Q3: 96 | R3: 42 | S3: 54 | T3: 43.8
A4: Checkpoint_3 | B4: 135.54 | C4: 46.94 | D4: 0 | E4: 0 | F4: 0 | G4: 0 | H4: 0 | I4: 48 | J4: 27 | K4: 21 | L4: 56.3 | M4: 0 | N4: 0 | O4: 0 | P4: 0 | Q4: 48 | R4: 27 | S4: 21 | T4: 56.3
A5: Checkpoint_4 | B5: 487.86 | C5: 352.32 | D5: 9 | E5: 9 | F5: 0 | G5: 9 | H5: 0 | I5: 0 | J5: 0 | K5: 0 | L5: 0 | M5: 0 | N5: 0 | O5: 0 | P5: 0 | Q5: 0 | R5: 0 | S5: 0 | T5: 0
A6: Checkpoint_5 | B6: 535.56 | C6: 47.7 | D6: 0 | E6: 9 | F6: 0 | G6: 0 | H6: 0 | I6: 0 | J6: 0 | K6: 0 | L6: 0 | M6: 0 | N6: 0 | O6: 0 | P6: 0 | Q6: 0 | R6: 0 | S6: 0 | T6: 0
A7: Checkpoint_6 | B7: 1130.82 | C7: 595.26 | D7: 1 | E7: 10 | F7: 0 | G7: 1 | H7: 25 | I7: 1209 | J7: 579 | K7: 630 | L7: 47.9 | M7: 18 | N7: 0 | O7: 18 | P7: 0 | Q7: 1227 | R7: 579 | S7: 648 | T7: 47.2
A8: Checkpoint_7 | B8: 1146.58 | C8: 15.76 | D8: 0 | E8: 10 | F8: 0 | G8: 0 | H8: 4 | I8: 12 | J8: 8 | K8: 4 | L8: 66.7 | M8: 4 | N8: 3 | O8: 1 | P8: 75 | Q8: 16 | R8: 11 | S8: 5 | T8: 68.8
A9: Checkpoint_8 | B9: 1163.56 | C9: 16.98 | D9: 0 | E9: 10 | F9: 0 | G9: 0 | H9: 0 | I9: 0 | J9: 0 | K9: 0 | L9: 0 | M9: 0 | N9: 0 | O9: 0 | P9: 0 | Q9: 0 | R9: 0 | S9: 0 | T9: 0
A10: Checkpoint_9 | B10: 1269.66 | C10: 106.1 | D10: 4 | E10: 14 | F10: 0 | G10: 4 | H10: 0 | I10: 11 | J10: 0 | K10: 11 | L10: 0 | M10: 0 | N10: 0 | O10: 0 | P10: 0 | Q10: 11 | R10: 0 | S10: 11 | T10: 0
A11: Checkpoint_10 | B11: 1277.1 | C11: 7.44 | D11: 0 | E11: 14 | F11: 0 | G11: 0 | H11: 0 | I11: 0 | J11: 0 | K11: 0 | L11: 0 | M11: 0 | N11: 0 | O11: 0 | P11: 0 | Q11: 0 | R11: 0 | S11: 0 | T11: 0
A12: Final_Level | B12: 1324.27 | C12: 47.17 | D12: 0 | E12: 14 | F12: 0 | G12: 0 | H12: 2 | I12: 93 | J12: 76 | K12: 17 | L12: 81.7 | M12: 7 | N12: 4 | O12: 3 | P12: 57.1 | Q12: 100 | R12: 80 | S12: 20 | T12: 80

Sheet AVERAGES
A1: Orientation | C1: AttemptID | D1: SegmentId | E1: TotalDuration_s | F1: AverageAngle_deg | G1: TimeLookingAway_s | H1: PercentTimeLookingAway | I1: ReorientationCount | J1: EndedInDeath | K1: TargetPlatform
C2: =AVERAGE(Orientation!A:A) -> 10 | D2: =AVERAGE(Orientation!B:B) -> #DIV/0! | E2: =AVERAGE(Orientation!C:C) -> 1.5583544 | F2: =AVERAGE(Orientation!D:D) -> 28.968212 | G2: =AVERAGE(Orientation!E:E) -> 0.60504193 | H2: =AVERAGE(Orientation!F:F) -> 0.36618015 | I2: =AVERAGE(Orientation!G:G) -> 0 | J2: =AVERAGE(Orientation!H:H) -> 0 | K2: =AVERAGE(Orientation!I:I) -> #DIV/0!
A4: Trajectory | C4: AttemptID | D4: StartTime | E4: Duration | F4: Efficiency | G4: ZigZag_Average | H4: Curvature_Normalized | I4: MaxLateralOffset | J4: LandingError | K4: TotalDistance | L4: VerticalOscillation | M4: EndedInDeath | N4: TargetAnchorName
C5: =AVERAGE(Trajectory!A:A) -> 10 | D5: =AVERAGE(Trajectory!B:B) -> 513.5354 | E5: =AVERAGE(Trajectory!C:C) -> 1.5544625 | F5: =AVERAGE(Trajectory!D:D) -> 1 | G5: =AVERAGE(Trajectory!E:E) -> 4.22143 | H5: =AVERAGE(Trajectory!F:F) -> 12.53884 | I5: =AVERAGE(Trajectory!G:G) -> 0.3311165 | J5: =AVERAGE(Trajectory!H:H) -> 2.4592141 | K5: =AVERAGE(Trajectory!I:I) -> 16.08565 | L5: =AVERAGE(Trajectory!J:J) -> 5.6741276 | M5: =AVERAGE(Trajectory!K:K) -> 0 | N5: =AVERAGE(Trajectory!L:L) -> #DIV/0!
A7: Landing | C7: AttemptID | D7: SegmentId | E7: TargetPlatform | F7: LandingOffset_m | G7: LandingOffset_Forward_m | H7: LandingOffset_Side_m | I7: SafetyMargin_m | J7: VerticalSpeed_mps | K7: ApproachAngle_deg | L7: MicroCorrections_0_5s | M7: PreLandingHorizontalJitter | N7: PostStabilizationTime_s | O7: PostLandingDrift_m | P7: LandingFailed | Q7: PostLandingFall | R7: LandingType
C8: =AVERAGE(Landing!A:A) -> 10 | D8: =AVERAGE(Landing!B:B) -> #DIV/0! | E8: =AVERAGE(Landing!C:C) -> #DIV/0! | F8: =AVERAGE(Landing!D:D) -> 1.8171543 | G8: =AVERAGE(Landing!E:E) -> 0.64588359 | H8: =AVERAGE(Landing!F:F) -> -0.36806711 | I8: =AVERAGE(Landing!G:G) -> 1.2530187 | J8: =AVERAGE(Landing!H:H) -> -8.7773401 | K8: =AVERAGE(Landing!I:I) -> 0 | L8: =AVERAGE(Landing!J:J) -> 0.14285714 | M8: =AVERAGE(Landing!K:K) -> 0.73113477 | N8: =AVERAGE(Landing!L:L) -> 0.69767541 | O8: =AVERAGE(Landing!M:M) -> 0.71154733 | P8: =AVERAGE(Landing!N:N) -> 0 | Q8: =AVERAGE(Landing!O:O) -> 0 | R8: =AVERAGE(Landing!P:P) -> #DIV/0!
A10: Jitter | C10: AttemptID | D10: RetryNumber | E10: WaveNumber | F10: Death | G10: CurrentJitter | H10: SmoothedJitter | I10: IsHard | J10: JitterPeak | K10: JitterVariance | L10: JitterStdDev | M10: JitterEvents | N10: OvershootCount | O10: JitterArea | P10: JitterDirectionBias | Q10: JitterClusters | R10: ExtraCol_15
C11: =AVERAGE(Jitter!A:A) -> 10.327093 | D11: =AVERAGE(Jitter!B:B) -> 9.2401879 | E11: =AVERAGE(Jitter!C:C) -> 4.1794322 | F11: =AVERAGE(Jitter!D:D) -> 1.075026 | G11: =AVERAGE(Jitter!E:E) -> 0.53080207 | H11: =AVERAGE(Jitter!F:F) -> 0.53073731 | I11: =AVERAGE(Jitter!G:G) -> 0 | J11: =AVERAGE(Jitter!H:H) -> 0.83019295 | K11: =AVERAGE(Jitter!I:I) -> 0.036183731 | L11: =AVERAGE(Jitter!J:J) -> 0.15866642 | M11: =AVERAGE(Jitter!K:K) -> 0.011398964 | N11: =AVERAGE(Jitter!L:L) -> 4.2331606 | O11: =AVERAGE(Jitter!M:M) -> 4.566458 | P11: =AVERAGE(Jitter!N:N) -> 0.00065740933 | Q11: =AVERAGE(Jitter!O:O) -> 0.011398964 | R11: =AVERAGE(Jitter!P:P) -> 0
A13: Movement | C13: EventType | D13: SegmentID | E13: ElementID | F13: TimeOnPlatform | G13: RelativePositionStd | H13: RelativePositionMean | I13: RelativePositionMax | J13: RelativePositionMin | K13: SampleCount | L13: EdgeRiskTime | M13: CorrectionPeaks | N13: RawCorrectionsCount | O13: ObstacleType | P13: ClearType | Q13: MinClearance | R13: MicroCorrections | S13: ObstacleDuration | T13: ExtraCol_17
C14: =AVERAGE(Movement!A:A) -> #DIV/0! | D14: =AVERAGE(Movement!B:B) -> 1.7666667 | E14: =AVERAGE(Movement!C:C) -> 0 | F14: =AVERAGE(Movement!D:D) -> 1.229 | G14: =AVERAGE(Movement!E:E) -> 0.25147 | H14: =AVERAGE(Movement!F:F) -> 7.8196733 | I14: =AVERAGE(Movement!G:G) -> 8.32916 | J14: =AVERAGE(Movement!H:H) -> 7.5190867 | K14: =AVERAGE(Movement!I:I) -> 33.966667 | L14: =AVERAGE(Movement!J:J) -> 0.081333333 | M14: =AVERAGE(Movement!K:K) -> 0.33333333 | N14: =AVERAGE(Movement!L:L) -> 9.5 | O14: =AVERAGE(Movement!M:M) -> #DIV/0! | P14: =AVERAGE(Movement!N:N) -> #DIV/0! | Q14: =AVERAGE(Movement!O:O) -> #DIV/0! | R14: =AVERAGE(Movement!P:P) -> #DIV/0! | S14: =AVERAGE(Movement!Q:Q) -> #DIV/0! | T14: =AVERAGE(Movement!R:R) -> #DIV/0!
A16: Obstacle | C16: EventType | D16: AttemptID | E16: SegmentID | F16: GateID | G16: EntryTime | H16: ExitTime | I16: TimeToClear_s | J16: Cleared | K16: ObstacleTouched | L16: ContactDuration_s | M16: ContactCount | N16: FirstContactTime_s | O16: JetpackActiveTime_s | P16: CrouchTime_s | Q16: AirborneTime_s | R16: ContactX | S16: ContactY | T16: ContactZ
C17: =AVERAGE(Obstacle!A:A) -> #DIV/0! | D17: =AVERAGE(Obstacle!B:B) -> 5.4090909 | E17: =AVERAGE(Obstacle!C:C) -> 5.4090909 | F17: =AVERAGE(Obstacle!D:D) -> 5.4090909 | G17: =AVERAGE(Obstacle!E:E) -> 1209.3755 | H17: =AVERAGE(Obstacle!F:F) -> 1210.5709 | I17: =AVERAGE(Obstacle!G:G) -> 1.1954773 | J17: =AVERAGE(Obstacle!H:H) -> 1 | K17: =AVERAGE(Obstacle!I:I) -> 0.36363636 | L17: =AVERAGE(Obstacle!J:J) -> 0.056363636 | M17: =AVERAGE(Obstacle!K:K) -> 0.63636364 | N17: =AVERAGE(Obstacle!L:L) -> -0.40180909 | O17: =AVERAGE(Obstacle!M:M) -> 0.059477273 | P17: =AVERAGE(Obstacle!N:N) -> 0 | Q17: =AVERAGE(Obstacle!O:O) -> 0.53421364 | R17: =AVERAGE(Obstacle!P:P) -> 46.589595 | S17: =AVERAGE(Obstacle!Q:Q) -> 0.96623182 | T17: =AVERAGE(Obstacle!R:R) -> 14.634564
A19: Multitasking | C19: AttemptID | D19: LapID | E19: LapDuration_s | F19: AttemptDuration_s | G19: LapProgress_0_1 | H19: DeathOccurred | I19: MeanDeviation_m | J19: SpeedSD_mps | K19: MicroCorrectionsRate_per_s | L19: ObstacleHitRate
C20: =AVERAGE(Multitasking!A:A) -> #DIV/0! | D20: =AVERAGE(Multitasking!B:B) -> #DIV/0! | E20: =AVERAGE(Multitasking!C:C) -> #DIV/0! | F20: =AVERAGE(Multitasking!D:D) -> #DIV/0! | G20: =AVERAGE(Multitasking!E:E) -> #DIV/0! | H20: =AVERAGE(Multitasking!F:F) -> #DIV/0! | I20: =AVERAGE(Multitasking!G:G) -> #DIV/0! | J20: =AVERAGE(Multitasking!H:H) -> #DIV/0! | K20: =AVERAGE(Multitasking!I:I) -> #DIV/0! | L20: =AVERAGE(Multitasking!J:J) -> #DIV/0!
A22: GeneralStats | C22: Checkpoint | D22: Tiempo Absoluto (seg) | E22: Tiempo Desde Anterior (seg) | F22: Muertes entre checkpoints | G22: Muertes totales | H22: Muertes por enemigos | I22: Muertes por vacío | J22: Enemigos eliminados | K22: Disparos Blaster | L22: Acertados Blaster | M22: Fallados Blaster | N22: Precisión Blaster (%) | O22: Disparos Escopeta | P22: Acertados Escopeta | Q22: Fallados Escopeta | R22: Precisión Escopeta (%) | S22: Disparos Totales | T22: Acertados Totales | U22: Fallados Totales | V22: Precisión Total (%)
C23: =AVERAGE(GeneralStats!A:A) -> #DIV/0! | D23: =AVERAGE(GeneralStats!B:B) -> 778.14091 | E23: =AVERAGE(GeneralStats!C:C) -> 120.38818 | F23: =AVERAGE(GeneralStats!D:D) -> 1.2727273 | G23: =AVERAGE(GeneralStats!E:E) -> 8.1818182 | H23: =AVERAGE(GeneralStats!F:F) -> 0 | I23: =AVERAGE(GeneralStats!G:G) -> 1.2727273 | J23: =AVERAGE(GeneralStats!H:H) -> 3.3636364 | K23: =AVERAGE(GeneralStats!I:I) -> 133.54545 | L23: =AVERAGE(GeneralStats!J:J) -> 66.545455 | M23: =AVERAGE(GeneralStats!K:K) -> 67 | N23: =AVERAGE(GeneralStats!L:L) -> 26.945455 | O23: =AVERAGE(GeneralStats!M:M) -> 2.6363636 | P23: =AVERAGE(GeneralStats!N:N) -> 0.63636364 | Q23: =AVERAGE(GeneralStats!O:O) -> 2 | R23: =AVERAGE(GeneralStats!P:P) -> 12.009091 | S23: =AVERAGE(GeneralStats!Q:Q) -> 136.18182 | T23: =AVERAGE(GeneralStats!R:R) -> 67.181818 | U23: =AVERAGE(GeneralStats!S:S) -> 69 | V23: =AVERAGE(GeneralStats!T:T) -> 26.918182
