Workbook

Sheet adap_CataAguilar
A1: EventType | B1: AttemptID | C1: SegmentID | D1: GateID | E1: EntryTime | F1: ExitTime | G1: TimeToClear_s | H1: Cleared | I1: ObstacleTouched | J1: ContactDuration_s | K1: ContactCount | L1: FirstContactTime_s | M1: JetpackActiveTime_s | N1: CrouchTime_s | O1: AirborneTime_s | P1: ContactX | Q1: ContactY | R1: ContactZ
A2: DEATH
A3: GATE | B3: 1 | C3: 1 | D3: 1 | E3: 93.88 | F3: 94.96 | G3: 1.08 | H3: 1 | I3: 1 | J3: 0.02 | K3: 1 | L3: 0.62 | M3: 0 | N3: 0 | O3: 0.583 | P3: 109.5629 | Q3: 2.2835 | R3: 10.4015
A4: GATE | B4: 2 | C4: 2 | D4: 2 | E4: 98.62 | F4: 100.02 | G4: 1.4 | H4: 1 | I4: 0 | J4: 0 | K4: 0 | L4: -1 | M4: 0 | N4: 0 | O4: 0.8995 | P4: 0 | Q4: 0 | R4: 0
A5: DEATH
A6: GATE | B6: 1 | C6: 1 | D6: 1 | E6: 112.44 | F6: 115.08 | G6: 2.64 | H6: 1 | I6: 0 | J6: 0 | K6: 0 | L6: -1 | M6: 0 | N6: 0 | O6: 1.3303 | P6: 109.4564 | Q6: 2.2934 | R6: 11.541
A7: DEATH
A8: GATE | B8: 1 | C8: 1 | D8: 1 | E8: 127.14 | F8: 128.38 | G8: 1.24 | H8: 1 | I8: 1 | J8: 0.1 | K8: 3 | L8: 0.7 | M8: 0.0818 | N8: 0 | O8: 0.5677 | P8: 109.5475 | Q8: 2.2614 | R8: 10.9245
A9: DEATH
A10: GATE | B10: 1 | C10: 1 | D10: 1 | E10: 139.96 | F10: 142.66 | G10: 2.7 | H10: 1 | I10: 1 | J10: 1 | K10: 3 | L10: 0.74 | M10: 1.5094 | N10: 0 | O10: 1.6516 | P10: 109.4928 | Q10: 2.7176 | R10: 12.4161
A11: DEATH
A12: GATE | B12: 1 | C12: 1 | D12: 1 | E12: 154.24 | F12: 155.94 | G12: 1.7 | H12: 1 | I12: 1 | J12: 0.2 | K12: 3 | L12: 0.76 | M12: 0 | N12: 1.6023 | O12: 0 | P12: 0 | Q12: 0 | R12: 0
A13: GATE | B13: 2 | C13: 2 | D13: 2 | E13: 159.22 | F13: 160.92 | G13: 1.7 | H13: 1 | I13: 1 | J13: 0.2 | K13: 3 | L13: 0.78 | M13: 0 | N13: 1.7031 | O13: 0 | P13: 0 | Q13: 0 | R13: 0
A14: GATE | B14: 3 | C14: 3 | D14: 3 | E14: 162.92 | F14: 164.54 | G14: 1.62 | H14: 1 | I14: 1 | J14: 0.22 | K14: 3 | L14: 0.76 | M14: 0.1677 | N14: 1.214 | O14: 0.3866 | P14: 0 | Q14: 0 | R14: 0
A15: GATE | B15: 4 | C15: 4 | D15: 4 | E15: 191.4 | F15: 192.64 | G15: 1.24 | H15: 1 | I15: 1 | J15: 0.78 | K15: 2 | L15: 0.46 | M15: 0 | N15: 0 | O15: 0.5362 | P15: 0 | Q15: 0 | R15: 0
A16: GATE | B16: 4 | C16: 4 | D16: 4 | E16: 192.7 | F16: 193.06 | G16: 0.36 | H16: 1 | I16: 1 | J16: 0.3 | K16: 3 | L16: 0.04 | M16: 0.131 | N16: 0 | O16: 0.3644 | P16: 0 | Q16: 0 | R16: 0
A17: DEATH
A18: GATE | B18: 4 | C18: 4 | D18: 4 | E18: 204.36 | F18: 206.62 | G18: 2.26 | H18: 1 | I18: 1 | J18: 0.5 | K18: 3 | L18: 0.46 | M18: 1.0905 | N18: 0 | O18: 1.7449 | P18: 178.6921 | Q18: 2.2715 | R18: 59.0783
A19: GATE | B19: 5 | C19: 5 | D19: 5 | E19: 206.66 | F19: 208.04 | G19: 1.38 | H19: 1 | I19: 0 | J19: 0 | K19: 0 | L19: -1 | M19: 0.3968 | N19: 0 | O19: 1.3657 | P19: 0 | Q19: 0 | R19: 0
A20: GATE | B20: 6 | C20: 6 | D20: 6 | E20: 208.38 | F20: 208.42 | G20: 0.04 | H20: 1 | I20: 0 | J20: 0 | K20: 0 | L20: -1 | M20: 0 | N20: 0 | O20: 0.0292 | P20: 0 | Q20: 0 | R20: 0
A21: DEATH
A22: GATE | B22: 4 | C22: 4 | D22: 4 | E22: 219.06 | F22: 219.84 | G22: 0.78 | H22: 1 | I22: 1 | J22: 0.12 | K22: 3 | L22: 0.34 | M22: 0.0685 | N22: 0 | O22: 0.6317 | P22: 178.4842 | Q22: 2.2616 | R22: 56.8317
A23: GATE | B23: 5 | C23: 5 | D23: 5 | E23: 219.86 | F23: 222.56 | G23: 2.7 | H23: 1 | I23: 1 | J23: 1.36 | K23: 3 | L23: 0.5 | M23: 0.8678 | N23: 0 | O23: 1.7735 | P23: 164.7283 | Q23: 2.0032 | R23: 60.3891
A24: DEATH
A25: GATE | B25: 4 | C25: 4 | D25: 4 | E25: 233.6 | F25: 234.68 | G25: 1.08 | H25: 1 | I25: 1 | J25: 0.1 | K25: 2 | L25: 0.5 | M25: 0 | N25: 0.7966 | O25: 0 | P25: 0 | Q25: 0 | R25: 0
A26: GATE | B26: 5 | C26: 5 | D26: 5 | E26: 234.68 | F26: 236.78 | G26: 2.1 | H26: 1 | I26: 0 | J26: 0 | K26: 0 | L26: -1 | M26: 1.3599 | N26: 0 | O26: 2.1004 | P26: 164.7738 | Q26: 4.5159 | R26: 58.4903
A27: GATE | B27: 6 | C27: 6 | D27: 6 | E27: 237.16 | F27: 238.58 | G27: 1.42 | H27: 1 | I27: 0 | J27: 0 | K27: 0 | L27: -1 | M27: 0.0566 | N27: 0 | O27: 1.3591 | P27: 0 | Q27: 0 | R27: 0
A28: DEATH
A29: GATE | B29: 4 | C29: 4 | D29: 4 | E29: 250.6 | F29: 251.68 | G29: 1.08 | H29: 1 | I29: 1 | J29: 0.14 | K29: 3 | L29: 0.48 | M29: 0 | N29: 1.0677 | O29: 0 | P29: 0 | Q29: 0 | R29: 0
A30: GATE | B30: 5 | C30: 5 | D30: 5 | E30: 251.7 | F30: 253.06 | G30: 1.36 | H30: 1 | I30: 1 | J30: 0.7 | K30: 3 | L30: 0.48 | M30: 0 | N30: 1.3555 | O30: 0.5282 | P30: 0 | Q30: 0 | R30: 0
A31: DEATH
A32: GATE | B32: 4 | C32: 4 | D32: 4 | E32: 265.8 | F32: 267 | G32: 1.2 | H32: 1 | I32: 1 | J32: 0.3 | K32: 3 | L32: 0.48 | M32: 0 | N32: 0.5326 | O32: 0 | P32: 0 | Q32: 0 | R32: 0
A33: GATE | B33: 5 | C33: 5 | D33: 5 | E33: 267.02 | F33: 269.02 | G33: 2 | H33: 1 | I33: 1 | J33: 0.94 | K33: 1 | L33: 0.24 | M33: 1.0107 | N33: 0 | O33: 1.192 | P33: 0 | Q33: 0 | R33: 0
A34: GATE | B34: 6 | C34: 6 | D34: 6 | E34: 269.38 | F34: 270.74 | G34: 1.36 | H34: 1 | I34: 0 | J34: 0 | K34: 0 | L34: -1 | M34: 0.1472 | N34: 0 | O34: 1.3568 | P34: 0 | Q34: 0 | R34: 0
A35: DEATH
A36: GATE | B36: 4 | C36: 4 | D36: 4 | E36: 282.68 | F36: 283.78 | G36: 1.1 | H36: 1 | I36: 1 | J36: 0.12 | K36: 3 | L36: 0.5 | M36: 0 | N36: 1.0501 | O36: 0.033 | P36: 0 | Q36: 0 | R36: 0
A37: GATE | B37: 5 | C37: 5 | D37: 5 | E37: 283.78 | F37: 285.74 | G37: 1.96 | H37: 1 | I37: 0 | J37: 0 | K37: 0 | L37: -1 | M37: 1.5241 | N37: 0 | O37: 1.9661 | P37: 164.6945 | Q37: 9.8082 | R37: 57.8064
A38: GATE | B38: 6 | C38: 6 | D38: 6 | E38: 286.1 | F38: 287.38 | G38: 1.28 | H38: 1 | I38: 0 | J38: 0 | K38: 0 | L38: -1 | M38: 0 | N38: 0 | O38: 1.2613 | P38: 0 | Q38: 0 | R38: 0
A39: DEATH
A40: GATE | B40: 4 | C40: 4 | D40: 4 | E40: 296.78 | F40: 299.32 | G40: 2.54 | H40: 1 | I40: 1 | J40: 1.06 | K40: 3 | L40: 0.48 | M40: 1.5157 | N40: 0 | O40: 1.8412 | P40: 178.7908 | Q40: 2.8681 | R40: 58.5991
...

Sheet adap_GonzaloCampos
A1: EventType | B1: AttemptID | C1: SegmentID | D1: GateID | E1: EntryTime | F1: ExitTime | G1: TimeToClear_s | H1: Cleared | I1: ObstacleTouched | J1: ContactDuration_s | K1: ContactCount | L1: FirstContactTime_s | M1: JetpackActiveTime_s | N1: CrouchTime_s | O1: AirborneTime_s | P1: ContactX | Q1: ContactY | R1: ContactZ
A2: DEATH
A3: GATE | B3: 1 | C3: 1 | D3: 1 | E3: 39.78 | F3: 40.66 | G3: 0.88 | H3: 1 | I3: 1 | J3: 0.24 | K3: 2 | L3: 0.64 | M3: 0.0228 | N3: 0 | O3: 0.8823 | P3: 0 | Q3: 0 | R3: 0
A4: DEATH
A5: GATE | B5: 1 | C5: 1 | D5: 1 | E5: 47.98 | F5: 49.68 | G5: 1.7 | H5: 1 | I5: 0 | J5: 0 | K5: 0 | L5: -1 | M5: 0.7828 | N5: 0 | O5: 1.7102 | P5: 109.5033 | Q5: 3.9277 | R5: 13.526
A6: DEATH
A7: GATE | B7: 1 | C7: 1 | D7: 1 | E7: 81.64 | F7: 84.26 | G7: 2.62 | H7: 1 | I7: 0 | J7: 0 | K7: 0 | L7: -1 | M7: 1.2673 | N7: 0 | O7: 2.6156 | P7: 109.6292 | Q7: 13.3561 | R7: 11.4262
A8: DEATH
A9: GATE | B9: 1 | C9: 1 | D9: 1 | E9: 91.68 | F9: 92.86 | G9: 1.18 | H9: 1 | I9: 0 | J9: 0 | K9: 0 | L9: -1 | M9: 0.52 | N9: 0 | O9: 1.1846 | P9: 109.6452 | Q9: 2.9023 | R9: 11.5489
A10: DEATH
A11: GATE | B11: 1 | C11: 1 | D11: 1 | E11: 104.84 | F11: 106.78 | G11: 1.94 | H11: 1 | I11: 0 | J11: 0 | K11: 0 | L11: -1 | M11: 0.557 | N11: 0 | O11: 1.7501 | P11: 109.572 | Q11: 9.2512 | R11: 10.8325
A12: GATE | B12: 2 | C12: 2 | D12: 2 | E12: 110.6 | F12: 111.84 | G12: 1.24 | H12: 1 | I12: 0 | J12: 0 | K12: 0 | L12: -1 | M12: 0.0382 | N12: 0 | O12: 1.1939 | P12: 157.5103 | Q12: 7.5989 | R12: 11.2263
A13: GATE | B13: 3 | C13: 3 | D13: 3 | E13: 113.04 | F13: 113.84 | G13: 0.8 | H13: 1 | I13: 1 | J13: 0.14 | K13: 2 | L13: 0.6 | M13: 0.0385 | N13: 0 | O13: 0.7935 | P13: 0 | Q13: 0 | R13: 0
A14: DEATH
A15: GATE | B15: 1 | C15: 1 | D15: 1 | E15: 121.32 | F15: 122.88 | G15: 1.56 | H15: 1 | I15: 1 | J15: 0.26 | K15: 1 | L15: 0.52 | M15: 0.1885 | N15: 0 | O15: 1.1206 | P15: 0 | Q15: 0 | R15: 0
A16: GATE | B16: 2 | C16: 2 | D16: 2 | E16: 126.76 | F16: 127.94 | G16: 1.18 | H16: 1 | I16: 1 | J16: 0.04 | K16: 1 | L16: 0.6 | M16: 0 | N16: 0 | O16: 0.7457 | P16: 157.7761 | Q16: 2.3013 | R16: 10.654
A17: DEATH
A18: GATE | B18: 1 | C18: 1 | D18: 1 | E18: 137.8 | F18: 139.46 | G18: 1.66 | H18: 1 | I18: 0 | J18: 0 | K18: 0 | L18: -1 | M18: 0 | N18: 0 | O18: 0.5647 | P18: 109.6706 | Q18: 2.2359 | R18: 10.3805
A19: GATE | B19: 2 | C19: 2 | D19: 2 | E19: 143.02 | F19: 144.34 | G19: 1.32 | H19: 1 | I19: 1 | J19: 0.08 | K19: 2 | L19: 0.52 | M19: 0 | N19: 0 | O19: 0.7107 | P19: 157.6926 | Q19: 2.3774 | R19: 10.3807
A20: GATE | B20: 3 | C20: 3 | D20: 3 | E20: 146.28 | F20: 147.74 | G20: 1.46 | H20: 1 | I20: 1 | J20: 0.02 | K20: 1 | L20: 0.76 | M20: 0 | N20: 0 | O20: 0.6774 | P20: 187.4834 | Q20: 2.2352 | R20: 10.5247
A21: GATE | B21: 4 | C21: 4 | D21: 4 | E21: 178.96 | F21: 179.72 | G21: 0.76 | H21: 1 | I21: 0 | J21: 0 | K21: 0 | L21: -1 | M21: 0.1091 | N21: 0 | O21: 0.6987 | P21: 178.6695 | Q21: 2.2372 | R21: 60.1017
A22: GATE | B22: 5 | C22: 5 | D22: 5 | E22: 179.76 | F22: 181.26 | G22: 1.5 | H22: 1 | I22: 1 | J22: 0.48 | K22: 1 | L22: 0.5 | M22: 0.0963 | N22: 0 | O22: 0.9238 | P22: 164.6473 | Q22: 1.8571 | R22: 61.7295
A23: GATE | B23: 6 | C23: 6 | D23: 6 | E23: 181.44 | F23: 182.14 | G23: 0.7 | H23: 1 | I23: 0 | J23: 0 | K23: 0 | L23: -1 | M23: 0.1629 | N23: 0 | O23: 0.6686 | P23: 147.5811 | Q23: 2.304 | R23: 58.9818
A24: GATE | B24: 7 | C24: 7 | D24: 7 | E24: 184.14 | F24: 186.26 | G24: 2.12 | H24: 1 | I24: 1 | J24: 0.94 | K24: 3 | L24: 0.46 | M24: 0 | N24: 0 | O24: 1.822 | P24: 108.2417 | Q24: 2.3142 | R24: 60.2909
A25: GATE | B25: 8 | C25: 8 | D25: 8 | E25: 187 | F25: 188.36 | G25: 1.36 | H25: 1 | I25: 0 | J25: 0 | K25: 0 | L25: -1 | M25: 1.0524 | N25: 0 | O25: 1.3703 | P25: 87.2445 | Q25: 4.8332 | R25: 59.6969
A26: DEATH
A27: DEATH
A28: DEATH
A29: DEATH
A30: DEATH
A31: DEATH
A32: DEATH
A33: DEATH
A34: DEATH
A35: DEATH
A36: DEATH
A37: DEATH

Sheet adap_IgnaciaDelgado
A1: EventType | B1: AttemptID | C1: SegmentID | D1: GateID | E1: EntryTime | F1: ExitTime | G1: TimeToClear_s | H1: Cleared | I1: ObstacleTouched | J1: ContactDuration_s | K1: ContactCount | L1: FirstContactTime_s | M1: JetpackActiveTime_s | N1: CrouchTime_s | O1: AirborneTime_s | P1: ContactX | Q1: ContactY | R1: ContactZ
A2: DEATH
A3: DEATH
A4: DEATH
A5: DEATH
A6: DEATH
A7: DEATH
A8: DEATH
A9: DEATH
A10: GATE | B10: 1 | C10: 1 | D10: 1 | E10: 977.58 | F10: 979.32 | G10: 1.7401 | H10: 1 | I10: 0 | J10: 0 | K10: 0 | L10: -1 | M10: 0.6866 | N10: 0 | O10: 1.7093 | P10: 109.5386 | Q10: 5.8149 | R10: 10.4604
A11: GATE | B11: 2 | C11: 2 | D11: 2 | E11: 983.52 | F11: 984.86 | G11: 1.34 | H11: 1 | I11: 0 | J11: 0 | K11: 0 | L11: -1 | M11: 0 | N11: 0 | O11: 1.3517 | P11: 157.5071 | Q11: 12.3463 | R11: 8.7172
A12: GATE | B12: 3 | C12: 3 | D12: 3 | E12: 986.22 | F12: 987.46 | G12: 1.24 | H12: 1 | I12: 0 | J12: 0 | K12: 0 | L12: -1 | M12: 0 | N12: 0 | O12: 1.1192 | P12: 187.5899 | Q12: 2.2507 | R12: 7.833
A13: GATE | B13: 4 | C13: 4 | D13: 4 | E13: 995.74 | F13: 996.82 | G13: 1.08 | H13: 1 | I13: 0 | J13: 0 | K13: 0 | L13: -1 | M13: 0 | N13: 0 | O13: 0 | P13: 0 | Q13: 0 | R13: 0
A14: GATE | B14: 5 | C14: 5 | D14: 5 | E14: 996.82 | F14: 997.62 | G14: 0.8 | H14: 1 | I14: 0 | J14: 0 | K14: 0 | L14: -1 | M14: 0 | N14: 0 | O14: 0.7449 | P14: 164.4799 | Q14: 2.0632 | R14: 58.1871
A15: GATE | B15: 6 | C15: 6 | D15: 6 | E15: 997.88 | F15: 1000.5 | G15: 2.62 | H15: 1 | I15: 0 | J15: 0 | K15: 0 | L15: -1 | M15: 1.509 | N15: 0 | O15: 2.587 | P15: 147.4518 | Q15: 2.3725 | R15: 58.7484
A16: DEATH
A17: GATE | B17: 4 | C17: 4 | D17: 4 | E17: 1011.5 | F17: 1012.88 | G17: 1.38 | H17: 1 | I17: 0 | J17: 0 | K17: 0 | L17: -1 | M17: 0.4003 | N17: 0 | O17: 1.3705 | P17: 178.7469 | Q17: 7.9103 | R17: 62.7355
A18: GATE | B18: 5 | C18: 5 | D18: 5 | E18: 1012.9 | F18: 1013.58 | G18: 0.68 | H18: 1 | I18: 0 | J18: 0 | K18: 0 | L18: -1 | M18: 0.0336 | N18: 0 | O18: 0.6851 | P18: 0 | Q18: 0 | R18: 0
A19: DEATH
A20: GATE | B20: 4 | C20: 4 | D20: 4 | E20: 1022.64 | F20: 1024.78 | G20: 2.1401 | H20: 1 | I20: 0 | J20: 0 | K20: 0 | L20: -1 | M20: 1.5005 | N20: 0 | O20: 2.1377 | P20: 178.8131 | Q20: 4.2627 | R20: 58.7184
A21: GATE | B21: 5 | C21: 5 | D21: 5 | E21: 1024.8 | F21: 1026.16 | G21: 1.3601 | H21: 1 | I21: 0 | J21: 0 | K21: 0 | L21: -1 | M21: 0.0182 | N21: 0 | O21: 1.3701 | P21: 164.7345 | Q21: 4.8313 | R21: 60.5144
A22: DEATH
A23: GATE | B23: 4 | C23: 4 | D23: 4 | E23: 1035.08 | F23: 1036.14 | G23: 1.0601 | H23: 1 | I23: 1 | J23: 0.12 | K23: 2 | L23: 0.48 | M23: 0 | N23: 0.997 | O23: 0.0641 | P23: 0 | Q23: 0 | R23: 0
A24: GATE | B24: 5 | C24: 5 | D24: 5 | E24: 1036.16 | F24: 1038.02 | G24: 1.86 | H24: 1 | I24: 0 | J24: 0 | K24: 0 | L24: -1 | M24: 0.8427 | N24: 0 | O24: 1.8465 | P24: 164.5558 | Q24: 6.2466 | R24: 59.3173
A25: GATE | B25: 6 | C25: 6 | D25: 6 | E25: 1038.4 | F25: 1039.58 | G25: 1.1799 | H25: 1 | I25: 1 | J25: 0.1799 | K25: 3 | L25: 0.62 | M25: 0.2337 | N25: 0 | O25: 1.1761 | P25: 0 | Q25: 0 | R25: 0
A26: DEATH
A27: GATE | B27: 4 | C27: 4 | D27: 4 | E27: 1048.54 | F27: 1049.54 | G27: 1 | H27: 1 | I27: 1 | J27: 0.1 | K27: 3 | L27: 0.4801 | M27: 0.033 | N27: 0.7362 | O27: 0.2644 | P27: 0 | Q27: 0 | R27: 0
A28: GATE | B28: 5 | C28: 5 | D28: 5 | E28: 1049.54 | F28: 1050.76 | G28: 1.2201 | H28: 1 | I28: 0 | J28: 0 | K28: 0 | L28: -1 | M28: 0.5312 | N28: 0 | O28: 1.2183 | P28: 164.595 | Q28: 4.4879 | R28: 59.6872
A29: GATE | B29: 6 | C29: 6 | D29: 6 | E29: 1050.98 | F29: 1051.94 | G29: 0.96 | H29: 1 | I29: 1 | J29: 0.1801 | K29: 2 | L29: 0.3199 | M29: 0 | N29: 0.6128 | O29: 0 | P29: 0 | Q29: 0 | R29: 0
A30: GATE | B30: 7 | C30: 7 | D30: 7 | E30: 1053.9 | F30: 1054.94 | G30: 1.0399 | H30: 1 | I30: 1 | J30: 0.14 | K30: 3 | L30: 0.48 | M30: 0 | N30: 0.7791 | O30: 0.2625 | P30: 0 | Q30: 0 | R30: 0
A31: GATE | B31: 8 | C31: 8 | D31: 8 | E31: 1055.34 | F31: 1056.68 | G31: 1.34 | H31: 1 | I31: 0 | J31: 0 | K31: 0 | L31: -1 | M31: 1.1833 | N31: 0 | O31: 1.333 | P31: 87.2614 | Q31: 5.4001 | R31: 58.4461
A32: DEATH
A33: DEATH
A34: DEATH
A35: DEATH
A36: DEATH
A37: DEATH
A38: DEATH
A39: DEATH

Sheet adap_IsidoraToledo
A1: EventType | B1: AttemptID | C1: SegmentID | D1: GateID | E1: EntryTime | F1: ExitTime | G1: TimeToClear_s | H1: Cleared | I1: ObstacleTouched | J1: ContactDuration_s | K1: ContactCount | L1: FirstContactTime_s | M1: JetpackActiveTime_s | N1: CrouchTime_s | O1: AirborneTime_s | P1: ContactX | Q1: ContactY | R1: ContactZ
A2: GATE | B2: 1 | C2: 1 | D2: 1 | E2: 84.84 | F2: 85.84 | G2: 1 | H2: 1 | I2: 0 | J2: 0 | K2: 0 | L2: -1 | M2: 0 | N2: 0 | O2: 0.6659 | P2: 109.895 | Q2: 2.3542 | R2: 11.4407
A3: GATE | B3: 2 | C3: 2 | D3: 2 | E3: 90.06 | F3: 91.06 | G3: 1 | H3: 1 | I3: 0 | J3: 0 | K3: 0 | L3: -1 | M3: 0.2256 | N3: 0 | O3: 0.9322 | P3: 0 | Q3: 0 | R3: 0
A4: GATE | B4: 3 | C4: 3 | D4: 3 | E4: 92.7 | F4: 94.06 | G4: 1.36 | H4: 1 | I4: 0 | J4: 0 | K4: 0 | L4: -1 | M4: 0.0652 | N4: 0 | O4: 1.3541 | P4: 187.5143 | Q4: 3.8941 | R4: 11.1527
A5: DEATH
A6: GATE | B6: 1 | C6: 1 | D6: 1 | E6: 108.64 | F6: 111.46 | G6: 2.82 | H6: 1 | I6: 0 | J6: 0 | K6: 0 | L6: -1 | M6: 0 | N6: 0 | O6: 1.7088 | P6: 109.462 | Q6: 2.3348 | R6: 11.2391
A7: DEATH
A8: GATE | B8: 1 | C8: 1 | D8: 1 | E8: 119.98 | F8: 122.52 | G8: 2.54 | H8: 1 | I8: 1 | J8: 0.06 | K8: 3 | L8: 0.76 | M8: 0 | N8: 0 | O8: 1.7303 | P8: 109.7126 | Q8: 2.4077 | R8: 10.5476
A9: DEATH
A10: GATE | B10: 1 | C10: 1 | D10: 1 | E10: 130.46 | F10: 132.72 | G10: 2.26 | H10: 1 | I10: 0 | J10: 0 | K10: 0 | L10: -1 | M10: 0 | N10: 0 | O10: 1.1298 | P10: 0 | Q10: 0 | R10: 0
A11: DEATH
A12: GATE | B12: 1 | C12: 1 | D12: 1 | E12: 142.6 | F12: 144.3 | G12: 1.7 | H12: 1 | I12: 1 | J12: 0.24 | K12: 3 | L12: 0.72 | M12: 0 | N12: 1.6924 | O12: 0 | P12: 0 | Q12: 0 | R12: 0
A13: GATE | B13: 2 | C13: 2 | D13: 2 | E13: 149.22 | F13: 150.48 | G13: 1.26 | H13: 1 | I13: 0 | J13: 0 | K13: 0 | L13: -1 | M13: 0 | N13: 0 | O13: 1.2649 | P13: 157.712 | Q13: 12.446 | R13: 10.307
A14: DEATH
A15: GATE | B15: 1 | C15: 1 | D15: 1 | E15: 160.02 | F15: 161.72 | G15: 1.7 | H15: 1 | I15: 1 | J15: 0.2 | K15: 3 | L15: 0.76 | M15: 0 | N15: 1.5881 | O15: 0 | P15: 0 | Q15: 0 | R15: 0
A16: GATE | B16: 2 | C16: 2 | D16: 2 | E16: 165.18 | F16: 166.86 | G16: 1.68 | H16: 1 | I16: 1 | J16: 0.22 | K16: 3 | L16: 0.74 | M16: 0 | N16: 1.5321 | O16: 0.1437 | P16: 0 | Q16: 0 | R16: 0
A17: GATE | B17: 3 | C17: 3 | D17: 3 | E17: 168.36 | F17: 169.72 | G17: 1.36 | H17: 1 | I17: 0 | J17: 0 | K17: 0 | L17: -1 | M17: 1.0189 | N17: 0 | O17: 1.3461 | P17: 187.6946 | Q17: 5.5079 | R17: 11.2371
A18: GATE | B18: 4 | C18: 4 | D18: 4 | E18: 191.92 | F18: 192.96 | G18: 1.04 | H18: 1 | I18: 1 | J18: 0.18 | K18: 3 | L18: 0.44 | M18: 0 | N18: 0.8136 | O18: 0 | P18: 0 | Q18: 0 | R18: 0
A19: GATE | B19: 5 | C19: 5 | D19: 5 | E19: 193.02 | F19: 194.24 | G19: 1.22 | H19: 1 | I19: 0 | J19: 0 | K19: 0 | L19: -1 | M19: 0.7674 | N19: 0 | O19: 1.2263 | P19: 164.6301 | Q19: 2.1515 | R19: 59.174
A20: GATE | B20: 6 | C20: 6 | D20: 6 | E20: 194.6 | F20: 195.94 | G20: 1.34 | H20: 1 | I20: 0 | J20: 0 | K20: 0 | L20: -1 | M20: 0.423 | N20: 0 | O20: 1.3506 | P20: 147.1329 | Q20: 11.76 | R20: 59.0075
A21: DEATH
A22: DEATH
A23: GATE | B23: 4 | C23: 4 | D23: 4 | E23: 234.64 | F23: 236.46 | G23: 1.82 | H23: 1 | I23: 0 | J23: 0 | K23: 0 | L23: -1 | M23: 0.2991 | N23: 0 | O23: 1.0903 | P23: 0 | Q23: 0 | R23: 0
A24: GATE | B24: 5 | C24: 5 | D24: 5 | E24: 236.46 | F24: 237.82 | G24: 1.36 | H24: 1 | I24: 0 | J24: 0 | K24: 0 | L24: -1 | M24: 1.2184 | N24: 0 | O24: 1.3593 | P24: 164.3613 | Q24: 4.3063 | R24: 57.92
A25: GATE | B25: 6 | C25: 6 | D25: 6 | E25: 238.18 | F25: 239.56 | G25: 1.38 | H25: 1 | I25: 0 | J25: 0 | K25: 0 | L25: -1 | M25: 0.0663 | N25: 0 | O25: 1.3782 | P25: 147.1425 | Q25: 4.939 | R25: 58.3312
A26: DEATH
A27: GATE | B27: 4 | C27: 4 | D27: 4 | E27: 251.06 | F27: 252.12 | G27: 1.06 | H27: 1 | I27: 1 | J27: 0.1 | K27: 3 | L27: 0.5 | M27: 0 | N27: 0.8346 | O27: 0 | P27: 0 | Q27: 0 | R27: 0
A28: GATE | B28: 5 | C28: 5 | D28: 5 | E28: 252.12 | F28: 253.86 | G28: 1.74 | H28: 1 | I28: 1 | J28: 0.22 | K28: 1 | L28: 1.28 | M28: 0 | N28: 0 | O28: 1.3623 | P28: 164.2075 | Q28: 2.0752 | R28: 56.3083
A29: DEATH
A30: GATE | B30: 4 | C30: 4 | D30: 4 | E30: 271.8 | F30: 272.82 | G30: 1.02 | H30: 1 | I30: 1 | J30: 0.18 | K30: 3 | L30: 0.44 | M30: 0 | N30: 0.7539 | O30: 0 | P30: 0 | Q30: 0 | R30: 0
A31: GATE | B31: 5 | C31: 5 | D31: 5 | E31: 272.88 | F31: 273.66 | G31: 0.78 | H31: 1 | I31: 0 | J31: 0 | K31: 0 | L31: -1 | M31: 0 | N31: 0 | O31: 0.6269 | P31: 0 | Q31: 0 | R31: 0
A32: GATE | B32: 6 | C32: 6 | D32: 6 | E32: 273.82 | F32: 274.04 | G32: 0.22 | H32: 1 | I32: 0 | J32: 0 | K32: 0 | L32: -1 | M32: 0 | N32: 0 | O32: 0.2239 | P32: 0 | Q32: 0 | R32: 0
A33: DEATH
A34: GATE | B34: 4 | C34: 4 | D34: 4 | E34: 290.7 | F34: 291.8 | G34: 1.1 | H34: 1 | I34: 1 | J34: 0.1 | K34: 3 | L34: 0.5 | M34: 0 | N34: 0.5951 | O34: 0 | P34: 0 | Q34: 0 | R34: 0
A35: GATE | B35: 5 | C35: 5 | D35: 5 | E35: 291.8 | F35: 292.68 | G35: 0.88 | H35: 1 | I35: 0 | J35: 0 | K35: 0 | L35: -1 | M35: 0 | N35: 0 | O35: 0.7261 | P35: 164.5534 | Q35: 2.148 | R35: 56.8313
A36: GATE | B36: 6 | C36: 6 | D36: 6 | E36: 292.9 | F36: 293.98 | G36: 1.08 | H36: 1 | I36: 1 | J36: 0.16 | K36: 3 | L36: 0.5 | M36: 0 | N36: 0.8035 | O36: 0 | P36: 0 | Q36: 0 | R36: 0
A37: GATE | B37: 7 | C37: 7 | D37: 7 | E37: 295.92 | F37: 297.02 | G37: 1.1 | H37: 1 | I37: 1 | J37: 0.14 | K37: 3 | L37: 0.48 | M37: 0 | N37: 1.0845 | O37: 0 | P37: 0 | Q37: 0 | R37: 0
A38: GATE | B38: 8 | C38: 8 | D38: 8 | E38: 297.52 | F38: 298.46 | G38: 0.94 | H38: 1 | I38: 0 | J38: 0 | K38: 0 | L38: -1 | M38: 0 | N38: 0 | O38: 0.6816 | P38: 87.4245 | Q38: 1.9367 | R38: 56.8966
A39: DEATH
A40: GATE | B40: 4 | C40: 4 | D40: 4 | E40: 319.12 | F40: 320.14 | G40: 1.02 | H40: 1 | I40: 1 | J40: 0.16 | K40: 3 | L40: 0.46 | M40: 0 | N40: 1.0306 | O40: 0 | P40: 0 | Q40: 0 | R40: 0
...

Sheet adap_JavierSalinas
A1: EventType | B1: AttemptID | C1: SegmentID | D1: GateID | E1: EntryTime | F1: ExitTime | G1: TimeToClear_s | H1: Cleared | I1: ObstacleTouched | J1: ContactDuration_s | K1: ContactCount | L1: FirstContactTime_s | M1: JetpackActiveTime_s | N1: CrouchTime_s | O1: AirborneTime_s | P1: ContactX | Q1: ContactY | R1: ContactZ
A2: DEATH
A3: GATE | B3: 1 | C3: 1 | D3: 1 | E3: 53.9 | F3: 55.32 | G3: 1.42 | H3: 1 | I3: 0 | J3: 0 | K3: 0 | L3: -1 | M3: 0.7736 | N3: 0 | O3: 1.417 | P3: 109.6303 | Q3: 7.5107 | R3: 13.6019
A4: DEATH
A5: GATE | B5: 1 | C5: 1 | D5: 1 | E5: 66.44 | F5: 68.98 | G5: 2.54 | H5: 1 | I5: 0 | J5: 0 | K5: 0 | L5: -1 | M5: 1.1921 | N5: 0 | O5: 2.5478 | P5: 109.7084 | Q5: 13.6093 | R5: 11.6935
A6: DEATH
A7: GATE | B7: 1 | C7: 1 | D7: 1 | E7: 75.94 | F7: 77.42 | G7: 1.48 | H7: 1 | I7: 1 | J7: 0.04 | K7: 1 | L7: 0.7 | M7: 0.4109 | N7: 0 | O7: 0.9014 | P7: 109.5506 | Q7: 2.3591 | R7: 9.621
A8: GATE | B8: 2 | C8: 2 | D8: 2 | E8: 80.8 | F8: 80.98 | G8: 0.18 | H8: 1 | I8: 0 | J8: 0 | K8: 0 | L8: -1 | M8: 0 | N8: 0 | O8: 0.1602 | P8: 0 | Q8: 0 | R8: 0
A9: DEATH
A10: GATE | B10: 1 | C10: 1 | D10: 1 | E10: 101.58 | F10: 104.62 | G10: 3.04 | H10: 1 | I10: 1 | J10: 1.68 | K10: 3 | L10: 0.74 | M10: 1.1794 | N10: 0 | O10: 1.625 | P10: 0 | Q10: 0 | R10: 0
A11: DEATH
A12: GATE | B12: 1 | C12: 1 | D12: 1 | E12: 114.76 | F12: 116.96 | G12: 2.2 | H12: 1 | I12: 0 | J12: 0 | K12: 0 | L12: -1 | M12: 0.6726 | N12: 0 | O12: 2.1372 | P12: 109.9271 | Q12: 2.2524 | R12: 12.2544
A13: DEATH
A14: GATE | B14: 1 | C14: 1 | D14: 1 | E14: 123.36 | F14: 124.4 | G14: 1.04 | H14: 1 | I14: 0 | J14: 0 | K14: 0 | L14: -1 | M14: 0.7861 | N14: 0 | O14: 1.0408 | P14: 109.7336 | Q14: 2.4422 | R14: 10.5293
A15: DEATH
A16: GATE | B16: 1 | C16: 1 | D16: 1 | E16: 133.78 | F16: 136.14 | G16: 2.36 | H16: 1 | I16: 1 | J16: 1.4 | K16: 3 | L16: 0.76 | M16: 0.2377 | N16: 0 | O16: 1.0798 | P16: 0 | Q16: 0 | R16: 0
A17: DEATH
A18: GATE | B18: 1 | C18: 1 | D18: 1 | E18: 143.56 | F18: 145.44 | G18: 1.88 | H18: 1 | I18: 1 | J18: 0.18 | K18: 2 | L18: 1.7 | M18: 0.4944 | N18: 0 | O18: 1.8157 | P18: 0 | Q18: 0 | R18: 0
A19: DEATH
A20: GATE | B20: 1 | C20: 1 | D20: 1 | E20: 151.62 | F20: 152.82 | G20: 1.2 | H20: 1 | I20: 0 | J20: 0 | K20: 0 | L20: -1 | M20: 0.2011 | N20: 0 | O20: 1.1575 | P20: 109.7124 | Q20: 2.9046 | R20: 9.9529
A21: DEATH
A22: GATE | B22: 1 | C22: 1 | D22: 1 | E22: 159.48 | F22: 161.04 | G22: 1.56 | H22: 1 | I22: 1 | J22: 0.06 | K22: 2 | L22: 0.62 | M22: 0.4095 | N22: 0 | O22: 1.0593 | P22: 109.5254 | Q22: 2.3414 | R22: 12.3292
A23: GATE | B23: 2 | C23: 2 | D23: 2 | E23: 164.78 | F23: 165.92 | G23: 1.14 | H23: 1 | I23: 0 | J23: 0 | K23: 0 | L23: -1 | M23: 0 | N23: 0 | O23: 0.6596 | P23: 157.6619 | Q23: 2.3836 | R23: 12.4502
A24: DEATH
A25: GATE | B25: 1 | C25: 1 | D25: 1 | E25: 172.96 | F25: 174.24 | G25: 1.28 | H25: 1 | I25: 0 | J25: 0 | K25: 0 | L25: -1 | M25: 0.1354 | N25: 0 | O25: 0.9145 | P25: 109.4594 | Q25: 2.3494 | R25: 11.6633
A26: DEATH
A27: GATE | B27: 1 | C27: 1 | D27: 1 | E27: 201.28 | F27: 202.52 | G27: 1.24 | H27: 1 | I27: 0 | J27: 0 | K27: 0 | L27: -1 | M27: 0 | N27: 0 | O27: 0.9582 | P27: 109.6107 | Q27: 4.7792 | R27: 10.8894
A28: GATE | B28: 2 | C28: 2 | D28: 2 | E28: 206.46 | F28: 208.96 | G28: 2.5 | H28: 1 | I28: 1 | J28: 0.36 | K28: 3 | L28: 1.38 | M28: 0.5873 | N28: 0 | O28: 2.2313 | P28: 157.5285 | Q28: 2.293 | R28: 11.6806
A29: DEATH
A30: GATE | B30: 1 | C30: 1 | D30: 1 | E30: 216.06 | F30: 218.28 | G30: 2.22 | H30: 1 | I30: 0 | J30: 0 | K30: 0 | L30: -1 | M30: 0.9074 | N30: 0 | O30: 1.8171 | P30: 109.498 | Q30: 3.034 | R30: 12.4917
A31: GATE | B31: 2 | C31: 2 | D31: 2 | E31: 221.12 | F31: 222.38 | G31: 1.26 | H31: 1 | I31: 0 | J31: 0 | K31: 0 | L31: -1 | M31: 0.1205 | N31: 0 | O31: 1.0688 | P31: 157.7324 | Q31: 2.5712 | R31: 10.9359
A32: DEATH
A33: GATE | B33: 1 | C33: 1 | D33: 1 | E33: 229.4 | F33: 231.62 | G33: 2.22 | H33: 1 | I33: 0 | J33: 0 | K33: 0 | L33: -1 | M33: 1.3628 | N33: 0 | O33: 2.0031 | P33: 109.6819 | Q33: 6.3651 | R33: 11.5396
A34: GATE | B34: 2 | C34: 2 | D34: 2 | E34: 234.38 | F34: 235.92 | G34: 1.54 | H34: 1 | I34: 0 | J34: 0 | K34: 0 | L34: -1 | M34: 0.4154 | N34: 0 | O34: 1.1098 | P34: 157.8035 | Q34: 2.564 | R34: 8.6585
A35: GATE | B35: 3 | C35: 3 | D35: 3 | E35: 237.82 | F35: 239.52 | G35: 1.7 | H35: 1 | I35: 0 | J35: 0 | K35: 0 | L35: -1 | M35: 1.2773 | N35: 0 | O35: 1.6102 | P35: 187.5592 | Q35: 3.5373 | R35: 11.908
A36: GATE | B36: 4 | C36: 4 | D36: 4 | E36: 251.7 | F36: 253.02 | G36: 1.32 | H36: 1 | I36: 0 | J36: 0 | K36: 0 | L36: -1 | M36: 0.7359 | N36: 0 | O36: 1.3349 | P36: 178.8429 | Q36: 2.3473 | R36: 55.5297
A37: GATE | B37: 5 | C37: 5 | D37: 5 | E37: 253.08 | F37: 254.14 | G37: 1.06 | H37: 1 | I37: 1 | J37: 0.1 | K37: 1 | L37: 0.68 | M37: 0 | N37: 0 | O37: 0.6904 | P37: 0 | Q37: 0 | R37: 0
A38: GATE | B38: 6 | C38: 6 | D38: 6 | E38: 254.34 | F38: 256.92 | G38: 2.58 | H38: 1 | I38: 1 | J38: 1.1 | K38: 6 | L38: 0.28 | M38: 0.9924 | N38: 0 | O38: 2.1537 | P38: 147.5688 | Q38: 2.7337 | R38: 56.4778
A39: DEATH
A40: GATE | B40: 4 | C40: 4 | D40: 4 | E40: 268.96 | F40: 270.28 | G40: 1.32 | H40: 1 | I40: 0 | J40: 0 | K40: 0 | L40: -1 | M40: 0.4733 | N40: 0 | O40: 1.1922 | P40: 178.7503 | Q40: 2.308 | R40: 59.5254
...

Sheet adap_MariannaMaregatti
A1: EventType | B1: AttemptID | C1: SegmentID | D1: GateID | E1: EntryTime | F1: ExitTime | G1: TimeToClear_s | H1: Cleared | I1: ObstacleTouched | J1: ContactDuration_s | K1: ContactCount | L1: FirstContactTime_s | M1: JetpackActiveTime_s | N1: CrouchTime_s | O1: AirborneTime_s | P1: ContactX | Q1: ContactY | R1: ContactZ
A2: GATE | B2: 1 | C2: 1 | D2: 1 | E2: 52.74 | F2: 54.62 | G2: 1.88 | H2: 1 | I2: 1 | J2: 0.3 | K2: 3 | L2: 0.64 | M2: 0.6685 | N2: 0 | O2: 1.3625 | P2: 109.5034 | Q2: 2.2669 | R2: 9.8613
A3: DEATH
A4: GATE | B4: 1 | C4: 1 | D4: 1 | E4: 67.82 | F4: 69.52 | G4: 1.7 | H4: 1 | I4: 1 | J4: 0.24 | K4: 3 | L4: 0.74 | M4: 0 | N4: 1.6665 | O4: 0 | P4: 0 | Q4: 0 | R4: 0
A5: GATE | B5: 1 | C5: 1 | D5: 1 | E5: 73.42 | F5: 75.14 | G5: 1.72 | H5: 1 | I5: 1 | J5: 0.22 | K5: 3 | L5: 0.76 | M5: 0 | N5: 1.3921 | O5: 0 | P5: 0 | Q5: 0 | R5: 0
A6: GATE | B6: 1 | C6: 1 | D6: 1 | E6: 80.82 | F6: 82.56 | G6: 1.74 | H6: 1 | I6: 1 | J6: 0.2 | K6: 2 | L6: 0.78 | M6: 0 | N6: 1.5581 | O6: 0.1787 | P6: 0 | Q6: 0 | R6: 0
A7: GATE | B7: 2 | C7: 2 | D7: 2 | E7: 86 | F7: 87.72 | G7: 1.72 | H7: 1 | I7: 1 | J7: 0.2 | K7: 3 | L7: 0.76 | M7: 0 | N7: 1.4469 | O7: 0 | P7: 0 | Q7: 0 | R7: 0
A8: GATE | B8: 3 | C8: 3 | D8: 3 | E8: 89.7 | F8: 91.24 | G8: 1.54 | H8: 1 | I8: 1 | J8: 0.22 | K8: 3 | L8: 0.74 | M8: 0 | N8: 1.2165 | O8: 0.393 | P8: 0 | Q8: 0 | R8: 0
A9: GATE | B9: 4 | C9: 4 | D9: 4 | E9: 100.9 | F9: 101.94 | G9: 1.04 | H9: 1 | I9: 1 | J9: 0.1 | K9: 3 | L9: 0.46 | M9: 0 | N9: 0.9772 | O9: 0.0627 | P9: 0 | Q9: 0 | R9: 0
A10: GATE | B10: 5 | C10: 5 | D10: 5 | E10: 101.94 | F10: 104.32 | G10: 2.38 | H10: 1 | I10: 0 | J10: 0 | K10: 0 | L10: -1 | M10: 0.9759 | N10: 1.5227 | O10: 1.8404 | P10: 164.4351 | Q10: 2.2302 | R10: 58.5335
A11: GATE | B11: 6 | C11: 6 | D11: 6 | E11: 104.68 | F11: 106.04 | G11: 1.36 | H11: 1 | I11: 0 | J11: 0 | K11: 0 | L11: -1 | M11: 0.4759 | N11: 1.348 | O11: 1.348 | P11: 147.2045 | Q11: 5.1117 | R11: 59.4768
A12: DEATH
A13: DEATH
A14: GATE | B14: 4 | C14: 4 | D14: 4 | E14: 131.02 | F14: 133.58 | G14: 2.56 | H14: 1 | I14: 1 | J14: 0.02 | K14: 1 | L14: 1.26 | M14: 0 | N14: 0.5065 | O14: 1.0541 | P14: 0 | Q14: 0 | R14: 0
A15: DEATH
A16: GATE | B16: 4 | C16: 4 | D16: 4 | E16: 146.58 | F16: 147.62 | G16: 1.04 | H16: 1 | I16: 1 | J16: 0.1 | K16: 3 | L16: 0.48 | M16: 0 | N16: 1.0226 | O16: 0 | P16: 0 | Q16: 0 | R16: 0
A17: GATE | B17: 5 | C17: 5 | D17: 5 | E17: 147.62 | F17: 148.82 | G17: 1.2 | H17: 1 | I17: 0 | J17: 0 | K17: 0 | L17: -1 | M17: 0 | N17: 0.2489 | O17: 0.7592 | P17: 164.5992 | Q17: 2.0351 | R17: 60.0054
A18: GATE | B18: 6 | C18: 6 | D18: 6 | E18: 149.08 | F18: 150.26 | G18: 1.18 | H18: 1 | I18: 1 | J18: 0.66 | K18: 3 | L18: 0.46 | M18: 0 | N18: 1.1551 | O18: 0.4575 | P18: 0 | Q18: 0 | R18: 0
A19: DEATH
A20: GATE | B20: 4 | C20: 4 | D20: 4 | E20: 162.4 | F20: 164.68 | G20: 2.28 | H20: 1 | I20: 1 | J20: 0.36 | K20: 6 | L20: 0.54 | M20: 1.3351 | N20: 0 | O20: 1.6773 | P20: 0 | Q20: 0 | R20: 0
A21: GATE | B21: 5 | C21: 5 | D21: 5 | E21: 164.68 | F21: 166.38 | G21: 1.7 | H21: 1 | I21: 0 | J21: 0 | K21: 0 | L21: -1 | M21: 0.2672 | N21: 0 | O21: 1.7 | P21: 164.25 | Q21: 9.952 | R21: 57.6164
A22: GATE | B22: 6 | C22: 6 | D22: 6 | E22: 166.76 | F22: 166.94 | G22: 0.18 | H22: 1 | I22: 0 | J22: 0 | K22: 0 | L22: -1 | M22: 0 | N22: 0 | O22: 0.1824 | P22: 0 | Q22: 0 | R22: 0
A23: DEATH
A24: GATE | B24: 4 | C24: 4 | D24: 4 | E24: 176.7 | F24: 177.78 | G24: 1.08 | H24: 1 | I24: 1 | J24: 0.14 | K24: 3 | L24: 0.46 | M24: 0 | N24: 0.7006 | O24: 0 | P24: 0 | Q24: 0 | R24: 0
A25: GATE | B25: 5 | C25: 5 | D25: 5 | E25: 177.78 | F25: 179.88 | G25: 2.1 | H25: 1 | I25: 0 | J25: 0 | K25: 0 | L25: -1 | M25: 0 | N25: 0.4219 | O25: 1.1833 | P25: 0 | Q25: 0 | R25: 0
A26: GATE | B26: 6 | C26: 6 | D26: 6 | E26: 180.28 | F26: 181.74 | G26: 1.46 | H26: 1 | I26: 1 | J26: 0.2 | K26: 3 | L26: 0.62 | M26: 1.005 | N26: 0 | O26: 1.4254 | P26: 0 | Q26: 0 | R26: 0
A27: DEATH
A28: GATE | B28: 4 | C28: 4 | D28: 4 | E28: 193.8 | F28: 194.98 | G28: 1.18 | H28: 1 | I28: 1 | J28: 0.74 | K28: 2 | L28: 0.44 | M28: 0 | N28: 1.1581 | O28: 0.5184 | P28: 0 | Q28: 0 | R28: 0
A29: DEATH
A30: GATE | B30: 4 | C30: 4 | D30: 4 | E30: 207.1 | F30: 209.42 | G30: 2.32 | H30: 1 | I30: 1 | J30: 1.26 | K30: 3 | L30: 0.46 | M30: 1.1122 | N30: 0 | O30: 1.7358 | P30: 0 | Q30: 0 | R30: 0
A31: GATE | B31: 5 | C31: 5 | D31: 5 | E31: 209.42 | F31: 210.84 | G31: 1.42 | H31: 1 | I31: 0 | J31: 0 | K31: 0 | L31: -1 | M31: 0.427 | N31: 0 | O31: 1.406 | P31: 164.7761 | Q31: 4.8737 | R31: 59.8191
A32: DEATH
A33: GATE | B33: 4 | C33: 4 | D33: 4 | E33: 219.44 | F33: 220.72 | G33: 1.28 | H33: 1 | I33: 1 | J33: 0.5 | K33: 3 | L33: 0.44 | M33: 0 | N33: 1.2691 | O33: 0.5165 | P33: 0 | Q33: 0 | R33: 0
A34: DEATH
A35: GATE | B35: 4 | C35: 4 | D35: 4 | E35: 232.18 | F35: 233.22 | G35: 1.04 | H35: 1 | I35: 1 | J35: 0.08 | K35: 3 | L35: 0.52 | M35: 0 | N35: 1.0368 | O35: 0 | P35: 0 | Q35: 0 | R35: 0
A36: GATE | B36: 5 | C36: 5 | D36: 5 | E36: 233.28 | F36: 234.8 | G36: 1.52 | H36: 1 | I36: 0 | J36: 0 | K36: 0 | L36: -1 | M36: 0.6875 | N36: 0 | O36: 1.519 | P36: 164.5678 | Q36: 4.6339 | R36: 55.7702
A37: GATE | B37: 6 | C37: 6 | D37: 6 | E37: 235.18 | F37: 236.64 | G37: 1.46 | H37: 1 | I37: 1 | J37: 0.14 | K37: 3 | L37: 0.66 | M37: 0.7961 | N37: 1.2787 | O37: 1.4597 | P37: 0 | Q37: 0 | R37: 0
A38: DEATH
A39: DEATH
A40: GATE | B40: 4 | C40: 4 | D40: 4 | E40: 256.18 | F40: 257.22 | G40: 1.04 | H40: 1 | I40: 1 | J40: 0.14 | K40: 3 | L40: 0.48 | M40: 0 | N40: 0.7828 | O40: 0.2506 | P40: 0 | Q40: 0 | R40: 0
...

Sheet adap_SebastianRatto
A1: EventType | B1: AttemptID | C1: SegmentID | D1: GateID | E1: EntryTime | F1: ExitTime | G1: TimeToClear_s | H1: Cleared | I1: ObstacleTouched | J1: ContactDuration_s | K1: ContactCount | L1: FirstContactTime_s | M1: JetpackActiveTime_s | N1: CrouchTime_s | O1: AirborneTime_s | P1: ContactX | Q1: ContactY | R1: ContactZ
A2: GATE | B2: 1 | C2: 1 | D2: 1 | E2: 50.8 | F2: 53.26 | G2: 2.46 | H2: 1 | I2: 1 | J2: 0.88 | K2: 3 | L2: 0.72 | M2: 0.6822 | N2: 0 | O2: 1.0142 | P2: 109.5711 | Q2: 2.3585 | R2: 9.7896
A3: GATE | B3: 2 | C3: 2 | D3: 2 | E3: 55.9 | F3: 57.2 | G3: 1.3 | H3: 1 | I3: 0 | J3: 0 | K3: 0 | L3: -1 | M3: 0.3337 | N3: 0 | O3: 1.2358 | P3: 157.6503 | Q3: 2.4354 | R3: 10.2909
A4: DEATH
A5: GATE | B5: 1 | C5: 1 | D5: 1 | E5: 67.84 | F5: 69.02 | G5: 1.18 | H5: 1 | I5: 0 | J5: 0 | K5: 0 | L5: -1 | M5: 0.1389 | N5: 0 | O5: 0.6961 | P5: 109.7719 | Q5: 2.3263 | R5: 10.6011
A6: DEATH
A7: GATE | B7: 1 | C7: 1 | D7: 1 | E7: 81.24 | F7: 83.06 | G7: 1.82 | H7: 1 | I7: 1 | J7: 0.5 | K7: 3 | L7: 0.74 | M7: 0 | N7: 0 | O7: 0.727 | P7: 109.5426 | Q7: 2.359 | R7: 10.5929
A8: GATE | B8: 2 | C8: 2 | D8: 2 | E8: 87.58 | F8: 88.92 | G8: 1.34 | H8: 1 | I8: 0 | J8: 0 | K8: 0 | L8: -1 | M8: 0.1267 | N8: 0 | O8: 1.3524 | P8: 157.7667 | Q8: 5.0747 | R8: 10.9962
A9: DEATH
A10: GATE | B10: 1 | C10: 1 | D10: 1 | E10: 96.24 | F10: 97.86 | G10: 1.62 | H10: 1 | I10: 1 | J10: 0.38 | K10: 3 | L10: 0.68 | M10: 0 | N10: 0 | O10: 0.6638 | P10: 109.5692 | Q10: 2.3508 | R10: 10.6224
A11: GATE | B11: 2 | C11: 2 | D11: 2 | E11: 101.34 | F11: 102.74 | G11: 1.4 | H11: 1 | I11: 1 | J11: 0.1 | K11: 3 | L11: 0.7 | M11: 0 | N11: 0 | O11: 0.7977 | P11: 157.5228 | Q11: 2.3592 | R11: 11.4671
A12: GATE | B12: 2 | C12: 2 | D12: 2 | E12: 103.4 | F12: 103.9 | G12: 0.5 | H12: 1 | I12: 0 | J12: 0 | K12: 0 | L12: -1 | M12: 0.1307 | N12: 0 | O12: 0.4871 | P12: 0 | Q12: 0 | R12: 0
A13: GATE | B13: 2 | C13: 2 | D13: 2 | E13: 104.58 | F13: 105.14 | G13: 0.56 | H13: 1 | I13: 0 | J13: 0 | K13: 0 | L13: -1 | M13: 0.2461 | N13: 0 | O13: 0.5578 | P13: 0 | Q13: 0 | R13: 0
A14: DEATH
A15: GATE | B15: 1 | C15: 1 | D15: 1 | E15: 113.24 | F15: 114.7 | G15: 1.46 | H15: 1 | I15: 1 | J15: 0.16 | K15: 3 | L15: 0.64 | M15: 0 | N15: 0 | O15: 0.6889 | P15: 109.5881 | Q15: 2.3394 | R15: 11.1388
A16: GATE | B16: 2 | C16: 2 | D16: 2 | E16: 118 | F16: 119.48 | G16: 1.48 | H16: 1 | I16: 1 | J16: 0.12 | K16: 3 | L16: 0.76 | M16: 0 | N16: 0 | O16: 0.719 | P16: 157.5422 | Q16: 2.3706 | R16: 11.2408
A17: GATE | B17: 2 | C17: 2 | D17: 2 | E17: 121.72 | F17: 122.94 | G17: 1.22 | H17: 1 | I17: 0 | J17: 0 | K17: 0 | L17: -1 | M17: 0.0676 | N17: 0 | O17: 1.2272 | P17: 0 | Q17: 0 | R17: 0
A18: DEATH
A19: GATE | B19: 1 | C19: 1 | D19: 1 | E19: 131.48 | F19: 133 | G19: 1.52 | H19: 1 | I19: 1 | J19: 0.22 | K19: 3 | L19: 0.7 | M19: 0 | N19: 0 | O19: 0.6987 | P19: 109.5322 | Q19: 2.3434 | R19: 10.9697
A20: GATE | B20: 2 | C20: 2 | D20: 2 | E20: 136.8 | F20: 138.06 | G20: 1.26 | H20: 1 | I20: 1 | J20: 0.04 | K20: 1 | L20: 0.54 | M20: 0 | N20: 0 | O20: 0.6817 | P20: 157.5583 | Q20: 2.3668 | R20: 10.9692
A21: GATE | B21: 3 | C21: 3 | D21: 3 | E21: 140.06 | F21: 141.42 | G21: 1.36 | H21: 1 | I21: 0 | J21: 0 | K21: 0 | L21: -1 | M21: 0.0386 | N21: 0 | O21: 0.7654 | P21: 187.9135 | Q21: 2.2665 | R21: 11.5279
A22: GATE | B22: 4 | C22: 4 | D22: 4 | E22: 154.58 | F22: 156.58 | G22: 2 | H22: 1 | I22: 1 | J22: 0.68 | K22: 6 | L22: 0.52 | M22: 0.2569 | N22: 0 | O22: 1.5437 | P22: 178.1803 | Q22: 2.5499 | R22: 58.7311
A23: DEATH
A24: GATE | B24: 4 | C24: 4 | D24: 4 | E24: 165.1 | F24: 166.44 | G24: 1.34 | H24: 1 | I24: 1 | J24: 0.9 | K24: 2 | L24: 0.44 | M24: 0 | N24: 0.3551 | O24: 0.4795 | P24: 0 | Q24: 0 | R24: 0
A25: GATE | B25: 5 | C25: 5 | D25: 5 | E25: 167.46 | F25: 168.78 | G25: 1.32 | H25: 1 | I25: 0 | J25: 0 | K25: 0 | L25: -1 | M25: 0.7541 | N25: 1.3019 | O25: 1.3019 | P25: 164.3627 | Q25: 2.4894 | R25: 55.3762
A26: GATE | B26: 6 | C26: 6 | D26: 6 | E26: 169.14 | F26: 169.64 | G26: 0.5 | H26: 1 | I26: 0 | J26: 0 | K26: 0 | L26: -1 | M26: 0 | N26: 0.2687 | O26: 0.4753 | P26: 0 | Q26: 0 | R26: 0
A27: DEATH
A28: GATE | B28: 4 | C28: 4 | D28: 4 | E28: 178.78 | F28: 180.96 | G28: 2.18 | H28: 1 | I28: 1 | J28: 0.16 | K28: 3 | L28: 1.42 | M28: 1.4681 | N28: 2.1779 | O28: 2.1157 | P28: 0 | Q28: 0 | R28: 0
A29: GATE | B29: 5 | C29: 5 | D29: 5 | E29: 180.96 | F29: 182.32 | G29: 1.36 | H29: 1 | I29: 0 | J29: 0 | K29: 0 | L29: -1 | M29: 0.0749 | N29: 1.3426 | O29: 1.3426 | P29: 164.7193 | Q29: 8.009 | R29: 59.5956
A30: DEATH
A31: GATE | B31: 4 | C31: 4 | D31: 4 | E31: 190.3 | F31: 191.38 | G31: 1.08 | H31: 1 | I31: 1 | J31: 0.14 | K31: 3 | L31: 0.5 | M31: 0 | N31: 1.0849 | O31: 0 | P31: 0 | Q31: 0 | R31: 0
A32: GATE | B32: 5 | C32: 5 | D32: 5 | E32: 191.38 | F32: 192.84 | G32: 1.46 | H32: 1 | I32: 0 | J32: 0 | K32: 0 | L32: -1 | M32: 0.3639 | N32: 0.2456 | O32: 1.209 | P32: 164.5775 | Q32: 2.1864 | R32: 58.7304
A33: GATE | B33: 6 | C33: 6 | D33: 6 | E33: 192.96 | F33: 194.84 | G33: 1.88 | H33: 1 | I33: 1 | J33: 0.9 | K33: 3 | L33: 0.26 | M33: 0.5266 | N33: 0 | O33: 1.5627 | P33: 147.0648 | Q33: 2.4958 | R33: 58.4087
A34: DEATH
A35: GATE | B35: 4 | C35: 4 | D35: 4 | E35: 205 | F35: 206.08 | G35: 1.08 | H35: 1 | I35: 1 | J35: 0.08 | K35: 3 | L35: 0.52 | M35: 0 | N35: 1.0482 | O35: 0 | P35: 0 | Q35: 0 | R35: 0
A36: GATE | B36: 5 | C36: 5 | D36: 5 | E36: 206.12 | F36: 206.98 | G36: 0.86 | H36: 1 | I36: 0 | J36: 0 | K36: 0 | L36: -1 | M36: 0.1203 | N36: 0 | O36: 0.812 | P36: 0 | Q36: 0 | R36: 0
A37: GATE | B37: 6 | C37: 6 | D37: 6 | E37: 207.18 | F37: 208.2 | G37: 1.02 | H37: 1 | I37: 1 | J37: 0.14 | K37: 3 | L37: 0.44 | M37: 0 | N37: 0.6374 | O37: 0.0651 | P37: 0 | Q37: 0 | R37: 0
A38: GATE | B38: 7 | C38: 7 | D38: 7 | E38: 210.16 | F38: 211.22 | G38: 1.06 | H38: 1 | I38: 1 | J38: 0.12 | K38: 3 | L38: 0.48 | M38: 0 | N38: 1.047 | O38: 0 | P38: 0 | Q38: 0 | R38: 0
A39: GATE | B39: 8 | C39: 8 | D39: 8 | E39: 211.74 | F39: 213.18 | G39: 1.44 | H39: 1 | I39: 0 | J39: 0 | K39: 0 | L39: -1 | M39: 0.5336 | N39: 0 | O39: 1.3368 | P39: 87.1244 | Q39: 2.4673 | R39: 59.0273
A40: DEATH
...

Sheet adap_SofiaVidal
A1: EventType | B1: AttemptID | C1: SegmentID | D1: GateID | E1: EntryTime | F1: ExitTime | G1: TimeToClear_s | H1: Cleared | I1: ObstacleTouched | J1: ContactDuration_s | K1: ContactCount | L1: FirstContactTime_s | M1: JetpackActiveTime_s | N1: CrouchTime_s | O1: AirborneTime_s | P1: ContactX | Q1: ContactY | R1: ContactZ
A2: DEATH
A3: DEATH
A4: DEATH
A5: DEATH
A6: DEATH
A7: DEATH
A8: DEATH
A9: DEATH
A10: DEATH
A11: DEATH
A12: DEATH
A13: DEATH
... A50: DEATH
A51: GATE | B51: 1 | C51: 1 | D51: 1 | E51: 4279.68 | F51: 4281.36 | G51: 1.6802 | H51: 1 | I51: 1 | J51: 0.2002 | K51: 2 | L51: 0.7402 | M51: 0 | N51: 1.6366 | O51: 0 | P51: 0 | Q51: 0 | R51: 0
A52: GATE | B52: 1 | C52: 1 | D52: 1 | E52: 4285.56 | F52: 4287.26 | G52: 1.6997 | H52: 1 | I52: 1 | J52: 0.2202 | K52: 3 | L52: 0.7397 | M52: 0 | N52: 1.6866 | O52: 0 | P52: 0 | Q52: 0 | R52: 0
A53: GATE | B53: 1 | C53: 1 | D53: 1 | E53: 4292.7 | F53: 4294.38 | G53: 1.6802 | H53: 1 | I53: 1 | J53: 0.2002 | K53: 2 | L53: 0.7402 | M53: 0 | N53: 1.3848 | O53: 0 | P53: 0 | Q53: 0 | R53: 0
A54: DEATH
A55: GATE | B55: 1 | C55: 1 | D55: 1 | E55: 4307.52 | F55: 4309.22 | G55: 1.6997 | H55: 1 | I55: 1 | J55: 0.2002 | K55: 2 | L55: 0.7598 | M55: 0 | N55: 1.7005 | O55: 0 | P55: 0 | Q55: 0 | R55: 0
A56: GATE | B56: 2 | C56: 2 | D56: 2 | E56: 4312.78 | F56: 4314.74 | G56: 1.96 | H56: 1 | I56: 1 | J56: 0.6797 | K56: 3 | L56: 0.7402 | M56: 0 | N56: 0.904 | O56: 0 | P56: 0 | Q56: 0 | R56: 0
A57: GATE | B57: 3 | C57: 3 | D57: 3 | E57: 4316.5 | F57: 4318.86 | G57: 2.3599 | H57: 1 | I57: 1 | J57: 0.2002 | K57: 2 | L57: 0.7598 | M57: 0.2677 | N57: 1.5519 | O57: 0.795 | P57: 0 | Q57: 0 | R57: 0
A58: GATE | B58: 4 | C58: 4 | D58: 4 | E58: 4328.62 | F58: 4330.94 | G58: 2.3198 | H58: 1 | I58: 1 | J58: 0.0996 | K58: 3 | L58: 0.48 | M58: 0.5565 | N58: 0 | O58: 1.3639 | P58: 178.6913 | Q58: 2.4845 | R58: 57.5185
A59: GATE | B59: 5 | C59: 5 | D59: 5 | E59: 4330.94 | F59: 4332.3 | G59: 1.3599 | H59: 1 | I59: 0 | J59: 0 | K59: 0 | L59: -1 | M59: 0.9645 | N59: 0 | O59: 1.3748 | P59: 164.6922 | Q59: 10.5712 | R59: 57.1065
A60: GATE | B60: 6 | C60: 6 | D60: 6 | E60: 4332.66 | F60: 4334.06 | G60: 1.4004 | H60: 1 | I60: 0 | J60: 0 | K60: 0 | L60: -1 | M60: 0.2136 | N60: 0 | O60: 1.3959 | P60: 147.3706 | Q60: 6.8987 | R60: 56.5967
A61: DEATH
A62: GATE | B62: 4 | C62: 4 | D62: 4 | E62: 4344.54 | F62: 4345.5 | G62: 0.96 | H62: 1 | I62: 1 | J62: 0.1401 | K62: 3 | L62: 0.4399 | M62: 0 | N62: 0.969 | O62: 0 | P62: 0 | Q62: 0 | R62: 0
A63: GATE | B63: 5 | C63: 5 | D63: 5 | E63: 4345.5 | F63: 4346.32 | G63: 0.8198 | H63: 1 | I63: 0 | J63: 0 | K63: 0 | L63: -1 | M63: 0 | N63: 0.2061 | O63: 0.6205 | P63: 164.4689 | Q63: 1.9322 | R63: 58.3411
A64: GATE | B64: 6 | C64: 6 | D64: 6 | E64: 4346.5 | F64: 4348.56 | G64: 2.0601 | H64: 1 | I64: 1 | J64: 1.5801 | K64: 3 | L64: 0.48 | M64: 0.2008 | N64: 0 | O64: 0.884 | P64: 0 | Q64: 0 | R64: 0
A65: DEATH
A66: GATE | B66: 4 | C66: 4 | D66: 4 | E66: 4359.02 | F66: 4360.6 | G66: 1.5801 | H66: 1 | I66: 1 | J66: 1.1201 | K66: 2 | L66: 0.46 | M66: 0.2122 | N66: 0 | O66: 1.5085 | P66: 0 | Q66: 0 | R66: 0
A67: DEATH
A68: GATE | B68: 4 | C68: 4 | D68: 4 | E68: 4369.56 | F68: 4370.6 | G68: 1.04 | H68: 1 | I68: 1 | J68: 0.1001 | K68: 2 | L68: 0.48 | M68: 0 | N68: 1.0353 | O68: 0 | P68: 0 | Q68: 0 | R68: 0
A69: GATE | B69: 5 | C69: 5 | D69: 5 | E69: 4370.62 | F69: 4372.78 | G69: 2.1597 | H69: 1 | I69: 1 | J69: 0.1396 | K69: 1 | L69: 0.5 | M69: 0.0575 | N69: 0.4651 | O69: 1.621 | P69: 164.5858 | Q69: 1.8334 | R69: 56.916
A70: GATE | B70: 6 | C70: 6 | D70: 6 | E70: 4373.98 | F70: 4374.52 | G70: 0.54 | H70: 1 | I70: 0 | J70: 0 | K70: 0 | L70: -1 | M70: 0.2082 | N70: 0 | O70: 0.5254 | P70: 0 | Q70: 0 | R70: 0
A71: DEATH
A72: GATE | B72: 4 | C72: 4 | D72: 4 | E72: 4385.88 | F72: 4387 | G72: 1.1201 | H72: 1 | I72: 1 | J72: 0.1802 | K72: 2 | L72: 0.46 | M72: 0 | N72: 1.104 | O72: 0.0315 | P72: 0 | Q72: 0 | R72: 0
A73: GATE | B73: 5 | C73: 5 | D73: 5 | E73: 4387 | F73: 4387.8 | G73: 0.7998 | H73: 1 | I73: 0 | J73: 0 | K73: 0 | L73: -1 | M73: 0.1192 | N73: 0 | O73: 0.7869 | P73: 164.6801 | Q73: 2.3581 | R73: 55.7993
A74: GATE | B74: 6 | C74: 6 | D74: 6 | E74: 4387.94 | F74: 4389 | G74: 1.0601 | H74: 1 | I74: 1 | J74: 0.1201 | K74: 3 | L74: 0.48 | M74: 0 | N74: 0.8587 | O74: 0 | P74: 0 | Q74: 0 | R74: 0
A75: GATE | B75: 7 | C75: 7 | D75: 7 | E75: 4390.96 | F75: 4392.2 | G75: 1.2397 | H75: 1 | I75: 1 | J75: 0.2998 | K75: 3 | L75: 0.48 | M75: 0 | N75: 1.2484 | O75: 0 | P75: 0 | Q75: 0 | R75: 0
A76: GATE | B76: 8 | C76: 8 | D76: 8 | E76: 4392.74 | F76: 4393.5 | G76: 0.7603 | H76: 1 | I76: 0 | J76: 0 | K76: 0 | L76: -1 | M76: 0.1834 | N76: 0 | O76: 0.738 | P76: 87.1773 | Q76: 1.8746 | R76: 55.7519
...

Sheet adap_VicenteOlguin
A1: EventType | B1: AttemptID | C1: SegmentID | D1: GateID | E1: EntryTime | F1: ExitTime | G1: TimeToClear_s | H1: Cleared | I1: ObstacleTouched | J1: ContactDuration_s | K1: ContactCount | L1: FirstContactTime_s | M1: JetpackActiveTime_s | N1: CrouchTime_s | O1: AirborneTime_s | P1: ContactX | Q1: ContactY | R1: ContactZ
A2: DEATH
A3: DEATH
A4: DEATH
A5: DEATH
A6: DEATH
A7: DEATH
A8: DEATH
A9: DEATH
A10: DEATH
A11: GATE | B11: 1 | C11: 1 | D11: 1 | E11: 1119.6 | F11: 1121.16 | G11: 1.5601 | H11: 1 | I11: 1 | J11: 0.1799 | K11: 2 | L11: 0.78 | M11: 0 | N11: 1.2598 | O11: 0 | P11: 0 | Q11: 0 | R11: 0
A12: GATE | B12: 2 | C12: 2 | D12: 2 | E12: 1125.36 | F12: 1126.92 | G12: 1.5599 | H12: 1 | I12: 0 | J12: 0 | K12: 0 | L12: -1 | M12: 0.6542 | N12: 0 | O12: 1.565 | P12: 157.5208 | Q12: 3.977 | R12: 9.1353
A13: GATE | B13: 3 | C13: 3 | D13: 3 | E13: 1127.82 | F13: 1129.2 | G13: 1.38 | H13: 1 | I13: 0 | J13: 0 | K13: 0 | L13: -1 | M13: 0.4496 | N13: 0 | O13: 1.36 | P13: 187.576 | Q13: 3.5662 | R13: 11.8527
A14: GATE | B14: 4 | C14: 4 | D14: 4 | E14: 1141.1 | F14: 1142.24 | G14: 1.14 | H14: 1 | I14: 1 | J14: 0.22 | K14: 3 | L14: 0.54 | M14: 0 | N14: 0.599 | O14: 0 | P14: 0 | Q14: 0 | R14: 0
A15: GATE | B15: 5 | C15: 5 | D15: 5 | E15: 1142.24 | F15: 1143.7 | G15: 1.46 | H15: 1 | I15: 1 | J15: 0.0599 | K15: 3 | L15: 0.38 | M15: 0.3583 | N15: 0.2676 | O15: 1.1859 | P15: 164.5919 | Q15: 1.9232 | R15: 58.1572
A16: GATE | B16: 6 | C16: 6 | D16: 6 | E16: 1144.04 | F16: 1145.42 | G16: 1.38 | H16: 1 | I16: 1 | J16: 0.1799 | K16: 3 | L16: 0.6201 | M16: 0.9975 | N16: 0 | O16: 1.3794 | P16: 0 | Q16: 0 | R16: 0
A17: DEATH
A18: GATE | B18: 4 | C18: 4 | D18: 4 | E18: 1155.84 | F18: 1156.88 | G18: 1.04 | H18: 1 | I18: 1 | J18: 0.12 | K18: 3 | L18: 0.48 | M18: 0 | N18: 0.5806 | O18: 0.067 | P18: 0 | Q18: 0 | R18: 0
A19: GATE | B19: 5 | C19: 5 | D19: 5 | E19: 1156.88 | F19: 1157.8 | G19: 0.9199 | H19: 1 | I19: 0 | J19: 0 | K19: 0 | L19: -1 | M19: 0.1725 | N19: 0 | O19: 0.9064 | P19: 0 | Q19: 0 | R19: 0
A20: GATE | B20: 6 | C20: 6 | D20: 6 | E20: 1158.2 | F20: 1159.24 | G20: 1.04 | H20: 1 | I20: 1 | J20: 0.22 | K20: 3 | L20: 0.38 | M20: 0 | N20: 0.5741 | O20: 0 | P20: 0 | Q20: 0 | R20: 0
A21: GATE | B21: 7 | C21: 7 | D21: 7 | E21: 1161.24 | F21: 1162.26 | G21: 1.02 | H21: 1 | I21: 1 | J21: 0.12 | K21: 3 | L21: 0.48 | M21: 0 | N21: 0.9025 | O21: 0 | P21: 0 | Q21: 0 | R21: 0
A22: GATE | B22: 8 | C22: 8 | D22: 8 | E22: 1162.9 | F22: 1163.98 | G22: 1.08 | H22: 1 | I22: 0 | J22: 0 | K22: 0 | L22: -1 | M22: 0.1384 | N22: 0 | O22: 0.79 | P22: 87.0868 | Q22: 1.8584 | R22: 59.0065
A23: DEATH

Sheet adap_VicenteQuintana
A1: EventType | B1: AttemptID | C1: SegmentID | D1: GateID | E1: EntryTime | F1: ExitTime | G1: TimeToClear_s | H1: Cleared | I1: ObstacleTouched | J1: ContactDuration_s | K1: ContactCount | L1: FirstContactTime_s | M1: JetpackActiveTime_s | N1: CrouchTime_s | O1: AirborneTime_s | P1: ContactX | Q1: ContactY | R1: ContactZ
A2: GATE | B2: 1 | C2: 1 | D2: 1 | E2: 30.04 | F2: 31.7 | G2: 1.66 | H2: 1 | I2: 1 | J2: 0.2 | K2: 3 | L2: 0.76 | M2: 0 | N2: 1.6376 | O2: 0 | P2: 0 | Q2: 0 | R2: 0
A3: GATE | B3: 2 | C3: 2 | D3: 2 | E3: 35.24 | F3: 37 | G3: 1.76 | H3: 1 | I3: 1 | J3: 0.5 | K3: 6 | L3: 0.38 | M3: 0.0945 | N3: 0 | O3: 1.0229 | P3: 157.6107 | Q3: 2.3425 | R3: 9.8967
A4: GATE | B4: 3 | C4: 3 | D4: 3 | E4: 38.68 | F4: 40.08 | G4: 1.4 | H4: 1 | I4: 1 | J4: 0.22 | K4: 3 | L4: 0.76 | M4: 0 | N4: 1.3665 | O4: 0.038 | P4: 0 | Q4: 0 | R4: 0
A5: GATE | B5: 4 | C5: 4 | D5: 4 | E5: 52.9 | F5: 53.8 | G5: 0.9 | H5: 1 | I5: 1 | J5: 0.14 | K5: 3 | L5: 0.46 | M5: 0 | N5: 0.8999 | O5: 0 | P5: 0 | Q5: 0 | R5: 0
A6: GATE | B6: 5 | C6: 5 | D6: 5 | E6: 53.8 | F6: 54.72 | G6: 0.92 | H6: 1 | I6: 0 | J6: 0 | K6: 0 | L6: -1 | M6: 0.1773 | N6: 0 | O6: 0.9143 | P6: 0 | Q6: 0 | R6: 0
A7: GATE | B7: 6 | C7: 6 | D7: 6 | E7: 55 | F7: 56.26 | G7: 1.26 | H7: 1 | I7: 1 | J7: 0.24 | K7: 3 | L7: 0.58 | M7: 0.1665 | N7: 0 | O7: 0.9842 | P7: 0 | Q7: 0 | R7: 0
A8: GATE | B8: 7 | C8: 7 | D8: 7 | E8: 58.14 | F8: 59.22 | G8: 1.08 | H8: 1 | I8: 1 | J8: 0.14 | K8: 3 | L8: 0.48 | M8: 0 | N8: 1.0676 | O8: 0 | P8: 0 | Q8: 0 | R8: 0
A9: GATE | B9: 8 | C9: 8 | D9: 8 | E9: 59.78 | F9: 60.68 | G9: 0.9 | H9: 1 | I9: 0 | J9: 0 | K9: 0 | L9: -1 | M9: 0 | N9: 0.1826 | O9: 0.7117 | P9: 87.4749 | Q9: 1.985 | R9: 58.7615
A10: DEATH
A11: DEATH
A12: DEATH
A13: DEATH
A14: DEATH
A15: DEATH
A16: DEATH
A17: DEATH
A18: DEATH

Sheet adap_VicenteVidal
A1: EventType | B1: AttemptID | C1: SegmentID | D1: GateID | E1: EntryTime | F1: ExitTime | G1: TimeToClear_s | H1: Cleared | I1: ObstacleTouched | J1: ContactDuration_s | K1: ContactCount | L1: FirstContactTime_s | M1: JetpackActiveTime_s | N1: CrouchTime_s | O1: AirborneTime_s | P1: ContactX | Q1: ContactY | R1: ContactZ
A2: DEATH
A3: DEATH
A4: DEATH
A5: DEATH
A6: DEATH
A7: DEATH
A8: DEATH
A9: DEATH
A10: GATE | B10: 1 | C10: 1 | D10: 1 | E10: 1009.76 | F10: 1011.44 | G10: 1.6801 | H10: 1 | I10: 1 | J10: 0.2 | K10: 2 | L10: 0.7401 | M10: 0 | N10: 1.6809 | O10: 0 | P10: 0 | Q10: 0 | R10: 0
A11: GATE | B11: 2 | C11: 2 | D11: 2 | E11: 1015.36 | F11: 1016.56 | G11: 1.2 | H11: 1 | I11: 0 | J11: 0 | K11: 0 | L11: -1 | M11: 0.3365 | N11: 0 | O11: 1.0999 | P11: 157.4678 | Q11: 4.8795 | R11: 10.1287
A12: GATE | B12: 3 | C12: 3 | D12: 3 | E12: 1018.14 | F12: 1019.82 | G12: 1.6801 | H12: 1 | I12: 1 | J12: 0.22 | K12: 3 | L12: 0.78 | M12: 0 | N12: 1.5825 | O12: 0.0806 | P12: 0 | Q12: 0 | R12: 0
A13: GATE | B13: 4 | C13: 4 | D13: 4 | E13: 1026.42 | F13: 1027.44 | G13: 1.02 | H13: 1 | I13: 1 | J13: 0.12 | K13: 3 | L13: 0.4601 | M13: 0 | N13: 1.0214 | O13: 0 | P13: 0 | Q13: 0 | R13: 0
A14: GATE | B14: 5 | C14: 5 | D14: 5 | E14: 1027.48 | F14: 1030.02 | G14: 2.54 | H14: 1 | I14: 1 | J14: 0.5599 | K14: 1 | L14: 1.3 | M14: 1.092 | N14: 0 | O14: 2.553 | P14: 0 | Q14: 0 | R14: 0
A15: DEATH
A16: GATE | B16: 4 | C16: 4 | D16: 4 | E16: 1040.58 | F16: 1041.66 | G16: 1.0801 | H16: 1 | I16: 1 | J16: 0.14 | K16: 3 | L16: 0.48 | M16: 0 | N16: 1.0051 | O16: 0.0637 | P16: 0 | Q16: 0 | R16: 0
A17: GATE | B17: 5 | C17: 5 | D17: 5 | E17: 1041.66 | F17: 1043.64 | G17: 1.98 | H17: 1 | I17: 0 | J17: 0 | K17: 0 | L17: -1 | M17: 0.234 | N17: 0 | O17: 1.9304 | P17: 164.5193 | Q17: 1.9615 | R17: 58.9519
A18: GATE | B18: 6 | C18: 6 | D18: 6 | E18: 1044 | F18: 1045.38 | G18: 1.38 | H18: 1 | I18: 0 | J18: 0 | K18: 0 | L18: -1 | M18: 0.9212 | N18: 0 | O18: 1.3947 | P18: 147.5808 | Q18: 5.6485 | R18: 60.3339
A19: DEATH
A20: GATE | B20: 4 | C20: 4 | D20: 4 | E20: 1056.38 | F20: 1057.42 | G20: 1.0399 | H20: 1 | I20: 1 | J20: 0.14 | K20: 3 | L20: 0.46 | M20: 0 | N20: 0.6981 | O20: 0 | P20: 0 | Q20: 0 | R20: 0
A21: GATE | B21: 5 | C21: 5 | D21: 5 | E21: 1057.46 | F21: 1058.34 | G21: 0.88 | H21: 1 | I21: 0 | J21: 0 | K21: 0 | L21: -1 | M21: 0 | N21: 0 | O21: 0.6073 | P21: 164.3743 | Q21: 1.8829 | R21: 56.7539
A22: GATE | B22: 6 | C22: 6 | D22: 6 | E22: 1058.5 | F22: 1059.56 | G22: 1.0599 | H22: 1 | I22: 1 | J22: 0.1 | K22: 3 | L22: 0.5 | M22: 0 | N22: 0.7602 | O22: 0 | P22: 0 | Q22: 0 | R22: 0
A23: GATE | B23: 7 | C23: 7 | D23: 7 | E23: 1061.54 | F23: 1062.64 | G23: 1.1001 | H23: 1 | I23: 1 | J23: 0.14 | K23: 3 | L23: 0.5 | M23: 0 | N23: 0.7943 | O23: 0 | P23: 0 | Q23: 0 | R23: 0
A24: GATE | B24: 8 | C24: 8 | D24: 8 | E24: 1063.18 | F24: 1064.3 | G24: 1.12 | H24: 1 | I24: 1 | J24: 0.0601 | K24: 1 | L24: 0.5 | M24: 0 | N24: 0 | O24: 0.7192 | P24: 87.4439 | Q24: 1.8131 | R24: 58.2096
A25: DEATH
A26: DEATH
A27: DEATH

Sheet adap_yo
A1: EventType | B1: AttemptID | C1: SegmentID | D1: GateID | E1: EntryTime | F1: ExitTime | G1: TimeToClear_s | H1: Cleared | I1: ObstacleTouched | J1: ContactDuration_s | K1: ContactCount | L1: FirstContactTime_s | M1: JetpackActiveTime_s | N1: CrouchTime_s | O1: AirborneTime_s | P1: ContactX | Q1: ContactY | R1: ContactZ
A2: DEATH
A3: GATE | B3: 1 | C3: 1 | D3: 1 | E3: 709.46 | F3: 711.16 | G3: 1.7 | H3: 1 | I3: 1 | J3: 0.2 | K3: 3 | L3: 0.76 | M3: 0 | N3: 1.0006 | O3: 0 | P3: 0 | Q3: 0 | R3: 0
A4: GATE | B4: 2 | C4: 2 | D4: 2 | E4: 714.32 | F4: 716.36 | G4: 2.04 | H4: 1 | I4: 1 | J4: 0.5 | K4: 3 | L4: 0.96 | M4: 0 | N4: 1.2339 | O4: 0 | P4: 0 | Q4: 0 | R4: 0
A5: GATE | B5: 3 | C5: 3 | D5: 3 | E5: 717.8 | F5: 718.72 | G5: 0.92 | H5: 1 | I5: 0 | J5: 0 | K5: 0 | L5: -1 | M5: 0.3178 | N5: 0 | O5: 0.9161 | P5: 187.6497 | Q5: 3.2691 | R5: 12.6177
A6: GATE | B6: 4 | C6: 4 | D6: 4 | E6: 724.12 | F6: 725.16 | G6: 1.04 | H6: 1 | I6: 1 | J6: 0.14 | K6: 3 | L6: 0.46 | M6: 0 | N6: 0.8642 | O6: 0 | P6: 0 | Q6: 0 | R6: 0
A7: GATE | B7: 5 | C7: 5 | D7: 5 | E7: 725.2 | F7: 726.28 | G7: 1.08 | H7: 1 | I7: 0 | J7: 0 | K7: 0 | L7: -1 | M7: 0.1341 | N7: 0 | O7: 0.8331 | P7: 164.6186 | Q7: 1.8409 | R7: 58.8905
A8: GATE | B8: 6 | C8: 6 | D8: 6 | E8: 726.52 | F8: 727.58 | G8: 1.06 | H8: 1 | I8: 1 | J8: 0.12 | K8: 3 | L8: 0.48 | M8: 0 | N8: 0.8443 | O8: 0 | P8: 0 | Q8: 0 | R8: 0
A9: GATE | B9: 7 | C9: 7 | D9: 7 | E9: 729.52 | F9: 730.58 | G9: 1.06 | H9: 1 | I9: 1 | J9: 0.12 | K9: 3 | L9: 0.48 | M9: 0 | N9: 1.0597 | O9: 0 | P9: 0 | Q9: 0 | R9: 0
A10: GATE | B10: 8 | C10: 8 | D10: 8 | E10: 731.04 | F10: 731.86 | G10: 0.82 | H10: 1 | I10: 0 | J10: 0 | K10: 0 | L10: -1 | M10: 0.3609 | N10: 0 | O10: 0.8208 | P10: 87.3592 | Q10: 2.4715 | R10: 60.072
A11: DEATH
A12: DEATH

Sheet Sheet1
A1: Jugador | B1: TimeToClear_s | C1: Cleared | D1: ObstacleTouched | E1: ContactDuration_s | F1: ContactCount | G1: FirstContactTime_s | H1: JetpackActiveTime_s | I1: CrouchTime_s | J1: AirborneTime_s | K1: ContactX | L1: ContactY | M1: ContactZ
A2: Jug1 | B2: =AVERAGE(adap_CataAguilar!G:G) -> 1.4052632 | C2: =AVERAGE(adap_CataAguilar!H:H) -> 1 | D2: =AVERAGE(adap_CataAguilar!I:I) -> 0.45614035 | E2: =AVERAGE(adap_CataAguilar!J:J) -> 0.22105263 | F2: =AVERAGE(adap_CataAguilar!K:K) -> 1.122807 | G2: =AVERAGE(adap_CataAguilar!L:L) -> -0.30210526 | H2: =AVERAGE(adap_CataAguilar!M:M) -> 0.39971404 | I2: =AVERAGE(adap_CataAguilar!N:N) -> 0.16681404 | J2: =AVERAGE(adap_CataAguilar!O:O) -> 0.97499649 | K2: =AVERAGE(adap_CataAguilar!P:P) -> 75.395423 | L2: =AVERAGE(adap_CataAguilar!Q:Q) -> 1.9426246 | M2: =AVERAGE(adap_CataAguilar!R:R) -> 25.150874
A3: Jug2 | B3: =AVERAGE(adap_GonzaloCampos!G:G) -> 1.4105882 | C3: =AVERAGE(adap_GonzaloCampos!H:H) -> 1 | D3: =AVERAGE(adap_GonzaloCampos!I:I) -> 0.47058824 | E3: =AVERAGE(adap_GonzaloCampos!J:J) -> 0.12941176 | F3: =AVERAGE(adap_GonzaloCampos!K:K) -> 0.76470588 | G3: =AVERAGE(adap_GonzaloCampos!L:L) -> -0.25882353 | H3: =AVERAGE(adap_GonzaloCampos!M:M) -> 0.28445882 | I3: =AVERAGE(adap_GonzaloCampos!N:N) -> 0 | J3: =AVERAGE(adap_GonzaloCampos!O:O) -> 1.1431 | K3: =AVERAGE(adap_GonzaloCampos!P:P) -> 111.46275 | L3: =AVERAGE(adap_GonzaloCampos!Q:Q) -> 3.5136294 | M3: =AVERAGE(adap_GonzaloCampos!R:R) -> 23.605918
A4: Jug3 | B4: =AVERAGE(adap_IgnaciaDelgado!G:G) -> 1.3355722 | C4: =AVERAGE(adap_IgnaciaDelgado!H:H) -> 1 | D4: =AVERAGE(adap_IgnaciaDelgado!I:I) -> 0.27777778 | E4: =AVERAGE(adap_IgnaciaDelgado!J:J) -> 0.04 | F4: =AVERAGE(adap_IgnaciaDelgado!K:K) -> 0.72222222 | G4: =AVERAGE(adap_IgnaciaDelgado!L:L) -> -0.59 | H4: =AVERAGE(adap_IgnaciaDelgado!M:M) -> 0.38733889 | I4: =AVERAGE(adap_IgnaciaDelgado!N:N) -> 0.17361667 | J4: =AVERAGE(adap_IgnaciaDelgado!O:O) -> 1.0689111 | K4: =AVERAGE(adap_IgnaciaDelgado!P:P) -> 94.737444 | L4: =AVERAGE(adap_IgnaciaDelgado!Q:Q) -> 3.2214722 | M4: =AVERAGE(adap_IgnaciaDelgado!R:R) -> 27.964722
A5: Jug4 | B5: =AVERAGE(adap_IsidoraToledo!G:G) -> 1.3151515 | C5: =AVERAGE(adap_IsidoraToledo!H:H) -> 1 | D5: =AVERAGE(adap_IsidoraToledo!I:I) -> 0.45454545 | E5: =AVERAGE(adap_IsidoraToledo!J:J) -> 0.084242424 | F5: =AVERAGE(adap_IsidoraToledo!K:K) -> 1.2424242 | G5: =AVERAGE(adap_IsidoraToledo!L:L) -> -0.27272727 | H5: =AVERAGE(adap_IsidoraToledo!M:M) -> 0.12375455 | I5: =AVERAGE(adap_IsidoraToledo!N:N) -> 0.38210303 | J5: =AVERAGE(adap_IsidoraToledo!O:O) -> 0.66877273 | K5: =AVERAGE(adap_IsidoraToledo!P:P) -> 57.619476 | L5: =AVERAGE(adap_IsidoraToledo!Q:Q) -> 1.765497 | M5: =AVERAGE(adap_IsidoraToledo!R:R) -> 14.254336
A6: Jug5 | B6: =AVERAGE(adap_JavierSalinas!G:G) -> 1.5011765 | C6: =AVERAGE(adap_JavierSalinas!H:H) -> 1 | D6: =AVERAGE(adap_JavierSalinas!I:I) -> 0.32352941 | E6: =AVERAGE(adap_JavierSalinas!J:J) -> 0.16529412 | F6: =AVERAGE(adap_JavierSalinas!K:K) -> 0.82352941 | G6: =AVERAGE(adap_JavierSalinas!L:L) -> -0.43705882 | H6: =AVERAGE(adap_JavierSalinas!M:M) -> 0.45883824 | I6: =AVERAGE(adap_JavierSalinas!N:N) -> 0 | J6: =AVERAGE(adap_JavierSalinas!O:O) -> 1.2517588 | K6: =AVERAGE(adap_JavierSalinas!P:P) -> 91.402897 | L6: =AVERAGE(adap_JavierSalinas!Q:Q) -> 2.9737971 | M6: =AVERAGE(adap_JavierSalinas!R:R) -> 17.189426
A7: Jug6 | B7: =AVERAGE(adap_MariannaMaregatti!G:G) -> 1.6461017 | C7: =AVERAGE(adap_MariannaMaregatti!H:H) -> 1 | D7: =AVERAGE(adap_MariannaMaregatti!I:I) -> 0.66101695 | E7: =AVERAGE(adap_MariannaMaregatti!J:J) -> 0.23254237 | F7: =AVERAGE(adap_MariannaMaregatti!K:K) -> 1.8305085 | G7: =AVERAGE(adap_MariannaMaregatti!L:L) -> 0.25423729 | H7: =AVERAGE(adap_MariannaMaregatti!M:M) -> 0.24888136 | I7: =AVERAGE(adap_MariannaMaregatti!N:N) -> 0.84068983 | J7: =AVERAGE(adap_MariannaMaregatti!O:O) -> 0.95917119 | K7: =AVERAGE(adap_MariannaMaregatti!P:P) -> 37.118547 | L7: =AVERAGE(adap_MariannaMaregatti!Q:Q) -> 1.3130763 | M7: =AVERAGE(adap_MariannaMaregatti!R:R) -> 13.927632
A8: Jug7 | B8: =AVERAGE(adap_SebastianRatto!G:G) -> 1.3468966 | C8: =AVERAGE(adap_SebastianRatto!H:H) -> 1 | D8: =AVERAGE(adap_SebastianRatto!I:I) -> 0.55172414 | E8: =AVERAGE(adap_SebastianRatto!J:J) -> 0.19034483 | F8: =AVERAGE(adap_SebastianRatto!K:K) -> 1.6551724 | G8: =AVERAGE(adap_SebastianRatto!L:L) -> -0.10137931 | H8: =AVERAGE(adap_SebastianRatto!M:M) -> 0.20216897 | I8: =AVERAGE(adap_SebastianRatto!N:N) -> 0.3279069 | J8: =AVERAGE(adap_SebastianRatto!O:O) -> 0.84679655 | K8: =AVERAGE(adap_SebastianRatto!P:P) -> 87.570962 | L8: =AVERAGE(adap_SebastianRatto!Q:Q) -> 1.7637379 | M8: =AVERAGE(adap_SebastianRatto!R:R) -> 16.554341
A9: Jug8 | B9: =AVERAGE(adap_SofiaVidal!G:G) -> 1.4428333 | C9: =AVERAGE(adap_SofiaVidal!H:H) -> 1 | D9: =AVERAGE(adap_SofiaVidal!I:I) -> 0.71428571 | E9: =AVERAGE(adap_SofiaVidal!J:J) -> 0.26097143 | F9: =AVERAGE(adap_SofiaVidal!K:K) -> 1.7142857 | G9: =AVERAGE(adap_SofiaVidal!L:L) -> 0.13046667 | H9: =AVERAGE(adap_SofiaVidal!M:M) -> 0.14207619 | I9: =AVERAGE(adap_SofiaVidal!N:N) -> 0.70242857 | J9: =AVERAGE(adap_SofiaVidal!O:O) -> 0.55454286 | K9: =AVERAGE(adap_SofiaVidal!P:P) -> 51.031724 | L9: =AVERAGE(adap_SofiaVidal!Q:Q) -> 1.331081 | M9: =AVERAGE(adap_SofiaVidal!R:R) -> 18.95381
A10: Jug9 | B10: =AVERAGE(adap_VicenteOlguin!G:G) -> 1.2345364 | C10: =AVERAGE(adap_VicenteOlguin!H:H) -> 1 | D10: =AVERAGE(adap_VicenteOlguin!I:I) -> 0.63636364 | E10: =AVERAGE(adap_VicenteOlguin!J:J) -> 0.099972727 | F10: =AVERAGE(adap_VicenteOlguin!K:K) -> 1.8181818 | G10: =AVERAGE(adap_VicenteOlguin!L:L) -> -0.0309 | H10: =AVERAGE(adap_VicenteOlguin!M:M) -> 0.25186364 | I10: =AVERAGE(adap_VicenteOlguin!N:N) -> 0.38032727 | J10: =AVERAGE(adap_VicenteOlguin!O:O) -> 0.65942727 | K10: =AVERAGE(adap_VicenteOlguin!P:P) -> 54.252318 | L10: =AVERAGE(adap_VicenteOlguin!Q:Q) -> 1.0295273 | M10: =AVERAGE(adap_VicenteOlguin!R:R) -> 12.559245
A11: Jug10 | B11: =AVERAGE(adap_VicenteQuintana!G:G) -> 1.235 | C11: =AVERAGE(adap_VicenteQuintana!H:H) -> 1 | D11: =AVERAGE(adap_VicenteQuintana!I:I) -> 0.75 | E11: =AVERAGE(adap_VicenteQuintana!J:J) -> 0.18 | F11: =AVERAGE(adap_VicenteQuintana!K:K) -> 2.625 | G11: =AVERAGE(adap_VicenteQuintana!L:L) -> 0.1775 | H11: =AVERAGE(adap_VicenteQuintana!M:M) -> 0.0547875 | I11: =AVERAGE(adap_VicenteQuintana!N:N) -> 0.644275 | J11: =AVERAGE(adap_VicenteQuintana!O:O) -> 0.4588875 | K11: =AVERAGE(adap_VicenteQuintana!P:P) -> 30.6357 | L11: =AVERAGE(adap_VicenteQuintana!Q:Q) -> 0.5409375 | M11: =AVERAGE(adap_VicenteQuintana!R:R) -> 8.582275
A12: Jug11 | B12: =AVERAGE(adap_VicenteVidal!G:G) -> 1.3661692 | C12: =AVERAGE(adap_VicenteVidal!H:H) -> 1 | D12: =AVERAGE(adap_VicenteVidal!I:I) -> 0.69230769 | E12: =AVERAGE(adap_VicenteVidal!J:J) -> 0.12923077 | F12: =AVERAGE(adap_VicenteVidal!K:K) -> 1.6923077 | G12: =AVERAGE(adap_VicenteVidal!L:L) -> 0.13232308 | H12: =AVERAGE(adap_VicenteVidal!M:M) -> 0.19874615 | I12: =AVERAGE(adap_VicenteVidal!N:N) -> 0.58019231 | J12: =AVERAGE(adap_VicenteVidal!O:O) -> 0.64990769 | K12: =AVERAGE(adap_VicenteVidal!P:P) -> 55.491238 | L12: =AVERAGE(adap_VicenteVidal!Q:Q) -> 1.2450385 | M12: =AVERAGE(adap_VicenteVidal!R:R) -> 18.798308
A13: Jug12 | B13: =AVERAGE(adap_yo!G:G) -> 1.215 | C13: =AVERAGE(adap_yo!H:H) -> 1 | D13: =AVERAGE(adap_yo!I:I) -> 0.625 | E13: =AVERAGE(adap_yo!J:J) -> 0.135 | F13: =AVERAGE(adap_yo!K:K) -> 1.875 | G13: =AVERAGE(adap_yo!L:L) -> 0.0175 | H13: =AVERAGE(adap_yo!M:M) -> 0.1016 | I13: =AVERAGE(adap_yo!N:N) -> 0.6253375 | J13: =AVERAGE(adap_yo!O:O) -> 0.32125 | K13: =AVERAGE(adap_yo!P:P) -> 54.953437 | L13: =AVERAGE(adap_yo!Q:Q) -> 0.9476875 | M13: =AVERAGE(adap_yo!R:R) -> 16.447525
