Workbook

Sheet adap_CataAguilar
A1: EventType | B1: SegmentID | C1: ElementID | D1: TimeOnPlatform | E1: RelativePositionStd | F1: RelativePositionMean | G1: RelativePositionMax | H1: RelativePositionMin | I1: SampleCount | J1: EdgeRiskTime | K1: CorrectionPeaks | L1: ObstacleType | M1: ClearType | N1: MinClearance | O1: MicroCorrections | P1: ObstacleDuration
A2: DEATH
A3: Platform | B3: 0 | C3: 0 | D3: 0.02 | E3: 0 | F3: 5.678 | G3: 5.678 | H3: 5.678 | I3: 1 | J3: 0 | K3: 0 | L3: 0
A4: Platform | B4: 0 | C4: 0 | D4: 3.07 | E4: 0.5023 | F4: 0.9585 | G4: 1.8496 | H4: 0.0582 | I4: 184 | J4: 0.3 | K4: 0 | L4: 4
A5: Platform | B5: 0 | C5: 0 | D5: 1.55 | E5: 0.2787 | F5: 4.7292 | G5: 5.0226 | H5: 4.3313 | I5: 92 | J5: 0.02 | K5: 0 | L5: 1
A6: Platform | B6: 1 | C6: 0 | D6: 0.8 | E6: 0.0232 | F6: 9.7651 | G6: 9.7952 | H6: 9.6707 | I6: 48 | J6: 0.18 | K6: 0 | L6: 0
A7: Platform | B7: 1 | C7: 0 | D7: 0.02 | E7: 0 | F7: 10.5939 | G7: 10.5939 | H7: 10.5939 | I7: 1 | J7: 0 | K7: 0 | L7: 0
A8: Platform | B8: 1 | C8: 0 | D8: 0.01 | E8: 0 | F8: 10.5363 | G8: 10.5363 | H8: 10.5363 | I8: 1 | J8: 0 | K8: 0 | L8: 0
A9: DEATH
A10: Platform | B10: 0 | C10: 0 | D10: 2.9 | E10: 0.2958 | F10: 1.4345 | G10: 1.8753 | H10: 0.526 | I10: 174 | J10: 0.15 | K10: 0 | L10: 1
A11: Platform | B11: 0 | C11: 0 | D11: 0.46 | E11: 1.2479 | F11: 2.296 | G11: 4.7501 | H11: 0.8511 | I11: 28 | J11: 0.28 | K11: 0 | L11: 2
A12: DEATH
A13: Platform | B13: 0 | C13: 0 | D13: 3.24 | E13: 0.0738 | F13: 0.7352 | G13: 0.845 | H13: 0.5563 | I13: 194 | J13: 0.23 | K13: 0 | L13: 1
A14: DEATH
A15: Platform | B15: 0 | C15: 0 | D15: 3.9 | E15: 0.9244 | F15: 2.0829 | G15: 4.7999 | H15: 0.3244 | I15: 233 | J15: 3.16 | K15: 0 | L15: 4
A16: DEATH
A17: Platform | B17: 0 | C17: 0 | D17: 1.78 | E17: 0.7153 | F17: 1.7722 | G17: 4.4911 | H17: 0.8748 | I17: 107 | J17: 0 | K17: 0 | L17: 3
A18: Platform | B18: 0 | C18: 0 | D18: 3.62 | E18: 0.3634 | F18: 1.2775 | G18: 3.6833 | H18: 1.1156 | I18: 215 | J18: 0.54 | K18: 0 | L18: 2
A19: Platform | B19: 1 | C19: 0 | D19: 0.51 | E19: 0.0706 | F19: 8.6722 | G19: 8.7255 | H19: 8.4148 | I19: 30 | J19: 0.07 | K19: 0 | L19: 0
A20: Platform | B20: 1 | C20: 0 | D20: 5.12 | E20: 0.0796 | F20: 8.5766 | G20: 8.7349 | H20: 8.3687 | I20: 303 | J20: 0.16 | K20: 0 | L20: 1
A21: Platform | B21: 2 | C21: 0 | D21: 0.03 | E21: 0 | F21: 4.7969 | G21: 4.7969 | H21: 4.7969 | I21: 1 | J21: 0 | K21: 0 | L21: 0
A22: Platform | B22: 2 | C22: 0 | D22: 3.15 | E22: 1.9301 | F22: 8.3218 | G22: 12.7962 | H22: 4.3547 | I22: 108 | J22: 1.94 | K22: 4 | L22: 4
A23: DEATH
A24: Platform | B24: 2 | C24: 0 | D24: 0.05 | E24: 0.0226 | F24: 4.6539 | G24: 4.6765 | H24: 4.6314 | I24: 2 | J24: 0 | K24: 0 | L24: 0
A25: Platform | B25: 2 | C25: 0 | D25: 1.94 | E25: 0.6564 | F25: 6.4782 | G25: 7.2317 | H25: 4.8921 | I25: 64 | J25: 1.15 | K25: 0 | L25: 2
A26: DEATH
A27: Platform | B27: 2 | C27: 0 | D27: 0.07 | E27: 0.0926 | F27: 2.5835 | G27: 2.6761 | H27: 2.4909 | I27: 2 | J27: 0 | K27: 0 | L27: 0
A28: Platform | B28: 2 | C28: 0 | D28: 2.35 | E28: 1.2089 | F28: 6.2015 | G28: 8.305 | H28: 2.9332 | I28: 70 | J28: 0.51 | K28: 0 | L28: 1
A29: Platform | B29: 2 | C29: 0 | D29: 0.03 | E29: 0 | F29: 7.0428 | G29: 7.0428 | H29: 7.0428 | I29: 1 | J29: 0 | K29: 0 | L29: 0
A30: Platform | B30: 2 | C30: 0 | D30: 0.03 | E30: 0 | F30: 7.4863 | G30: 7.4863 | H30: 7.4863 | I30: 1 | J30: 0 | K30: 0 | L30: 0
A31: DEATH
A32: Platform | B32: 2 | C32: 0 | D32: 2.59 | E32: 0.962 | F32: 7.3267 | G32: 7.9317 | H32: 4.8538 | I32: 89 | J32: 1.11 | K32: 0 | L32: 2
A33: Platform | B33: 2 | C33: 0 | D33: 0.77 | E33: 0.0135 | F33: 7.9186 | G33: 7.9621 | H33: 7.9052 | I33: 26 | J33: 0.1 | K33: 0 | L33: 0
A34: DEATH
A35: Platform | B35: 2 | C35: 0 | D35: 0.06 | E35: 0.1895 | F35: 4.5262 | G35: 4.7158 | H35: 4.3367 | I35: 2 | J35: 0 | K35: 0 | L35: 0
A36: Platform | B36: 2 | C36: 0 | D36: 1.67 | E36: 1.2371 | F36: 7.6329 | G36: 8.3947 | H36: 4.7026 | I36: 55 | J36: 0.66 | K36: 0 | L36: 0
A37: Platform | B37: 2 | C37: 0 | D37: 2.56 | E37: 0.7601 | F37: 8.1455 | G37: 11.367 | H37: 7.6694 | I37: 86 | J37: 0.35 | K37: 0 | L37: 2
A38: DEATH
A39: Platform | B39: 2 | C39: 0 | D39: 2.84 | E39: 0.5495 | F39: 4.825 | G39: 6.3251 | H39: 3.3364 | I39: 96 | J39: 1.63 | K39: 0 | L39: 0
A40: Platform | B40: 2 | C40: 0 | D40: 1.44 | E40: 1.3402 | F40: 6.5252 | G40: 9.9216 | H40: 4.1409 | I40: 49 | J40: 0.26 | K40: 0 | L40: 2
...

Sheet adap_GonzaloCampos
A1: EventType | B1: SegmentID | C1: ElementID | D1: TimeOnPlatform | E1: RelativePositionStd | F1: RelativePositionMean | G1: RelativePositionMax | H1: RelativePositionMin | I1: SampleCount | J1: EdgeRiskTime | K1: CorrectionPeaks | L1: ObstacleType | M1: ClearType | N1: MinClearance | O1: MicroCorrections | P1: ObstacleDuration
A2: DEATH
A3: DEATH
A4: Platform | B4: 0 | C4: 0 | D4: 0.74 | E4: 1.873 | F4: 2.6713 | G4: 6.5205 | H4: 0.1062 | I4: 34 | J4: 0.38 | K4: 1 | L4: 2
A5: Platform | B5: 0 | C5: 0 | D5: 0.1 | E5: 0.0214 | F5: 5.582 | G5: 5.6068 | H5: 5.5494 | I5: 5 | J5: 0 | K5: 0 | L5: 0
A6: DEATH
A7: Platform | B7: 0 | C7: 0 | D7: 0.04 | E7: 0.0007 | F7: 5.0742 | G7: 5.0749 | H7: 5.0735 | I7: 2 | J7: 0 | K7: 0 | L7: 0
A8: Platform | B8: 0 | C8: 0 | D8: 2.22 | E8: 0.2524 | F8: 1.8151 | G8: 2.7527 | H8: 1.5587 | I8: 112 | J8: 0 | K8: 0 | L8: 4
A9: DEATH
A10: Platform | B10: 0 | C10: 0 | D10: 0.04 | E10: 0.0495 | F10: 5.9416 | G10: 5.991 | H10: 5.8921 | I10: 2 | J10: 0 | K10: 0 | L10: 1
A11: Platform | B11: 0 | C11: 0 | D11: 2.24 | E11: 0.7766 | F11: 1.4495 | G11: 4.4105 | H11: 0.2678 | I11: 113 | J11: 0 | K11: 0 | L11: 6
A12: DEATH
A13: Platform | B13: 0 | C13: 0 | D13: 2.67 | E13: 0.0782 | F13: 0.7602 | G13: 0.8591 | H13: 0.6209 | I13: 134 | J13: 0.13 | K13: 0 | L13: 5
A14: Platform | B14: 0 | C14: 0 | D14: 2.07 | E14: 0.8963 | F14: 0.9758 | G14: 4.6958 | H14: 0.5339 | I14: 104 | J14: 0.82 | K14: 0 | L14: 0
A15: Platform | B15: 1 | C15: 0 | D15: 0.58 | E15: 1.4431 | F15: 8.755 | G15: 10.5976 | H15: 6.2262 | I15: 28 | J15: 0.47 | K15: 0 | L15: 0
A16: DEATH
A17: Platform | B17: 0 | C17: 0 | D17: 2.16 | E17: 0.5156 | F17: 0.8152 | G17: 3.3848 | H17: 0.5275 | I17: 109 | J17: 0.45 | K17: 0 | L17: 4
A18: Platform | B18: 0 | C18: 0 | D18: 2.43 | E18: 0.7263 | F18: 3.1718 | G18: 4.7845 | H18: 2.057 | I18: 124 | J18: 0.11 | K18: 0 | L18: 8
A19: Platform | B19: 1 | C19: 0 | D19: 0.44 | E19: 0.3931 | F19: 5.9949 | G19: 6.3421 | H19: 5.2222 | I19: 22 | J19: 0.24 | K19: 0 | L19: 0
A20: Platform | B20: 1 | C20: 0 | D20: 0.62 | E20: 0.9422 | F20: 7.299 | G20: 8.1204 | H20: 5.4682 | I20: 32 | J20: 0.4 | K20: 0 | L20: 2
A21: Platform | B21: 1 | C21: 0 | D21: 0.08 | E21: 0.0604 | F21: 10.7903 | G21: 10.8787 | H21: 10.7233 | I21: 4 | J21: 0 | K21: 0 | L21: 0
A22: Platform | B22: 1 | C22: 0 | D22: 0.12 | E22: 0.1253 | F22: 8.5327 | G22: 8.7 | H22: 8.3348 | I22: 6 | J22: 0 | K22: 0 | L22: 1
A23: Platform | B23: 1 | C23: 0 | D23: 0.06 | E23: 0.0807 | F23: 6.0464 | G23: 6.1429 | H23: 5.9453 | I23: 3 | J23: 0 | K23: 0 | L23: 1
A24: DEATH
A25: Platform | B25: 0 | C25: 0 | D25: 0.02 | E25: 0 | F25: 4.9927 | G25: 4.9927 | H25: 4.9927 | I25: 1 | J25: 0 | K25: 0 | L25: 0
A26: Platform | B26: 0 | C26: 0 | D26: 2.9 | E26: 0.3789 | F26: 0.6778 | G26: 2.118 | H26: 0.2692 | I26: 147 | J26: 0 | K26: 0 | L26: 4
A27: Platform | B27: 0 | C27: 0 | D27: 2.11 | E27: 0.5918 | F27: 1.9418 | G27: 4.5612 | H27: 0.64 | I27: 108 | J27: 0.38 | K27: 0 | L27: 2
A28: Platform | B28: 1 | C28: 0 | D28: 1.8 | E28: 0.641 | F28: 5.6524 | G28: 6.8737 | H28: 4.1912 | I28: 90 | J28: 1.39 | K28: 0 | L28: 0
A29: Platform | B29: 1 | C29: 0 | D29: 2.58 | E29: 0.1369 | F29: 8.8871 | G29: 8.9488 | H29: 7.8574 | I29: 121 | J29: 0.04 | K29: 0 | L29: 2
A30: Platform | B30: 1 | C30: 0 | D30: 0.02 | E30: 0 | F30: 10.4112 | G30: 10.4112 | H30: 10.4112 | I30: 1 | J30: 0 | K30: 0 | L30: 0
A31: Platform | B31: 2 | C31: 0 | D31: 0.04 | E31: 0 | F31: 9.7131 | G31: 9.7131 | H31: 9.7131 | I31: 1 | J31: 0 | K31: 0 | L31: 0
A32: Platform | B32: 2 | C32: 0 | D32: 2.3 | E32: 0.4814 | F32: 6.1255 | G32: 7.6162 | H32: 5.8402 | I32: 69 | J32: 0 | K32: 0 | L32: 4
A33: Platform | B33: 2 | C33: 0 | D33: 0.04 | E33: 0 | F33: 6.6187 | G33: 6.6187 | H33: 6.6187 | I33: 1 | J33: 0 | K33: 0 | L33: 0
A34: Platform | B34: 2 | C34: 0 | D34: 0.07 | E34: 0.0703 | F34: 5.0722 | G34: 5.1426 | H34: 5.0019 | I34: 2 | J34: 0 | K34: 0 | L34: 0
A35: Platform | B35: 2 | C35: 0 | D35: 1.13 | E35: 0.1121 | F35: 5.5469 | G35: 5.9751 | H35: 5.4988 | I35: 36 | J35: 0 | K35: 0 | L35: 1
A36: Platform | B36: 2 | C36: 0 | D36: 0.21 | E36: 0.5729 | F36: 7.9723 | G36: 8.8546 | H36: 7.1324 | I36: 7 | J36: 0.06 | K36: 0 | L36: 0
A37: DEATH
A38: DEATH
A39: DEATH
A40: DEATH
...

Sheet adap_IgnaciaDelgado
A1: EventType | B1: SegmentID | C1: ElementID | D1: TimeOnPlatform | E1: RelativePositionStd | F1: RelativePositionMean | G1: RelativePositionMax | H1: RelativePositionMin | I1: SampleCount | J1: EdgeRiskTime | K1: CorrectionPeaks | L1: ObstacleType | M1: ClearType | N1: MinClearance | O1: MicroCorrections | P1: ObstacleDuration
A2: DEATH
A3: DEATH
A4: DEATH
A5: DEATH
A6: DEATH
A7: DEATH
A8: DEATH
A9: DEATH
A10: Platform | B10: 0 | C10: 0 | D10: 1.71 | E10: 0.222 | F10: 0.9174 | G10: 1.0775 | H10: 0.0866 | I10: 93 | J10: 0.34 | K10: 0 | L10: 4
A11: Platform | B11: 0 | C11: 0 | D11: 2.06 | E11: 1.0913 | F11: 2.9143 | G11: 4.5836 | H11: 0.716 | I11: 119 | J11: 0.65 | K11: 0 | L11: 3
A12: Platform | B12: 1 | C12: 0 | D12: 1.38 | E12: 1.4021 | F12: 6.6488 | G12: 8.7515 | H12: 3.509 | I12: 74 | J12: 0.83 | K12: 0 | L12: 2
A13: Platform | B13: 2 | C13: 0 | D13: 3.62 | E13: 0.5405 | F13: 6.9895 | G13: 8.9186 | H13: 6.6259 | I13: 114 | J13: 0.13 | K13: 0 | L13: 6
A14: Platform | B14: 2 | C14: 0 | D14: 0.23 | E14: 0.5338 | F14: 4.7616 | G14: 5.6476 | H14: 4.102 | I14: 7 | J14: 0 | K14: 0 | L14: 1
A15: DEATH
A16: Platform | B16: 2 | C16: 0 | D16: 0.03 | E16: 0 | F16: 8.5231 | G16: 8.5231 | H16: 8.5231 | I16: 1 | J16: 0 | K16: 0 | L16: 0
A17: Platform | B17: 2 | C17: 0 | D17: 1.65 | E17: 1.3078 | F17: 7.8072 | G17: 9.9007 | H17: 5.6624 | I17: 49 | J17: 0.7 | K17: 0 | L17: 4
A18: Platform | B18: 2 | C18: 0 | D18: 0.16 | E18: 0.4045 | F18: 12.4456 | G18: 13.0256 | H18: 11.8827 | I18: 5 | J18: 0 | K18: 0 | L18: 0
A19: DEATH
A20: Platform | B20: 2 | C20: 0 | D20: 0.06 | E20: 0.1931 | F20: 6.1507 | G20: 6.3438 | H20: 5.9576 | I20: 2 | J20: 0 | K20: 0 | L20: 0
A21: Platform | B21: 2 | C21: 0 | D21: 2.08 | E21: 1.3129 | F21: 8.4254 | G21: 10.3893 | H21: 6.7297 | I21: 62 | J21: 1.12 | K21: 0 | L21: 1
A22: DEATH
A23: Platform | B23: 2 | C23: 0 | D23: 0.03 | E23: 0 | F23: 7.2595 | G23: 7.2595 | H23: 7.2595 | I23: 1 | J23: 0 | K23: 0 | L23: 0
A24: Platform | B24: 2 | C24: 0 | D24: 1.87 | E24: 0.9143 | F24: 7.3797 | G24: 8.8743 | H24: 6.2356 | I24: 58 | J24: 1.18 | K24: 0 | L24: 2
A25: Platform | B25: 2 | C25: 0 | D25: 1.37 | E25: 0.074 | F25: 8.7291 | G25: 8.8761 | H25: 8.6294 | I25: 45 | J25: 0 | K25: 0 | L25: 1
A26: DEATH
A27: Platform | B27: 2 | C27: 0 | D27: 0.03 | E27: 0 | F27: 5.5012 | G27: 5.5012 | H27: 5.5012 | I27: 1 | J27: 0 | K27: 0 | L27: 0
A28: Platform | B28: 2 | C28: 0 | D28: 0.86 | E28: 0.3324 | F28: 5.988 | G28: 6.5023 | H28: 5.5364 | I28: 26 | J28: 0.65 | K28: 0 | L28: 0
A29: Platform | B29: 2 | C29: 0 | D29: 2.02 | E29: 0.2505 | F29: 7.1238 | G29: 7.2552 | H29: 6.4712 | I29: 64 | J29: 0.52 | K29: 0 | L29: 0
A30: Platform | B30: 2 | C30: 0 | D30: 0.33 | E30: 0.1363 | F30: 6.5707 | G30: 6.7741 | H30: 6.3638 | I30: 19 | J30: 0 | K30: 0 | L30: 2
A31: Platform | B31: 2 | C31: 0 | D31: 2.54 | E31: 0.0525 | F31: 6.5856 | G31: 6.6901 | H31: 6.5218 | I31: 104 | J31: 1.69 | K31: 0 | L31: 1
A32: Platform | B32: 2 | C32: 0 | D32: 0.75 | E32: 0.1718 | F32: 6.8023 | G32: 7.087 | H32: 6.666 | I32: 23 | J32: 0.33 | K32: 0 | L32: 0
A33: DEATH
A34: DEATH
A35: DEATH
A36: DEATH
A37: DEATH
A38: DEATH
A39: DEATH
A40: DEATH

Sheet adap_IsidoraToledo
A1: EventType | B1: SegmentID | C1: ElementID | D1: TimeOnPlatform | E1: RelativePositionStd | F1: RelativePositionMean | G1: RelativePositionMax | H1: RelativePositionMin | I1: SampleCount | J1: EdgeRiskTime | K1: CorrectionPeaks | L1: RawCorrectionsCount | M1: Unnamed: 12 | N1: ExtraCol_13 | O1: ExtraCol_14 | P1: ExtraCol_15
A2: Platform | B2: 0 | C2: 0 | D2: 0.04 | E2: 0 | F2: 4.9709 | G2: 4.9709 | H2: 4.9709 | I2: 1 | J2: 0 | K2: 0 | L2: 0
A3: Platform | B3: 0 | C3: 0 | D3: 2.98 | E3: 0.8422 | F3: 1.6066 | G3: 4.2307 | H3: 0.811 | I3: 85 | J3: 0 | K3: 1 | L3: 23
A4: Platform | B4: 0 | C4: 0 | D4: 0.03 | E4: 0 | F4: 5.2602 | G4: 5.2602 | H4: 5.2602 | I4: 1 | J4: 0 | K4: 0 | L4: 0
A5: Platform | B5: 1 | C5: 0 | D5: 1.26 | E5: 0.4517 | F5: 5.3977 | G5: 5.9133 | H5: 4.6876 | I5: 37 | J5: 0.68 | K5: 0 | L5: 6
A6: DEATH
A7: Platform | B7: 0 | C7: 0 | D7: 1.31 | E7: 0.0387 | F7: 4.9165 | G7: 4.9539 | H7: 4.852 | I7: 38 | J7: 0.49 | K7: 0 | L7: 0
A8: Platform | B8: 0 | C8: 0 | D8: 0.03 | E8: 0 | F8: 5.0691 | G8: 5.0691 | H8: 5.0691 | I8: 1 | J8: 0 | K8: 0 | L8: 0
A9: Platform | B9: 0 | C9: 0 | D9: 2.52 | E9: 1.2972 | F9: 2.957 | G9: 4.2145 | H9: 0.7252 | I9: 76 | J9: 0.83 | K9: 2 | L9: 11
A10: DEATH
A11: Platform | B11: 0 | C11: 0 | D11: 2.93 | E11: 0.7073 | F11: 1.9008 | G11: 2.5521 | H11: 0.4562 | I11: 82 | J11: 1.33 | K11: 0 | L11: 34
A12: DEATH
A13: Platform | B13: 0 | C13: 0 | D13: 2.89 | E13: 0.0599 | F13: 0.3046 | G13: 0.4752 | H13: 0.0811 | I13: 88 | J13: 0 | K13: 0 | L13: 1
A14: DEATH
A15: Platform | B15: 0 | C15: 0 | D15: 1 | E15: 0.2918 | F15: 1.344 | G15: 2.4231 | H15: 1.1844 | I15: 29 | J15: 0 | K15: 0 | L15: 5
A16: Platform | B16: 0 | C16: 0 | D16: 0.03 | E16: 0 | F16: 1.1977 | G16: 1.1977 | H16: 1.1977 | I16: 1 | J16: 0 | K16: 0 | L16: 0
A17: Platform | B17: 0 | C17: 0 | D17: 5.99 | E17: 0.3991 | F17: 1.2695 | G17: 3.6218 | H17: 1.0685 | I17: 177 | J17: 1.18 | K17: 0 | L17: 18
A18: DEATH
A19: Platform | B19: 0 | C19: 0 | D19: 0.43 | E19: 0.0164 | F19: 1.4538 | G19: 1.477 | H19: 1.4282 | I19: 13 | J19: 0.09 | K19: 0 | L19: 0
A20: Platform | B20: 0 | C20: 0 | D20: 5.85 | E20: 0.461 | F20: 1.022 | G20: 2.1481 | H20: 0.2065 | I20: 175 | J20: 0.4 | K20: 0 | L20: 20
A21: Platform | B21: 1 | C21: 0 | D21: 0.6 | E21: 0.8875 | F21: 6.1705 | G21: 7.3781 | H21: 5.0847 | I21: 18 | J21: 0.44 | K21: 0 | L21: 1
A22: Platform | B22: 1 | C22: 0 | D22: 1.58 | E22: 0.3302 | F22: 7.4204 | G22: 7.9036 | H22: 6.738 | I22: 46 | J22: 0.49 | K22: 0 | L22: 9
A23: Platform | B23: 1 | C23: 0 | D23: 0.22 | E23: 0.0369 | F23: 7.0674 | G23: 7.1081 | H23: 6.9859 | I23: 7 | J23: 0 | K23: 0 | L23: 0
A24: Platform | B24: 2 | C24: 0 | D24: 1.69 | E24: 0.1659 | F24: 7.7616 | G24: 8.3119 | H24: 7.5457 | I24: 25 | J24: 0 | K24: 0 | L24: 11
A25: Platform | B25: 2 | C25: 0 | D25: 1.83 | E25: 0.668 | F25: 8.7404 | G25: 9.5287 | H25: 7.6557 | I25: 25 | J25: 1.4 | K25: 0 | L25: 10
A26: DEATH
A27: Platform | B27: 2 | C27: 0 | D27: 2.37 | E27: 0.708 | F27: 5.3698 | G27: 8.4296 | H27: 5.024 | I27: 36 | J27: 0.5 | K27: 4 | L27: 12
A28: Platform | B28: 2 | C28: 0 | D28: 0.07 | E28: 0 | F28: 9.2873 | G28: 9.2873 | H28: 9.2873 | I28: 1 | J28: 0 | K28: 0 | L28: 0
A29: DEATH
A30: Platform | B30: 2 | C30: 0 | D30: 0.06 | E30: 0 | F30: 6.2698 | G30: 6.2698 | H30: 6.2698 | I30: 1 | J30: 0 | K30: 0 | L30: 0
A31: Platform | B31: 2 | C31: 0 | D31: 2.4 | E31: 0.7369 | F31: 8.5677 | G31: 9.4317 | H31: 7.0755 | I31: 38 | J31: 1.97 | K31: 0 | L31: 17
A32: DEATH
A33: Platform | B33: 2 | C33: 0 | D33: 1.65 | E33: 1.0283 | F33: 6.0914 | G33: 7.0627 | H33: 3.3714 | I33: 23 | J33: 0.9 | K33: 1 | L33: 8
A34: Platform | B34: 2 | C34: 0 | D34: 2.08 | E34: 0.1675 | F34: 6.7054 | G34: 7.0674 | H34: 6.5149 | I34: 28 | J34: 0.08 | K34: 0 | L34: 11
A35: DEATH
A36: Platform | B36: 2 | C36: 0 | D36: 2.12 | E36: 0.7095 | F36: 8.1008 | G36: 8.6688 | H36: 6.4687 | I36: 29 | J36: 0.78 | K36: 0 | L36: 11
A37: Platform | B37: 2 | C37: 0 | D37: 1.46 | E37: 0.2129 | F37: 8.4363 | G37: 8.6888 | H37: 8.1048 | I37: 19 | J37: 0 | K37: 0 | L37: 3
A38: DEATH
A39: Platform | B39: 2 | C39: 0 | D39: 2.81 | E39: 0.786 | F39: 6.8446 | G39: 7.7972 | H39: 4.9515 | I39: 43 | J39: 1.37 | K39: 0 | L39: 15
A40: Platform | B40: 2 | C40: 0 | D40: 0.83 | E40: 0.0698 | F40: 7.2006 | G40: 7.3167 | H40: 7.03 | I40: 11 | J40: 0 | K40: 0 | L40: 2
...

Sheet adap_JavierSalinas
A1: EventType | B1: SegmentID | C1: ElementID | D1: TimeOnPlatform | E1: RelativePositionStd | F1: RelativePositionMean | G1: RelativePositionMax | H1: RelativePositionMin | I1: SampleCount | J1: EdgeRiskTime | K1: CorrectionPeaks | L1: ObstacleType | M1: ClearType | N1: MinClearance | O1: MicroCorrections | P1: ObstacleDuration
A2: DEATH
A3: Platform | B3: 0 | C3: 0 | D3: 0.04 | E3: 0 | F3: 5.8079 | G3: 5.8079 | H3: 5.8079 | I3: 1 | J3: 0 | K3: 0 | L3: 0
A4: Platform | B4: 0 | C4: 0 | D4: 0.9 | E4: 1.1692 | F4: 1.7013 | G4: 4.7433 | H4: 0.4496 | I4: 27 | J4: 0.5 | K4: 0 | L4: 2
A5: Platform | B5: 0 | C5: 0 | D5: 0.03 | E5: 0 | F5: 5.0094 | G5: 5.0094 | H5: 5.0094 | I5: 1 | J5: 0 | K5: 0 | L5: 0
A6: Platform | B6: 0 | C6: 0 | D6: 0.03 | E6: 0 | F6: 5.2005 | G6: 5.2005 | H6: 5.2005 | I6: 1 | J6: 0 | K6: 0 | L6: 0
A7: DEATH
A8: Platform | B8: 0 | C8: 0 | D8: 2.68 | E8: 0.0132 | F8: 1.7328 | G8: 1.7706 | H8: 1.7019 | I8: 78 | J8: 0.36 | K8: 0 | L8: 1
A9: DEATH
A10: Platform | B10: 0 | C10: 0 | D10: 3.17 | E10: 0.1187 | F10: 1.2147 | G10: 1.5024 | H10: 1.0825 | I10: 93 | J10: 0 | K10: 0 | L10: 1
A11: Platform | B11: 0 | C11: 0 | D11: 0.16 | E11: 0.0827 | F11: 4.7129 | G11: 4.8143 | H11: 4.6013 | I11: 5 | J11: 0 | K11: 0 | L11: 1
A12: Platform | B12: 0 | C12: 0 | D12: 0.31 | E12: 0.0533 | F12: 4.5498 | G12: 4.6672 | H12: 4.4741 | I12: 9 | J12: 0 | K12: 0 | L12: 2
A13: Platform | B13: 0 | C13: 0 | D13: 0.03 | E13: 0 | F13: 4.9689 | G13: 4.9689 | H13: 4.9689 | I13: 1 | J13: 0 | K13: 0 | L13: 0
A14: Platform | B14: 1 | C14: 0 | D14: 0.06 | E14: 0.094 | F14: 5.4562 | G14: 5.5502 | H14: 5.3622 | I14: 2 | J14: 0 | K14: 0 | L14: 0
A15: Platform | B15: 1 | C15: 0 | D15: 0.27 | E15: 0.1268 | F15: 7.6918 | G15: 7.8858 | H15: 7.5011 | I15: 8 | J15: 0.1 | K15: 0 | L15: 0
A16: DEATH
A17: Platform | B17: 0 | C17: 0 | D17: 3.96 | E17: 0.6862 | F17: 1.4429 | G17: 4.7585 | H17: 1.0083 | I17: 116 | J17: 0.49 | K17: 0 | L17: 4
A18: Platform | B18: 0 | C18: 0 | D18: 0.07 | E18: 0.1724 | F18: 2.6338 | G18: 2.8062 | H18: 2.4613 | I18: 2 | J18: 0 | K18: 0 | L18: 0
A19: DEATH
A20: Platform | B20: 0 | C20: 0 | D20: 0.06 | E20: 0 | F20: 4.8157 | G20: 4.8157 | H20: 4.8157 | I20: 1 | J20: 0 | K20: 0 | L20: 0
A21: Platform | B21: 0 | C21: 0 | D21: 2.58 | E21: 0.0105 | F21: 1.6627 | G21: 1.6764 | H21: 1.5901 | I21: 76 | J21: 0 | K21: 0 | L21: 0
A22: DEATH
A23: Platform | B23: 0 | C23: 0 | D23: 2.49 | E23: 0.0309 | F23: 0.4232 | G23: 0.5211 | H23: 0.3506 | I23: 74 | J23: 0.28 | K23: 0 | L23: 6
A24: DEATH
A25: Platform | B25: 0 | C25: 0 | D25: 0.03 | E25: 0 | F25: 4.7641 | G25: 4.7641 | H25: 4.7641 | I25: 1 | J25: 0 | K25: 0 | L25: 0
A26: Platform | B26: 0 | C26: 0 | D26: 3.97 | E26: 0.6062 | F26: 1.5925 | G26: 4.6584 | H26: 1.3365 | I26: 117 | J26: 0.55 | K26: 0 | L26: 0
A27: DEATH
A28: Platform | B28: 0 | C28: 0 | D28: 2.71 | E28: 0.022 | F28: 0.1869 | G28: 0.3185 | H28: 0.1464 | I28: 77 | J28: 0.04 | K28: 0 | L28: 1
A29: DEATH
A30: Platform | B30: 0 | C30: 0 | D30: 2.4 | E30: 0.8551 | F30: 1.8114 | G30: 3.1268 | H30: 0.8053 | I30: 73 | J30: 0.75 | K30: 0 | L30: 1
A31: DEATH
A32: Platform | B32: 0 | C32: 0 | D32: 2.99 | E32: 0.5906 | F32: 2.2386 | G32: 3.929 | H32: 1.6399 | I32: 91 | J32: 0 | K32: 0 | L32: 2
A33: Platform | B33: 0 | C33: 0 | D33: 1.34 | E33: 0.6921 | F33: 3.5409 | G33: 4.7795 | H33: 2.9669 | I33: 41 | J33: 0 | K33: 0 | L33: 1
A34: Platform | B34: 1 | C34: 0 | D34: 1.65 | E34: 0.4802 | F34: 7.4172 | G34: 7.7127 | H34: 6.3781 | I34: 50 | J34: 0.55 | K34: 0 | L34: 0
A35: Platform | B35: 1 | C35: 0 | D35: 0.04 | E35: 0 | F35: 11.0832 | G35: 11.0832 | H35: 11.0832 | I35: 1 | J35: 0 | K35: 0 | L35: 0
A36: Platform | B36: 1 | C36: 0 | D36: 0.07 | E36: 0.0391 | F36: 11.122 | G36: 11.1611 | H36: 11.0829 | I36: 2 | J36: 0 | K36: 0 | L36: 0
A37: Platform | B37: 1 | C37: 0 | D37: 0.19 | E37: 0.1935 | F37: 11.9047 | G37: 12.2577 | H37: 11.6588 | I37: 6 | J37: 0.03 | K37: 0 | L37: 0
A38: DEATH
A39: Platform | B39: 0 | C39: 0 | D39: 2.69 | E39: 0.8642 | F39: 3.4131 | G39: 4.1566 | H39: 1.379 | I39: 80 | J39: 0 | K39: 0 | L39: 2
A40: DEATH
...

Sheet adap_MariannaMaregatti
A1: EventType | B1: SegmentID | C1: ElementID | D1: TimeOnPlatform | E1: RelativePositionStd | F1: RelativePositionMean | G1: RelativePositionMax | H1: RelativePositionMin | I1: SampleCount | J1: EdgeRiskTime | K1: CorrectionPeaks | L1: RawCorrectionsCount | M1: Unnamed: 12 | N1: ExtraCol_13 | O1: ExtraCol_14 | P1: ExtraCol_15
A2: Platform | B2: 0 | C2: 0 | D2: 0.03 | E2: 0 | F2: 5.3154 | G2: 5.3154 | H2: 5.3154 | I2: 1 | J2: 0 | K2: 0 | L2: 0
A3: Platform | B3: 0 | C3: 0 | D3: 2.19 | E3: 0.7691 | F3: 2.3759 | G3: 3.0199 | H3: 1.0588 | I3: 64 | J3: 0.87 | K3: 0 | L3: 5
A4: Platform | B4: 0 | C4: 0 | D4: 0.04 | E4: 0 | F4: 4.868 | G4: 4.868 | H4: 4.868 | I4: 1 | J4: 0 | K4: 0 | L4: 0
A5: DEATH
A6: Platform | B6: 0 | C6: 0 | D6: 1.99 | E6: 0.3078 | F6: 1.1035 | G6: 1.4488 | H6: 0.752 | I6: 59 | J6: 1 | K6: 0 | L6: 2
A7: Platform | B7: 0 | C7: 0 | D7: 3.85 | E7: 0.07 | F7: 1.3901 | G7: 1.4771 | H7: 1.2518 | I7: 113 | J7: 0.51 | K7: 0 | L7: 3
A8: Platform | B8: 0 | C8: 0 | D8: 0.18 | E8: 0.0564 | F8: 1.1425 | G8: 1.2553 | H8: 1.1127 | I8: 5 | J8: 0 | K8: 0 | L8: 1
A9: Platform | B9: 0 | C9: 0 | D9: 1.17 | E9: 0.0021 | F9: 1.0203 | G9: 1.0254 | H9: 1.018 | I9: 35 | J9: 0 | K9: 0 | L9: 0
A10: Platform | B10: 0 | C10: 0 | D10: 1.75 | E10: 0.006 | F10: 1.0288 | G10: 1.0412 | H10: 1.0175 | I10: 51 | J10: 0.69 | K10: 0 | L10: 0
A11: Platform | B11: 0 | C11: 0 | D11: 3.84 | E11: 0.2082 | F11: 1.2656 | G11: 1.4725 | H11: 1.0216 | I11: 115 | J11: 1.97 | K11: 0 | L11: 0
A12: Platform | B12: 0 | C12: 0 | D12: 2.28 | E12: 0.0461 | F12: 1.49 | G12: 1.5684 | H12: 1.4462 | I12: 67 | J12: 0.87 | K12: 0 | L12: 0
A13: Platform | B13: 0 | C13: 0 | D13: 0.63 | E13: 0.0507 | F13: 1.5258 | G13: 1.5552 | H13: 1.3501 | I13: 20 | J13: 0 | K13: 0 | L13: 1
A14: Platform | B14: 1 | C14: 0 | D14: 0.65 | E14: 0.2259 | F14: 6.2875 | G14: 6.4308 | H14: 5.6382 | I14: 20 | J14: 0 | K14: 0 | L14: 1
A15: Platform | B15: 1 | C15: 0 | D15: 3.55 | E15: 0.1026 | F15: 5.3823 | G15: 5.5548 | H15: 5.2475 | I15: 106 | J15: 0.1 | K15: 0 | L15: 1
A16: Platform | B16: 1 | C16: 0 | D16: 1.72 | E16: 0.2862 | F16: 5.3785 | G16: 6.6543 | H16: 5.1038 | I16: 50 | J16: 0.4 | K16: 0 | L16: 4
A17: Platform | B17: 2 | C17: 0 | D17: 0.04 | E17: 0 | F17: 4.761 | G17: 4.761 | H17: 4.761 | I17: 1 | J17: 0 | K17: 0 | L17: 0
... A19: Platform | B19: 2 | C19: 0 | D19: 1.42 | E19: 0.1731 | F19: 8.3067 | G19: 8.4479 | H19: 7.9602 | I19: 23 | J19: 0.37 | K19: 0 | L19: 0
A20: DEATH
A21: Platform | B21: 2 | C21: 0 | D21: 0.06 | E21: 0 | F21: 1.3447 | G21: 1.3447 | H21: 1.3447 | I21: 1 | J21: 0 | K21: 0 | L21: 0
A22: DEATH
A23: Platform | B23: 2 | C23: 0 | D23: 0.06 | E23: 0 | F23: 5.7146 | G23: 5.7146 | H23: 5.7146 | I23: 1 | J23: 0 | K23: 0 | L23: 0
A24: Platform | B24: 2 | C24: 0 | D24: 1.62 | E24: 0.7256 | F24: 7.6189 | G24: 8.4259 | H24: 6.657 | I24: 27 | J24: 0.82 | K24: 0 | L24: 2
A25: Platform | B25: 2 | C25: 0 | D25: 0.06 | E25: 0 | F25: 7.6192 | G25: 7.6192 | H25: 7.6192 | I25: 1 | J25: 0 | K25: 0 | L25: 0
A26: DEATH
A27: Platform | B27: 2 | C27: 0 | D27: 0.07 | E27: 0 | F27: 6.2514 | G27: 6.2514 | H27: 6.2514 | I27: 1 | J27: 0 | K27: 0 | L27: 0
A28: Platform | B28: 2 | C28: 0 | D28: 1.42 | E28: 0.5595 | F28: 7.7374 | G28: 8.3634 | H28: 7.0414 | I28: 21 | J28: 0.62 | K28: 0 | L28: 4
A29: Platform | B29: 2 | C29: 0 | D29: 2.01 | E29: 0.7788 | F29: 9.213 | G29: 10.3908 | H29: 8.2462 | I29: 31 | J29: 0.9 | K29: 0 | L29: 5
A30: Platform | B30: 2 | C30: 0 | D30: 0.96 | E30: 0.6112 | F30: 8.5506 | G30: 10.1492 | H30: 7.4864 | I30: 15 | J30: 0.12 | K30: 3 | L30: 2
A31: DEATH
A32: Platform | B32: 2 | C32: 0 | D32: 3.22 | E32: 1.2129 | F32: 9.6734 | G32: 13.389 | H32: 8.0954 | I32: 53 | J32: 1.48 | K32: 5 | L32: 4
A33: DEATH
A34: Platform | B34: 2 | C34: 0 | D34: 1.63 | E34: 1.0981 | F34: 7.8991 | G34: 9.4609 | H34: 6.575 | I34: 26 | J34: 0.98 | K34: 3 | L34: 3
A35: Platform | B35: 2 | C35: 0 | D35: 1.9 | E35: 0.0193 | F35: 9.4006 | G35: 9.4489 | H35: 9.3697 | I35: 30 | J35: 0.33 | K35: 0 | L35: 0
A36: DEATH
A37: Platform | B37: 2 | C37: 0 | D37: 1.71 | E37: 1.432 | F37: 8.827 | G37: 11.2564 | H37: 7.2352 | I37: 29 | J37: 1.06 | K37: 4 | L37: 3
A38: Platform | B38: 2 | C38: 0 | D38: 1.43 | E38: 0.2652 | F38: 11.2976 | G38: 12.3811 | H38: 11.1868 | I38: 22 | J38: 0.27 | K38: 2 | L38: 2
A39: DEATH
A40: Platform | B40: 2 | C40: 0 | D40: 3.19 | E40: 1.0348 | F40: 9.3701 | G40: 11.2873 | H40: 6.8405 | I40: 53 | J40: 1.29 | K40: 6 | L40: 6
A41: DEATH
...

Sheet adap_SebastianRatto
A1: EventType | B1: SegmentID | C1: ElementID | D1: TimeOnPlatform | E1: RelativePositionStd | F1: RelativePositionMean | G1: RelativePositionMax | H1: RelativePositionMin | I1: SampleCount | J1: EdgeRiskTime | K1: CorrectionPeaks | L1: RawCorrectionsCount | M1: Unnamed: 12 | N1: ExtraCol_13 | O1: ExtraCol_14 | P1: ExtraCol_15
A2: Platform | B2: 0 | C2: 0 | D2: 0.03 | E2: 0 | F2: 4.89 | G2: 4.89 | H2: 4.89 | I2: 1 | J2: 0 | K2: 0 | L2: 0
A3: Platform | B3: 0 | C3: 0 | D3: 3.7 | E3: 0.7356 | F3: 1.7224 | G3: 3.2047 | H3: 0.52 | I3: 110 | J3: 1.11 | K3: 0 | L3: 6
A4: Platform | B4: 0 | C4: 0 | D4: 0.47 | E4: 1.3397 | F4: 1.9885 | G4: 4.5341 | H4: 0.1912 | I4: 13 | J4: 0.23 | K4: 4 | L4: 2
A5: Platform | B5: 1 | C5: 0 | D5: 0.04 | E5: 0 | F5: 4.1285 | G5: 4.1285 | H5: 4.1285 | I5: 1 | J5: 0 | K5: 0 | L5: 0
A6: Platform | B6: 1 | C6: 0 | D6: 0.54 | E6: 0.0395 | F6: 8.6863 | G6: 8.7369 | H6: 8.5709 | I6: 16 | J6: 0.13 | K6: 0 | L6: 0
A7: DEATH
A8: Platform | B8: 0 | C8: 0 | D8: 2.99 | E8: 0.6087 | F8: 1.2153 | G8: 1.8974 | H8: 0.5379 | I8: 86 | J8: 0.04 | K8: 0 | L8: 2
A9: Platform | B9: 0 | C9: 0 | D9: 0.03 | E9: 0 | F9: 4.9495 | G9: 4.9495 | H9: 4.9495 | I9: 1 | J9: 0 | K9: 0 | L9: 0
A10: Platform | B10: 0 | C10: 0 | D10: 0.45 | E10: 0.034 | F10: 4.7298 | G10: 4.7785 | H10: 4.6653 | I10: 15 | J10: 0.11 | K10: 0 | L10: 3
A11: DEATH
A12: Platform | B12: 0 | C12: 0 | D12: 3.59 | E12: 0.116 | F12: 1.0333 | G12: 1.2983 | H12: 0.449 | I12: 102 | J12: 0.21 | K12: 0 | L12: 2
A13: Platform | B13: 0 | C13: 0 | D13: 0.03 | E13: 0 | F13: 0.7249 | G13: 0.7249 | H13: 0.7249 | I13: 1 | J13: 0 | K13: 0 | L13: 0
A14: Platform | B14: 0 | C14: 0 | D14: 0.94 | E14: 1.4831 | F14: 2.4427 | G14: 4.7929 | H14: 0.3839 | I14: 31 | J14: 0.13 | K14: 0 | L14: 2
A15: Platform | B15: 1 | C15: 0 | D15: 0.05 | E15: 0 | F15: 5.1898 | G15: 5.1898 | H15: 5.1898 | I15: 1 | J15: 0 | K15: 0 | L15: 0
A16: Platform | B16: 1 | C16: 0 | D16: 0.26 | E16: 0.0183 | F16: 5.2112 | G16: 5.2287 | H16: 5.1704 | I16: 8 | J16: 0 | K16: 0 | L16: 0
A17: Platform | B17: 0 | C17: 0 | D17: 0.07 | E17: 0.1172 | F17: 4.6505 | G17: 4.7677 | H17: 4.5334 | I17: 2 | J17: 0 | K17: 0 | L17: 1
A18: Platform | B18: 0 | C18: 0 | D18: 0.11 | E18: 0.1208 | F18: 4.2782 | G18: 4.4463 | H18: 4.1676 | I18: 3 | J18: 0 | K18: 0 | L18: 2
A19: Platform | B19: 0 | C19: 0 | D19: 0.13 | E19: 0.0063 | F19: 4.4008 | G19: 4.4074 | H19: 4.3924 | I19: 3 | J19: 0 | K19: 0 | L19: 0
A20: DEATH
A21: Platform | B21: 0 | C21: 0 | D21: 3.25 | E21: 0.5369 | F21: 1.8071 | G21: 2.8256 | H21: 0.7219 | I21: 92 | J21: 1.25 | K21: 0 | L21: 3
A22: Platform | B22: 0 | C22: 0 | D22: 1.85 | E22: 0.3468 | F22: 3.834 | G22: 4.454 | H22: 2.7287 | I22: 56 | J22: 0.07 | K22: 1 | L22: 4
A23: Platform | B23: 1 | C23: 0 | D23: 1.51 | E23: 0.5464 | F23: 8.8408 | G23: 9.1253 | H23: 6.9638 | I23: 44 | J23: 0.22 | K23: 0 | L23: 4
A24: Platform | B24: 1 | C24: 0 | D24: 0.03 | E24: 0 | F24: 10.9276 | G24: 10.9276 | H24: 10.9276 | I24: 1 | J24: 0 | K24: 0 | L24: 0
A25: Platform | B25: 1 | C25: 0 | D25: 0.03 | E25: 0 | F25: 8.4708 | G25: 8.4708 | H25: 8.4708 | I25: 1 | J25: 0 | K25: 0 | L25: 0
A26: Platform | B26: 1 | C26: 0 | D26: 0.03 | E26: 0 | F26: 8.1998 | G26: 8.1998 | H26: 8.1998 | I26: 1 | J26: 0 | K26: 0 | L26: 0
A27: Platform | B27: 1 | C27: 0 | D27: 0.03 | E27: 0 | F27: 6.6586 | G27: 6.6586 | H27: 6.6586 | I27: 1 | J27: 0 | K27: 0 | L27: 0
A28: DEATH
A29: Platform | B29: 0 | C29: 0 | D29: 3.39 | E29: 0.0309 | F29: 1.1745 | G29: 1.2344 | H29: 1.0341 | I29: 94 | J29: 0.23 | K29: 0 | L29: 7
A30: Platform | B30: 0 | C30: 0 | D30: 2.34 | E30: 0.6534 | F30: 1.3796 | G30: 4.4458 | H30: 0.508 | I30: 69 | J30: 0.36 | K30: 0 | L30: 4
A31: Platform | B31: 1 | C31: 0 | D31: 0.11 | E31: 0.0339 | F31: 5.0931 | G31: 5.1394 | H31: 5.0593 | I31: 3 | J31: 0 | K31: 0 | L31: 0
A32: Platform | B32: 1 | C32: 0 | D32: 0.9 | E32: 0.2279 | F32: 8.6051 | G32: 9.3646 | H32: 8.4561 | I32: 26 | J32: 0 | K32: 0 | L32: 1
A33: Platform | B33: 1 | C33: 0 | D33: 0.07 | E33: 0.1457 | F33: 10.1738 | G33: 10.3195 | H33: 10.028 | I33: 2 | J33: 0 | K33: 0 | L33: 0
A34: Platform | B34: 1 | C34: 0 | D34: 0.03 | E34: 0 | F34: 10.7735 | G34: 10.7735 | H34: 10.7735 | I34: 1 | J34: 0 | K34: 0 | L34: 0
A35: Platform | B35: 1 | C35: 0 | D35: 0.03 | E35: 0 | F35: 10.9338 | G35: 10.9338 | H35: 10.9338 | I35: 1 | J35: 0 | K35: 0 | L35: 0
A36: DEATH
A37: Platform | B37: 0 | C37: 0 | D37: 3.28 | E37: 0.1471 | F37: 0.878 | G37: 1.1027 | H37: 0.626 | I37: 93 | J37: 0 | K37: 0 | L37: 2
A38: Platform | B38: 0 | C38: 0 | D38: 2.41 | E38: 0.6115 | F38: 2.1231 | G38: 4.3488 | H38: 1.5537 | I38: 72 | J38: 0.17 | K38: 0 | L38: 2
A39: Platform | B39: 1 | C39: 0 | D39: 0.04 | E39: 0 | F39: 4.4051 | G39: 4.4051 | H39: 4.4051 | I39: 1 | J39: 0 | K39: 0 | L39: 0
A40: Platform | B40: 1 | C40: 0 | D40: 1.68 | E40: 0.4328 | F40: 5.9988 | G40: 6.2476 | H40: 4.4897 | I40: 49 | J40: 0.28 | K40: 0 | L40: 0
...

Sheet adap_SofiaVidal
A1: EventType | B1: SegmentID | C1: ElementID | D1: TimeOnPlatform | E1: RelativePositionStd | F1: RelativePositionMean | G1: RelativePositionMax | H1: RelativePositionMin | I1: SampleCount | J1: EdgeRiskTime | K1: CorrectionPeaks | L1: ObstacleType | M1: ClearType | N1: MinClearance | O1: MicroCorrections | P1: ObstacleDuration
A2: DEATH
A3: DEATH
A4: DEATH
A5: DEATH
A6: DEATH
A7: DEATH
A8: DEATH
A9: DEATH
A10: DEATH
A11: DEATH
A12: DEATH
A13: DEATH
... A49: DEATH
A50: Platform | B50: 0 | C50: 0 | D50: 0.04 | E50: 0.02 | F50: 5.1169 | G50: 5.1369 | H50: 5.097 | I50: 2 | J50: 0 | K50: 0 | L50: 0
A51: DEATH
A52: Platform | B52: 0 | C52: 0 | D52: 0.03 | E52: 0.0056 | F52: 5.1407 | G52: 5.1463 | H52: 5.1351 | I52: 2 | J52: 0 | K52: 0 | L52: 0
A53: Platform | B53: 0 | C53: 0 | D53: 2.52 | E53: 0.3179 | F53: 1.4711 | G53: 1.9155 | H53: 0.7687 | I53: 148 | J53: 0.18 | K53: 0 | L53: 4
A54: Platform | B54: 0 | C54: 0 | D54: 15.06 | E54: 0.0891 | F54: 1.5725 | G54: 1.7262 | H54: 1.4469 | I54: 876 | J54: 6.58 | K54: 0 | L54: 1
A55: Platform | B55: 0 | C55: 0 | D55: 1.95 | E55: 0.8929 | F55: 1.9362 | G55: 4.9118 | H55: 1.451 | I55: 117 | J55: 0.96 | K55: 0 | L55: 0
A56: DEATH
A57: Platform | B57: 0 | C57: 0 | D57: 1.08 | E57: 0.0206 | F57: 1.799 | G57: 1.8171 | H57: 1.6995 | I57: 64 | J57: 0.1 | K57: 0 | L57: 0
A58: Platform | B58: 0 | C58: 0 | D58: 4.93 | E58: 0.3698 | F58: 1.3636 | G58: 2.8239 | H58: 1.058 | I58: 291 | J58: 0.41 | K58: 0 | L58: 2
A59: Platform | B59: 1 | C59: 0 | D59: 2.07 | E59: 0.2729 | F59: 6.906 | G59: 7.0288 | H59: 5.8108 | I59: 124 | J59: 0.09 | K59: 0 | L59: 1
A60: Platform | B60: 1 | C60: 0 | D60: 4.21 | E60: 0.531 | F60: 6.4944 | G60: 7.4524 | H60: 5.4703 | I60: 248 | J60: 1.52 | K60: 0 | L60: 2
A61: Platform | B61: 2 | C61: 0 | D61: 0.02 | E61: 0 | F61: 4.8435 | G61: 4.8435 | H61: 4.8435 | I61: 1 | J61: 0 | K61: 0 | L61: 0
A62: Platform | B62: 2 | C62: 0 | D62: 2.47 | E62: 0.8734 | F62: 6.0573 | G62: 7.2643 | H62: 4.9097 | I62: 96 | J62: 1.37 | K62: 0 | L62: 0
A63: DEATH
A64: Platform | B64: 2 | C64: 0 | D64: 0.04 | E64: 0.1444 | F64: 5.9302 | G64: 6.0747 | H64: 5.7858 | I64: 2 | J64: 0 | K64: 0 | L64: 0
A65: Platform | B65: 2 | C65: 0 | D65: 2.36 | E65: 0.5772 | F65: 7.1551 | G65: 8.2113 | H65: 6.1257 | I65: 84 | J65: 1.13 | K65: 0 | L65: 1
A66: Platform | B66: 2 | C66: 0 | D66: 1.2 | E66: 0.499 | F66: 7.4073 | G66: 7.9632 | H66: 6.7376 | I66: 41 | J66: 0.91 | K66: 0 | L66: 2
A67: Platform | B67: 2 | C67: 0 | D67: 1.22 | E67: 1.7073 | F67: 6.344 | G67: 10.5133 | H67: 5.0577 | I67: 43 | J67: 0.65 | K67: 0 | L67: 2
A68: DEATH
A69: Platform | B69: 2 | C69: 0 | D69: 0.02 | E69: 0 | F69: 7.6474 | G69: 7.6474 | H69: 7.6474 | I69: 1 | J69: 0 | K69: 0 | L69: 0
A70: Platform | B70: 2 | C70: 0 | D70: 2.41 | E70: 0.81 | F70: 9.0716 | G70: 11.1108 | H70: 7.9582 | I70: 84 | J70: 1.67 | K70: 0 | L70: 0
A71: Platform | B71: 2 | C71: 0 | D71: 0.03 | E71: 0 | F71: 11.9922 | G71: 11.9922 | H71: 11.9922 | I71: 1 | J71: 0 | K71: 0 | L71: 0
A72: DEATH
A73: Platform | B73: 2 | C73: 0 | D73: 0.02 | E73: 0 | F73: 7.1166 | G73: 7.1166 | H73: 7.1166 | I73: 1 | J73: 0 | K73: 0 | L73: 0
A74: Platform | B74: 2 | C74: 0 | D74: 2.13 | E74: 0.374 | F74: 8.3464 | G74: 8.5725 | H74: 7.166 | I74: 75 | J74: 0.57 | K74: 0 | L74: 0
A75: Platform | B75: 2 | C75: 0 | D75: 1.86 | E75: 0.0131 | F75: 8.5068 | G75: 8.5555 | H75: 8.4769 | I75: 63 | J75: 0.09 | K75: 0 | L75: 1
...

Sheet adap_VicenteOlguin
A1: EventType | B1: SegmentID | C1: ElementID | D1: TimeOnPlatform | E1: RelativePositionStd | F1: RelativePositionMean | G1: RelativePositionMax | H1: RelativePositionMin | I1: SampleCount | J1: EdgeRiskTime | K1: CorrectionPeaks | L1: ObstacleType | M1: ClearType | N1: MinClearance | O1: MicroCorrections | P1: ObstacleDuration
A2: DEATH
A3: DEATH
A4: DEATH
A5: DEATH
A6: DEATH
A7: DEATH
A8: DEATH
A9: DEATH
A10: DEATH
A11: Platform | B11: 0 | C11: 0 | D11: 2.05 | E11: 0.4971 | F11: 1.4318 | G11: 3.1503 | H11: 0.7671 | I11: 117 | J11: 0.32 | K11: 0 | L11: 3
A12: Platform | B12: 0 | C12: 0 | D12: 4.24 | E12: 0.5806 | F12: 1.0692 | G12: 1.9478 | H12: 0.1458 | I12: 248 | J12: 1.38 | K12: 0 | L12: 4
A13: Platform | B13: 1 | C13: 0 | D13: 0.02 | E13: 0 | F13: 4.5495 | G13: 4.5495 | H13: 4.5495 | I13: 1 | J13: 0 | K13: 0 | L13: 0
A14: Platform | B14: 1 | C14: 0 | D14: 0.1 | E14: 0.3417 | F14: 9.4532 | G14: 9.9469 | H14: 8.9564 | I14: 6 | J14: 0.02 | K14: 0 | L14: 0
A15: Platform | B15: 2 | C15: 0 | D15: 2.8 | E15: 1.0139 | F15: 6.1172 | G15: 7.5668 | H15: 4.2745 | I15: 85 | J15: 0.44 | K15: 0 | L15: 2
A16: Platform | B16: 2 | C16: 0 | D16: 0.87 | E16: 0.5088 | F16: 8.0209 | G16: 8.5589 | H16: 6.9339 | I16: 26 | J16: 0 | K16: 0 | L16: 1
A17: DEATH
A18: Platform | B18: 2 | C18: 0 | D18: 0.07 | E18: 0.1034 | F18: 5.5503 | G18: 5.6537 | H18: 5.4468 | I18: 2 | J18: 0 | K18: 0 | L18: 1
A19: Platform | B19: 2 | C19: 0 | D19: 1.1 | E19: 0.3453 | F19: 5.7022 | G19: 6.093 | H19: 5.0714 | I19: 36 | J19: 0.78 | K19: 0 | L19: 4
A20: Platform | B20: 2 | C20: 0 | D20: 1.98 | E20: 0.3382 | F20: 5.8462 | G20: 6.1775 | H20: 5.2019 | I20: 68 | J20: 0.46 | K20: 0 | L20: 2
A21: Platform | B21: 2 | C21: 0 | D21: 0.88 | E21: 0.1508 | F21: 6.6157 | G21: 6.8306 | H21: 6.2943 | I21: 41 | J21: 0.31 | K21: 0 | L21: 1
A22: Platform | B22: 2 | C22: 0 | D22: 2.37 | E22: 0.3083 | F22: 5.8158 | G22: 6.4766 | H22: 5.4221 | I22: 99 | J22: 0.44 | K22: 0 | L22: 4
A23: Platform | B23: 2 | C23: 0 | D23: 2.11 | E23: 0.3458 | F23: 5.2512 | G23: 6.0599 | H23: 4.8986 | I23: 69 | J23: 0.26 | K23: 0 | L23: 4
A24: Platform | B24: 2 | C24: 0 | D24: 0.06 | E24: 0.0718 | F24: 4.2976 | G24: 4.3859 | H24: 4.2099 | I24: 3 | J24: 0 | K24: 0 | L24: 1
A25: DEATH

Sheet adap_VicenteQuintana
A1: EventType | B1: SegmentID | C1: ElementID | D1: TimeOnPlatform | E1: RelativePositionStd | F1: RelativePositionMean | G1: RelativePositionMax | H1: RelativePositionMin | I1: SampleCount | J1: EdgeRiskTime | K1: CorrectionPeaks | L1: RawCorrectionsCount | M1: Unnamed: 12 | N1: ExtraCol_13 | O1: ExtraCol_14 | P1: ExtraCol_15
A2: Platform | B2: 0 | C2: 0 | D2: 0.04 | E2: 0 | F2: 4.8294 | G2: 4.8294 | H2: 4.8294 | I2: 1 | J2: 0 | K2: 0 | L2: 0
A3: Platform | B3: 0 | C3: 0 | D3: 1.51 | E3: 0.0742 | F3: 0.7108 | G3: 1.1473 | H3: 0.6775 | I3: 43 | J3: 0 | K3: 0 | L3: 1
A4: Platform | B4: 0 | C4: 0 | D4: 4.84 | E4: 0.4913 | F4: 1.3316 | G4: 2.698 | H4: 0.6676 | I4: 141 | J4: 3.25 | K4: 0 | L4: 0
A5: Platform | B5: 1 | C5: 0 | D5: 0.66 | E5: 1.1333 | F5: 6.4973 | G5: 8.4825 | H5: 4.9113 | I5: 20 | J5: 0 | K5: 0 | L5: 1
A6: Platform | B6: 1 | C6: 0 | D6: 0.86 | E6: 0.313 | F6: 7.6068 | G6: 7.9968 | H6: 7.245 | I6: 26 | J6: 0.03 | K6: 0 | L6: 1
A7: Platform | B7: 1 | C7: 0 | D7: 1.87 | E7: 0.4029 | F7: 7.368 | G7: 8.95 | H7: 6.9974 | I7: 56 | J7: 0.47 | K7: 0 | L7: 4
A8: Platform | B8: 2 | C8: 0 | D8: 0.99 | E8: 0.042 | F8: 7.4177 | G8: 7.5225 | H8: 7.3811 | I8: 16 | J8: 0 | K8: 0 | L8: 3
A9: Platform | B9: 2 | C9: 0 | D9: 2.26 | E9: 0.5065 | F9: 6.9265 | G9: 7.4408 | H9: 5.4339 | I9: 37 | J9: 0 | K9: 0 | L9: 5
A10: Platform | B10: 2 | C10: 0 | D10: 0.28 | E10: 0.1017 | F10: 4.6013 | G10: 4.6835 | H10: 4.4289 | I10: 5 | J10: 0 | K10: 0 | L10: 0
A11: Platform | B11: 2 | C11: 0 | D11: 0.05 | E11: 0 | F11: 3.2781 | G11: 3.2781 | H11: 3.2781 | I11: 1 | J11: 0 | K11: 0 | L11: 0
A12: Platform | B12: 2 | C12: 0 | D12: 1.38 | E12: 0.6541 | F12: 4.3612 | G12: 4.8372 | H12: 2.7728 | I12: 26 | J12: 0.4 | K12: 3 | L12: 2
A13: Platform | B13: 2 | C13: 0 | D13: 2.2 | E13: 0.1062 | F13: 5.0478 | G13: 5.1325 | H13: 4.784 | I13: 42 | J13: 0.49 | K13: 0 | L13: 2
A14: Platform | B14: 2 | C14: 0 | D14: 0.05 | E14: 0 | F14: 3.9983 | G14: 3.9983 | H14: 3.9983 | I14: 1 | J14: 0 | K14: 0 | L14: 0
A15: DEATH
A16: DEATH
A17: DEATH
A18: DEATH
A19: DEATH
A20: DEATH
A21: DEATH
A22: DEATH
A23: DEATH

Sheet adap_VicenteVidal
A1: EventType | B1: SegmentID | C1: ElementID | D1: TimeOnPlatform | E1: RelativePositionStd | F1: RelativePositionMean | G1: RelativePositionMax | H1: RelativePositionMin | I1: SampleCount | J1: EdgeRiskTime | K1: CorrectionPeaks | L1: ObstacleType | M1: ClearType | N1: MinClearance | O1: MicroCorrections | P1: ObstacleDuration
A2: DEATH
A3: DEATH
A4: DEATH
A5: DEATH
A6: DEATH
A7: DEATH
A8: DEATH
A9: DEATH
A10: Platform | B10: 0 | C10: 0 | D10: 0.59 | E10: 0.0704 | F10: 0.9182 | G10: 1.2023 | H10: 0.871 | I10: 35 | J10: 0 | K10: 0 | L10: 1
A11: Platform | B11: 0 | C11: 0 | D11: 5.76 | E11: 0.2428 | F11: 1.4097 | G11: 2.193 | H11: 0.8644 | I11: 345 | J11: 2.95 | K11: 0 | L11: 2
A12: Platform | B12: 1 | C12: 0 | D12: 0.73 | E12: 1.0845 | F12: 7.7296 | G12: 8.637 | H12: 5.635 | I12: 42 | J12: 0.48 | K12: 0 | L12: 0
A13: Platform | B13: 1 | C13: 0 | D13: 2.49 | E13: 0.406 | F13: 8.0897 | G13: 8.9236 | H13: 7.531 | I13: 149 | J13: 0.15 | K13: 0 | L13: 2
A14: Platform | B14: 2 | C14: 0 | D14: 0.04 | E14: 0 | F14: 7.317 | G14: 7.317 | H14: 7.317 | I14: 1 | J14: 0 | K14: 0 | L14: 0
A15: Platform | B15: 2 | C15: 0 | D15: 1.85 | E15: 0.9548 | F15: 6.9847 | G15: 8.8416 | H15: 5.8269 | I15: 50 | J15: 0.35 | K15: 2 | L15: 2
A16: Platform | B16: 2 | C16: 0 | D16: 1.49 | E16: 0.3279 | F16: 8.3801 | G16: 8.8633 | H16: 8.0658 | I16: 48 | J16: 0 | K16: 0 | L16: 1
A17: DEATH
A18: Platform | B18: 2 | C18: 0 | D18: 0.05 | E18: 0.1285 | F18: 3.6246 | G18: 3.753 | H18: 3.4961 | I18: 2 | J18: 0 | K18: 0 | L18: 0
A19: Platform | B19: 2 | C19: 0 | D19: 1.46 | E19: 1.2589 | F19: 5.125 | G19: 6.5356 | H19: 3.5064 | I19: 48 | J19: 1.19 | K19: 0 | L19: 2
A20: Platform | B20: 2 | C20: 0 | D20: 1.7 | E20: 0.3811 | F20: 6.921 | G20: 7.4532 | H20: 6.5158 | I20: 57 | J20: 1.28 | K20: 0 | L20: 0
A21: DEATH
A22: Platform | B22: 2 | C22: 0 | D22: 0.04 | E22: 0 | F22: 4.8516 | G22: 4.8516 | H22: 4.8516 | I22: 1 | J22: 0 | K22: 0 | L22: 0
A23: Platform | B23: 2 | C23: 0 | D23: 1.56 | E23: 0.5449 | F23: 8.0441 | G23: 8.4397 | H23: 5.8833 | I23: 48 | J23: 0.25 | K23: 0 | L23: 1
A24: Platform | B24: 2 | C24: 0 | D24: 2.07 | E24: 0.21 | F24: 7.7234 | G24: 8.1625 | H24: 7.5652 | I24: 71 | J24: 0 | K24: 0 | L24: 2
A25: Platform | B25: 2 | C25: 0 | D25: 0.37 | E25: 0.2865 | F25: 5.2951 | G25: 6.0578 | H25: 5.1031 | I25: 13 | J25: 0.14 | K25: 0 | L25: 2
A26: Platform | B26: 2 | C26: 0 | D26: 3.02 | E26: 0.1174 | F26: 6.3552 | G26: 6.4684 | H26: 6.1742 | I26: 105 | J26: 0.03 | K26: 0 | L26: 0
A27: Platform | B27: 2 | C27: 0 | D27: 1.72 | E27: 0.4015 | F27: 5.1326 | G27: 6.4461 | H27: 4.9386 | I27: 62 | J27: 0 | K27: 0 | L27: 2
A28: Platform | B28: 2 | C28: 0 | D28: 0.56 | E28: 0.1582 | F28: 4.8087 | G28: 5.1555 | H28: 4.3993 | I28: 22 | J28: 0 | K28: 0 | L28: 1
A29: DEATH
A30: DEATH
A31: DEATH

Sheet adap_yo
A1: EventType | B1: SegmentID | C1: ElementID | D1: TimeOnPlatform | E1: RelativePositionStd | F1: RelativePositionMean | G1: RelativePositionMax | H1: RelativePositionMin | I1: SampleCount | J1: EdgeRiskTime | K1: CorrectionPeaks | L1: ObstacleType | M1: ClearType | N1: MinClearance | O1: MicroCorrections | P1: ObstacleDuration
A2: DEATH
A3: Platform | B3: 0 | C3: 0 | D3: 0.69 | E3: 0.4017 | F3: 1.1469 | G3: 2.0018 | H3: 0.8196 | I3: 48 | J3: 0.19 | K3: 0 | L3: 2
A4: Platform | B4: 0 | C4: 0 | D4: 3.8 | E4: 0.3996 | F4: 2.1367 | G4: 4.7511 | H4: 1.964 | I4: 263 | J4: 1.77 | K4: 0 | L4: 2
A5: Platform | B5: 1 | C5: 0 | D5: 0.33 | E5: 1.0052 | F5: 7.8194 | G5: 9.5198 | H5: 6.176 | I5: 23 | J5: 0.25 | K5: 0 | L5: 0
A6: Platform | B6: 1 | C6: 0 | D6: 1.6 | E6: 0.658 | F6: 9.642 | G6: 10.3559 | H6: 8.2123 | I6: 113 | J6: 0.03 | K6: 0 | L6: 1
A7: Platform | B7: 1 | C7: 0 | D7: 1.96 | E7: 0.4623 | F7: 8.0121 | G7: 9.277 | H7: 7.1231 | I7: 137 | J7: 1.18 | K7: 0 | L7: 2
A8: Platform | B8: 2 | C8: 0 | D8: 0.99 | E8: 0.8718 | F8: 6.0512 | G8: 6.8192 | H8: 3.4488 | I8: 35 | J8: 0.31 | K8: 0 | L8: 1
A9: Platform | B9: 2 | C9: 0 | D9: 2.61 | E9: 0.406 | F9: 7.1065 | G9: 7.5222 | H9: 6.3226 | I9: 98 | J9: 2.32 | K9: 0 | L9: 0
A10: Platform | B10: 2 | C10: 0 | D10: 0.18 | E10: 0.2358 | F10: 7.7408 | G10: 7.9458 | H10: 7.2863 | I10: 7 | J10: 0 | K10: 0 | L10: 1
A11: Platform | B11: 2 | C11: 0 | D11: 2.84 | E11: 0.3138 | F11: 6.5757 | G11: 7.0743 | H11: 5.4271 | I11: 108 | J11: 0 | K11: 0 | L11: 1
A12: Platform | B12: 2 | C12: 0 | D12: 1.45 | E12: 0.1877 | F12: 5.5775 | G12: 5.8542 | H12: 5.4084 | I12: 56 | J12: 0.66 | K12: 0 | L12: 0
A13: DEATH
A14: DEATH

Sheet Sheet1
A1: Jugador | B1: TimeOnPlatform | C1: RelativePositionStd | D1: RelativePositionMean | E1: RelativePositionMax | F1: RelativePositionMin | G1: SampleCount | H1: EdgeRiskTime | I1: CorrectionPeaks | J1: RawCorrectionsCount | K1: AbandonoPilar
A2: Jug1 | B2: =AVERAGE(adap_CataAguilar!D:D) -> 1.1695385 | C2: =AVERAGE(adap_CataAguilar!E:E) -> 0.45703538 | D2: =AVERAGE(adap_CataAguilar!F:F) -> 6.0007031 | E2: =AVERAGE(adap_CataAguilar!G:G) -> 6.8204538 | F2: =AVERAGE(adap_CataAguilar!H:H) -> 5.0950892 | G2: =AVERAGE(adap_CataAguilar!I:I) -> 49.430769 | H2: =AVERAGE(adap_CataAguilar!J:J) -> 0.36276923 | I2: =AVERAGE(adap_CataAguilar!K:K) -> 0.076923077 | J2: =AVERAGE(adap_CataAguilar!L:L) -> 0.75384615 | K2: 3
A3: Jug2 | B3: =AVERAGE(adap_GonzaloCampos!D:D) -> 1.0653571 | C3: =AVERAGE(adap_GonzaloCampos!E:E) -> 0.40071786 | D3: =AVERAGE(adap_GonzaloCampos!F:F) -> 5.3316679 | E3: =AVERAGE(adap_GonzaloCampos!G:G) -> 6.3102929 | F3: =AVERAGE(adap_GonzaloCampos!H:H) -> 4.7240643 | G3: =AVERAGE(adap_GonzaloCampos!I:I) -> 50.642857 | H3: =AVERAGE(adap_GonzaloCampos!J:J) -> 0.17392857 | I3: =AVERAGE(adap_GonzaloCampos!K:K) -> 0.035714286 | J3: =AVERAGE(adap_GonzaloCampos!L:L) -> 1.6785714 | K3: 4
A4: Jug3 | B4: =AVERAGE(adap_IgnaciaDelgado!D:D) -> 1.1989474 | C4: =AVERAGE(adap_IgnaciaDelgado!E:E) -> 0.47051579 | D4: =AVERAGE(adap_IgnaciaDelgado!F:F) -> 6.7117632 | E4: =AVERAGE(adap_IgnaciaDelgado!G:G) -> 7.4726895 | F4: =AVERAGE(adap_IgnaciaDelgado!H:H) -> 5.9463105 | G4: =AVERAGE(adap_IgnaciaDelgado!I:I) -> 45.631579 | H4: =AVERAGE(adap_IgnaciaDelgado!J:J) -> 0.42842105 | I4: =AVERAGE(adap_IgnaciaDelgado!K:K) -> 0 | J4: =AVERAGE(adap_IgnaciaDelgado!L:L) -> 1.4210526 | K4: 5
A5: Jug4 | B5: =AVERAGE(adap_IsidoraToledo!D:D) -> 0.6488 | C5: =AVERAGE(adap_IsidoraToledo!E:E) -> 0.152944 | D5: =AVERAGE(adap_IsidoraToledo!F:F) -> 8.968202 | E5: =AVERAGE(adap_IsidoraToledo!G:G) -> 9.222746 | F5: =AVERAGE(adap_IsidoraToledo!H:H) -> 8.712649 | G5: =AVERAGE(adap_IsidoraToledo!I:I) -> 13.81 | H5: =AVERAGE(adap_IsidoraToledo!J:J) -> 0.1448 | I5: =AVERAGE(adap_IsidoraToledo!K:K) -> 0.18 | J5: =AVERAGE(adap_IsidoraToledo!L:L) -> 2.79 | K5: 6
A6: Jug5 | B6: =AVERAGE(adap_JavierSalinas!D:D) -> 1.0531579 | C6: =AVERAGE(adap_JavierSalinas!E:E) -> 0.30139649 | D6: =AVERAGE(adap_JavierSalinas!F:F) -> 4.6322614 | E6: =AVERAGE(adap_JavierSalinas!G:G) -> 5.2664333 | F6: =AVERAGE(adap_JavierSalinas!H:H) -> 4.2560035 | G6: =AVERAGE(adap_JavierSalinas!I:I) -> 29.807018 | H6: =AVERAGE(adap_JavierSalinas!J:J) -> 0.11929825 | I6: =AVERAGE(adap_JavierSalinas!K:K) -> 0.33333333 | J6: =AVERAGE(adap_JavierSalinas!L:L) -> 1.3508772 | K6: 7
A7: Jug6 | B7: =AVERAGE(adap_MariannaMaregatti!D:D) -> 1.3449315 | C7: =AVERAGE(adap_MariannaMaregatti!E:E) -> 0.52738082 | D7: =AVERAGE(adap_MariannaMaregatti!F:F) -> 5.965726 | E7: =AVERAGE(adap_MariannaMaregatti!G:G) -> 6.8759959 | F7: =AVERAGE(adap_MariannaMaregatti!H:H) -> 5.1996767 | G7: =AVERAGE(adap_MariannaMaregatti!I:I) -> 26.219178 | H7: =AVERAGE(adap_MariannaMaregatti!J:J) -> 0.56246575 | I7: =AVERAGE(adap_MariannaMaregatti!K:K) -> 1.2465753 | J7: =AVERAGE(adap_MariannaMaregatti!L:L) -> 1.6575342 | K7: 8
A8: Jug7 | B8: =AVERAGE(adap_SebastianRatto!D:D) -> 1.1125 | C8: =AVERAGE(adap_SebastianRatto!E:E) -> 0.34543462 | D8: =AVERAGE(adap_SebastianRatto!F:F) -> 6.1267288 | E8: =AVERAGE(adap_SebastianRatto!G:G) -> 6.7447596 | F8: =AVERAGE(adap_SebastianRatto!H:H) -> 5.5919865 | G8: =AVERAGE(adap_SebastianRatto!I:I) -> 27.076923 | H8: =AVERAGE(adap_SebastianRatto!J:J) -> 0.23307692 | I8: =AVERAGE(adap_SebastianRatto!K:K) -> 0.53846154 | J8: =AVERAGE(adap_SebastianRatto!L:L) -> 1.3269231 | K8: 9
A9: Jug8 | B9: =AVERAGE(adap_SofiaVidal!D:D) -> 1.9278571 | C9: =AVERAGE(adap_SofiaVidal!E:E) -> 0.30868929 | D9: =AVERAGE(adap_SofiaVidal!F:F) -> 5.8572357 | E9: =AVERAGE(adap_SofiaVidal!G:G) -> 6.4839286 | F9: =AVERAGE(adap_SofiaVidal!H:H) -> 5.4197143 | G9: =AVERAGE(adap_SofiaVidal!I:I) -> 94.75 | H9: =AVERAGE(adap_SofiaVidal!J:J) -> 0.68142857 | I9: =AVERAGE(adap_SofiaVidal!K:K) -> 0 | J9: =AVERAGE(adap_SofiaVidal!L:L) -> 0.71428571 | K9: 10
A10: Jug9 | B10: =AVERAGE(adap_VicenteOlguin!D:D) -> 1.4346154 | C10: =AVERAGE(adap_VicenteOlguin!E:E) -> 0.35428462 | D10: =AVERAGE(adap_VicenteOlguin!F:F) -> 5.3631385 | E10: =AVERAGE(adap_VicenteOlguin!G:G) -> 5.9536462 | F10: =AVERAGE(adap_VicenteOlguin!H:H) -> 4.7824769 | G10: =AVERAGE(adap_VicenteOlguin!I:I) -> 61.615385 | H10: =AVERAGE(adap_VicenteOlguin!J:J) -> 0.33923077 | I10: =AVERAGE(adap_VicenteOlguin!K:K) -> 0 | J10: =AVERAGE(adap_VicenteOlguin!L:L) -> 2.0769231 | K10: 11
A11: Jug10 | B11: =AVERAGE(adap_VicenteQuintana!D:D) -> 1.3069231 | C11: =AVERAGE(adap_VicenteQuintana!E:E) -> 0.29424615 | D11: =AVERAGE(adap_VicenteQuintana!F:F) -> 4.9211385 | E11: =AVERAGE(adap_VicenteQuintana!G:G) -> 5.4613 | F11: =AVERAGE(adap_VicenteQuintana!H:H) -> 4.4157923 | G11: =AVERAGE(adap_VicenteQuintana!I:I) -> 31.923077 | H11: =AVERAGE(adap_VicenteQuintana!J:J) -> 0.35692308 | I11: =AVERAGE(adap_VicenteQuintana!K:K) -> 0.23076923 | J11: =AVERAGE(adap_VicenteQuintana!L:L) -> 1.4615385 | K11: 12
A12: Jug11 | B12: =AVERAGE(adap_VicenteVidal!D:D) -> 1.5 | C12: =AVERAGE(adap_VicenteVidal!E:E) -> 0.38667059 | D12: =AVERAGE(adap_VicenteVidal!F:F) -> 5.8064882 | E12: =AVERAGE(adap_VicenteVidal!G:G) -> 6.4294824 | F12: =AVERAGE(adap_VicenteVidal!H:H) -> 5.2085118 | G12: =AVERAGE(adap_VicenteVidal!I:I) -> 64.647059 | H12: =AVERAGE(adap_VicenteVidal!J:J) -> 0.40117647 | I12: =AVERAGE(adap_VicenteVidal!K:K) -> 0.11764706 | J12: =AVERAGE(adap_VicenteVidal!L:L) -> 1.0588235 | K12: 13
A13: Jug12 | B13: =AVERAGE(adap_yo!D:D) -> 1.645 | C13: =AVERAGE(adap_yo!E:E) -> 0.49419 | D13: =AVERAGE(adap_yo!F:F) -> 6.18088 | E13: =AVERAGE(adap_yo!G:G) -> 7.11213 | F13: =AVERAGE(adap_yo!H:H) -> 5.21882 | G13: =AVERAGE(adap_yo!I:I) -> 88.8 | H13: =AVERAGE(adap_yo!J:J) -> 0.671 | I13: =AVERAGE(adap_yo!K:K) -> 0 | J13: =AVERAGE(adap_yo!L:L) -> 1 | K13: 14
